Workbook

Sheet ProcComm
B1: ~FI_Process | J1: MovedToSysSettings
B2: Sets | C2: TechName | D2: TechDesc | E2: Tact | F2: Tcap | G2: Tslvl | H2: PrimaryCG | J2: Csets | K2: CommName | L2: CommDesc | M2: Unit | N2: LimType | O2: CTSLvl | P2: PeakTS | Q2: Ctype
B3: PRE | C3: SUPELC00 | D3: Fuel Tech - Electricity (SUP) | E3: PJ | F3: PJa | G3: DAYNITE | J3: NRG | K3: BIODRY | L3: Dry Bio waste | M3: PJ
C4: SUPHTH00 | D4: Fuel Tech - High Temperature Heat (SUP) | E4: PJ | F4: PJa | G4: SEASON | J4: NRG | K4: BIOGAS | L4: Biogas | M4: PJ
B5: MIN | C5: MINCOHRSV1 | D5: Hard Coal - Located reserves - Step 1 | E5: PJ | G5: ANNUAL | J5: NRG | K5: BIOLIQ | L5: Biofuels | M5: PJ
B6: MIN | C6: MINCOHRSV2 | D6: Hard Coal - Reserves growth - Step 1 | E6: PJ | G6: ANNUAL | J6: NRG | K6: BIOMUN | L6: Municipal Waste | M6: PJ
B7: MIN | C7: MINCOHRSV3 | D7: Hard Coal - New discovery | E7: PJ | G7: ANNUAL | J7: NRG | K7: BIOSLU | L7: Industrial Waste-Sludge | M7: PJ
B8: MIN | C8: MINCOLRSV1 | D8: Lignite - Located reserves - Step 1 | E8: PJ | G8: ANNUAL | J8: NRG | K8: BIOWOO | L8: Wood Products | M8: PJ
B9: MIN | C9: MINCOLRSV2 | D9: Lignite - Reserves growth - Step 1 | E9: PJ | G9: ANNUAL | J9: NRG | K9: COABRO | L9: Brown Coal | M9: PJ
B10: MIN | C10: MINCOLRSV3 | D10: Lignite - New discovery | E10: PJ | G10: ANNUAL | J10: NRG | K10: COACOK | L10: Coke | M10: PJ
B11: MIN | C11: MINCOOFRE1 | D11: Source Free cooling agent | E11: t | G11: ANNUAL | J11: NRG | K11: COAHAR | L11: Hard Coal | M11: PJ
B12: MIN | C12: MINGASRSV1 | D12: Natural gas - Located reserves - Step 1 | E12: PJ | G12: SEASON | J12: NRG | K12: COALIG | L12: Lignite | M12: PJ
B13: MIN | C13: MINGASRSV4 | D13: Natural gas - Reserves growth - Step 1 | E13: PJ | G13: SEASON | J13: NRG | K13: COHRSV | L13: Hard Coal Reserves | M13: PJ
B14: MIN | C14: MINGASRSV7 | D14: Natural gas - New discovery - Step 1 | E14: PJ | G14: SEASON | J14: NRG | K14: COLRSV | L14: Lignite Reserves | M14: PJ
B15: MIN | C15: MINMALBAU1 | D15: Source Aluminium: Bauxite | E15: t | G15: ANNUAL | J15: NRG | K15: GASBFG | L15: Blast-Furnace Gas | M15: PJ
B16: MIN | C16: MINMALSCR1 | D16: Source Aluminium: Scrap | E16: t | G16: ANNUAL | J16: NRG | K16: GASCOG | L16: Coke-Oven Gas | M16: PJ
B17: MIN | C17: MINMCUORE1 | D17: Source Copper: Ore | E17: t | G17: ANNUAL | J17: NRG | K17: GASGWG | L17: Gasworks Gas | M17: PJ
B18: MIN | C18: MINMCUSCR1 | D18: Source Copper: Scrap | E18: t | G18: ANNUAL | J18: NRG | K18: GASNAT | L18: Natural Gas | M18: PJ | O18: SEASON
B19: MIN | C19: MINMGHRYC1 | D19: Source Glass: Recycled | E19: t | G19: ANNUAL | J19: NRG | K19: GASPIP | L19: Natural Gas Pre-Pipeline | M19: PJ | O19: SEASON
B20: MIN | C20: MINMPPGYP1 | D20: Source Paper: Gypsum | E20: t | G20: ANNUAL | J20: NRG | K20: GASRSV | L20: Natural Gas Reserves | M20: PJ | O20: SEASON
B21: MIN | C21: MINMPPKAO1 | D21: Source Paper: Kaolin | E21: t | G21: ANNUAL | J21: NRG | K21: OILCRD | L21: Crude Oil | M21: PJ
B22: MIN | C22: MINMPPNOH1 | D22: Source Paper: Sodium Hydraxide | E22: t | G22: ANNUAL | J22: NRG | K22: OILDST | L22: Diesel | M22: PJ
B23: MIN | C23: MINMPPOXY1 | D23: Source Paper: Oxygen | E23: t | G23: ANNUAL | J23: NRG | K23: OILFDS | L23: Feedstocks | M23: PJ
B24: MIN | C24: MINMPPRYC1 | D24: Source Paper: Recycled | E24: t | G24: ANNUAL | J24: NRG | K24: OILGSL | L24: Motor Spirit | M24: PJ
B25: MIN | C25: MINMPPWOO1 | D25: Source Paper: Wood | E25: t | G25: ANNUAL | J25: NRG | K25: OILHFO | L25: Residual Fuel Oil | M25: PJ
B26: MIN | C26: MINOILRSV1 | D26: Crude Oil - Located reserves - Step 1 | E26: PJ | G26: ANNUAL | J26: NRG | K26: OILKER | L26: Kerosenes - Jet Fuels | M26: PJ
B27: MIN | C27: MINOILRSV2 | D27: Crude Oil - Located reserves - Step 2 | E27: PJ | G27: ANNUAL | J27: NRG | K27: OILLPG | L27: Liquified Petroleum Gas | M27: PJ
B28: MIN | C28: MINOILRSV4 | D28: Crude Oil - Reserves growth - Step 1 | E28: PJ | G28: ANNUAL | J28: NRG | K28: OILNAP | L28: Naphtha | M28: PJ
B29: MIN | C29: MINOILRSV7 | D29: Crude Oil - New discovery - Step 1 | E29: PJ | G29: ANNUAL | J29: NRG | K29: OILNEU | L29: Non Energy | M29: PJ
B30: MIN | C30: MINRENGEO1 | D30: Geothermal Potential | E30: PJ | G30: ANNUAL | J30: NRG | K30: OILOTH | L30: Other Petroleum Products | M30: PJ
B31: MIN | C31: MINRENHYD1 | D31: Hydro Potential | E31: PJ | G31: ANNUAL | J31: NRG | K31: OILPIP | L31: Crude Oil Pre-Pipeline | M31: PJ
B32: MIN | C32: MINRENSOL1 | D32: Solar Potential | E32: PJ | G32: ANNUAL | J32: NRG | K32: OILRFG | L32: Refinery Gas | M32: PJ
B33: MIN | C33: MINRENWIN1 | D33: Wind Potential | E33: PJ | G33: ANNUAL | J33: NRG | K33: OILRSV | L33: Crude Oil Reserves | M33: PJ
B34: PRE | C34: SUPCRD00 | D34: Fuel Tech - Crude Oil (SUP) | E34: PJ | F34: PJa | G34: ANNUAL | J34: NRG | K34: RENGEO | L34: Geothermal | M34: PJ
B35: PRE | C35: SUPGAS00 | D35: Fuel Tech - Natural Gas (SUP) | E35: PJ | F35: PJa | G35: SEASON | J35: NRG | K35: RENHYD | L35: Hydro | M35: PJ
B36: PRE | C36: SUPRPG00 | D36: Fuel Tech - Refinery Gas and LPG (SUP) | E36: PJ | F36: PJa | G36: ANNUAL | J36: NRG | K36: RENSOL | L36: Solar | M36: PJ
B37: PRE | C37: SUPRPP00 | D37: Fuel Tech - Refined Petroleum Products (SUP) | E37: PJ | F37: PJa | G37: ANNUAL | J37: NRG | K37: RENWIN | L37: Wind | M37: PJ
B38: PRE | C38: SPIPGAS100 | D38: Gas Pipelines | E38: PJ | F38: PJa | G38: SEASON | J38: NRG | K38: SUPBIO | L38: Biomass (SUP) | M38: PJ
B39: PRE | C39: SPIPOIL100 | D39: Oil Pipelines | E39: PJ | F39: PJa | G39: ANNUAL | J39: NRG | K39: SUPCOA | L39: Coal (SUP) | M39: PJ
B40: PRE | C40: SPRICOH100 | D40: Hardcoal Production | E40: PJ | F40: PJa | G40: ANNUAL | J40: NRG | K40: SUPCRD | L40: Crude Oil (SUP) | M40: PJ
...

Sheet Reserves
G2: ~FI_T
C3: TechName | D3: Attribute | E3: LimType | F3: CommName | G3: Year | H3: AL | I3: AT | J3: BA | K3: BE | L3: BG | M3: CH | N3: CY | O3: CZ | P3: DE | Q3: DK | R3: EE | S3: ES | T3: FI | U3: FR | V3: EL | W3: HR | X3: HU | Y3: IE | Z3: IS | AA3: IT | AB3: KS | AC3: LT | AD3: LU | AE3: LV | AF3: ME | AG3: MK | AH3: MT | AI3: NL | AJ3: NO | AK3: PL | AL3: PT | AM3: RO | AN3: RS | AO3: SE | AP3: SI | AQ3: SK | AR3: UK
C4: *EXPIALY | D4: BNDACT | E4: LO | G4: 2010 | Z4: 0.3
C5: *EXPIALY | D5: BNDACT | E5: LO | G5: 2050 | Z5: 0.5
C6: MINCOHRSV1 | D6: BNDACT | E6: UP | G6: 2015 | L6: 2.5 | O6: 450 | P6: 1500 | S6: 274 | Z6: 5 | AA6: 2.51208 | AK6: 2478 | AM6: 100 | AN6: 52 | AP6: 33.72 | AR6: 800
C7: MINCOHRSV1 | D7: BNDACT | E7: UP | G7: 2050 | L7: 10 | O7: 400 | S7: 274 | Z7: 5 | AA7: 2.51208 | AK7: 2500 | AM7: 100 | AN7: 78 | AP7: 0 | AR7: 1600
C8: MINCOHRSV1 | D8: CUM | E8: UP | G8: 2005 | L8: 3000 | O8: 2677.5 | P8: 630200 | S8: 21035.732 | U8: 598 | X8: 5968.314 | AA8: 1686 | AK8: 261168.39 | AM8: 11383.812 | AN8: 5200 | AP8: 1124 | AR8: 4950
C9: MINCOHRSV1 | D9: COST | F9: COHRSV | G9: 2005 | L9: 1.4 | O9: 1.2 | P9: 1.4 | S9: 1.4 | U9: 2.64495 | X9: 2.64495 | Z9: 1.2 | AA9: 1.4 | AK9: 1.2 | AM9: 1.2 | AN9: 1.4 | AP9: 1.4 | AR9: 1.3
C10: MINCOHRSV1 | D10: COST | F10: COHRSV | G10: 2050 | L10: 2.3 | O10: 1.5955 | P10: 2.3 | S10: 2.3 | U10: 2.64495 | Z10: 1.2 | AA10: 2.3 | AK10: 1.5955 | AM10: 1.5955 | AN10: 2.3 | AP10: 2.3 | AR10: 1.43
C11: MINCOHRSV2 | D11: BNDACT | E11: UP | G11: 2015 | O11: 50 | AA11: 0 | AJ11: 25 | AM11: 50 | AP11: 48.051 | AR11: 387.9
C12: MINCOHRSV2 | D12: BNDACT | E12: UP | G12: 2050 | O12: 50 | AA12: 0 | AJ12: 25 | AM12: 50 | AP12: 50.45355 | AR12: 775.8
C13: MINCOHRSV2 | D13: CUM | E13: UP | G13: 2005 | O13: 319792.5 | P13: 6302000 | S13: 82232.243 | AA13: 7868 | AJ13: 99999 | AK13: 2436393 | AM13: 13316.644 | AP13: 1601.7 | AR13: 45000
C14: MINCOHRSV2 | D14: COST | F14: COHRSV | G14: 2005 | O14: 1.4 | P14: 2.64495 | S14: 2.1 | AA14: 2.64495 | AJ14: 1.2 | AK14: 1.4 | AM14: 1.2 | AP14: 2.64495 | AR14: 1.2
C15: MINCOHRSV2 | D15: COST | F15: COHRSV | G15: 2050 | O15: 2.3 | P15: 2.64495 | S15: 3.45 | AA15: 2.64495 | AJ15: 1.5955 | AK15: 2.3 | AM15: 1.5955 | AP15: 2.64495 | AR15: 1.5955
C16: MINCOHRSV3 | D16: BNDACT | E16: UP | G16: 2015 | S16: 274 | AA16: 0 | AM16: 50
C17: MINCOHRSV3 | D17: BNDACT | E17: UP | G17: 2050 | AA17: 0 | AM17: 50
C18: MINCOHRSV3 | D18: CUM | E18: UP | G18: 2005 | S18: 0 | AA18: 0 | AM18: 0
C19: MINCOHRSV3 | D19: COST | F19: COHRSV | G19: 2005 | S19: 2.64495 | AA19: 2.64495 | AM19: 1.4
C20: MINCOHRSV3 | D20: COST | F20: COHRSV | G20: 2050 | S20: 2.64495 | AA20: 2.64495 | AM20: 2.3
C21: MINCOLRSV1 | D21: BNDACT | E21: UP | G21: 2015 | H21: 0.921096 | L21: 178 | O21: 480.675 | P21: 1609.9083 | R21: 500 | S21: 96.2926 | T21: 89.136972 | V21: 357.46898 | X21: 73.185264 | Y21: 39 | AA21: 0 | AB21: 56.7 | AC21: 5 | AF21: 22 | AG21: 53.961 | AK21: 533.23085 | AM21: 300 | AN21: 361.15337 | AO21: 43 | AP21: 53.11 | AQ21: 26.669916
C22: MINCOLRSV1 | D22: BNDACT | E22: UP | G22: 2050 | L22: 178 | O22: 550 | P22: 1565 | R22: 500 | S22: 96.2926 | T22: 89.136972 | X22: 219.55579 | Y22: 39 | AA22: 0 | AF22: 33 | AG22: 80.9415 | AK22: 450 | AN22: 541.73005 | AO22: 65 | AQ22: 26.669916
C23: MINCOLRSV1 | D23: CUM | E23: UP | G23: 2005 | H23: 4814.82 | I23: 300 | J23: 33925 | L23: 12917.6 | O23: 5060.25 | P23: 318240 | R23: 5500 | S23: 4157.022 | V23: 12441 | X23: 20982 | Y23: 1960 | AA23: 140.7 | AB23: 2835 | AC23: 49 | AE23: 100 | AF23: 3000 | AG23: 780 | AK23: 16598.2 | AM23: 9548 | AN23: 103500 | AO23: 14400 | AP23: 1243 | AQ23: 1243
C24: MINCOLRSV1 | D24: COST | F24: COLRSV | G24: 2005 | H24: 1.1 | I24: 0.994 | J24: 1.1 | L24: 1.1 | O24: 0.994 | P24: 1.1 | R24: 0.994 | S24: 1.5 | T24: 0.994 | V24: 1.5 | X24: 1.2 | Y24: 0.994 | AA24: 1.1 | AB24: 1.1 | AC24: 0.994 | AE24: 0.994 | AF24: 1.1 | AG24: 1.1 | AK24: 0.994 | AM24: 0.994 | AN24: 1.1 | AO24: 1.1 | AP24: 1.1 | AQ24: 1.1
C25: MINCOLRSV1 | D25: COST | F25: COLRSV | G25: 2050 | H25: 1.34 | I25: 1.2 | J25: 1.34 | L25: 1.4973 | O25: 1.2 | P25: 1.34 | R25: 1.2 | S25: 1.5 | T25: 0.994 | V25: 1.5 | Y25: 1.2 | AA25: 1.34 | AB25: 1.34 | AC25: 1.2 | AE25: 1.2 | AF25: 1.34 | AG25: 1.34 | AK25: 1.2 | AM25: 1.2 | AN25: 1.34 | AO25: 1.34 | AP25: 1.34 | AQ25: 1.34
C26: MINCOLRSV2 | D26: BNDACT | E26: UP | G26: 2015 | O26: 100 | R26: 0 | T26: 25 | V26: 30 | Y26: 0 | AA26: 0 | AK26: 100 | AM26: 100 | AP26: 53.11
C27: MINCOLRSV2 | D27: BNDACT | E27: UP | G27: 2050 | O27: 100 | T27: 25 | V27: 200 | Y27: 0 | AA27: 0 | AK27: 100 | AM27: 100 | AP27: 55.7655
C28: MINCOLRSV2 | D28: CUM | E28: UP | G28: 2005 | J28: 33925 | L28: 24857 | O28: 47970 | P28: 606840 | R28: 500 | S28: 4157.022 | V28: 25636 | X28: 58363.5 | Y28: 2400 | AA28: 442.2 | AK28: 229400 | AM28: 24766 | AP28: 6960.8 | AQ28: 6960.8
C29: MINCOLRSV2 | D29: COST | F29: COLRSV | G29: 2005 | J29: 1.5 | O29: 1.1 | P29: 1.5 | R29: 1.1 | S29: 2.25 | T29: 0.994 | V29: 1.5 | Y29: 0.994 | AA29: 1.5 | AK29: 1.1 | AM29: 1.1 | AP29: 1.4973
C30: MINCOLRSV2 | D30: COST | F30: COLRSV | G30: 2050 | J30: 1.5 | O30: 1.34 | P30: 1.5 | R30: 1.34 | S30: 2.25 | T30: 0.994 | V30: 1.5 | Y30: 1.2 | AA30: 1.5 | AK30: 1.34 | AM30: 1.34 | AP30: 1.4973
C31: MINCOLRSV3 | D31: BNDACT | E31: UP | G31: 2015 | R31: 0 | S31: 50 | T31: 25 | AA31: 0 | AM31: 100
C32: MINCOLRSV3 | D32: BNDACT | E32: UP | G32: 2050 | R32: 75 | T32: 25 | AA32: 0 | AM32: 100
C33: MINCOLRSV3 | D33: CUM | E33: UP | G33: 2005 | R33: 1000 | S33: 0 | AA33: 402 | AM33: 0
C34: MINCOLRSV3 | D34: COST | F34: COLRSV | G34: 2005 | R34: 1.1 | S34: 1.5 | T34: 1.1 | AA34: 1.5 | AM34: 1.1
C35: MINCOLRSV3 | D35: COST | F35: COLRSV | G35: 2050 | R35: 1.34 | S35: 1.5 | T35: 1.34 | AA35: 1.5 | AM35: 1.34
C36: MINCOOFRE1 | D36: BNDACT | E36: UP | G36: 2005 | M36: 0 | R36: 0 | V36: 0 | AA36: 0 | AC36: 0 | AE36: 0 | AM36: 0 | AP36: 0 | AR36: 0
C37: MINCOOFRE1 | D37: BNDACT | E37: UP | G37: 2050 | M37: 0 | AA37: 0 | AM37: 1 | AP37: 0 | AR37: 0
C38: MINCOOFRE1 | D38: COST | F38: COOFRE | G38: 2005 | H38: 0.01 | I38: 0.01 | J38: 0.01 | K38: 0.01 | L38: 0.01 | M38: 0.01 | N38: 0.01 | O38: 0.01 | P38: 0.01 | Q38: 0.01 | R38: 0.01 | S38: 3 | T38: 0.01 | U38: 0.01 | V38: 0.01 | W38: 0.01 | X38: 0.01 | Y38: 1000 | Z38: 0.01 | AA38: 0.01 | AB38: 0.01 | AC38: 0.01 | AD38: 0.01 | AE38: 0.01 | AF38: 0.01 | AG38: 0.01 | AH38: 0.01 | AI38: 1000 | AJ38: 0.01 | AK38: 0.01 | AL38: 0.01 | AM38: 0.01 | AN38: 0.01 | AO38: 0.01 | AP38: 3 | AQ38: 0.01 | AR38: 0.01
C39: MINCOOFRE1 | D39: COST | F39: COOFRE | G39: 2050 | AP39: 0.15
C40: MINGASRSV1 | D40: BNDACT | E40: UP | G40: 2015 | H40: 0.586152 | I40: 61 | O40: 7.5272983 | P40: 595.53043 | Q40: 392.84744 | S40: 12.97908 | U40: 43.043424 | V40: 0.753624 | W40: 78.092 | X40: 97.594308 | Y40: 21.309676 | AA40: 414.2944 | AI40: 2355.703 | AJ40: 3193.7329 | AK40: 162.61531 | AM40: 464.256 | AN40: 9.545904 | AQ40: 5.5129509 | AR40: 3324.1936
C41: MINGASRSV1 | D41: BNDACT | E41: UP | G41: 2050 | I41: 61 | O41: 7.5272983 | P41: 595.53043 | Q41: 392.84744 | S41: 12.97908 | V41: 0.753624 | W41: 117.138 | X41: 97.594308 | Y41: 21.309676 | AA41: 414.2944 | AI41: 2355.703 | AJ41: 3193.7329 | AK41: 162.61531 | AM41: 464.256 | AN41: 14.318856 | AQ41: 5.5129509 | AR41: 6648.3872
...

Sheet Topology
E1: ~FI_T
B2: TechName | C2: Comm-IN | D2: Comm-IN-A | E2: Comm-OUT | F2: EFF | I2: Commodity | J2: IO
B3: MINCOHRSV1 | C3: =IF(J3="IN",I3,"") | D3: =IF(J3="IN-A",I3,"") | E3: =IF(J3="OUT",I3,"") -> COHRSV | I3: COHRSV | J3: OUT
B4: MINCOHRSV2 | C4: =IF(J4="IN",I4,"") | D4: =IF(J4="IN-A",I4,"") | E4: =IF(J4="OUT",I4,"") -> COHRSV | I4: COHRSV | J4: OUT
B5: MINCOHRSV3 | E5: =IF(J5="OUT",I5,"") -> COHRSV | I5: COHRSV | J5: OUT
B6: MINCOLRSV1 | C6: =IF(J6="IN",I6,"") | D6: =IF(J6="IN-A",I6,"") | E6: =IF(J6="OUT",I6,"") -> COLRSV | I6: COLRSV | J6: OUT
B7: MINCOLRSV2 | C7: =IF(J7="IN",I7,"") | D7: =IF(J7="IN-A",I7,"") | E7: =IF(J7="OUT",I7,"") -> COLRSV | I7: COLRSV | J7: OUT
B8: MINCOLRSV3 | C8: =IF(J8="IN",I8,"") | D8: =IF(J8="IN-A",I8,"") | E8: =IF(J8="OUT",I8,"") -> COLRSV | I8: COLRSV | J8: OUT
B9: MINCOOFRE1 | C9: =IF(J9="IN",I9,"") | D9: =IF(J9="IN-A",I9,"") | E9: =IF(J9="OUT",I9,"") -> COOFRE | I9: COOFRE | J9: OUT
B10: MINGASRSV1 | C10: =IF(J10="IN",I10,"") | D10: =IF(J10="IN-A",I10,"") | E10: =IF(J10="OUT",I10,"") -> GASRSV | I10: GASRSV | J10: OUT
B11: MINGASRSV4 | C11: =IF(J11="IN",I11,"") | D11: =IF(J11="IN-A",I11,"") | E11: =IF(J11="OUT",I11,"") -> GASRSV | I11: GASRSV | J11: OUT
B12: MINGASRSV7 | C12: =IF(J12="IN",I12,"") | D12: =IF(J12="IN-A",I12,"") | E12: =IF(J12="OUT",I12,"") -> GASRSV | I12: GASRSV | J12: OUT
B13: MINMALBAU1 | C13: =IF(J13="IN",I13,"") | D13: =IF(J13="IN-A",I13,"") | E13: =IF(J13="OUT",I13,"") -> MALBAU | I13: MALBAU | J13: OUT
B14: MINMALSCR1 | C14: =IF(J14="IN",I14,"") | D14: =IF(J14="IN-A",I14,"") | E14: =IF(J14="OUT",I14,"") -> MALSCR | I14: MALSCR | J14: OUT
B15: MINMCUORE1 | C15: =IF(J15="IN",I15,"") | D15: =IF(J15="IN-A",I15,"") | E15: =IF(J15="OUT",I15,"") -> MCUORE | I15: MCUORE | J15: OUT
B16: MINMCUSCR1 | C16: =IF(J16="IN",I16,"") | D16: =IF(J16="IN-A",I16,"") | E16: =IF(J16="OUT",I16,"") -> MCUSCR | I16: MCUSCR | J16: OUT
B17: MINMGHRYC1 | C17: =IF(J17="IN",I17,"") | D17: =IF(J17="IN-A",I17,"") | E17: =IF(J17="OUT",I17,"") -> MGHRYC | I17: MGHRYC | J17: OUT
... B31: MINRENWIN1 | C31: =IF(J31="IN",I31,"") | D31: =IF(J31="IN-A",I31,"") | E31: =IF(J31="OUT",I31,"") -> RENWIN | I31: RENWIN | J31: OUT
B32: SUPBIO00 | C32: =IF(J32="IN",I32,"") -> BIOGAS | D32: =IF(J32="IN-A",I32,"") | E32: =IF(J32="OUT",I32,"") | F32: =IF(B32<>B31,1,"") -> 1 | I32: BIOGAS | J32: IN
B33: SUPBIO00 | C33: =IF(J33="IN",I33,"") -> BIOLIQ | D33: =IF(J33="IN-A",I33,"") | E33: =IF(J33="OUT",I33,"") | F33: =IF(B33<>B32,1,"") | I33: BIOLIQ | J33: IN
B34: SUPBIO00 | C34: =IF(J34="IN",I34,"") -> BIOMUN | D34: =IF(J34="IN-A",I34,"") | E34: =IF(J34="OUT",I34,"") | F34: =IF(B34<>B33,1,"") | I34: BIOMUN | J34: IN
B35: SUPBIO00 | C35: =IF(J35="IN",I35,"") -> BIOSLU | D35: =IF(J35="IN-A",I35,"") | E35: =IF(J35="OUT",I35,"") | F35: =IF(B35<>B34,1,"") | I35: BIOSLU | J35: IN
B36: SUPBIO00 | C36: =IF(J36="IN",I36,"") -> BIOWOO | D36: =IF(J36="IN-A",I36,"") | E36: =IF(J36="OUT",I36,"") | F36: =IF(B36<>B35,1,"") | I36: BIOWOO | J36: IN
B37: SUPBIO00 | C37: =IF(J37="IN",I37,"") | D37: =IF(J37="IN-A",I37,"") | E37: =IF(J37="OUT",I37,"") -> SUPBIO | F37: =IF(B37<>B36,1,"") | I37: SUPBIO | J37: OUT
B38: SUPCOA00 | C38: =IF(J38="IN",I38,"") -> COABRO | D38: =IF(J38="IN-A",I38,"") | E38: =IF(J38="OUT",I38,"") | F38: =IF(B38<>B37,1,"") -> 1 | I38: COABRO | J38: IN
B39: SUPCOA00 | C39: =IF(J39="IN",I39,"") -> COACOK | D39: =IF(J39="IN-A",I39,"") | E39: =IF(J39="OUT",I39,"") | F39: =IF(B39<>B38,1,"") | I39: COACOK | J39: IN
B40: SUPCOA00 | C40: =IF(J40="IN",I40,"") -> COAHAR | D40: =IF(J40="IN-A",I40,"") | E40: =IF(J40="OUT",I40,"") | F40: =IF(B40<>B39,1,"") | I40: COAHAR | J40: IN
B41: SUPCOA00 | C41: =IF(J41="IN",I41,"") -> COALIG | D41: =IF(J41="IN-A",I41,"") | E41: =IF(J41="OUT",I41,"") | F41: =IF(B41<>B40,1,"") | I41: COALIG | J41: IN
B42: SUPCOA00 | C42: =IF(J42="IN",I42,"") -> GASBFG | D42: =IF(J42="IN-A",I42,"") | E42: =IF(J42="OUT",I42,"") | F42: =IF(B42<>B41,1,"") | I42: GASBFG | J42: IN
B43: SUPCOA00 | C43: =IF(J43="IN",I43,"") -> GASCOG | D43: =IF(J43="IN-A",I43,"") | E43: =IF(J43="OUT",I43,"") | F43: =IF(B43<>B42,1,"") | I43: GASCOG | J43: IN
... B54: SUPGAS00 | C54: =IF(J54="IN",I54,"") -> GASP2G | D54: =IF(J54="IN-A",I54,"") | E54: =IF(J54="OUT",I54,"") | F54: =IF(B54<>B53,1,"") | I54: GASP2G | J54: IN
B55: SUPGAS00 | C55: =IF(J55="IN",I55,"") | D55: =IF(J55="IN-A",I55,"") | E55: =IF(J55="OUT",I55,"") -> SUPGAS | F55: =IF(B55<>B53,1,"") | I55: SUPGAS | J55: OUT
B56: SUPHTH00 | C56: =IF(J56="IN",I56,"") -> HETHTH | D56: =IF(J56="IN-A",I56,"") | E56: =IF(J56="OUT",I56,"") | F56: =IF(B56<>B55,1,"") -> 1 | I56: HETHTH | J56: IN
B57: SUPHTH00 | C57: =IF(J57="IN",I57,"") | D57: =IF(J57="IN-A",I57,"") | E57: =IF(J57="OUT",I57,"") -> SUPHTH | F57: =IF(B57<>B56,1,"") | I57: SUPHTH | J57: OUT
B58: SUPRPG00 | C58: =IF(J58="IN",I58,"") -> OILLPG | D58: =IF(J58="IN-A",I58,"") | E58: =IF(J58="OUT",I58,"") | F58: =IF(B58<>B57,1,"") -> 1 | I58: OILLPG | J58: IN
B59: SUPRPG00 | C59: =IF(J59="IN",I59,"") -> OILRFG | D59: =IF(J59="IN-A",I59,"") | E59: =IF(J59="OUT",I59,"") | F59: =IF(B59<>B58,1,"") | I59: OILRFG | J59: IN
B60: SUPRPG00 | C60: =IF(J60="IN",I60,"") | D60: =IF(J60="IN-A",I60,"") | E60: =IF(J60="OUT",I60,"") -> SUPRPG | F60: =IF(B60<>B59,1,"") | I60: SUPRPG | J60: OUT
B61: SUPRPP00 | C61: =IF(J61="IN",I61,"") -> OILDST | D61: =IF(J61="IN-A",I61,"") | E61: =IF(J61="OUT",I61,"") | F61: =IF(B61<>B60,1,"") -> 1 | I61: OILDST | J61: IN
B62: SUPRPP00 | C62: =IF(J62="IN",I62,"") -> OILGSL | D62: =IF(J62="IN-A",I62,"") | E62: =IF(J62="OUT",I62,"") | F62: =IF(B62<>B61,1,"") | I62: OILGSL | J62: IN
B63: SUPRPP00 | C63: =IF(J63="IN",I63,"") -> OILHFO | D63: =IF(J63="IN-A",I63,"") | E63: =IF(J63="OUT",I63,"") | F63: =IF(B63<>B62,1,"") | I63: OILHFO | J63: IN
...

Sheet VEDA Tables
A1: Primary Production
D3: ~FI_T: INPUT
B4: Comm-OUT | C4: TechName | D4: Comm-IN | E4: 2010 | F4: ='Copied Pivots'!C$15 -> AL | G4: ='Copied Pivots'!D$15 -> AT | H4: ='Copied Pivots'!E$15 -> BE | I4: ='Copied Pivots'!F$15 -> BG | J4: ='Copied Pivots'!G$15 -> CY | K4: ='Copied Pivots'!H$15 -> CZ | L4: ='Copied Pivots'!I$15 -> DE | M4: ='Copied Pivots'!J$15 -> DK | ... AE4: ='Copied Pivots'!AB$15 -> UK
C5: =C6 -> SPRICOH100 | D5: COHRSV | E5: 1
C6: SPRICOH100 | D6: SUPCOA | E6: =AVERAGE(F6:AE6) -> 0.0019809122 | F6: =IF(IFERROR(SUMIF('Copied Pivots'!$A$17:$A$38,$D6,'Copied Pivots'!C$17:C$38)/SUMPRODUCT(('Copied Pivots'!$C$3:$AL$3='Copied Pivots'!C$15)*('Copied Pivots'!$B$5:$B$11='Copied Pivots'!$B$6)*'Copied Pivots'!$C$5:$AL$11),"")=0,"",IFERROR(SUMIF('Copied Pivots'!$A$17:$A$38,$D6,'Copied Pivots'!C$17:C$38)/SUMPRODUCT(('Copied Pivots'!$C$3:$AL$3='Copied Pivots'!C$15)*('Copied Pivots'!$B$5:$B$11='Copied Pivots'!$B$6)*'Copied Pivots'!$C$5:$AL$11),"")) | G6: =IF(IFERROR(SUMIF('Copied Pivots'!$A$17:$A$38,$D6,'Copied Pivots'!D$17:D$38)/SUMPRODUCT(('Copied Pivots'!$C$3:$AL$3='Copied Pivots'!D$15)*('Copied Pivots'!$B$5:$B$11='Copied Pivots'!$B$6)*'Copied Pivots'!$C$5:$AL$11),"")=0,"",IFERROR(SUMIF('Copied Pivots'!$A$17:$A$38,$D6,'Copied Pivots'!D$17:D$38)/SUMPRODUCT(('Copied Pivots'!$C$3:$AL$3='Copied Pivots'!D$15)*('Copied Pivots'!$B$5:$B$11='Copied Pivots'!$B$6)*'Copied Pivots'!$C$5:$AL$11),"")) | H6: =IF(IFERROR(SUMIF('Copied Pivots'!$A$17:$A$38,$D6,'Copied Pivots'!E$17:E$38)/SUMPRODUCT(('Copied Pivots'!$C$3:$AL$3='Copied Pivots'!E$15)*('Copied Pivots'!$B$5:$B$11='Copied Pivots'!$B$6)*'Copied Pivots'!$C$5:$AL$11),"")=0,"",IFERROR(SUMIF('Copied Pivots'!$A$17:$A$38,$D6,'Copied Pivots'!E$17:E$38)/SUMPRODUCT(('Copied Pivots'!$C$3:$AL$3='Copied Pivots'!E$15)*('Copied Pivots'!$B$5:$B$11='Copied Pivots'!$B$6)*'Copied Pivots'!$C$5:$AL$11),"")) | I6: =IF(IFERROR(SUMIF('Copied Pivots'!$A$17:$A$38,$D6,'Copied Pivots'!F$17:F$38)/SUMPRODUCT(('Copied Pivots'!$C$3:$AL$3='Copied Pivots'!F$15)*('Copied Pivots'!$B$5:$B$11='Copied Pivots'!$B$6)*'Copied Pivots'!$C$5:$AL$11),"")=0,"",IFERROR(SUMIF('Copied Pivots'!$A$17:$A$38,$D6,'Copied Pivots'!F$17:F$38)/SUMPRODUCT(('Copied Pivots'!$C$3:$AL$3='Copied Pivots'!F$15)*('Copied Pivots'!$B$5:$B$11='Copied Pivots'!$B$6)*'Copied Pivots'!$C$5:$AL$11),"")) -> 0.00024032594 | J6: =IF(IFERROR(SUMIF('Copied Pivots'!$A$17:$A$38,$D6,'Copied Pivots'!G$17:G$38)/SUMPRODUCT(('Copied Pivots'!$C$3:$AL$3='Copied Pivots'!G$15)*('Copied Pivots'!$B$5:$B$11='Copied Pivots'!$B$6)*'Copied Pivots'!$C$5:$AL$11),"")=0,"",IFERROR(SUMIF('Copied Pivots'!$A$17:$A$38,$D6,'Copied Pivots'!G$17:G$38)/SUMPRODUCT(('Copied Pivots'!$C$3:$AL$3='Copied Pivots'!G$15)*('Copied Pivots'!$B$5:$B$11='Copied Pivots'!$B$6)*'Copied Pivots'!$C$5:$AL$11),"")) | K6: =IF(IFERROR(SUMIF('Copied Pivots'!$A$17:$A$38,$D6,'Copied Pivots'!H$17:H$38)/SUMPRODUCT(('Copied Pivots'!$C$3:$AL$3='Copied Pivots'!H$15)*('Copied Pivots'!$B$5:$B$11='Copied Pivots'!$B$6)*'Copied Pivots'!$C$5:$AL$11),"")=0,"",IFERROR(SUMIF('Copied Pivots'!$A$17:$A$38,$D6,'Copied Pivots'!H$17:H$38)/SUMPRODUCT(('Copied Pivots'!$C$3:$AL$3='Copied Pivots'!H$15)*('Copied Pivots'!$B$5:$B$11='Copied Pivots'!$B$6)*'Copied Pivots'!$C$5:$AL$11),"")) -> 0.013616555 | L6: =IF(IFERROR(SUMIF('Copied Pivots'!$A$17:$A$38,$D6,'Copied Pivots'!I$17:I$38)/SUMPRODUCT(('Copied Pivots'!$C$3:$AL$3='Copied Pivots'!I$15)*('Copied Pivots'!$B$5:$B$11='Copied Pivots'!$B$6)*'Copied Pivots'!$C$5:$AL$11),"")=0,"",IFERROR(SUMIF('Copied Pivots'!$A$17:$A$38,$D6,'Copied Pivots'!I$17:I$38)/SUMPRODUCT(('Copied Pivots'!$C$3:$AL$3='Copied Pivots'!I$15)*('Copied Pivots'!$B$5:$B$11='Copied Pivots'!$B$6)*'Copied Pivots'!$C$5:$AL$11),"")) -> 9.9395475e-05 | M6: =IF(IFERROR(SUMIF('Copied Pivots'!$A$17:$A$38,$D6,'Copied Pivots'!J$17:J$38)/SUMPRODUCT(('Copied Pivots'!$C$3:$AL$3='Copied Pivots'!J$15)*('Copied Pivots'!$B$5:$B$11='Copied Pivots'!$B$6)*'Copied Pivots'!$C$5:$AL$11),"")=0,"",IFERROR(SUMIF('Copied Pivots'!$A$17:$A$38,$D6,'Copied Pivots'!J$17:J$38)/SUMPRODUCT(('Copied Pivots'!$C$3:$AL$3='Copied Pivots'!J$15)*('Copied Pivots'!$B$5:$B$11='Copied Pivots'!$B$6)*'Copied Pivots'!$C$5:$AL$11),"")) | ... AE6: =IF(IFERROR(SUMIF('Copied Pivots'!$A$17:$A$38,$D6,'Copied Pivots'!AB$17:AB$38)/SUMPRODUCT(('Copied Pivots'!$C$3:$AL$3='Copied Pivots'!AB$15)*('Copied Pivots'!$B$5:$B$11='Copied Pivots'!$B$6)*'Copied Pivots'!$C$5:$AL$11),"")=0,"",IFERROR(SUMIF('Copied Pivots'!$A$17:$A$38,$D6,'Copied Pivots'!AB$17:AB$38)/SUMPRODUCT(('Copied Pivots'!$C$3:$AL$3='Copied Pivots'!AB$15)*('Copied Pivots'!$B$5:$B$11='Copied Pivots'!$B$6)*'Copied Pivots'!$C$5:$AL$11),"")) -> 0.00023116561
C7: SPRICOH100 | D7: SUPELC | E7: =AVERAGE(F7:AE7) -> 0.011946036 | F7: =IF(IFERROR(SUMIF('Copied Pivots'!$A$17:$A$38,$D7,'Copied Pivots'!C$17:C$38)/SUMPRODUCT(('Copied Pivots'!$C$3:$AL$3='Copied Pivots'!C$15)*('Copied Pivots'!$B$5:$B$11='Copied Pivots'!$B$6)*'Copied Pivots'!$C$5:$AL$11),"")=0,"",IFERROR(SUMIF('Copied Pivots'!$A$17:$A$38,$D7,'Copied Pivots'!C$17:C$38)/SUMPRODUCT(('Copied Pivots'!$C$3:$AL$3='Copied Pivots'!C$15)*('Copied Pivots'!$B$5:$B$11='Copied Pivots'!$B$6)*'Copied Pivots'!$C$5:$AL$11),"")) | G7: =IF(IFERROR(SUMIF('Copied Pivots'!$A$17:$A$38,$D7,'Copied Pivots'!D$17:D$38)/SUMPRODUCT(('Copied Pivots'!$C$3:$AL$3='Copied Pivots'!D$15)*('Copied Pivots'!$B$5:$B$11='Copied Pivots'!$B$6)*'Copied Pivots'!$C$5:$AL$11),"")=0,"",IFERROR(SUMIF('Copied Pivots'!$A$17:$A$38,$D7,'Copied Pivots'!D$17:D$38)/SUMPRODUCT(('Copied Pivots'!$C$3:$AL$3='Copied Pivots'!D$15)*('Copied Pivots'!$B$5:$B$11='Copied Pivots'!$B$6)*'Copied Pivots'!$C$5:$AL$11),"")) | H7: =IF(IFERROR(SUMIF('Copied Pivots'!$A$17:$A$38,$D7,'Copied Pivots'!E$17:E$38)/SUMPRODUCT(('Copied Pivots'!$C$3:$AL$3='Copied Pivots'!E$15)*('Copied Pivots'!$B$5:$B$11='Copied Pivots'!$B$6)*'Copied Pivots'!$C$5:$AL$11),"")=0,"",IFERROR(SUMIF('Copied Pivots'!$A$17:$A$38,$D7,'Copied Pivots'!E$17:E$38)/SUMPRODUCT(('Copied Pivots'!$C$3:$AL$3='Copied Pivots'!E$15)*('Copied Pivots'!$B$5:$B$11='Copied Pivots'!$B$6)*'Copied Pivots'!$C$5:$AL$11),"")) | I7: =IF(IFERROR(SUMIF('Copied Pivots'!$A$17:$A$38,$D7,'Copied Pivots'!F$17:F$38)/SUMPRODUCT(('Copied Pivots'!$C$3:$AL$3='Copied Pivots'!F$15)*('Copied Pivots'!$B$5:$B$11='Copied Pivots'!$B$6)*'Copied Pivots'!$C$5:$AL$11),"")=0,"",IFERROR(SUMIF('Copied Pivots'!$A$17:$A$38,$D7,'Copied Pivots'!F$17:F$38)/SUMPRODUCT(('Copied Pivots'!$C$3:$AL$3='Copied Pivots'!F$15)*('Copied Pivots'!$B$5:$B$11='Copied Pivots'!$B$6)*'Copied Pivots'!$C$5:$AL$11),"")) -> 0.0098420983 | J7: =IF(IFERROR(SUMIF('Copied Pivots'!$A$17:$A$38,$D7,'Copied Pivots'!G$17:G$38)/SUMPRODUCT(('Copied Pivots'!$C$3:$AL$3='Copied Pivots'!G$15)*('Copied Pivots'!$B$5:$B$11='Copied Pivots'!$B$6)*'Copied Pivots'!$C$5:$AL$11),"")=0,"",IFERROR(SUMIF('Copied Pivots'!$A$17:$A$38,$D7,'Copied Pivots'!G$17:G$38)/SUMPRODUCT(('Copied Pivots'!$C$3:$AL$3='Copied Pivots'!G$15)*('Copied Pivots'!$B$5:$B$11='Copied Pivots'!$B$6)*'Copied Pivots'!$C$5:$AL$11),"")) | K7: =IF(IFERROR(SUMIF('Copied Pivots'!$A$17:$A$38,$D7,'Copied Pivots'!H$17:H$38)/SUMPRODUCT(('Copied Pivots'!$C$3:$AL$3='Copied Pivots'!H$15)*('Copied Pivots'!$B$5:$B$11='Copied Pivots'!$B$6)*'Copied Pivots'!$C$5:$AL$11),"")=0,"",IFERROR(SUMIF('Copied Pivots'!$A$17:$A$38,$D7,'Copied Pivots'!H$17:H$38)/SUMPRODUCT(('Copied Pivots'!$C$3:$AL$3='Copied Pivots'!H$15)*('Copied Pivots'!$B$5:$B$11='Copied Pivots'!$B$6)*'Copied Pivots'!$C$5:$AL$11),"")) -> 0.0059883349 | L7: =IF(IFERROR(SUMIF('Copied Pivots'!$A$17:$A$38,$D7,'Copied Pivots'!I$17:I$38)/SUMPRODUCT(('Copied Pivots'!$C$3:$AL$3='Copied Pivots'!I$15)*('Copied Pivots'!$B$5:$B$11='Copied Pivots'!$B$6)*'Copied Pivots'!$C$5:$AL$11),"")=0,"",IFERROR(SUMIF('Copied Pivots'!$A$17:$A$38,$D7,'Copied Pivots'!I$17:I$38)/SUMPRODUCT(('Copied Pivots'!$C$3:$AL$3='Copied Pivots'!I$15)*('Copied Pivots'!$B$5:$B$11='Copied Pivots'!$B$6)*'Copied Pivots'!$C$5:$AL$11),"")) -> 0.0032015806 | M7: =IF(IFERROR(SUMIF('Copied Pivots'!$A$17:$A$38,$D7,'Copied Pivots'!J$17:J$38)/SUMPRODUCT(('Copied Pivots'!$C$3:$AL$3='Copied Pivots'!J$15)*('Copied Pivots'!$B$5:$B$11='Copied Pivots'!$B$6)*'Copied Pivots'!$C$5:$AL$11),"")=0,"",IFERROR(SUMIF('Copied Pivots'!$A$17:$A$38,$D7,'Copied Pivots'!J$17:J$38)/SUMPRODUCT(('Copied Pivots'!$C$3:$AL$3='Copied Pivots'!J$15)*('Copied Pivots'!$B$5:$B$11='Copied Pivots'!$B$6)*'Copied Pivots'!$C$5:$AL$11),"")) | ... AE7: =IF(IFERROR(SUMIF('Copied Pivots'!$A$17:$A$38,$D7,'Copied Pivots'!AB$17:AB$38)/SUMPRODUCT(('Copied Pivots'!$C$3:$AL$3='Copied Pivots'!AB$15)*('Copied Pivots'!$B$5:$B$11='Copied Pivots'!$B$6)*'Copied Pivots'!$C$5:$AL$11),"")=0,"",IFERROR(SUMIF('Copied Pivots'!$A$17:$A$38,$D7,'Copied Pivots'!AB$17:AB$38)/SUMPRODUCT(('Copied Pivots'!$C$3:$AL$3='Copied Pivots'!AB$15)*('Copied Pivots'!$B$5:$B$11='Copied Pivots'!$B$6)*'Copied Pivots'!$C$5:$AL$11),"")) -> 0.0087236965
C8: SPRICOH100 | D8: SUPGAS | E8: =AVERAGE(F8:AE8) -> 0.0005421764 | F8: =IF(IFERROR(SUMIF('Copied Pivots'!$A$17:$A$38,$D8,'Copied Pivots'!C$17:C$38)/SUMPRODUCT(('Copied Pivots'!$C$3:$AL$3='Copied Pivots'!C$15)*('Copied Pivots'!$B$5:$B$11='Copied Pivots'!$B$6)*'Copied Pivots'!$C$5:$AL$11),"")=0,"",IFERROR(SUMIF('Copied Pivots'!$A$17:$A$38,$D8,'Copied Pivots'!C$17:C$38)/SUMPRODUCT(('Copied Pivots'!$C$3:$AL$3='Copied Pivots'!C$15)*('Copied Pivots'!$B$5:$B$11='Copied Pivots'!$B$6)*'Copied Pivots'!$C$5:$AL$11),"")) | G8: =IF(IFERROR(SUMIF('Copied Pivots'!$A$17:$A$38,$D8,'Copied Pivots'!D$17:D$38)/SUMPRODUCT(('Copied Pivots'!$C$3:$AL$3='Copied Pivots'!D$15)*('Copied Pivots'!$B$5:$B$11='Copied Pivots'!$B$6)*'Copied Pivots'!$C$5:$AL$11),"")=0,"",IFERROR(SUMIF('Copied Pivots'!$A$17:$A$38,$D8,'Copied Pivots'!D$17:D$38)/SUMPRODUCT(('Copied Pivots'!$C$3:$AL$3='Copied Pivots'!D$15)*('Copied Pivots'!$B$5:$B$11='Copied Pivots'!$B$6)*'Copied Pivots'!$C$5:$AL$11),"")) | H8: =IF(IFERROR(SUMIF('Copied Pivots'!$A$17:$A$38,$D8,'Copied Pivots'!E$17:E$38)/SUMPRODUCT(('Copied Pivots'!$C$3:$AL$3='Copied Pivots'!E$15)*('Copied Pivots'!$B$5:$B$11='Copied Pivots'!$B$6)*'Copied Pivots'!$C$5:$AL$11),"")=0,"",IFERROR(SUMIF('Copied Pivots'!$A$17:$A$38,$D8,'Copied Pivots'!E$17:E$38)/SUMPRODUCT(('Copied Pivots'!$C$3:$AL$3='Copied Pivots'!E$15)*('Copied Pivots'!$B$5:$B$11='Copied Pivots'!$B$6)*'Copied Pivots'!$C$5:$AL$11),"")) | I8: =IF(IFERROR(SUMIF('Copied Pivots'!$A$17:$A$38,$D8,'Copied Pivots'!F$17:F$38)/SUMPRODUCT(('Copied Pivots'!$C$3:$AL$3='Copied Pivots'!F$15)*('Copied Pivots'!$B$5:$B$11='Copied Pivots'!$B$6)*'Copied Pivots'!$C$5:$AL$11),"")=0,"",IFERROR(SUMIF('Copied Pivots'!$A$17:$A$38,$D8,'Copied Pivots'!F$17:F$38)/SUMPRODUCT(('Copied Pivots'!$C$3:$AL$3='Copied Pivots'!F$15)*('Copied Pivots'!$B$5:$B$11='Copied Pivots'!$B$6)*'Copied Pivots'!$C$5:$AL$11),"")) | J8: =IF(IFERROR(SUMIF('Copied Pivots'!$A$17:$A$38,$D8,'Copied Pivots'!G$17:G$38)/SUMPRODUCT(('Copied Pivots'!$C$3:$AL$3='Copied Pivots'!G$15)*('Copied Pivots'!$B$5:$B$11='Copied Pivots'!$B$6)*'Copied Pivots'!$C$5:$AL$11),"")=0,"",IFERROR(SUMIF('Copied Pivots'!$A$17:$A$38,$D8,'Copied Pivots'!G$17:G$38)/SUMPRODUCT(('Copied Pivots'!$C$3:$AL$3='Copied Pivots'!G$15)*('Copied Pivots'!$B$5:$B$11='Copied Pivots'!$B$6)*'Copied Pivots'!$C$5:$AL$11),"")) | K8: =IF(IFERROR(SUMIF('Copied Pivots'!$A$17:$A$38,$D8,'Copied Pivots'!H$17:H$38)/SUMPRODUCT(('Copied Pivots'!$C$3:$AL$3='Copied Pivots'!H$15)*('Copied Pivots'!$B$5:$B$11='Copied Pivots'!$B$6)*'Copied Pivots'!$C$5:$AL$11),"")=0,"",IFERROR(SUMIF('Copied Pivots'!$A$17:$A$38,$D8,'Copied Pivots'!H$17:H$38)/SUMPRODUCT(('Copied Pivots'!$C$3:$AL$3='Copied Pivots'!H$15)*('Copied Pivots'!$B$5:$B$11='Copied Pivots'!$B$6)*'Copied Pivots'!$C$5:$AL$11),"")) -> 0.00053381966 | L8: =IF(IFERROR(SUMIF('Copied Pivots'!$A$17:$A$38,$D8,'Copied Pivots'!I$17:I$38)/SUMPRODUCT(('Copied Pivots'!$C$3:$AL$3='Copied Pivots'!I$15)*('Copied Pivots'!$B$5:$B$11='Copied Pivots'!$B$6)*'Copied Pivots'!$C$5:$AL$11),"")=0,"",IFERROR(SUMIF('Copied Pivots'!$A$17:$A$38,$D8,'Copied Pivots'!I$17:I$38)/SUMPRODUCT(('Copied Pivots'!$C$3:$AL$3='Copied Pivots'!I$15)*('Copied Pivots'!$B$5:$B$11='Copied Pivots'!$B$6)*'Copied Pivots'!$C$5:$AL$11),"")) -> 8.9368738e-05 | M8: =IF(IFERROR(SUMIF('Copied Pivots'!$A$17:$A$38,$D8,'Copied Pivots'!J$17:J$38)/SUMPRODUCT(('Copied Pivots'!$C$3:$AL$3='Copied Pivots'!J$15)*('Copied Pivots'!$B$5:$B$11='Copied Pivots'!$B$6)*'Copied Pivots'!$C$5:$AL$11),"")=0,"",IFERROR(SUMIF('Copied Pivots'!$A$17:$A$38,$D8,'Copied Pivots'!J$17:J$38)/SUMPRODUCT(('Copied Pivots'!$C$3:$AL$3='Copied Pivots'!J$15)*('Copied Pivots'!$B$5:$B$11='Copied Pivots'!$B$6)*'Copied Pivots'!$C$5:$AL$11),"")) | ... AE8: =IF(IFERROR(SUMIF('Copied Pivots'!$A$17:$A$38,$D8,'Copied Pivots'!AB$17:AB$38)/SUMPRODUCT(('Copied Pivots'!$C$3:$AL$3='Copied Pivots'!AB$15)*('Copied Pivots'!$B$5:$B$11='Copied Pivots'!$B$6)*'Copied Pivots'!$C$5:$AL$11),"")=0,"",IFERROR(SUMIF('Copied Pivots'!$A$17:$A$38,$D8,'Copied Pivots'!AB$17:AB$38)/SUMPRODUCT(('Copied Pivots'!$C$3:$AL$3='Copied Pivots'!AB$15)*('Copied Pivots'!$B$5:$B$11='Copied Pivots'!$B$6)*'Copied Pivots'!$C$5:$AL$11),"")) -> 0.0017415972
C9: SPRICOH100 | D9: SUPHTH | E9: =AVERAGE(F9:AE9) -> 0.0040036844 | F9: =IF(IFERROR(SUMIF('Copied Pivots'!$A$17:$A$38,$D9,'Copied Pivots'!C$17:C$38)/SUMPRODUCT(('Copied Pivots'!$C$3:$AL$3='Copied Pivots'!C$15)*('Copied Pivots'!$B$5:$B$11='Copied Pivots'!$B$6)*'Copied Pivots'!$C$5:$AL$11),"")=0,"",IFERROR(SUMIF('Copied Pivots'!$A$17:$A$38,$D9,'Copied Pivots'!C$17:C$38)/SUMPRODUCT(('Copied Pivots'!$C$3:$AL$3='Copied Pivots'!C$15)*('Copied Pivots'!$B$5:$B$11='Copied Pivots'!$B$6)*'Copied Pivots'!$C$5:$AL$11),"")) | G9: =IF(IFERROR(SUMIF('Copied Pivots'!$A$17:$A$38,$D9,'Copied Pivots'!D$17:D$38)/SUMPRODUCT(('Copied Pivots'!$C$3:$AL$3='Copied Pivots'!D$15)*('Copied Pivots'!$B$5:$B$11='Copied Pivots'!$B$6)*'Copied Pivots'!$C$5:$AL$11),"")=0,"",IFERROR(SUMIF('Copied Pivots'!$A$17:$A$38,$D9,'Copied Pivots'!D$17:D$38)/SUMPRODUCT(('Copied Pivots'!$C$3:$AL$3='Copied Pivots'!D$15)*('Copied Pivots'!$B$5:$B$11='Copied Pivots'!$B$6)*'Copied Pivots'!$C$5:$AL$11),"")) | H9: =IF(IFERROR(SUMIF('Copied Pivots'!$A$17:$A$38,$D9,'Copied Pivots'!E$17:E$38)/SUMPRODUCT(('Copied Pivots'!$C$3:$AL$3='Copied Pivots'!E$15)*('Copied Pivots'!$B$5:$B$11='Copied Pivots'!$B$6)*'Copied Pivots'!$C$5:$AL$11),"")=0,"",IFERROR(SUMIF('Copied Pivots'!$A$17:$A$38,$D9,'Copied Pivots'!E$17:E$38)/SUMPRODUCT(('Copied Pivots'!$C$3:$AL$3='Copied Pivots'!E$15)*('Copied Pivots'!$B$5:$B$11='Copied Pivots'!$B$6)*'Copied Pivots'!$C$5:$AL$11),"")) | I9: =IF(IFERROR(SUMIF('Copied Pivots'!$A$17:$A$38,$D9,'Copied Pivots'!F$17:F$38)/SUMPRODUCT(('Copied Pivots'!$C$3:$AL$3='Copied Pivots'!F$15)*('Copied Pivots'!$B$5:$B$11='Copied Pivots'!$B$6)*'Copied Pivots'!$C$5:$AL$11),"")=0,"",IFERROR(SUMIF('Copied Pivots'!$A$17:$A$38,$D9,'Copied Pivots'!F$17:F$38)/SUMPRODUCT(('Copied Pivots'!$C$3:$AL$3='Copied Pivots'!F$15)*('Copied Pivots'!$B$5:$B$11='Copied Pivots'!$B$6)*'Copied Pivots'!$C$5:$AL$11),"")) -> 0.00034922363 | J9: =IF(IFERROR(SUMIF('Copied Pivots'!$A$17:$A$38,$D9,'Copied Pivots'!G$17:G$38)/SUMPRODUCT(('Copied Pivots'!$C$3:$AL$3='Copied Pivots'!G$15)*('Copied Pivots'!$B$5:$B$11='Copied Pivots'!$B$6)*'Copied Pivots'!$C$5:$AL$11),"")=0,"",IFERROR(SUMIF('Copied Pivots'!$A$17:$A$38,$D9,'Copied Pivots'!G$17:G$38)/SUMPRODUCT(('Copied Pivots'!$C$3:$AL$3='Copied Pivots'!G$15)*('Copied Pivots'!$B$5:$B$11='Copied Pivots'!$B$6)*'Copied Pivots'!$C$5:$AL$11),"")) | K9: =IF(IFERROR(SUMIF('Copied Pivots'!$A$17:$A$38,$D9,'Copied Pivots'!H$17:H$38)/SUMPRODUCT(('Copied Pivots'!$C$3:$AL$3='Copied Pivots'!H$15)*('Copied Pivots'!$B$5:$B$11='Copied Pivots'!$B$6)*'Copied Pivots'!$C$5:$AL$11),"")=0,"",IFERROR(SUMIF('Copied Pivots'!$A$17:$A$38,$D9,'Copied Pivots'!H$17:H$38)/SUMPRODUCT(('Copied Pivots'!$C$3:$AL$3='Copied Pivots'!H$15)*('Copied Pivots'!$B$5:$B$11='Copied Pivots'!$B$6)*'Copied Pivots'!$C$5:$AL$11),"")) -> 0.0050079346 | L9: =IF(IFERROR(SUMIF('Copied Pivots'!$A$17:$A$38,$D9,'Copied Pivots'!I$17:I$38)/SUMPRODUCT(('Copied Pivots'!$C$3:$AL$3='Copied Pivots'!I$15)*('Copied Pivots'!$B$5:$B$11='Copied Pivots'!$B$6)*'Copied Pivots'!$C$5:$AL$11),"")=0,"",IFERROR(SUMIF('Copied Pivots'!$A$17:$A$38,$D9,'Copied Pivots'!I$17:I$38)/SUMPRODUCT(('Copied Pivots'!$C$3:$AL$3='Copied Pivots'!I$15)*('Copied Pivots'!$B$5:$B$11='Copied Pivots'!$B$6)*'Copied Pivots'!$C$5:$AL$11),"")) -> 0.00014865727 | M9: =IF(IFERROR(SUMIF('Copied Pivots'!$A$17:$A$38,$D9,'Copied Pivots'!J$17:J$38)/SUMPRODUCT(('Copied Pivots'!$C$3:$AL$3='Copied Pivots'!J$15)*('Copied Pivots'!$B$5:$B$11='Copied Pivots'!$B$6)*'Copied Pivots'!$C$5:$AL$11),"")=0,"",IFERROR(SUMIF('Copied Pivots'!$A$17:$A$38,$D9,'Copied Pivots'!J$17:J$38)/SUMPRODUCT(('Copied Pivots'!$C$3:$AL$3='Copied Pivots'!J$15)*('Copied Pivots'!$B$5:$B$11='Copied Pivots'!$B$6)*'Copied Pivots'!$C$5:$AL$11),"")) | ... AE9: =IF(IFERROR(SUMIF('Copied Pivots'!$A$17:$A$38,$D9,'Copied Pivots'!AB$17:AB$38)/SUMPRODUCT(('Copied Pivots'!$C$3:$AL$3='Copied Pivots'!AB$15)*('Copied Pivots'!$B$5:$B$11='Copied Pivots'!$B$6)*'Copied Pivots'!$C$5:$AL$11),"")=0,"",IFERROR(SUMIF('Copied Pivots'!$A$17:$A$38,$D9,'Copied Pivots'!AB$17:AB$38)/SUMPRODUCT(('Copied Pivots'!$C$3:$AL$3='Copied Pivots'!AB$15)*('Copied Pivots'!$B$5:$B$11='Copied Pivots'!$B$6)*'Copied Pivots'!$C$5:$AL$11),""))
C10: SPRICOH100 | D10: SUPRPP | E10: =AVERAGE(F10:AE10) -> 0.0025047638 | F10: =IF(IFERROR(SUMIF('Copied Pivots'!$A$17:$A$38,$D10,'Copied Pivots'!C$17:C$38)/SUMPRODUCT(('Copied Pivots'!$C$3:$AL$3='Copied Pivots'!C$15)*('Copied Pivots'!$B$5:$B$11='Copied Pivots'!$B$6)*'Copied Pivots'!$C$5:$AL$11),"")=0,"",IFERROR(SUMIF('Copied Pivots'!$A$17:$A$38,$D10,'Copied Pivots'!C$17:C$38)/SUMPRODUCT(('Copied Pivots'!$C$3:$AL$3='Copied Pivots'!C$15)*('Copied Pivots'!$B$5:$B$11='Copied Pivots'!$B$6)*'Copied Pivots'!$C$5:$AL$11),"")) | G10: =IF(IFERROR(SUMIF('Copied Pivots'!$A$17:$A$38,$D10,'Copied Pivots'!D$17:D$38)/SUMPRODUCT(('Copied Pivots'!$C$3:$AL$3='Copied Pivots'!D$15)*('Copied Pivots'!$B$5:$B$11='Copied Pivots'!$B$6)*'Copied Pivots'!$C$5:$AL$11),"")=0,"",IFERROR(SUMIF('Copied Pivots'!$A$17:$A$38,$D10,'Copied Pivots'!D$17:D$38)/SUMPRODUCT(('Copied Pivots'!$C$3:$AL$3='Copied Pivots'!D$15)*('Copied Pivots'!$B$5:$B$11='Copied Pivots'!$B$6)*'Copied Pivots'!$C$5:$AL$11),"")) | H10: =IF(IFERROR(SUMIF('Copied Pivots'!$A$17:$A$38,$D10,'Copied Pivots'!E$17:E$38)/SUMPRODUCT(('Copied Pivots'!$C$3:$AL$3='Copied Pivots'!E$15)*('Copied Pivots'!$B$5:$B$11='Copied Pivots'!$B$6)*'Copied Pivots'!$C$5:$AL$11),"")=0,"",IFERROR(SUMIF('Copied Pivots'!$A$17:$A$38,$D10,'Copied Pivots'!E$17:E$38)/SUMPRODUCT(('Copied Pivots'!$C$3:$AL$3='Copied Pivots'!E$15)*('Copied Pivots'!$B$5:$B$11='Copied Pivots'!$B$6)*'Copied Pivots'!$C$5:$AL$11),"")) | I10: =IF(IFERROR(SUMIF('Copied Pivots'!$A$17:$A$38,$D10,'Copied Pivots'!F$17:F$38)/SUMPRODUCT(('Copied Pivots'!$C$3:$AL$3='Copied Pivots'!F$15)*('Copied Pivots'!$B$5:$B$11='Copied Pivots'!$B$6)*'Copied Pivots'!$C$5:$AL$11),"")=0,"",IFERROR(SUMIF('Copied Pivots'!$A$17:$A$38,$D10,'Copied Pivots'!F$17:F$38)/SUMPRODUCT(('Copied Pivots'!$C$3:$AL$3='Copied Pivots'!F$15)*('Copied Pivots'!$B$5:$B$11='Copied Pivots'!$B$6)*'Copied Pivots'!$C$5:$AL$11),"")) | J10: =IF(IFERROR(SUMIF('Copied Pivots'!$A$17:$A$38,$D10,'Copied Pivots'!G$17:G$38)/SUMPRODUCT(('Copied Pivots'!$C$3:$AL$3='Copied Pivots'!G$15)*('Copied Pivots'!$B$5:$B$11='Copied Pivots'!$B$6)*'Copied Pivots'!$C$5:$AL$11),"")=0,"",IFERROR(SUMIF('Copied Pivots'!$A$17:$A$38,$D10,'Copied Pivots'!G$17:G$38)/SUMPRODUCT(('Copied Pivots'!$C$3:$AL$3='Copied Pivots'!G$15)*('Copied Pivots'!$B$5:$B$11='Copied Pivots'!$B$6)*'Copied Pivots'!$C$5:$AL$11),"")) | K10: =IF(IFERROR(SUMIF('Copied Pivots'!$A$17:$A$38,$D10,'Copied Pivots'!H$17:H$38)/SUMPRODUCT(('Copied Pivots'!$C$3:$AL$3='Copied Pivots'!H$15)*('Copied Pivots'!$B$5:$B$11='Copied Pivots'!$B$6)*'Copied Pivots'!$C$5:$AL$11),"")=0,"",IFERROR(SUMIF('Copied Pivots'!$A$17:$A$38,$D10,'Copied Pivots'!H$17:H$38)/SUMPRODUCT(('Copied Pivots'!$C$3:$AL$3='Copied Pivots'!H$15)*('Copied Pivots'!$B$5:$B$11='Copied Pivots'!$B$6)*'Copied Pivots'!$C$5:$AL$11),"")) -> 0.00077788117 | L10: =IF(IFERROR(SUMIF('Copied Pivots'!$A$17:$A$38,$D10,'Copied Pivots'!I$17:I$38)/SUMPRODUCT(('Copied Pivots'!$C$3:$AL$3='Copied Pivots'!I$15)*('Copied Pivots'!$B$5:$B$11='Copied Pivots'!$B$6)*'Copied Pivots'!$C$5:$AL$11),"")=0,"",IFERROR(SUMIF('Copied Pivots'!$A$17:$A$38,$D10,'Copied Pivots'!I$17:I$38)/SUMPRODUCT(('Copied Pivots'!$C$3:$AL$3='Copied Pivots'!I$15)*('Copied Pivots'!$B$5:$B$11='Copied Pivots'!$B$6)*'Copied Pivots'!$C$5:$AL$11),"")) -> 0.00011160194 | M10: =IF(IFERROR(SUMIF('Copied Pivots'!$A$17:$A$38,$D10,'Copied Pivots'!J$17:J$38)/SUMPRODUCT(('Copied Pivots'!$C$3:$AL$3='Copied Pivots'!J$15)*('Copied Pivots'!$B$5:$B$11='Copied Pivots'!$B$6)*'Copied Pivots'!$C$5:$AL$11),"")=0,"",IFERROR(SUMIF('Copied Pivots'!$A$17:$A$38,$D10,'Copied Pivots'!J$17:J$38)/SUMPRODUCT(('Copied Pivots'!$C$3:$AL$3='Copied Pivots'!J$15)*('Copied Pivots'!$B$5:$B$11='Copied Pivots'!$B$6)*'Copied Pivots'!$C$5:$AL$11),"")) | ... AE10: =IF(IFERROR(SUMIF('Copied Pivots'!$A$17:$A$38,$D10,'Copied Pivots'!AB$17:AB$38)/SUMPRODUCT(('Copied Pivots'!$C$3:$AL$3='Copied Pivots'!AB$15)*('Copied Pivots'!$B$5:$B$11='Copied Pivots'!$B$6)*'Copied Pivots'!$C$5:$AL$11),"")=0,"",IFERROR(SUMIF('Copied Pivots'!$A$17:$A$38,$D10,'Copied Pivots'!AB$17:AB$38)/SUMPRODUCT(('Copied Pivots'!$C$3:$AL$3='Copied Pivots'!AB$15)*('Copied Pivots'!$B$5:$B$11='Copied Pivots'!$B$6)*'Copied Pivots'!$C$5:$AL$11),""))
B11: COAHAR | C11: =C10 -> SPRICOH100
C12: \I:
C13: =C14 -> SPRIGAS100 | D13: GASRSV | E13: 1
C14: SPRIGAS100 | D14: SUPCOA | F14: =IF(IFERROR(SUMIF('Copied Pivots'!$A$40:$A$61,$D14,'Copied Pivots'!C$40:C$61)/SUMPRODUCT(('Copied Pivots'!$C$3:$AL$3='Copied Pivots'!C$15)*('Copied Pivots'!$B$5:$B$12='Copied Pivots'!$B$12)*'Copied Pivots'!$C$5:$AL$12),"")=0,"",IFERROR(SUMIF('Copied Pivots'!$A$40:$A$61,$D14,'Copied Pivots'!C$40:C$61)/SUMPRODUCT(('Copied Pivots'!$C$3:$AL$3='Copied Pivots'!C$15)*('Copied Pivots'!$B$5:$B$12='Copied Pivots'!$B$12)*'Copied Pivots'!$C$5:$AL$12),"")) | G14: =IF(IFERROR(SUMIF('Copied Pivots'!$A$40:$A$61,$D14,'Copied Pivots'!D$40:D$61)/SUMPRODUCT(('Copied Pivots'!$C$3:$AL$3='Copied Pivots'!D$15)*('Copied Pivots'!$B$5:$B$12='Copied Pivots'!$B$12)*'Copied Pivots'!$C$5:$AL$12),"")=0,"",IFERROR(SUMIF('Copied Pivots'!$A$40:$A$61,$D14,'Copied Pivots'!D$40:D$61)/SUMPRODUCT(('Copied Pivots'!$C$3:$AL$3='Copied Pivots'!D$15)*('Copied Pivots'!$B$5:$B$12='Copied Pivots'!$B$12)*'Copied Pivots'!$C$5:$AL$12),"")) | H14: =IF(IFERROR(SUMIF('Copied Pivots'!$A$40:$A$61,$D14,'Copied Pivots'!E$40:E$61)/SUMPRODUCT(('Copied Pivots'!$C$3:$AL$3='Copied Pivots'!E$15)*('Copied Pivots'!$B$5:$B$12='Copied Pivots'!$B$12)*'Copied Pivots'!$C$5:$AL$12),"")=0,"",IFERROR(SUMIF('Copied Pivots'!$A$40:$A$61,$D14,'Copied Pivots'!E$40:E$61)/SUMPRODUCT(('Copied Pivots'!$C$3:$AL$3='Copied Pivots'!E$15)*('Copied Pivots'!$B$5:$B$12='Copied Pivots'!$B$12)*'Copied Pivots'!$C$5:$AL$12),"")) | I14: =IF(IFERROR(SUMIF('Copied Pivots'!$A$40:$A$61,$D14,'Copied Pivots'!F$40:F$61)/SUMPRODUCT(('Copied Pivots'!$C$3:$AL$3='Copied Pivots'!F$15)*('Copied Pivots'!$B$5:$B$12='Copied Pivots'!$B$12)*'Copied Pivots'!$C$5:$AL$12),"")=0,"",IFERROR(SUMIF('Copied Pivots'!$A$40:$A$61,$D14,'Copied Pivots'!F$40:F$61)/SUMPRODUCT(('Copied Pivots'!$C$3:$AL$3='Copied Pivots'!F$15)*('Copied Pivots'!$B$5:$B$12='Copied Pivots'!$B$12)*'Copied Pivots'!$C$5:$AL$12),"")) | J14: =IF(IFERROR(SUMIF('Copied Pivots'!$A$40:$A$61,$D14,'Copied Pivots'!G$40:G$61)/SUMPRODUCT(('Copied Pivots'!$C$3:$AL$3='Copied Pivots'!G$15)*('Copied Pivots'!$B$5:$B$12='Copied Pivots'!$B$12)*'Copied Pivots'!$C$5:$AL$12),"")=0,"",IFERROR(SUMIF('Copied Pivots'!$A$40:$A$61,$D14,'Copied Pivots'!G$40:G$61)/SUMPRODUCT(('Copied Pivots'!$C$3:$AL$3='Copied Pivots'!G$15)*('Copied Pivots'!$B$5:$B$12='Copied Pivots'!$B$12)*'Copied Pivots'!$C$5:$AL$12),"")) | K14: =IF(IFERROR(SUMIF('Copied Pivots'!$A$40:$A$61,$D14,'Copied Pivots'!H$40:H$61)/SUMPRODUCT(('Copied Pivots'!$C$3:$AL$3='Copied Pivots'!H$15)*('Copied Pivots'!$B$5:$B$12='Copied Pivots'!$B$12)*'Copied Pivots'!$C$5:$AL$12),"")=0,"",IFERROR(SUMIF('Copied Pivots'!$A$40:$A$61,$D14,'Copied Pivots'!H$40:H$61)/SUMPRODUCT(('Copied Pivots'!$C$3:$AL$3='Copied Pivots'!H$15)*('Copied Pivots'!$B$5:$B$12='Copied Pivots'!$B$12)*'Copied Pivots'!$C$5:$AL$12),"")) | L14: =IF(IFERROR(SUMIF('Copied Pivots'!$A$40:$A$61,$D14,'Copied Pivots'!I$40:I$61)/SUMPRODUCT(('Copied Pivots'!$C$3:$AL$3='Copied Pivots'!I$15)*('Copied Pivots'!$B$5:$B$12='Copied Pivots'!$B$12)*'Copied Pivots'!$C$5:$AL$12),"")=0,"",IFERROR(SUMIF('Copied Pivots'!$A$40:$A$61,$D14,'Copied Pivots'!I$40:I$61)/SUMPRODUCT(('Copied Pivots'!$C$3:$AL$3='Copied Pivots'!I$15)*('Copied Pivots'!$B$5:$B$12='Copied Pivots'!$B$12)*'Copied Pivots'!$C$5:$AL$12),"")) | M14: =IF(IFERROR(SUMIF('Copied Pivots'!$A$40:$A$61,$D14,'Copied Pivots'!J$40:J$61)/SUMPRODUCT(('Copied Pivots'!$C$3:$AL$3='Copied Pivots'!J$15)*('Copied Pivots'!$B$5:$B$12='Copied Pivots'!$B$12)*'Copied Pivots'!$C$5:$AL$12),"")=0,"",IFERROR(SUMIF('Copied Pivots'!$A$40:$A$61,$D14,'Copied Pivots'!J$40:J$61)/SUMPRODUCT(('Copied Pivots'!$C$3:$AL$3='Copied Pivots'!J$15)*('Copied Pivots'!$B$5:$B$12='Copied Pivots'!$B$12)*'Copied Pivots'!$C$5:$AL$12),"")) | ... V14: =IF(IFERROR(SUMIF('Copied Pivots'!$A$40:$A$61,$D14,'Copied Pivots'!S$40:S$61)/SUMPRODUCT(('Copied Pivots'!$C$3:$AL$3='Copied Pivots'!S$15)*('Copied Pivots'!$B$5:$B$12='Copied Pivots'!$B$12)*'Copied Pivots'!$C$5:$AL$12),"")=0,"",IFERROR(SUMIF('Copied Pivots'!$A$40:$A$61,$D14,'Copied Pivots'!S$40:S$61)/SUMPRODUCT(('Copied Pivots'!$C$3:$AL$3='Copied Pivots'!S$15)*('Copied Pivots'!$B$5:$B$12='Copied Pivots'!$B$12)*'Copied Pivots'!$C$5:$AL$12),"")) | W14: =IF(IFERROR(SUMIF('Copied Pivots'!$A$40:$A$61,$D14,'Copied Pivots'!T$40:T$57)/SUMPRODUCT(('Copied Pivots'!$C$3:$AL$3='Copied Pivots'!T$15)*('Copied Pivots'!$B$5:$B$12='Copied Pivots'!$B$12)*'Copied Pivots'!$C$5:$AL$12),"")=0,"",IFERROR(SUMIF('Copied Pivots'!$A$40:$A$61,$D14,'Copied Pivots'!T$40:T$57)/SUMPRODUCT(('Copied Pivots'!$C$3:$AL$3='Copied Pivots'!T$15)*('Copied Pivots'!$B$5:$B$12='Copied Pivots'!$B$12)*'Copied Pivots'!$C$5:$AL$12),"")) | X14: =IF(IFERROR(SUMIF('Copied Pivots'!$A$40:$A$61,$D14,'Copied Pivots'!U$40:U$57)/SUMPRODUCT(('Copied Pivots'!$C$3:$AL$3='Copied Pivots'!U$15)*('Copied Pivots'!$B$5:$B$12='Copied Pivots'!$B$12)*'Copied Pivots'!$C$5:$AL$12),"")=0,"",IFERROR(SUMIF('Copied Pivots'!$A$40:$A$61,$D14,'Copied Pivots'!U$40:U$57)/SUMPRODUCT(('Copied Pivots'!$C$3:$AL$3='Copied Pivots'!U$15)*('Copied Pivots'!$B$5:$B$12='Copied Pivots'!$B$12)*'Copied Pivots'!$C$5:$AL$12),"")) | Y14: =IF(IFERROR(SUMIF('Copied Pivots'!$A$40:$A$61,$D14,'Copied Pivots'!V$40:V$57)/SUMPRODUCT(('Copied Pivots'!$C$3:$AL$3='Copied Pivots'!V$15)*('Copied Pivots'!$B$5:$B$12='Copied Pivots'!$B$12)*'Copied Pivots'!$C$5:$AL$12),"")=0,"",IFERROR(SUMIF('Copied Pivots'!$A$40:$A$61,$D14,'Copied Pivots'!V$40:V$57)/SUMPRODUCT(('Copied Pivots'!$C$3:$AL$3='Copied Pivots'!V$15)*('Copied Pivots'!$B$5:$B$12='Copied Pivots'!$B$12)*'Copied Pivots'!$C$5:$AL$12),"")) | Z14: =IF(IFERROR(SUMIF('Copied Pivots'!$A$40:$A$61,$D14,'Copied Pivots'!W$40:W$57)/SUMPRODUCT(('Copied Pivots'!$C$3:$AL$3='Copied Pivots'!W$15)*('Copied Pivots'!$B$5:$B$12='Copied Pivots'!$B$12)*'Copied Pivots'!$C$5:$AL$12),"")=0,"",IFERROR(SUMIF('Copied Pivots'!$A$40:$A$61,$D14,'Copied Pivots'!W$40:W$57)/SUMPRODUCT(('Copied Pivots'!$C$3:$AL$3='Copied Pivots'!W$15)*('Copied Pivots'!$B$5:$B$12='Copied Pivots'!$B$12)*'Copied Pivots'!$C$5:$AL$12),"")) | AA14: =IF(IFERROR(SUMIF('Copied Pivots'!$A$40:$A$61,$D14,'Copied Pivots'!X$40:X$57)/SUMPRODUCT(('Copied Pivots'!$C$3:$AL$3='Copied Pivots'!X$15)*('Copied Pivots'!$B$5:$B$12='Copied Pivots'!$B$12)*'Copied Pivots'!$C$5:$AL$12),"")=0,"",IFERROR(SUMIF('Copied Pivots'!$A$40:$A$61,$D14,'Copied Pivots'!X$40:X$57)/SUMPRODUCT(('Copied Pivots'!$C$3:$AL$3='Copied Pivots'!X$15)*('Copied Pivots'!$B$5:$B$12='Copied Pivots'!$B$12)*'Copied Pivots'!$C$5:$AL$12),"")) | AB14: =IF(IFERROR(SUMIF('Copied Pivots'!$A$40:$A$61,$D14,'Copied Pivots'!Y$40:Y$57)/SUMPRODUCT(('Copied Pivots'!$C$3:$AL$3='Copied Pivots'!Y$15)*('Copied Pivots'!$B$5:$B$12='Copied Pivots'!$B$12)*'Copied Pivots'!$C$5:$AL$12),"")=0,"",IFERROR(SUMIF('Copied Pivots'!$A$40:$A$61,$D14,'Copied Pivots'!Y$40:Y$57)/SUMPRODUCT(('Copied Pivots'!$C$3:$AL$3='Copied Pivots'!Y$15)*('Copied Pivots'!$B$5:$B$12='Copied Pivots'!$B$12)*'Copied Pivots'!$C$5:$AL$12),"")) | AC14: =IF(IFERROR(SUMIF('Copied Pivots'!$A$40:$A$61,$D14,'Copied Pivots'!Z$40:Z$57)/SUMPRODUCT(('Copied Pivots'!$C$3:$AL$3='Copied Pivots'!Z$15)*('Copied Pivots'!$B$5:$B$12='Copied Pivots'!$B$12)*'Copied Pivots'!$C$5:$AL$12),"")=0,"",IFERROR(SUMIF('Copied Pivots'!$A$40:$A$61,$D14,'Copied Pivots'!Z$40:Z$57)/SUMPRODUCT(('Copied Pivots'!$C$3:$AL$3='Copied Pivots'!Z$15)*('Copied Pivots'!$B$5:$B$12='Copied Pivots'!$B$12)*'Copied Pivots'!$C$5:$AL$12),"")) | AD14: =IF(IFERROR(SUMIF('Copied Pivots'!$A$40:$A$61,$D14,'Copied Pivots'!AA$40:AA$57)/SUMPRODUCT(('Copied Pivots'!$C$3:$AL$3='Copied Pivots'!AA$15)*('Copied Pivots'!$B$5:$B$12='Copied Pivots'!$B$12)*'Copied Pivots'!$C$5:$AL$12),"")=0,"",IFERROR(SUMIF('Copied Pivots'!$A$40:$A$61,$D14,'Copied Pivots'!AA$40:AA$57)/SUMPRODUCT(('Copied Pivots'!$C$3:$AL$3='Copied Pivots'!AA$15)*('Copied Pivots'!$B$5:$B$12='Copied Pivots'!$B$12)*'Copied Pivots'!$C$5:$AL$12),"")) | AE14: =IF(IFERROR(SUMIF('Copied Pivots'!$A$40:$A$61,$D14,'Copied Pivots'!AB$40:AB$57)/SUMPRODUCT(('Copied Pivots'!$C$3:$AL$3='Copied Pivots'!AB$15)*('Copied Pivots'!$B$5:$B$12='Copied Pivots'!$B$12)*'Copied Pivots'!$C$5:$AL$12),"")=0,"",IFERROR(SUMIF('Copied Pivots'!$A$40:$A$61,$D14,'Copied Pivots'!AB$40:AB$57)/SUMPRODUCT(('Copied Pivots'!$C$3:$AL$3='Copied Pivots'!AB$15)*('Copied Pivots'!$B$5:$B$12='Copied Pivots'!$B$12)*'Copied Pivots'!$C$5:$AL$12),""))
C15: SPRIGAS100 | D15: SUPELC | E15: =AVERAGE(F15:AE15) -> 0.0097056802 | F15: =IF(IFERROR(SUMIF('Copied Pivots'!$A$40:$A$61,$D15,'Copied Pivots'!C$40:C$61)/SUMPRODUCT(('Copied Pivots'!$C$3:$AL$3='Copied Pivots'!C$15)*('Copied Pivots'!$B$5:$B$12='Copied Pivots'!$B$12)*'Copied Pivots'!$C$5:$AL$12),"")=0,"",IFERROR(SUMIF('Copied Pivots'!$A$40:$A$61,$D15,'Copied Pivots'!C$40:C$61)/SUMPRODUCT(('Copied Pivots'!$C$3:$AL$3='Copied Pivots'!C$15)*('Copied Pivots'!$B$5:$B$12='Copied Pivots'!$B$12)*'Copied Pivots'!$C$5:$AL$12),"")) -> 0.018998222 | G15: =IF(IFERROR(SUMIF('Copied Pivots'!$A$40:$A$61,$D15,'Copied Pivots'!D$40:D$61)/SUMPRODUCT(('Copied Pivots'!$C$3:$AL$3='Copied Pivots'!D$15)*('Copied Pivots'!$B$5:$B$12='Copied Pivots'!$B$12)*'Copied Pivots'!$C$5:$AL$12),"")=0,"",IFERROR(SUMIF('Copied Pivots'!$A$40:$A$61,$D15,'Copied Pivots'!D$40:D$61)/SUMPRODUCT(('Copied Pivots'!$C$3:$AL$3='Copied Pivots'!D$15)*('Copied Pivots'!$B$5:$B$12='Copied Pivots'!$B$12)*'Copied Pivots'!$C$5:$AL$12),"")) -> 0.0082897658 | H15: =IF(IFERROR(SUMIF('Copied Pivots'!$A$40:$A$61,$D15,'Copied Pivots'!E$40:E$61)/SUMPRODUCT(('Copied Pivots'!$C$3:$AL$3='Copied Pivots'!E$15)*('Copied Pivots'!$B$5:$B$12='Copied Pivots'!$B$12)*'Copied Pivots'!$C$5:$AL$12),"")=0,"",IFERROR(SUMIF('Copied Pivots'!$A$40:$A$61,$D15,'Copied Pivots'!E$40:E$61)/SUMPRODUCT(('Copied Pivots'!$C$3:$AL$3='Copied Pivots'!E$15)*('Copied Pivots'!$B$5:$B$12='Copied Pivots'!$B$12)*'Copied Pivots'!$C$5:$AL$12),"")) | I15: =IF(IFERROR(SUMIF('Copied Pivots'!$A$40:$A$61,$D15,'Copied Pivots'!F$40:F$61)/SUMPRODUCT(('Copied Pivots'!$C$3:$AL$3='Copied Pivots'!F$15)*('Copied Pivots'!$B$5:$B$12='Copied Pivots'!$B$12)*'Copied Pivots'!$C$5:$AL$12),"")=0,"",IFERROR(SUMIF('Copied Pivots'!$A$40:$A$61,$D15,'Copied Pivots'!F$40:F$61)/SUMPRODUCT(('Copied Pivots'!$C$3:$AL$3='Copied Pivots'!F$15)*('Copied Pivots'!$B$5:$B$12='Copied Pivots'!$B$12)*'Copied Pivots'!$C$5:$AL$12),"")) -> 0.0013802062 | J15: =IF(IFERROR(SUMIF('Copied Pivots'!$A$40:$A$61,$D15,'Copied Pivots'!G$40:G$61)/SUMPRODUCT(('Copied Pivots'!$C$3:$AL$3='Copied Pivots'!G$15)*('Copied Pivots'!$B$5:$B$12='Copied Pivots'!$B$12)*'Copied Pivots'!$C$5:$AL$12),"")=0,"",IFERROR(SUMIF('Copied Pivots'!$A$40:$A$61,$D15,'Copied Pivots'!G$40:G$61)/SUMPRODUCT(('Copied Pivots'!$C$3:$AL$3='Copied Pivots'!G$15)*('Copied Pivots'!$B$5:$B$12='Copied Pivots'!$B$12)*'Copied Pivots'!$C$5:$AL$12),"")) | K15: =IF(IFERROR(SUMIF('Copied Pivots'!$A$40:$A$61,$D15,'Copied Pivots'!H$40:H$61)/SUMPRODUCT(('Copied Pivots'!$C$3:$AL$3='Copied Pivots'!H$15)*('Copied Pivots'!$B$5:$B$12='Copied Pivots'!$B$12)*'Copied Pivots'!$C$5:$AL$12),"")=0,"",IFERROR(SUMIF('Copied Pivots'!$A$40:$A$61,$D15,'Copied Pivots'!H$40:H$61)/SUMPRODUCT(('Copied Pivots'!$C$3:$AL$3='Copied Pivots'!H$15)*('Copied Pivots'!$B$5:$B$12='Copied Pivots'!$B$12)*'Copied Pivots'!$C$5:$AL$12),"")) -> 0.0013018714 | L15: =IF(IFERROR(SUMIF('Copied Pivots'!$A$40:$A$61,$D15,'Copied Pivots'!I$40:I$61)/SUMPRODUCT(('Copied Pivots'!$C$3:$AL$3='Copied Pivots'!I$15)*('Copied Pivots'!$B$5:$B$12='Copied Pivots'!$B$12)*'Copied Pivots'!$C$5:$AL$12),"")=0,"",IFERROR(SUMIF('Copied Pivots'!$A$40:$A$61,$D15,'Copied Pivots'!I$40:I$61)/SUMPRODUCT(('Copied Pivots'!$C$3:$AL$3='Copied Pivots'!I$15)*('Copied Pivots'!$B$5:$B$12='Copied Pivots'!$B$12)*'Copied Pivots'!$C$5:$AL$12),"")) -> 0.0039616848 | M15: =IF(IFERROR(SUMIF('Copied Pivots'!$A$40:$A$61,$D15,'Copied Pivots'!J$40:J$61)/SUMPRODUCT(('Copied Pivots'!$C$3:$AL$3='Copied Pivots'!J$15)*('Copied Pivots'!$B$5:$B$12='Copied Pivots'!$B$12)*'Copied Pivots'!$C$5:$AL$12),"")=0,"",IFERROR(SUMIF('Copied Pivots'!$A$40:$A$61,$D15,'Copied Pivots'!J$40:J$61)/SUMPRODUCT(('Copied Pivots'!$C$3:$AL$3='Copied Pivots'!J$15)*('Copied Pivots'!$B$5:$B$12='Copied Pivots'!$B$12)*'Copied Pivots'!$C$5:$AL$12),"")) | ... V15: =IF(IFERROR(SUMIF('Copied Pivots'!$A$40:$A$61,$D15,'Copied Pivots'!S$40:S$61)/SUMPRODUCT(('Copied Pivots'!$C$3:$AL$3='Copied Pivots'!S$15)*('Copied Pivots'!$B$5:$B$12='Copied Pivots'!$B$12)*'Copied Pivots'!$C$5:$AL$12),"")=0,"",IFERROR(SUMIF('Copied Pivots'!$A$40:$A$61,$D15,'Copied Pivots'!S$40:S$61)/SUMPRODUCT(('Copied Pivots'!$C$3:$AL$3='Copied Pivots'!S$15)*('Copied Pivots'!$B$5:$B$12='Copied Pivots'!$B$12)*'Copied Pivots'!$C$5:$AL$12),"")) | W15: =IF(IFERROR(SUMIF('Copied Pivots'!$A$40:$A$61,$D15,'Copied Pivots'!T$40:T$57)/SUMPRODUCT(('Copied Pivots'!$C$3:$AL$3='Copied Pivots'!T$15)*('Copied Pivots'!$B$5:$B$12='Copied Pivots'!$B$12)*'Copied Pivots'!$C$5:$AL$12),"")=0,"",IFERROR(SUMIF('Copied Pivots'!$A$40:$A$61,$D15,'Copied Pivots'!T$40:T$57)/SUMPRODUCT(('Copied Pivots'!$C$3:$AL$3='Copied Pivots'!T$15)*('Copied Pivots'!$B$5:$B$12='Copied Pivots'!$B$12)*'Copied Pivots'!$C$5:$AL$12),"")) -> 0.0030243804 | X15: =IF(IFERROR(SUMIF('Copied Pivots'!$A$40:$A$61,$D15,'Copied Pivots'!U$40:U$57)/SUMPRODUCT(('Copied Pivots'!$C$3:$AL$3='Copied Pivots'!U$15)*('Copied Pivots'!$B$5:$B$12='Copied Pivots'!$B$12)*'Copied Pivots'!$C$5:$AL$12),"")=0,"",IFERROR(SUMIF('Copied Pivots'!$A$40:$A$61,$D15,'Copied Pivots'!U$40:U$57)/SUMPRODUCT(('Copied Pivots'!$C$3:$AL$3='Copied Pivots'!U$15)*('Copied Pivots'!$B$5:$B$12='Copied Pivots'!$B$12)*'Copied Pivots'!$C$5:$AL$12),"")) -> 0.0027738498 | Y15: =IF(IFERROR(SUMIF('Copied Pivots'!$A$40:$A$61,$D15,'Copied Pivots'!V$40:V$57)/SUMPRODUCT(('Copied Pivots'!$C$3:$AL$3='Copied Pivots'!V$15)*('Copied Pivots'!$B$5:$B$12='Copied Pivots'!$B$12)*'Copied Pivots'!$C$5:$AL$12),"")=0,"",IFERROR(SUMIF('Copied Pivots'!$A$40:$A$61,$D15,'Copied Pivots'!V$40:V$57)/SUMPRODUCT(('Copied Pivots'!$C$3:$AL$3='Copied Pivots'!V$15)*('Copied Pivots'!$B$5:$B$12='Copied Pivots'!$B$12)*'Copied Pivots'!$C$5:$AL$12),"")) -> 0.0021889089 | Z15: =IF(IFERROR(SUMIF('Copied Pivots'!$A$40:$A$61,$D15,'Copied Pivots'!W$40:W$57)/SUMPRODUCT(('Copied Pivots'!$C$3:$AL$3='Copied Pivots'!W$15)*('Copied Pivots'!$B$5:$B$12='Copied Pivots'!$B$12)*'Copied Pivots'!$C$5:$AL$12),"")=0,"",IFERROR(SUMIF('Copied Pivots'!$A$40:$A$61,$D15,'Copied Pivots'!W$40:W$57)/SUMPRODUCT(('Copied Pivots'!$C$3:$AL$3='Copied Pivots'!W$15)*('Copied Pivots'!$B$5:$B$12='Copied Pivots'!$B$12)*'Copied Pivots'!$C$5:$AL$12),"")) | AA15: =IF(IFERROR(SUMIF('Copied Pivots'!$A$40:$A$61,$D15,'Copied Pivots'!X$40:X$57)/SUMPRODUCT(('Copied Pivots'!$C$3:$AL$3='Copied Pivots'!X$15)*('Copied Pivots'!$B$5:$B$12='Copied Pivots'!$B$12)*'Copied Pivots'!$C$5:$AL$12),"")=0,"",IFERROR(SUMIF('Copied Pivots'!$A$40:$A$61,$D15,'Copied Pivots'!X$40:X$57)/SUMPRODUCT(('Copied Pivots'!$C$3:$AL$3='Copied Pivots'!X$15)*('Copied Pivots'!$B$5:$B$12='Copied Pivots'!$B$12)*'Copied Pivots'!$C$5:$AL$12),"")) -> 0.0077164301 | AB15: =IF(IFERROR(SUMIF('Copied Pivots'!$A$40:$A$61,$D15,'Copied Pivots'!Y$40:Y$57)/SUMPRODUCT(('Copied Pivots'!$C$3:$AL$3='Copied Pivots'!Y$15)*('Copied Pivots'!$B$5:$B$12='Copied Pivots'!$B$12)*'Copied Pivots'!$C$5:$AL$12),"")=0,"",IFERROR(SUMIF('Copied Pivots'!$A$40:$A$61,$D15,'Copied Pivots'!Y$40:Y$57)/SUMPRODUCT(('Copied Pivots'!$C$3:$AL$3='Copied Pivots'!Y$15)*('Copied Pivots'!$B$5:$B$12='Copied Pivots'!$B$12)*'Copied Pivots'!$C$5:$AL$12),"")) -> 0.0046730202 | AC15: =IF(IFERROR(SUMIF('Copied Pivots'!$A$40:$A$61,$D15,'Copied Pivots'!Z$40:Z$57)/SUMPRODUCT(('Copied Pivots'!$C$3:$AL$3='Copied Pivots'!Z$15)*('Copied Pivots'!$B$5:$B$12='Copied Pivots'!$B$12)*'Copied Pivots'!$C$5:$AL$12),"")=0,"",IFERROR(SUMIF('Copied Pivots'!$A$40:$A$61,$D15,'Copied Pivots'!Z$40:Z$57)/SUMPRODUCT(('Copied Pivots'!$C$3:$AL$3='Copied Pivots'!Z$15)*('Copied Pivots'!$B$5:$B$12='Copied Pivots'!$B$12)*'Copied Pivots'!$C$5:$AL$12),"")) | AD15: =IF(IFERROR(SUMIF('Copied Pivots'!$A$40:$A$61,$D15,'Copied Pivots'!AA$40:AA$57)/SUMPRODUCT(('Copied Pivots'!$C$3:$AL$3='Copied Pivots'!AA$15)*('Copied Pivots'!$B$5:$B$12='Copied Pivots'!$B$12)*'Copied Pivots'!$C$5:$AL$12),"")=0,"",IFERROR(SUMIF('Copied Pivots'!$A$40:$A$61,$D15,'Copied Pivots'!AA$40:AA$57)/SUMPRODUCT(('Copied Pivots'!$C$3:$AL$3='Copied Pivots'!AA$15)*('Copied Pivots'!$B$5:$B$12='Copied Pivots'!$B$12)*'Copied Pivots'!$C$5:$AL$12),"")) -> 0.0076177285 | AE15: =IF(IFERROR(SUMIF('Copied Pivots'!$A$40:$A$61,$D15,'Copied Pivots'!AB$40:AB$57)/SUMPRODUCT(('Copied Pivots'!$C$3:$AL$3='Copied Pivots'!AB$15)*('Copied Pivots'!$B$5:$B$12='Copied Pivots'!$B$12)*'Copied Pivots'!$C$5:$AL$12),"")=0,"",IFERROR(SUMIF('Copied Pivots'!$A$40:$A$61,$D15,'Copied Pivots'!AB$40:AB$57)/SUMPRODUCT(('Copied Pivots'!$C$3:$AL$3='Copied Pivots'!AB$15)*('Copied Pivots'!$B$5:$B$12='Copied Pivots'!$B$12)*'Copied Pivots'!$C$5:$AL$12),"")) -> 0.00054863866
