Workbook
Name _.DMD.: #REF!
Name _.DMD.: #REF!
Name Cars_12: '[1]TechRep-Doc'!#REF!
Name Cars_12: '[1]TechRep-Doc'!#REF!
Name Cars_12: '[1]TechRep-Doc'!#REF!
Name ddddd: [2]AGR_Fuels!$A$2
Name DISCRATE: '[1]TechRep-Doc'!#REF!
Name DISCRATE: '[1]TechRep-Doc'!#REF!
Name DISCRATE: '[1]TechRep-Doc'!#REF!
Name FID_1: [1]AGR_Fuels!$A$2
Name FID_1: [1]AGR_Fuels!$A$2
Name FID_1: [3]AGR_Fuels!$A$2
Name GROWTH: '[1]TechRep-Doc'!#REF!
Name GROWTH: '[1]TechRep-Doc'!#REF!
Name GROWTH: '[1]TechRep-Doc'!#REF!
Name GROWTH_TID: '[1]TechRep-Doc'!#REF!
Name GROWTH_TID: '[1]TechRep-Doc'!#REF!
Name GROWTH_TID: '[1]TechRep-Doc'!#REF!
Name INVCOST: '[1]TechRep-Doc'!#REF!
Name INVCOST: '[1]TechRep-Doc'!#REF!
Name INVCOST: '[1]TechRep-Doc'!#REF!
Name LIFE: '[1]TechRep-Doc'!#REF!
Name LIFE: '[1]TechRep-Doc'!#REF!
Name LIFE: '[1]TechRep-Doc'!#REF!
Name NAs_CCAR: '[1]TechRep-Doc'!#REF!
Name NAs_CCAR: '[1]TechRep-Doc'!#REF!
Name NAs_CCAR: '[1]TechRep-Doc'!#REF!
Name SETS: '[1]TechRep-Doc'!#REF!
Name SETS: '[1]TechRep-Doc'!#REF!
Name SETS: '[1]TechRep-Doc'!#REF!
Name TRTGAB005: '[1]TechRep-Doc'!#REF!
Name TRTGAB005: '[1]TechRep-Doc'!#REF!
Name TRTGAB005: '[1]TechRep-Doc'!#REF!
Name TRTGAC005: '[1]TechRep-Doc'!#REF!
Name TRTGAC005: '[1]TechRep-Doc'!#REF!
Name TRTGAC005: '[1]TechRep-Doc'!#REF!
Name Trucks_15: '[1]TechRep-Doc'!#REF!
Name Trucks_15: '[1]TechRep-Doc'!#REF!
Name Trucks_15: '[1]TechRep-Doc'!#REF!
Name TSUB_COST: '[1]TechRep-Doc'!#REF!
Name TSUB_COST: '[1]TechRep-Doc'!#REF!
Name TSUB_COST: '[1]TechRep-Doc'!#REF!
Name x: [1]AGR_Fuels!$A$2

Sheet ELC
A1: \I: All costs in euros 2010
A2: \I: Cogeneration Power Plants -Public
G3: ~FI_T: EUR10
A4: Sets | B4: Unts | C4: TechName | D4: TechDesc | E4: Comm-IN | F4: Comm-OUT | G4: YEAR | H4: Cap2Act | I4: START | J4: EFF~2006 | K4: EFF~2010 | L4: EFF~2015 | M4: EFF~2020 | N4: EFF~2030 | O4: AFA | P4: Peak~WP | Q4: CEH~2006 | R4: CEH~2010 | S4: CEH~2015 | T4: CEH~2020 | U4: CEH~2030 | V4: CHPR~UP~2006 | W4: CHPR~UP~2010 | X4: CHPR~UP~2015 | Y4: CHPR~UP~2020 | Z4: CHPR~UP~2030 | AA4: CHPR~2006 | AB4: CHPR~2010 | AC4: CHPR~2015 | AD4: CHPR~2020 | AE4: CHPR~2030 | AF4: LIFE | AG4: ILED | AH4: INVCOST~2006 | AI4: INVCOST~2010 | AJ4: INVCOST~2015 | AK4: INVCOST~2020 | AL4: INVCOST~2030 | AM4: FIXOM~2006 | AN4: FIXOM~2010 | AO4: FIXOM~2015 | AP4: FIXOM~2020 | AQ4: FIXOM~2030 | AR4: VAROM~2006 | AS4: VAROM~2010 | AT4: VAROM~2015 | AU4: VAROM~2020 | AV4: VAROM~2030 | AW4: ENV_ACT~2006 | AX4: ENV_ACT~2010 | AY4: ENV_ACT~2015 | AZ4: ENV_ACT~2020 | BA4: ENV_ACT~2030 | BC4: CURR | BF4: Fuel Consumption | BG4: Electricity Prod | BH4: Heat Prod
A5: \I: Units | H5: PJ/GW
C6: PUSMUN | D6: CHP: Steam.Turbine.MUN.PUB | E6: ELCMUN | F6: ELCHIG | H6: 31.536 | I6: 2023 | J6: 0.297 | K6: 0.33 | L6: 0.33 | M6: 0.337 | N6: 0.337 | O6: 0.9 | P6: 1 | Q6: 0.2 | V6: 3.07 | W6: 3.07 | X6: 3.07 | Y6: 3.07 | Z6: 3.07 | AF6: 30 | AG6: 2 | AH6: 3214.75 | AI6: 2529.72 | AJ6: 2401.13 | AK6: 2271.37 | AL6: 1807.27 | AM6: 64.295 | AN6: 50.6177 | AO6: 48.02252 | AP6: 45.4741 | AQ6: 36.1221 | AR6: 3.00433 | AS6: 3.00433 | AT6: 3.00433 | AU6: 3.00433 | AV6: 2.79391 | BC6: EUR10 | BF6: =1*H6*O6/J6 -> 95.563636 | BG6: =BF6*J6 -> 28.3824 | BH6: =BG6*V6 -> 87.133968 | BJ6: =(BG6+BH6)/BF6 -> 1.20879
F7: HETHTH
F8: ELCCOXN | AW8: 0.0556
F9: ELCSO2N | AW9: 0.0972
F10: ELCNOXN | AW10: 0.0972
F11: ELCCH4N | AW11: 0.0006
F12: ELCN2ON | AW12: 0.0057
A13: * | F13: ELCPMBN | AW13: 0.0029
F14: ELCPMAN | AW14: 0.00232
F15: ELCVOCN | AW15: 0.0017
C16: PUICBGS | D16: CHP: Int Combust.BGS.PUB | E16: ELCBGS | F16: ELCHIG | H16: 31.536 | I16: 2023 | J16: 0.4 | K16: 0.4042735 | L16: 0.40591966 | M16: 0.40333333 | N16: 0.40413223 | O16: 0.9 | P16: 1 | AA16: 1.14 | AB16: 1.1708108 | AC16: 1.1922936 | AD16: 1.2260377 | AE16: 1.2377143 | AF16: 25 | AG16: 2 | AH16: 1746.49 | AI16: 1745.32 | AJ16: 1744.15 | AK16: 1741.81 | AL16: 1707.91 | AM16: 34.9531 | AN16: 34.9531 | AO16: 34.87127 | AP16: 34.8362 | AQ16: 34.1348 | AR16: 2.54842 | AS16: 2.54842 | AT16: 2.54842 | AU16: 2.54842 | AV16: 2.54842 | BF16: =1*H16*O16/J16 -> 70.956 | BG16: =BF16*J16 -> 28.3824 | BH16: =BG16*AA16 -> 32.355936 | BJ16: =(BG16+BH16)/BF16 -> 0.856
F17: HETHTH | BC17: EUR10
F18: ELCCOXN | AW18: 0.000205
F19: ELCSO2N | AW19: 0
F20: ELCNOXN | AW20: 1.57e-05
F21: ELCCH4N | AW21: 5.33e-06
F22: ELCN2ON | AW22: 5.33e-06
F23: ELCPMAN | AW23: 4.27e-06
A24: * | F24: ELCPMBN | AW24: 1.33e-06
F25: ELCVOCN | AW25: 2.6e-05
C26: PUCAGAS | D26: CHP: Com cycle GT.Adv.GAS.PUB | E26: ELCGAS | F26: ELCHIG | H26: 31.536 | I26: 2023 | J26: 0.467 | K26: 0.46845083 | L26: 0.4744898 | M26: 0.48311688 | N26: 0.51072356 | O26: 0.9 | P26: 1 | Q26: 0.2 | V26: 1.07 | W26: 1.090381 | X26: 1.122451 | Y26: 1.15 | Z26: 1.18 | AF26: 25 | AG26: 2 | AH26: 1027.55 | AI26: 1019.37 | AJ26: 999.495 | AK26: 979.622 | AL26: 907.144 | AM26: 25.718 | AN26: 25.6011 | AO26: 25.40237 | AP26: 25.2504 | AQ26: 24.4321 | AR26: 2.37307 | AS26: 2.32631 | AT26: 2.27955 | AU26: 2.23279 | AV26: 2.12758 | BF26: =1*H26*O26/J26 -> 60.776017 | BG26: =BF26*J26 -> 28.3824 | BH26: =BG26*V26 -> 30.369168 | BJ26: =(BG26+BH26)/BF26 -> 0.96669
F27: HETHTH
F28: ELCCOXN | AW28: 0.01 | BC28: EUR10
F29: ELCSO2N | AW29: 0
F30: ELCNOXN | AW30: 0.09
F31: ELCCH4N | AW31: 0
F32: ELCN2ON | AW32: 0
A33: * | F33: ELCPMBN | AW33: 0
F34: ELCVOCN | AW34: 0
C35: PUGWOO | D35: CHP: Biomass.gasification.WOO.PUB | E35: ELCWOO | F35: ELCHIG | H35: 31.536 | I35: 2023 | J35: 0.336 | K35: 0.336 | L35: 0.336 | M35: 0.336 | N35: 0.336 | O35: 0.7 | P35: 1 | Q35: 0.2 | V35: 1.1041667 | W35: 1.1041667 | X35: 1.1041667 | Y35: 1.1041667 | Z35: 1.1041667 | AF35: 25 | AG35: 2 | AR35: 0 | AS35: 0 | AT35: 0 | AU35: 0 | AV35: 0 | BC35: EUR10 | BF35: =1*H35*O35/J35 -> 65.7 | BG35: =BF35*J35 -> 22.0752 | BH35: =BG35*V35 -> 24.3747 | BJ35: =(BG35+BH35)/BF35 -> 0.707
F36: HETHTH
F37: ELCCOXN | AW37: 0.0556
F38: ELCSO2N | AW38: 0.0972
F39: ELCNOXN | AW39: 0.0972
F40: ELCCH4N | AW40: 0.0006
...

Sheet ELC_Add
B3: ~FI_Process
B4: Sets | C4: TechName | D4: TechDesc | E4: Tact | F4: Tcap | G4: Tslvl | H4: PrimaryCG | I4: Vintage
B5: ELE | C5: EUSTIISGAS101 | D5: EPLT: Steam Turbine.IISGAS | E5: PJ | F5: GW | G5: DAYNITE | I5: NO
B6: ELE | C6: EUSTIISGASCS101 | D6: EPLT: Steam Turbine.CO2Seq.IISGAS | E6: PJ | F6: GW | G6: DAYNITE | I6: NO
B7: PRE | C7: ELCBFG01 | D7: Fuel Tech New - Blast Furnace Gas (ELC) | E7: PJ | F7: PJa | I7: NO
B8: PRE | C8: ELCBFT01 | D8: Fuel Tech New - Blast Furnace Gas TGR (ELC) | E8: PJ | F8: PJa | I8: NO
B9: PRE | C9: ELCCOG01 | D9: Fuel Tech New - Cokes Gas (ELC) | E9: PJ | F9: PJa | I9: NO
B10: PRE | C10: ELCIIS01 | D10: Fuel Tech New - IIS Gas - Corex Gas or BFG TGR with CCS or BOF (ELC) | E10: PJ | F10: PJa | I10: NO
B11: PRE | C11: ELCCOP01 | D11: Fuel Tech New - Corex with CCS Gas (ELC) | E11: PJ | F11: PJa | I11: NO
B13: MovedToSysSettings
B14: CSet | C14: CommName | D14: CommDesc | E14: Unit | F14: LimType | G14: CTSLvl | H14: PeakTS | I14: Ctype
B15: NRG | C15: ELCBFG | D15: Blast Furnace Gas (ELC) | E15: PJ
B16: NRG | C16: ELCBFT | D16: Blast Furnace Gas TGR (ELC) | E16: PJ
B17: NRG | C17: ELCCOG | D17: Cokes Gas (ELC) | E17: PJ
B18: NRG | C18: ELCIIS | D18: Gas from Corex and Blast Furnace TGR with CCS (ELC) | E18: PJ
B19: NRG | C19: ELCCOP | D19: Corex Gas from COREX with CCS (ELC) | E19: PJ
B20: *NRG | C20: ELCNGA | D20: Natural Gas (ELC) | E20: PJ
E23: ~FI_T
B24: TechName | C24: Comm-IN | D24: Comm-OUT | E24: YEAR | F24: Cap2Act | G24: START | H24: EFF~2006 | I24: EFF~2010 | J24: EFF~2015 | K24: EFF~2025 | L24: EFF~2035 | M24: INVCOST~2006 | N24: INVCOST~2010 | O24: INVCOST~2015 | P24: INVCOST~2025 | Q24: INVCOST~2035 | R24: FIXOM~2006 | S24: FIXOM~2010 | T24: FIXOM~2015 | U24: FIXOM~2025 | V24: FIXOM~2035 | W24: VAROM~2006 | X24: VAROM~2010 | Y24: VAROM~2015 | Z24: VAROM~2025 | AA24: VAROM~2035 | AB24: AFA | AC24: LIFE | AD24: Peak~Annual | AE24: ILED~2006 | AF24: ILED~0 | AG24: Share~UP
B25: \I: Units | F25: PJ/GW | M25: $/kW | N25: $/kW | O25: $/kW | P25: $/kW | Q25: $/kW | R25: $/kW | S25: $/kW | T25: $/kW | U25: $/kW | V25: $/kW | W25: $/GJ | X25: $/GJ | Y25: $/GJ | Z25: $/GJ | AA25: $/GJ
B26: \I: Electricity Power Plants
B27: EUSTIISGAS101 | C27: ELCBFG | D27: ELCHIG | E27: 2006 | F27: 31.536 | G27: 2006 | H27: 0.42 | I27: 0.42 | J27: 0.4425 | K27: 0.465 | L27: 0.4725 | M27: 1071.0134 | N27: 1071.0134 | O27: 1071.0134 | P27: 973.64855 | Q27: 876.2837 | R27: 25.331609 | S27: 22.516986 | W27: 0.4796118 | X27: 0.4796118 | Y27: 0.4796118 | Z27: 0.4796118 | AA27: 0.4796118 | AB27: 0.85 | AC27: 25 | AD27: 1 | AE27: 2 | AF27: 3 | AG27: 0.8
C28: ELCBFT
C29: ELCCOG
C30: ELCIIS
C31: ELCCOP
C32: \I:ELCGAS
B33: EUSTIISGASCS101 | C33: ELCBFG | D33: ELCHIG | E33: 2015 | F33: 31.536 | G33: 2015 | J33: 0.3525 | K33: 0.375 | L33: 0.3825 | O33: 1246.6514 | P33: 1169.6831 | Q33: 1092.7148 | S33: 59.107088 | X33: 0.52768557 | Y33: 0.52768557 | Z33: 0.52768557 | AA33: 0.52768557 | AB33: 0.85 | AC33: 25 | AD33: 1 | AE33: 2 | AF33: 3 | AG33: 0.8
C34: ELCBFT
C35: ELCCOG
C36: ELCIIS
C37: ELCCOP
C38: \I:ELCGAS
B41: \I:New Fuel Distribution technologies
B43: New infrastructure for electricity fuels | D43: ~FI_T
B44: TechName | C44: Comm-IN | D44: Comm-OUT | E44: EFF | F44: INVCOST | G44: Life | H44: START
D45: \I: UNITS | F45: $/GJ-Yr | G45: Yr
B46: ELCBFG01 | C46: GASBFG | E46: 1 | F46: 1 | G46: 60 | H46: 2006
D47: ELCBFG
B48: ELCBFT01 | C48: GASBFT | E48: 1 | F48: 1 | G48: 60 | H48: 2006
...

Sheet SUP
I2: ~FI_T
B3: TechName | C3: TechDesc | D3: TechCapUnit | E3: TechActUnit | F3: Comm-IN | G3: Comm-OUT | H3: Source | I3: Year | J3: AF | K3: CAPUNIT | L3: EFF | M3: FIXOM | N3: INPUT | O3: INVCOST | P3: LIFE | Q3: OUTPUT | R3: START | S3: VAROM
B4: BBLQDME110 | C4: Gasification, black liquor to DME | D4: GW | E4: PJ | K4: 31.536 | P4: 20 | R4: 2010
F5: INDBLQ | G5: BIODME | I5: 2010 | J5: 0.913 | M5: 12.222222 | N5: 1.77 | O5: 611.11111 | Q5: 1 | S5: 0.493827160493828
G6: IPPHTH | I6: 2010 | Q6: 0.2
B7: BBLQFTST110 | C7: Gasification, black liquor to FT-diesel | D7: GW | E7: PJ | K7: 31.536 | P7: 20 | R7: 2010
F8: INDBLQ | G8: BIODST | I8: 2010 | J8: 0.913 | M8: 18.888889 | N8: 2.13 | O8: 944.44444 | Q8: 1 | S8: 0.586419753086419
G9: IPPHTH | I9: 2010 | Q9: 0.2
B10: BBLQGAS110 | C10: Gasification, black liquor to methane | D10: GW | E10: PJ | K10: 31.536 | P10: 20 | R10: 2010
F11: INDBLQ | G11: BIOGAS | I11: 2010 | J11: 0.913 | M11: 12.888889 | N11: 1.92 | O11: 644.44444 | Q11: 1 | S11: 0.524691358024692
G12: IPPHTH | I12: 2010 | Q12: 0.2
B13: BBLQMtaH110 | C13: Gasification, black liquor to methanol | D13: GW | E13: PJ | K13: 31.536 | P13: 20 | R13: 2010
F14: INDBLQ | G14: BIOMtaH | I14: 2010 | J14: 0.913 | M14: 11.111111 | N14: 1.79 | O14: 555.55556 | Q14: 1 | S14: 0.493827160493828
G15: IPPHTH | I15: 2010 | Q15: 0.2
B16: BSLUGAS101 | C16: Decomposition, bio waste to biogas (methane) | D16: GW | E16: PJ | F16: BIOSLU | G16: BIOGAS | J16: 0.913 | K16: 31.536 | M16: 55.555556 | N16: 1.69 | O16: 2777.7778 | P16: 20 | Q16: 1 | R16: 2006 | S16: 1.04938271604938
B17: BWOOGAS110 | C17: Gasification, biomass (tree salix etc) to methane | D17: GW | E17: PJ | K17: 31.536 | P17: 20 | R17: 2010
F18: BIOWOO | G18: BIOGAS | I18: 2010 | J18: 0.913 | M18: 30 | N18: 2 | O18: 1500 | Q18: 1 | S18: 0.555555555555556
G19: SUPHTH | I19: 2010 | Q19: 0.2
B20: \I: | C20: Gasification, black liquor to hydrogen | D20: GW | E20: PJ | K20: 31.536 | P20: 20 | R20: 2010
B21: \I: | F21: INDBLQ | G21: SYNH2G | I21: 2010 | J21: 0.913 | M21: 11.111111 | N21: 1.69 | O21: 555.55556 | Q21: 1 | S21: 0.462962962962964
B22: \I: | G22: IPPHTH | I22: 2010 | Q22: 0.2
B23: SCOADME110 | C23: Gasification, coal to DME | D23: GW | E23: PJ | K23: 31.536 | P23: 20 | R23: 2010
F24: COAHAR | G24: SUPHTH | I24: 2010 | J24: 0.913 | M24: 28.888889 | N24: 1.75 | O24: 1444.4444 | Q24: 0.18 | S24: 0.493827160493828
G25: SYNDME | I25: 2010 | Q25: 1
B26: SCOADST110 | C26: Gasification, coal to FT-diesel | D26: GW | E26: PJ | K26: 31.536 | P26: 20 | R26: 2010
F27: COAHAR | G27: SYNDST | I27: 2010 | J27: 0.913 | M27: 38.888889 | N27: 2.22 | O27: 1944.4444 | Q27: 1 | S27: 0.617283950617283
G28: SUPHTH | I28: 2010 | Q28: 0.22
B29: SCOAGAS110 | C29: Gasification, coal to methane | D29: GW | E29: PJ | K29: 31.536 | P29: 20 | R29: 2010
F30: COAHAR | G30: GASNAT | I30: 2010 | J30: 0.913 | M30: 30 | N30: 2 | O30: 1500 | Q30: 1 | S30: 0.555555555555556
G31: SUPHTH | I31: 2010 | Q31: 0.2
B32: SCOAMtaH110 | C32: Gasification, coal to methanol | D32: GW | E32: PJ | K32: 31.536 | P32: 20 | R32: 2010
F33: COAHAR | G33: SYNMtaH | I33: 2010 | J33: 0.913 | M33: 27.777778 | N33: 1.85 | O33: 1388.8889 | Q33: 1 | S33: 0.524691358024692
G34: SUPHTH | I34: 2010 | Q34: 0.19
B35: SGASDME110 | C35: Synthesis, natural gas to DME | D35: GW | E35: PJ | F35: GASNAT | G35: SYNDME | J35: 0.913 | K35: 31.536 | M35: 25.86 | N35: 1.35 | O35: 555.55556 | P35: 20 | Q35: 1 | R35: 2010 | S35: 0.154320987654321
B36: SGASDST110 | C36: Synthesis, natural gas to F-T-diesel | D36: GW | E36: PJ | F36: GASNAT | G36: SYNDST | J36: 0.913 | K36: 31.536 | M36: 14.444444 | N36: 1.75 | O36: 722.22222 | P36: 20 | Q36: 1 | R36: 2010 | S36: 0.216049382716049
B37: SGASDST130 | C37: Synthesis, natural gas to F-T-diesel | D37: GW | E37: PJ | F37: GASNAT | G37: SYNDST | I37: 2030 | J37: 0.913 | K37: 31.536 | M37: 5.05 | N37: 1.54 | O37: 287.3 | P37: 20 | Q37: 1 | R37: 2030 | S37: 0.216049382716049
B38: SGASMtaH110 | C38: Synthesis, natural gas to methanol | D38: GW | E38: PJ | F38: GASNAT | G38: SYNMtaH | J38: 0.913 | K38: 31.536 | M38: 10.666667 | N38: 1.43 | O38: 533.33333 | P38: 20 | Q38: 1 | R38: 2010 | S38: 0.666666666666667
B39: \I: BCRPGAS101 | C39: Decomposition, crop for biogas (lucerne etc) to biogas (methane) | D39: GW | E39: PJ | F39: BIOCRP1 | G39: BIOGAS | J39: 0.913 | K39: 31.536 | M39: 20 | N39: 1.69 | O39: 1000 | P39: 20 | Q39: 1 | R39: 2006 | S39: =0.462962962962964 -> 0.46296296
B40: \I: BCRPETH130 | C40: Fermentation, crops (wheat) to ethanol | D40: GW | E40: PJ | F40: BIOCRP1 | G40: BIOGAS | I40: 2030 | J40: 0.913 | K40: 31.536 | M40: 21.13 | N40: 1.5625 | O40: 568 | P40: 20 | Q40: =1.85/2.5*0.2 -> 0.148 | R40: 2006
B41: \I: | G41: BIOETH | I41: 2030 | Q41: 1
...

Sheet IND
J1: ~FI_T
A2: Sets | B2: TechName | C2: TechDesc | D2: TechCapUnit | E2: TechActUnit | F2: Comm-IN | G2: Comm-IN-A | H2: Comm-OUT | I2: Source | J2: Year | K2: AF | L2: CAPUNIT | M2: EFF | N2: CEFF~MATI | O2: EMISSIONS~INDCO2P | P2: EMISSIONS~INDCXFN | Q2: EMISSIONS~INDSCO2N | R2: FIXOM | S2: INPUT | T2: INVCOST | U2: LIFE | V2: OUTPUT | W2: VAROM | X2: SHARE~UP | Y2: Start | Z2: Input~MATI
B3: IALFINPRO01 | C3: IAL.Finishing Processes.01 | D3: Mta | E3: Mt | I3: Prospects for Energy technologies in the Netherlands ECN-C--095-039; MATTER | J3: 2006 | L3: 1 | U3: 20
F4: IALHTH | H4: IAL | J4: 2006 | K4: 0.9 | R4: 25 | S4: 9999 | T4: 500 | V4: 1
F5: INDELC | J5: 2006 | S5: 9999
F6: INDGAS | J6: 2006 | S6: 9999
F7: INDLFO | J7: 2006 | S7: 9999
G8: MALCAL | J8: 2006 | S8: 9999
B9: IALHAHEPF01 | C9: IAL.Hall Heroult.Point Feeders.01 | D9: Mta | E9: Mt | H9: MALCAL | I9: Prospects for Energy technologies in the Netherlands ECN-C--095-039; MATTER | J9: 2006 | L9: 1 | U9: 20 | V9: 1
F10: INDLFO | J10: 2006 | K10: 0.95 | O10: 1000 | P10: 0.125 | R10: 154.54545 | S10: 0.5 | T10: 4700 | W10: 552.27273
F11: INDGAS | J11: 2006 | S11: 1.5
F12: INDELC | J12: 2006 | S12: 37.6
F13: MALBAU | J13: 2006 | S13: 2
B14: IALHAHERG01 | C14: IAL.Hall Heroult.Regular.011 | D14: Mta | E14: Mt | H14: MALCAL | I14: Prospects for Energy technologies in the Netherlands ECN-C--095-039; MATTER | J14: 2006 | L14: 1 | U14: 20 | V14: 1
F15: INDLFO | J15: 2006 | K15: 0.95 | O15: 10000 | P15: 1.25 | R15: 154.54545 | S15: 0.5 | T15: 4500 | W15: 552.27273
F16: INDGAS | J16: 2006 | S16: 1.5
F17: INDELC | J17: 2006 | S17: 39
F18: MALBAU | J18: 2006 | S18: 2
B19: IALHAHERG05 | C19: IAL.Hall Heroult.OPTIMAL ELECTROLYSIS.05 | D19: Mta | E19: Mt | H19: MALCAL | I19: ICARUS-4 Sector study for the Non-Ferrous Metals Industry NWS-E-2000-08 | J19: 2006 | L19: 1 | U19: 20 | V19: 1
F20: INDLFO | J20: 2006 | K20: 0.95 | O20: 7500 | P20: 1.25 | R20: 154.54545 | S20: 0.5 | T20: 4650 | W20: 552.27273
F21: INDGAS | J21: 2006 | S21: 1.5
F22: INDELC | J22: 2006 | S22: 38
F23: MALBAU | J23: 2006 | S23: 2
B24: IALHAHERG10 | C24: IAL.Hall Heroult.reduced electrolyte temperature.10 | D24: Mta | E24: Mt | H24: MALCAL | I24: ICARUS-4 Sector study for the Non-Ferrous Metals Industry NWS-E-2000-08 | J24: 2006 | L24: 1 | U24: 20 | V24: 1
F25: INDLFO | J25: 2010 | K25: 0.95 | O25: 7500 | P25: 1.25 | R25: 154.54545 | S25: 0.5 | T25: 4575 | W25: 552.27273
F26: INDGAS | J26: 2010 | S26: 1.5
F27: INDELC | J27: 2010 | S27: 36.5
F28: MALBAU | J28: 2010 | S28: 2
B29: IALINERAN01 | C29: IAL.Inert Anodes.01 | D29: Mta | E29: Mt | H29: MALCAL | I29: Prospects for Energy technologies in the Netherlands ECN-C--095-039; MATTER | J29: 2006 | L29: 1 | U29: 20 | V29: 1
F30: INDGAS | J30: 2006 | K30: 0.95 | O30: 0 | P30: 0 | R30: 145.45455 | S30: 1.5 | T30: 4100 | W30: 552.27273
F31: INDELC | J31: 2006 | S31: 44
F32: MALBAU | J32: 2006 | S32: 1.9
B33: IALRECYCP01 | C33: IAL.Recycled Production.01 | D33: Mta | E33: Mt | H33: MALCAL | I33: Prospects for Energy technologies in the Netherlands ECN-C--095-039; MATTER | J33: 2006 | L33: 1 | U33: 20 | V33: 1
F34: INDGAS | J34: 2006 | K34: 0.9 | P34: 0 | R34: 275 | S34: 4 | T34: 950 | W34: 160
F35: INDELC | J35: 2006 | S35: 1.38
F36: MALSCR | J36: 2006 | S36: 1.05
F37: MALBAU | J37: 2006 | S37: 2
F38: MALSCR | J38: 2010 | S38: 1.04
F39: MALSCR | J39: 2015 | S39: 1.035
F40: MALSCR | J40: 2020 | S40: 1.03
...

Sheet Renovation building stocks
C1: ~FI_T | AU1: 2019 | AV1: light | AY1: medium | BB1: full
A2: TechName | B2: Comm-OUT | C2: Year | D2: AT | E2: BE | F2: BG | G2: CH | H2: CY | I2: CZ | J2: DE | K2: DK | L2: EE | M2: ES | N2: FI | O2: FR | P2: EL | Q2: HR | R2: HU | S2: IE | T2: IS | U2: IT | V2: LT | W2: LU | X2: LV | Y2: MT | Z2: NL | AA2: NO | AB2: PL | AC2: PT | AD2: RO | AE2: SE | AF2: SI | AG2: SK | AH2: UK | AI2: AL | AJ2: BA | AK2: ME | AL2: MK | AM2: RS | AN2: KS | AO2: AF~FX | AP2: AF~FX~0 | AQ2: LIFE | AU2: Mm2 | AV2: SF Detached | AW2: SF Semi-detached | AX2: Flat | AY2: SF Detached | AZ2: SF Semi-detached | BA2: Flat | BB2: SF Detached | BC2: SF Semi-detached | BD2: Flat
A3: ICNBLRFLAT01 | B3: R_LRFlat | C3: 2019 | D3: =IFERROR(INDEX($AX$3:$AX$33,MATCH(D2,$AU$3:$AU$33,0)),0) -> 4.453241 | E3: =IFERROR(INDEX($AX$3:$AX$33,MATCH(E2,$AU$3:$AU$33,0)),0) -> 6.353707 | F3: =IFERROR(INDEX($AX$3:$AX$33,MATCH(F2,$AU$3:$AU$33,0)),0) -> 7.937044 | G3: =IFERROR(INDEX($AX$3:$AX$33,MATCH(G2,$AU$3:$AU$33,0)),0) -> 6.068384 | H3: =IFERROR(INDEX($AX$3:$AX$33,MATCH(H2,$AU$3:$AU$33,0)),0) -> 0.212601 | I3: =IFERROR(INDEX($AX$3:$AX$33,MATCH(I2,$AU$3:$AU$33,0)),0) -> 7.830872 | J3: =IFERROR(INDEX($AX$3:$AX$33,MATCH(J2,$AU$3:$AU$33,0)),0) -> 45.56301 | K3: =IFERROR(INDEX($AX$3:$AX$33,MATCH(K2,$AU$3:$AU$33,0)),0) -> 2.881297 | ... AN3: =IFERROR(INDEX($AX$3:$AX$33,MATCH(AN2,$AU$3:$AU$33,0)),0) -> 0 | AO3: 1 | AP3: 3 | AQ3: 200 | AU3: AT | AV3: 6.446572 | AW3: 1.101598 | AX3: 4.453241 | AY3: 3.320961 | AZ3: 0.56749 | BA3: 2.294094 | BB3: 0.390701 | BC3: 0.066764 | BD3: 0.269893
A4: ICNBLRDetH01 | B4: R_LRDetH | C4: 2019 | D4: =IFERROR(INDEX($AV$3:$AV$33,MATCH(D2,$AU$3:$AU$33,0)),0) -> 6.446572 | E4: =IFERROR(INDEX($AV$3:$AV$33,MATCH(E2,$AU$3:$AU$33,0)),0) -> 12.98469 | F4: =IFERROR(INDEX($AV$3:$AV$33,MATCH(F2,$AU$3:$AU$33,0)),0) -> 7.761844 | G4: =IFERROR(INDEX($AV$3:$AV$33,MATCH(G2,$AU$3:$AU$33,0)),0) -> 6.477246 | H4: =IFERROR(INDEX($AV$3:$AV$33,MATCH(H2,$AU$3:$AU$33,0)),0) -> 0.422667 | I4: =IFERROR(INDEX($AV$3:$AV$33,MATCH(I2,$AU$3:$AU$33,0)),0) -> 7.45063 | J4: =IFERROR(INDEX($AV$3:$AV$33,MATCH(J2,$AU$3:$AU$33,0)),0) -> 40.74363 | K4: =IFERROR(INDEX($AV$3:$AV$33,MATCH(K2,$AU$3:$AU$33,0)),0) -> 5.748304 | ... AN4: =IFERROR(INDEX($AV$3:$AV$33,MATCH(AN2,$AU$3:$AU$33,0)),0) -> 0 | AO4: 1 | AP4: 3 | AQ4: 200 | AU4: BE | AV4: 12.98469 | AW4: 14.71814 | AX4: 6.353707 | AY4: 1.997645 | AZ4: 2.264329 | BA4: 0.977493 | BB4: 0.399529 | BC4: 0.452866 | BD4: 0.195499
A5: ICNBLRSDtH01 | B5: R_LRSDetH | C5: 2019 | D5: =IFERROR(INDEX($AW$3:$AW$33,MATCH(D2,$AU$3:$AU$33,0)),0) -> 1.101598 | E5: =IFERROR(INDEX($AW$3:$AW$33,MATCH(E2,$AU$3:$AU$33,0)),0) -> 14.71814 | F5: =IFERROR(INDEX($AW$3:$AW$33,MATCH(F2,$AU$3:$AU$33,0)),0) -> 1.823089 | G5: =IFERROR(INDEX($AW$3:$AW$33,MATCH(G2,$AU$3:$AU$33,0)),0) -> 4.523377 | H5: =IFERROR(INDEX($AW$3:$AW$33,MATCH(H2,$AU$3:$AU$33,0)),0) -> 0.260417 | I5: =IFERROR(INDEX($AW$3:$AW$33,MATCH(I2,$AU$3:$AU$33,0)),0) -> 2.042125 | J5: =IFERROR(INDEX($AW$3:$AW$33,MATCH(J2,$AU$3:$AU$33,0)),0) -> 25.93085 | K5: =IFERROR(INDEX($AW$3:$AW$33,MATCH(K2,$AU$3:$AU$33,0)),0) -> 1.29654 | ... AN5: =IFERROR(INDEX($AW$3:$AW$33,MATCH(AN2,$AU$3:$AU$33,0)),0) -> 0 | AO5: 1 | AP5: 3 | AQ5: 200 | AU5: BG | AV5: 7.761844 | AW5: 1.823089 | AX5: 7.937044 | AY5: 1.173302 | AZ5: 0.275583 | BA5: 1.199786 | BB5: 0.090254 | BC5: 0.021199 | BD5: 0.092291
A6: ICNBMRFLAT01 | B6: R_MRFlat | C6: 2019 | D6: =IFERROR(INDEX($BA$3:$BA$33,MATCH(D2,$AU$3:$AU$33,0)),0) -> 2.294094 | E6: =IFERROR(INDEX($BA$3:$BA$33,MATCH(E2,$AU$3:$AU$33,0)),0) -> 0.977493 | F6: =IFERROR(INDEX($BA$3:$BA$33,MATCH(F2,$AU$3:$AU$33,0)),0) -> 1.199786 | G6: =IFERROR(INDEX($BA$3:$BA$33,MATCH(G2,$AU$3:$AU$33,0)),0) -> 1.548057 | H6: =IFERROR(INDEX($BA$3:$BA$33,MATCH(H2,$AU$3:$AU$33,0)),0) -> 0.132876 | I6: =IFERROR(INDEX($BA$3:$BA$33,MATCH(I2,$AU$3:$AU$33,0)),0) -> 2.409499 | J6: =IFERROR(INDEX($BA$3:$BA$33,MATCH(J2,$AU$3:$AU$33,0)),0) -> 11.7162 | K6: =IFERROR(INDEX($BA$3:$BA$33,MATCH(K2,$AU$3:$AU$33,0)),0) -> 0.540243 | ... AN6: =IFERROR(INDEX($BA$3:$BA$33,MATCH(AN2,$AU$3:$AU$33,0)),0) -> 0 | AO6: 1 | AP6: 3 | AQ6: 200 | AU6: CH | AV6: 6.477246 | AW6: 4.523377 | AX6: 6.068384 | AY6: 1.652359 | AZ6: 1.153923 | BA6: 1.548057 | BB6: 0.198283 | BC6: 0.138471 | BD6: 0.185767
A7: ICNBMRDetH01 | B7: R_MRDetH | C7: 2019 | D7: =IFERROR(INDEX($AY$3:$AY$33,MATCH(D2,$AU$3:$AU$33,0)),0) -> 3.320961 | E7: =IFERROR(INDEX($AY$3:$AY$33,MATCH(E2,$AU$3:$AU$33,0)),0) -> 1.997645 | F7: =IFERROR(INDEX($AY$3:$AY$33,MATCH(F2,$AU$3:$AU$33,0)),0) -> 1.173302 | G7: =IFERROR(INDEX($AY$3:$AY$33,MATCH(G2,$AU$3:$AU$33,0)),0) -> 1.652359 | H7: =IFERROR(INDEX($AY$3:$AY$33,MATCH(H2,$AU$3:$AU$33,0)),0) -> 0.264167 | I7: =IFERROR(INDEX($AY$3:$AY$33,MATCH(I2,$AU$3:$AU$33,0)),0) -> 2.292502 | J7: =IFERROR(INDEX($AY$3:$AY$33,MATCH(J2,$AU$3:$AU$33,0)),0) -> 10.47693 | K7: =IFERROR(INDEX($AY$3:$AY$33,MATCH(K2,$AU$3:$AU$33,0)),0) -> 1.077807 | ... AN7: =IFERROR(INDEX($AY$3:$AY$33,MATCH(AN2,$AU$3:$AU$33,0)),0) -> 0 | AO7: 1 | AP7: 3 | AQ7: 200 | AU7: CY | AV7: 0.422667 | AW7: 0.260417 | AX7: 0.212601 | AY7: 0.264167 | AZ7: 0.16276 | BA7: 0.132876 | BB7: 0.052833 | BC7: 0.032552 | BD7: 0.026575
A8: ICNBMRSDtH01 | B8: R_MRSDetH | C8: 2019 | D8: =IFERROR(INDEX($AZ$3:$AZ$33,MATCH(D2,$AU$3:$AU$33,0)),0) -> 0.56749 | E8: =IFERROR(INDEX($AZ$3:$AZ$33,MATCH(E2,$AU$3:$AU$33,0)),0) -> 2.264329 | F8: =IFERROR(INDEX($AZ$3:$AZ$33,MATCH(F2,$AU$3:$AU$33,0)),0) -> 0.275583 | G8: =IFERROR(INDEX($AZ$3:$AZ$33,MATCH(G2,$AU$3:$AU$33,0)),0) -> 1.153923 | H8: =IFERROR(INDEX($AZ$3:$AZ$33,MATCH(H2,$AU$3:$AU$33,0)),0) -> 0.16276 | I8: =IFERROR(INDEX($AZ$3:$AZ$33,MATCH(I2,$AU$3:$AU$33,0)),0) -> 0.628346 | J8: =IFERROR(INDEX($AZ$3:$AZ$33,MATCH(J2,$AU$3:$AU$33,0)),0) -> 6.667932 | K8: =IFERROR(INDEX($AZ$3:$AZ$33,MATCH(K2,$AU$3:$AU$33,0)),0) -> 0.243101 | ... AN8: =IFERROR(INDEX($AZ$3:$AZ$33,MATCH(AN2,$AU$3:$AU$33,0)),0) -> 0 | AO8: 1 | AP8: 3 | AQ8: 200 | AU8: CZ | AV8: 7.45063 | AW8: 2.042125 | AX8: 7.830872 | AY8: 2.292502 | AZ8: 0.628346 | BA8: 2.409499 | BB8: 0.143281 | BC8: 0.039272 | BD8: 0.150594
A9: ICNBFRFLAT01 | B9: R_FRFlat | C9: 2019 | D9: =IFERROR(INDEX($BD$3:$BD$33,MATCH(D2,$AU$3:$AU$33,0)),0) -> 0.269893 | E9: =IFERROR(INDEX($BD$3:$BD$33,MATCH(E2,$AU$3:$AU$33,0)),0) -> 0.195499 | F9: =IFERROR(INDEX($BD$3:$BD$33,MATCH(F2,$AU$3:$AU$33,0)),0) -> 0.092291 | G9: =IFERROR(INDEX($BD$3:$BD$33,MATCH(G2,$AU$3:$AU$33,0)),0) -> 0.185767 | H9: =IFERROR(INDEX($BD$3:$BD$33,MATCH(H2,$AU$3:$AU$33,0)),0) -> 0.026575 | I9: =IFERROR(INDEX($BD$3:$BD$33,MATCH(I2,$AU$3:$AU$33,0)),0) -> 0.150594 | J9: =IFERROR(INDEX($BD$3:$BD$33,MATCH(J2,$AU$3:$AU$33,0)),0) -> 1.3018 | K9: =IFERROR(INDEX($BD$3:$BD$33,MATCH(K2,$AU$3:$AU$33,0)),0) -> 0 | ... AN9: =IFERROR(INDEX($BD$3:$BD$33,MATCH(AN2,$AU$3:$AU$33,0)),0) -> 0 | AO9: 1 | AP9: 3 | AQ9: 200 | AU9: DE | AV9: 40.74363 | AW9: 25.93085 | AX9: 45.56301 | AY9: 10.47693 | AZ9: 6.667932 | BA9: 11.7162 | BB9: 1.164104 | BC9: 0.740881 | BD9: 1.3018
A10: ICNBFRDetH01 | B10: R_FRDetH | C10: 2019 | D10: =IFERROR(INDEX($BB$3:$BB$33,MATCH(D2,$AU$3:$AU$33,0)),0) -> 0.390701 | E10: =IFERROR(INDEX($BB$3:$BB$33,MATCH(E2,$AU$3:$AU$33,0)),0) -> 0.399529 | F10: =IFERROR(INDEX($BB$3:$BB$33,MATCH(F2,$AU$3:$AU$33,0)),0) -> 0.090254 | G10: =IFERROR(INDEX($BB$3:$BB$33,MATCH(G2,$AU$3:$AU$33,0)),0) -> 0.198283 | H10: =IFERROR(INDEX($BB$3:$BB$33,MATCH(H2,$AU$3:$AU$33,0)),0) -> 0.052833 | I10: =IFERROR(INDEX($BB$3:$BB$33,MATCH(I2,$AU$3:$AU$33,0)),0) -> 0.143281 | J10: =IFERROR(INDEX($BB$3:$BB$33,MATCH(J2,$AU$3:$AU$33,0)),0) -> 1.164104 | K10: =IFERROR(INDEX($BB$3:$BB$33,MATCH(K2,$AU$3:$AU$33,0)),0) -> 0 | ... AN10: =IFERROR(INDEX($BB$3:$BB$33,MATCH(AN2,$AU$3:$AU$33,0)),0) -> 0 | AO10: 1 | AP10: 3 | AQ10: 200 | AU10: DK | AV10: 5.748304 | AW10: 1.29654 | AX10: 2.881297 | AY10: 1.077807 | AZ10: 0.243101 | BA10: 0.540243 | BB10: 0 | BC10: 0 | BD10: 0
A11: ICNBFRSDtH01 | B11: R_FRSDetH | C11: 2019 | D11: =IFERROR(INDEX($BC$3:$BC$33,MATCH(D2,$AU$3:$AU$33,0)),0) -> 0.066764 | E11: =IFERROR(INDEX($BC$3:$BC$33,MATCH(E2,$AU$3:$AU$33,0)),0) -> 0.452866 | F11: =IFERROR(INDEX($BC$3:$BC$33,MATCH(F2,$AU$3:$AU$33,0)),0) -> 0.021199 | G11: =IFERROR(INDEX($BC$3:$BC$33,MATCH(G2,$AU$3:$AU$33,0)),0) -> 0.138471 | H11: =IFERROR(INDEX($BC$3:$BC$33,MATCH(H2,$AU$3:$AU$33,0)),0) -> 0.032552 | I11: =IFERROR(INDEX($BC$3:$BC$33,MATCH(I2,$AU$3:$AU$33,0)),0) -> 0.039272 | J11: =IFERROR(INDEX($BC$3:$BC$33,MATCH(J2,$AU$3:$AU$33,0)),0) -> 0.740881 | K11: =IFERROR(INDEX($BC$3:$BC$33,MATCH(K2,$AU$3:$AU$33,0)),0) -> 0 | ... AN11: =IFERROR(INDEX($BC$3:$BC$33,MATCH(AN2,$AU$3:$AU$33,0)),0) -> 0 | AO11: 1 | AP11: 3 | AQ11: 200 | AU11: EE | AV11: 0.421951 | AW11: 0.072112 | AX11: 0.824767 | AY11: 0.082046 | AZ11: 0.014022 | BA11: 0.160371 | BB11: 0.011721 | BC11: 0.002003 | BD11: 0.02291
AU12: EL | AV12: 2.644467 | AW12: 0.668062 | AX12: 3.887408 | AY12: 1.264745 | AZ12: 0.319508 | BA12: 1.859195 | BB12: 0.229954 | BC12: 0.058092 | BD12: 0.338035
AU13: ES | AV13: 4.79201 | AW13: 7.536778 | AX13: 22.78452 | AY13: 3.879246 | AZ13: 6.101201 | BA13: 18.44461 | BB13: 0.684573 | BC13: 1.076683 | BD13: 3.254932
AU14: FI | AV14: 3.103209 | AW14: 1.255439 | AX14: 2.00583 | AY14: 0.290926 | AZ14: 0.117697 | BA14: 0.188047 | BB14: 0 | BC14: 0 | BD14: 0
AU15: FR | AV15: 55.43492 | AW15: 28.34359 | AX15: 38.23877 | AY15: 11.79466 | AZ15: 6.03055 | BA15: 8.135908 | BB15: 2.358933 | BC15: 1.20611 | BD15: 1.627182
AU16: HR | AV16: 4.127591 | AW16: 0.356273 | AX16: 2.42609 | AY16: 0.924087 | AZ16: 0.079763 | BA16: 0.543155 | BB16: 0.061606 | BC16: 0.005318 | BD16: 0.03621
AU17: HU | AV17: 5.997683 | AW17: 0.571231 | AX17: 2.057853 | AY17: 1.86135 | AZ17: 0.177278 | BA17: 0.638644 | BB17: 0.206817 | BC17: 0.019698 | BD17: 0.07096
AU18: IE | AV18: 3.155957 | AW18: 3.163545 | AX18: 0.454844 | AY18: 0.556934 | AZ18: 0.558273 | BA18: 0.080267 | BB18: 0.092822 | BC18: 0.093045 | BD18: 0.013378
AU19: IS | AV19: 0.237076 | AW19: 0.130353 | AX19: 0.169754 | AY19: 0.060479 | AZ19: 0.033253 | BA19: 0.043305 | BB19: 0.007257 | BC19: 0.00399 | BD19: 0.005197
AU20: IT | AV20: 13.90986 | AW20: 17.00784 | AX20: 74.3579 | AY20: 5.216198 | AZ20: 6.377941 | BA20: 27.88421 | BB20: 1.04324 | BC20: 1.275588 | BD20: 5.576843
AU21: LT | AV21: 1.23157 | AW21: 0.251979 | AX21: 1.467619 | AY21: 0.297276 | AZ21: 0.060823 | BA21: 0.354253 | BB21: 0.084936 | BC21: 0.017378 | BD21: 0.101215
AU22: LU | AV22: 0.179775 | AW22: 0.148773 | AX22: 0.181553 | AY22: 0.031265 | AZ22: 0.025874 | BA22: 0.031574 | BB22: 0.007816 | BC22: 0.006468 | BD22: 0.007894
AU23: LV | AV23: 0.87648 | AW23: 0.103595 | AX23: 1.17242 | AY23: 0.232009 | AZ23: 0.027422 | BA23: 0.310346 | BB23: 0 | BC23: 0 | BD23: 0
... AU33: UK | AV33: 6.851098 | AW33: 14.01583 | AX33: 36.12353 | AY33: 2.791188 | AZ33: 5.710154 | BA33: 14.717 | BB33: 0.253744 | BC33: 0.519105 | BD33: 1.337909

Sheet IND_IIS
H4: ~FI_T
A5: Sets | B5: TechName | C5: Comm-IN | D5: Comm-OUT | E5: CommGRP | F5: Comm-IN-A | G5: Source | H5: Year | I5: AF | J5: CAPUNIT | K5: FIXOM | L5: INPUT | M5: OUTPUT | N5: INVCOST | O5: VAROM | P5: LIFE | Q5: Start | R5: ACT_EFF | S5: EFF | U5: ENV_ACT~SNKTOTCO2
A6: \I:Steel
B7: =IND!C1290 -> IISPELLET01 | G7: Etech-DB version8 | H7: 2006 | J7: 1 | P7: 25 | Q7: 2006
C8: MISORE | D8: MISPLT | H8: 2006 | I8: 0.95 | K8: 3.3775479 | L8: 1 | M8: 1 | N8: 61.921711 | O8: 4.841152
C9: INDELC | H9: 2006 | L9: 1.14
C10: INDCOK | H10: 2006 | L10: 1.01
B11: =IND!C1291 -> IISSINTER01 | E11: IIS_Gases | G11: Etech-DB version8 | H11: 2006 | J11: 1 | P11: 25 | Q11: 2006 | R11: 2
C12: MISORE | D12: MISSNT | H12: 2006 | I12: 0.95 | K12: 2.8146232 | L12: 1 | M12: 1 | N12: 56.292465 | O12: 6.1921711
C13: INDELC | H13: 2006 | L13: 0.1
C14: INDCOK | H14: 2006 | L14: 1.16
C15: INDGAS | H15: 2006
C16: INDCOG | H16: 2006
B17: =IND!C1292 -> IISSINTERBIO | G17: Etech-DB version8 | H17: 2006 | J17: 1 | P17: 25 | Q17: 2020
C18: MISORE | D18: MISSNT | H18: 2006 | I18: 0.95 | K18: 2.8146232 | L18: 1 | M18: 1 | N18: 70 | O18: 6.1921711
C19: INDELC | H19: 2006 | L19: 0.1
C20: INDBIO | H20: 2006 | L20: =L14+1/R11+0.2 -> 1.86
B21: =IND!C1293 -> IISOXYGEN01 | H21: 2006 | J21: 1 | P21: 30 | Q21: 2006
C22: INDELC | D22: MISOXY | H22: 2006 | I22: 0.85 | K22: 10 | L22: 0.72 | M22: 1 | N22: 200
B23: =IND!C1294 -> IISBLAFURBIO | H23: 2006 | J23: 1 | P23: 30 | Q23: 2006
C24: MISPLT | D24: MISRIR | H24: 2006 | I24: 0.85 | K24: 10 | L24: 0.155 | M24: 1 | N24: =1.4*N30 -> 382.2 | O24: 2
C25: MISSNT | D25: MISBFS | H25: 2006 | L25: 1.34 | M25: 0.25
C26: MISOXY | D26: GASBFG | H26: 2006 | L26: 0.05 | M26: 3.25
C27: INDBIO | H27: 2006 | L27: 18
C28: INDELC | H28: 2006 | L28: 0.5
B29: =IND!C1295 -> IISBLAFURDCI05 | H29: 2006 | J29: 1 | P29: 30 | Q29: 2005
C30: MISPLT | D30: MISRIR | H30: 2006 | I30: 0.85 | K30: 10 | L30: 0.155 | M30: 1 | N30: 273 | O30: 2
C31: MISSNT | D31: MISBFS | H31: 2006 | L31: 1.34 | M31: 0.25
C32: MISOXY | D32: GASBFG | H32: 2006 | L32: 0.05 | M32: 3.25
C33: INDCOK | H33: 2006 | L33: 9.3
C34: INDELC | H34: 2006 | L34: 0.5
C35: INDCOA | H35: 2006 | L35: 6.2
B36: =IND!C1298 -> IISBLAFURCS20 | H36: 2020 | J36: 1 | P36: 30 | Q36: 2020 | U36: 746 | V36: =U36/(V40+V42) -> 0.50030179
C37: MISPLT | D37: MISRIR | H37: 2020 | I37: 0.85 | K37: 15 | L37: 0.155 | M37: 1 | N37: 500 | O37: 5
C38: MISSNT | D38: MISBFS | H38: 2020 | L38: 1.34 | M38: 0.25
C39: MISOXY | D39: SYNH2CT | H39: 2020 | L39: 0.05 | M39: 3.014
C40: INDCOK | H40: 2020 | L40: 9.3 | V40: =L40*95 -> 883.5
C41: INDELC | H41: 2020 | L41: 1.112
C42: INDCOA | H42: 2020 | L42: 6.2 | V42: =L42*98 -> 607.6
B43: =IND!C1296 -> IISBLAFURTGR10 | H43: 2010 | J43: 1 | P43: 30 | Q43: 2010
...

Sheet GDPdeflator
A1: UNIT | B1: Price index, 2000=100 (based on euro) | C1: Price index, 2005=100 (based on euro) | E1: UNIT | F1: Price index, 2000=100 (based on euro) | G1: Price index, 2005=100 (based on euro)
A2: GEO | B2: European Union (27 countries) | C2: European Union (27 countries) | E2: TIME/GEO | F2: European Union (28 countries) | G2: European Union (28 countries)
A3: TIME | E3: 2000Q4 | F3: 101 | G3: 92.2
A4: 2004Q4 | B4: =F7 -> 107.9 | C4: =G7 -> 98.4 | E4: 2001Q4 | F4: 103 | G4: 93.9
A5: 2005Q4 | B5: =F8 -> 110.6 | C5: =G8 -> 100.9 | E5: 2002Q4 | F5: 105 | G5: 95.8
A6: 2006Q4 | B6: =F9 -> 113.4 | C6: =G9 -> 103.5 | E6: 2003Q4 | F6: 105.1 | G6: 95.9
A7: 2007Q4 | B7: =F10 -> 115.6 | C7: =G10 -> 105.5 | E7: 2004Q4 | F7: 107.9 | G7: 98.4
A8: 2008Q4 | B8: =F11 -> 115 | C8: =G11 -> 104.9 | E8: 2005Q4 | F8: 110.6 | G8: 100.9
A9: 2009Q4 | B9: =F12 -> 114.2 | C9: =G12 -> 104.2 | E9: 2006Q4 | F9: 113.4 | G9: 103.5
A10: 2010Q4 | B10: =F13 -> 116.9 | C10: =G13 -> 106.7 | E10: 2007Q4 | F10: 115.6 | G10: 105.5
A11: 2011Q4 | B11: =F14 -> 118.3 | C11: =G14 -> 108 | E11: 2008Q4 | F11: 115 | G11: 104.9
A12: 2012Q4 | B12: =F15 -> 121.4 | C12: =G15 -> 110.8 | E12: 2009Q4 | F12: 114.2 | G12: 104.2
E13: 2010Q4 | F13: 116.9 | G13: 106.7
A14: Reference: Eurostat | E14: 2011Q4 | F14: 118.3 | G14: 108
B15: GDP and main components - Price indices [namq_gdp_p] | E15: 2012Q4 | F15: 121.4 | G15: 110.8
B16: Last update: 16-11-2012 | E16: 2013Q1 | F16: 121.2 | G16: 110.6
B17: Gross domestic product at market prices
B18: Seasonally adjusted and adjusted data by working days | D18: 1 | E18: EUR 2004 | F18: =100/B4 -> 0.92678406 | G18: EUR 2000 | I18: 1 | J18: EUR 2000 | K18: =B4/100 -> 1.079 | L18: EUR 2004
B19: Price index, 2000=100 (based on euro) | D19: 1 | E19: EUR 2005 | F19: =100/B5 -> 0.90415913 | G19: EUR 2000 | I19: 1 | J19: EUR 2000 | K19: =B5/100 -> 1.106 | L19: EUR 2005
B20: Price index, 2005=100 (based on euro) | D20: 1 | E20: EUR 2006 | F20: =100/B6 -> 0.88183422 | G20: EUR 2000 | I20: 1 | J20: EUR 2000 | K20: =B6/100 -> 1.134 | L20: EUR 2006
A21: Last update | B21: 41456.848 | D21: 1 | E21: EUR 2007 | F21: =100/B7 -> 0.8650519 | G21: EUR 2000 | I21: 1 | J21: EUR 2000 | K21: =B7/100 -> 1.156 | L21: EUR 2007
A22: Extracted on | B22: 41457.706 | D22: 1 | E22: EUR 2008 | F22: =100/B8 -> 0.86956522 | G22: EUR 2000 | I22: 1 | J22: EUR 2000 | K22: =B8/100 -> 1.15 | L22: EUR 2008
A23: Source of data | B23: Eurostat | D23: 1 | E23: EUR 2009 | F23: =100/B9 -> 0.87565674 | G23: EUR 2000 | I23: 1 | J23: EUR 2000 | K23: =B9/100 -> 1.142 | L23: EUR 2009
D24: 1 | E24: EUR 2010 | F24: =100/B10 -> 0.85543199 | G24: EUR 2000 | I24: 1 | J24: EUR 2000 | K24: =B10/100 -> 1.169 | L24: EUR 2010
D25: 1 | E25: EUR 2011 | F25: =100/B11 -> 0.84530854 | G25: EUR 2000 | I25: 1 | J25: EUR 2000 | K25: =B11/100 -> 1.183 | L25: EUR 2011
D27: 1 | E27: EUR 2004 | F27: =100/C4 -> 1.0162602 | G27: EUR 2005 | I27: 1 | J27: EUR 2005 | K27: =C4/100 -> 0.984 | L27: EUR 2004
D28: 1 | E28: EUR 2005 | F28: =100/C5 -> 0.99108028 | G28: EUR 2005 | I28: 1 | J28: EUR 2005 | K28: =C5/100 -> 1.009 | L28: EUR 2005
D29: 1 | E29: EUR 2006 | F29: =100/C6 -> 0.96618357 | G29: EUR 2005 | I29: 1 | J29: EUR 2005 | K29: =C6/100 -> 1.035 | L29: EUR 2006
D30: 1 | E30: EUR 2007 | F30: =100/C7 -> 0.9478673 | G30: EUR 2005 | I30: 1 | J30: EUR 2005 | K30: =C7/100 -> 1.055 | L30: EUR 2007
D31: 1 | E31: EUR 2008 | F31: =100/C8 -> 0.95328885 | G31: EUR 2005 | I31: 1 | J31: EUR 2005 | K31: =C8/100 -> 1.049 | L31: EUR 2008
D32: 1 | E32: EUR 2009 | F32: =100/C9 -> 0.9596929 | G32: EUR 2005 | I32: 1 | J32: EUR 2005 | K32: =C9/100 -> 1.042 | L32: EUR 2009
D33: 1 | E33: EUR 2010 | F33: =100/C10 -> 0.93720712 | G33: EUR 2005 | I33: 1 | J33: EUR 2005 | K33: =C10/100 -> 1.067 | L33: EUR 2010
D34: 1 | E34: EUR 2011 | F34: =100/C11 -> 0.92592593 | G34: EUR 2005 | I34: 1 | J34: EUR 2005 | K34: =C11/100 -> 1.08 | L34: EUR 2011
D37: 1 | E37: EUR 2000 | F37: =B10/100 -> 1.169 | G37: EUR 2010
D38: 1 | E38: EUR 2004 | F38: =F27*K33 -> 1.0843496 | G38: EUR 2010
D39: 1 | E39: EUR 2005 | F39: =C10/100 -> 1.067 | G39: EUR 2010
D40: 1 | E40: EUR 2006 | F40: =F29*$K$33 -> 1.0309179 | G40: EUR 2010
D41: 1 | E41: EUR 2007 | F41: =F30*$K$33 -> 1.0113744 | G41: EUR 2010
D42: 1 | E42: EUR 2008 | F42: =F31*$K$33 -> 1.0171592 | G42: EUR 2010
D43: 1 | E43: EUR 2009 | F43: =F32*$K$33 -> 1.0239923 | G43: EUR 2010
...

Sheet Sheet1
A1: Multipliers used for CCS tech in paper industry - averages of changes for CCS tech in other sectors, already existing
A2: Change in fixed cost: | B2: 1.3
A3: Change in inputs
A4: ELC | B4: 1.0975332
A5: GAS | B5: 1.011571
A6: Change in Inv Cost | B6: 1.2812646
A7: Change in Varom | B7: 1.6189394

Sheet Folha1
B1: IGFFLATGL01 | E1: IGFFLATGL10 | H1: IGFFLATGL15
B2: ORIGINAL | C2: NEW UNIPI | D2: REDUCTION 2,5% CE*energy | E2: ORIGINAL | F2: NEW UNIPI | G2: REDUCTION 2,5% CE | H2: ORIGINAL | I2: NEW UNIPI | J2: REDUCTION 2,5% CE
A3: INDGAS | B3: 3 | C3: 2.45 | D3: =C3*(1-0.025) -> 2.38875 | E3: 2.25 | F3: =E3*(1+B9) -> 1.8375 | G3: =F3*(1-0.025) -> 1.7915625 | H3: 2.27603 | I3: =H3*(1+B9) -> 1.8587578 | J3: =I3*(1-0.025) -> 1.8122889
A4: INDELC | B4: 5.5 | C4: 4.5 | D4: =C4*(1-0.025) -> 4.3875 | E4: 4.125 | F4: =E4*(1+B10) -> 3.375 | G4: =F4*(1-0.025) -> 3.290625 | H4: 4.52732 | I4: =H4*(1+B10) -> 3.7041709 | J4: =I4*(1-0.025) -> 3.6115666
A5: FIXOM | B5: 10 | C5: 27.59 | D5: 11.28 | E5: 12 | F5: =E5*(1+B11) -> 33.108 | G5: 11.28 | H5: 15.6 | I5: =H5*(1+B11) -> 43.0404 | J5: 11.28
A6: VAROM | B6: 50 | C6: 60 | E6: 50 | F6: =E6*(1+B12) -> 60 | H6: 80.95 | I6: =H6*(1+B12) -> 97.14
B8: % VARIATION
A9: INDGAS | B9: =(C3-B3)/B3 -> -0.18333333
A10: INDELC | B10: =(C4-B4)/B4 -> -0.18181818
A11: FIXOM | B11: =(C5-B5)/B5 -> 1.759
A12: VAROM | B12: =(C6-B6)/B6 -> 0.2

Sheet calculation
A1: Extraction of relevant Raw Materials for construction of buildings and offshore energy
A2: Data source: | B2: https://ec.europa.eu/eurostat/databrowser/view/ENV_AC_MFA/default/table?lang=en
A4: 2021 | U4: CLAY | BE4: Energy Intensity | CJ4: Production share | CQ4: European Average Intensity
C5: MF2 | D5: MF21 | E5: % of iron in metal ore extraction | F5: MF3 | G5: % of non-metallic minerals potentially used in construction | H5: MF32 | I5: MF35 | J5: MF36 | K5: MF37 | L5: MF38 | M5: MF21 | N5: Total annual average production (kt) | Q5: MF32 | R5: MF35 | S5: MF36 * 98.8% | T5: MF36 *1.2% | U5: MF37 | V5: MF38*94% | W5: MF38*6% | Z5: INDCOA | AF5: INDGAS | AL5: INDHFO | AR5: INDBIO | AX5: INDELC | BE5: INDCOA | BK5: INDGAS | BQ5: INDHFO | BW5: INDBIO | CC5: INDELC | CJ5: MF35 | CK5: MF36 | CL5: MF37 | CM5: MF38 | CN5: MF21 | CQ5: INDCOA | CW5: INDGAS | DC5: INDHFO | DI5: INDBIO | DO5: INDELC
C6: Metal ores (gross ores) (kt) | D6: Iron (kt) | F6: Non-metallic minerals | H6: Chalk and dolomite | I6: Salt | J6: Limestone and gypsum | K6: Clays and kaolin | L6: Sand and gravel | M6: Iron (kt) | N6: Bricks | Q6: DOLOMITE | R6: Mining Salt for soda ash | S6: Mining Limestone | T6: GYPSUM | U6: Mining Coke Non energetic | V6: Common Sand | W6: Silica Sand | Z6: SALTISA | AA6: MLMSTN | AB6: CLAY | AC6: SANDFG | AD6: MISORE | AE6: MCLBR | AF6: SALTISA | AG6: MLMSTN | AH6: CLAY | AI6: SANDFG | AJ6: MISORE | AK6: MCLBR | AL6: SALTISA | AM6: MLMSTN | AN6: CLAY | AO6: SANDFG | AP6: MISORE | AQ6: MCLBR | AR6: SALTISA | AS6: MLMSTN | AT6: CLAY | AU6: SANDFG | AV6: MISORE | AW6: MCLBR | AX6: SALTISA | AY6: MLMSTN | AZ6: CLAY | BA6: SANDFG | BB6: MISORE | BC6: MCLBR | BE6: SALTISA | BF6: MLMSTN | BG6: CLAY | BH6: SANDFG | BI6: MISORE | BJ6: MCLBR | BK6: SALTISA | BL6: MLMSTN | BM6: CLAY | BN6: SANDFG | BO6: MISORE | BP6: MCLBR | BQ6: SALTISA | BR6: MLMSTN | BS6: CLAY | BT6: SANDFG | BU6: MISORE | BV6: MCLBR | BW6: SALTISA | BX6: MLMSTN | BY6: CLAY | BZ6: SANDFG | CA6: MISORE | CB6: MCLBR | CC6: SALTISA | CD6: MLMSTN | CE6: CLAY | CF6: SANDFG | CG6: MISORE | CH6: MCLBR | CJ6: Salt | CK6: Limestone and gypsum | CL6: Clays and kaolin | CM6: Sand and gravel | CN6: Iron (kt) | CO6: Bricks | CQ6: SALTISA | CR6: MLMSTN | CS6: CLAY | CT6: SANDFG | CU6: MISORE | CV6: MCLBR | CW6: SALTISA | CX6: MLMSTN | CY6: CLAY | CZ6: SANDFG | DA6: MISORE | DB6: MCLBR | DC6: SALTISA | DD6: MLMSTN | DE6: CLAY | DF6: SANDFG | DG6: MISORE | DH6: MCLBR | DI6: SALTISA | DJ6: MLMSTN | DK6: CLAY | DL6: SANDFG | DM6: MISORE | DN6: MCLBR | DO6: SALTISA | DP6: MLMSTN | DQ6: CLAY | DR6: SANDFG | DS6: MISORE | DT6: MCLBR
A7: EU27_2020 | B7: European Union - 27 countries (from 2020) | C7: 226098.03 | D7: 50041.19 | E7: 0.22132519 | F7: 3369058.8 | G7: 0.86526519 | H7: 59636.738 | I7: 46795.78 | J7: 477228.53 | K7: 67233.31 | L7: 2264235 | M7: 50041.19 | Q7: =H7/F7 -> 0.017701305 | R7: 0.013889867 | S7: =(J7/F7)*0.988 -> 0.1399506 | T7: 0.0016998048 | U7: 0.01995611 | V7: =($L7/$F7)*0.94 -> 0.63174346 | W7: =($L7/$F7)*0.06 -> 0.040324051 | Y7: EU27_2020 | AE7: 0 | AK7: 0 | AQ7: 0 | AW7: 0 | BC7: 0 | BE7: =IFERROR(Z7/I7,0) -> 0 | BF7: =IFERROR(AA7/J7,0) -> 0 | BG7: =IFERROR(AB7/K7,0) -> 0 | BH7: =IFERROR(AC7/L7,0) -> 0 | BI7: =IFERROR(AD7/M7,0) -> 0 | BJ7: =IFERROR(AE7/N7,0) -> 0 | BK7: =IFERROR(AF7/I7,0) -> 0 | BL7: =IFERROR(AG7/J7,0) -> 0 | BM7: =IFERROR(AH7/K7,0) -> 0 | BN7: =IFERROR(AI7/L7,0) -> 0 | BO7: =IFERROR(AJ7/M7,0) -> 0 | BP7: =IFERROR(AK7/N7,0) -> 0 | BQ7: =IFERROR(AL7/I7,0) -> 0 | BR7: =IFERROR(AM7/J7,0) -> 0 | BS7: =IFERROR(AN7/K7,0) -> 0 | BT7: =IFERROR(AO7/L7,0) -> 0 | BU7: =IFERROR(AP7/M7,0) -> 0 | BV7: =IFERROR(AQ7/N7,0) -> 0 | BW7: =IFERROR(AR7/I7,0) -> 0 | BX7: =IFERROR(AS7/J7,0) -> 0 | BY7: =IFERROR(AT7/K7,0) -> 0 | BZ7: =IFERROR(AU7/L7,0) -> 0 | CA7: =IFERROR(AV7/M7,0) -> 0 | CB7: =IFERROR(AW7/N7,0) -> 0 | CC7: =IFERROR(AX7/I7,0) -> 0 | CD7: =IFERROR(AY7/J7,0) -> 0 | CE7: =IFERROR(AZ7/K7,0) -> 0 | CF7: =IFERROR(BA7/L7,0) -> 0 | CG7: =IFERROR(BB7/M7,0) -> 0 | CH7: =IFERROR(BC7/N7,0) -> 0 | CQ7: =IFERROR(BE7*CJ7,0) -> 0 | CR7: =IFERROR(BF7*CK7,0) -> 0 | CS7: =IFERROR(BG7*CL7,0) -> 0 | CT7: =IFERROR(BH7*CM7,0) -> 0 | CU7: =IFERROR(BI7*CN7,0) -> 0 | CV7: =IFERROR(BJ7*CO7,0) -> 0 | CW7: =IFERROR(BK7*CJ7,0) -> 0 | CX7: =IFERROR(BL7*CK7,0) -> 0 | CY7: =IFERROR(BM7*CL7,0) -> 0 | CZ7: =IFERROR(BN7*CM7,0) -> 0 | DA7: =IFERROR(BO7*CN7,0) -> 0 | DB7: =IFERROR(BP7*CO7,0) -> 0 | DC7: =IFERROR(BQ7*CJ7,0) -> 0 | DD7: =IFERROR(BR7*CK7,0) -> 0 | DE7: =IFERROR(BS7*CL7,0) -> 0 | DF7: =IFERROR(BT7*CM7,0) -> 0 | DG7: =IFERROR(BU7*CN7,0) -> 0 | DH7: =IFERROR(BV7*CO7,0) -> 0 | DI7: =IFERROR(BW7*CJ7,0) -> 0 | DJ7: =IFERROR(BX7*CK7,0) -> 0 | DK7: =IFERROR(BY7*CL7,0) -> 0 | DL7: =IFERROR(BZ7*CM7,0) -> 0 | DM7: =IFERROR(CA7*CN7,0) -> 0 | DN7: =IFERROR(CB7*CO7,0) -> 0 | DO7: =IFERROR(CC7*CJ7,0) -> 0 | DP7: =IFERROR(CD7*CK7,0) -> 0 | DQ7: =IFERROR(CE7*CL7,0) -> 0 | DR7: =IFERROR(CF7*CM7,0) -> 0 | DS7: =IFERROR(CG7*CN7,0) -> 0 | DT7: =IFERROR(CH7*CO7,0) -> 0
A8: BE | B8: Belgium | C8: 0 | D8: 0 | F8: 54383.28 | G8: 0.84768182 | H8: 5440.037 | K8: 0.33 | L8: 40659.351 | M8: 0 | N8: 4980.76 | Q8: =H8/F8 -> 0.10003143 | R8: 0 | S8: =(J8/F8)*0.988 -> 0 | T8: 0 | U8: 6.0680415e-06 | V8: =($L8/$F8)*0.94 -> 0.70278567 | W8: =($L8/$F8)*0.06 -> 0.04485866 | Y8: BE | Z8: 0 | AA8: 0 | AB8: 0 | AC8: 0 | AD8: 0 | AE8: 723.52 | AF8: 0 | AG8: 0 | AH8: 0.0034583286 | AI8: 426.1012 | AJ8: 0 | AK8: 5608.23 | AL8: 0 | AM8: 0 | AN8: 0.0062312718 | AO8: 0 | AP8: 0 | AQ8: 221.15 | AR8: 0 | AS8: 0 | AT8: 0 | AU8: 0 | AV8: 0 | AW8: - | AX8: 0 | AY8: 0 | AZ8: 0.0062312718 | BA8: 767.75596 | BB8: 0 | BC8: 918.24 | BE8: =IFERROR(Z8/I8,0) -> 0 | BF8: =IFERROR(AA8/J8,0) -> 0 | BG8: =IFERROR(AB8/K8,0) -> 0 | BH8: =IFERROR(AC8/L8,0) -> 0 | BI8: =IFERROR(AD8/M8,0) -> 0 | BJ8: =IFERROR(AE8/N8,0) -> 0.14526297 | BK8: =IFERROR(AF8/I8,0) -> 0 | BL8: =IFERROR(AG8/J8,0) -> 0 | BM8: =IFERROR(AH8/K8,0) -> 0.010479783 | BN8: =IFERROR(AI8/L8,0) -> 0.010479783 | BO8: =IFERROR(AJ8/M8,0) -> 0 | BP8: =IFERROR(AK8/N8,0) -> 1.1259788 | BQ8: =IFERROR(AL8/I8,0) -> 0 | BR8: =IFERROR(AM8/J8,0) -> 0 | BS8: =IFERROR(AN8/K8,0) -> 0.018882642 | BT8: =IFERROR(AO8/L8,0) -> 0 | BU8: =IFERROR(AP8/M8,0) -> 0 | BV8: =IFERROR(AQ8/N8,0) -> 0.044400854 | BW8: =IFERROR(AR8/I8,0) -> 0 | BX8: =IFERROR(AS8/J8,0) -> 0 | BY8: =IFERROR(AT8/K8,0) -> 0 | BZ8: =IFERROR(AU8/L8,0) -> 0 | CA8: =IFERROR(AV8/M8,0) -> 0 | CB8: =IFERROR(AW8/N8,0) -> 0 | CC8: =IFERROR(AX8/I8,0) -> 0 | CD8: =IFERROR(AY8/J8,0) -> 0 | CE8: =IFERROR(AZ8/K8,0) -> 0.018882642 | CF8: =IFERROR(BA8/L8,0) -> 0.018882642 | CG8: =IFERROR(BB8/M8,0) -> 0 | CH8: =IFERROR(BC8/N8,0) -> 0.18435741 | CJ8: =IFERROR(I8/$I$39,0) -> 0 | CK8: =IFERROR(J8/$J$39,0) -> 0 | CL8: =IFERROR(K8/$K$39,0) -> 4.4767968e-06 | CM8: =IFERROR(L8/$L$39,0) -> 0.016617487 | CN8: =IFERROR(M8/$M$39,0) -> 0 | CO8: =IFERROR(N8/$N$39,0) -> 0.051379717 | CQ8: =IFERROR(BE8*CJ8,0) -> 0 | CR8: =IFERROR(BF8*CK8,0) -> 0 | CS8: =IFERROR(BG8*CL8,0) -> 0 | CT8: =IFERROR(BH8*CM8,0) -> 0 | CU8: =IFERROR(BI8*CN8,0) -> 0 | CV8: =IFERROR(BJ8*CO8,0) -> 0.0074635703 | CW8: =IFERROR(BK8*CJ8,0) -> 0 | CX8: =IFERROR(BL8*CK8,0) -> 0 | CY8: =IFERROR(BM8*CL8,0) -> 4.6915861e-08 | CZ8: =IFERROR(BN8*CM8,0) -> 0.00017414766 | DA8: =IFERROR(BO8*CN8,0) -> 0 | DB8: =IFERROR(BP8*CO8,0) -> 0.05785247 | DC8: =IFERROR(BQ8*CJ8,0) -> 0 | DD8: =IFERROR(BR8*CK8,0) -> 0 | DE8: =IFERROR(BS8*CL8,0) -> 8.4533751e-08 | DF8: =IFERROR(BT8*CM8,0) -> 0 | DG8: =IFERROR(BU8*CN8,0) -> 0 | DH8: =IFERROR(BV8*CO8,0) -> 0.0022813033 | DI8: =IFERROR(BW8*CJ8,0) -> 0 | DJ8: =IFERROR(BX8*CK8,0) -> 0 | DK8: =IFERROR(BY8*CL8,0) -> 0 | DL8: =IFERROR(BZ8*CM8,0) -> 0 | DM8: =IFERROR(CA8*CN8,0) -> 0 | DN8: =IFERROR(CB8*CO8,0) -> 0 | DO8: =IFERROR(CC8*CJ8,0) -> 0 | DP8: =IFERROR(CD8*CK8,0) -> 0 | DQ8: =IFERROR(CE8*CL8,0) -> 8.4533751e-08 | DR8: =IFERROR(CF8*CM8,0) -> 0.00031378205 | DS8: =IFERROR(CG8*CN8,0) -> 0 | DT8: =IFERROR(CH8*CO8,0) -> 0.0094722313
A9: BG | B9: Bulgaria | C9: 32354.937 | F9: 66261.233 | G9: 0.9100679 | H9: 237.504 | I9: 2399.26 | J9: 6360.438 | K9: 1337.416 | L9: 49967.603 | N9: 1136.74 | Q9: =H9/F9 -> 0.0035843583 | R9: 0.036209106 | S9: =(J9/F9)*0.988 -> 0.094838452 | T9: 0.001151884 | U9: 0.020183989 | V9: =($L9/$F9)*0.94 -> 0.7088541 | W9: =($L9/$F9)*0.06 -> 0.045246007 | Y9: BG | Z9: 0 | AA9: 0 | AB9: 0 | AC9: 0 | AD9: 0 | AE9: 19.93 | AF9: 0 | AG9: - | AH9: - | AI9: - | AJ9: 0 | AK9: 1315.5 | AL9: 0.081068504 | AM9: - | AN9: 10.970955 | AO9: 0 | AP9: 0 | AQ9: 79.8 | AR9: 0 | AS9: 0 | AT9: 0 | AU9: 0 | AV9: - | AW9: 0.12 | AX9: 0.38708482 | AY9: 52.175297 | AZ9: 10.970955 | BA9: 409.88915 | BB9: 0 | BC9: 289.75 | BE9: =IFERROR(Z9/I9,0) -> 0 | BF9: =IFERROR(AA9/J9,0) -> 0 | BG9: =IFERROR(AB9/K9,0) -> 0 | BH9: =IFERROR(AC9/L9,0) -> 0 | BI9: =IFERROR(AD9/M9,0) -> 0 | BJ9: =IFERROR(AE9/N9,0) -> 0.017532593 | BK9: =IFERROR(AF9/I9,0) -> 0 | BL9: =IFERROR(AG9/J9,0) -> 0 | BM9: =IFERROR(AH9/K9,0) -> 0 | BN9: =IFERROR(AI9/L9,0) -> 0 | BO9: =IFERROR(AJ9/M9,0) -> 0 | BP9: =IFERROR(AK9/N9,0) -> 1.1572567 | BQ9: =IFERROR(AL9/I9,0) -> 3.3788962e-05 | BR9: =IFERROR(AM9/J9,0) -> 0 | BS9: =IFERROR(AN9/K9,0) -> 0.0082030982 | BT9: =IFERROR(AO9/L9,0) -> 0 | BU9: =IFERROR(AP9/M9,0) -> 0 | BV9: =IFERROR(AQ9/N9,0) -> 0.07020075 | BW9: =IFERROR(AR9/I9,0) -> 0 | BX9: =IFERROR(AS9/J9,0) -> 0 | BY9: =IFERROR(AT9/K9,0) -> 0 | BZ9: =IFERROR(AU9/L9,0) -> 0 | CA9: =IFERROR(AV9/M9,0) -> 0 | CB9: =IFERROR(AW9/N9,0) -> 0.00010556504 | CC9: =IFERROR(AX9/I9,0) -> 0.00016133509 | CD9: =IFERROR(AY9/J9,0) -> 0.0082030982 | CE9: =IFERROR(AZ9/K9,0) -> 0.0082030982 | CF9: =IFERROR(BA9/L9,0) -> 0.0082030982 | CG9: =IFERROR(BB9/M9,0) -> 0 | CH9: =IFERROR(BC9/N9,0) -> 0.25489558 | CJ9: =IFERROR(I9/$I$39,0) -> 0.051620212 | CK9: =IFERROR(J9/$J$39,0) -> 0.011352879 | CL9: =IFERROR(K9/$K$39,0) -> 0.018143454 | CM9: =IFERROR(L9/$L$39,0) -> 0.020421771 | CN9: =IFERROR(M9/$M$39,0) -> 0 | CO9: =IFERROR(N9/$N$39,0) -> 0.011726198 | CQ9: =IFERROR(BE9*CJ9,0) -> 0 | CR9: =IFERROR(BF9*CK9,0) -> 0 | CS9: =IFERROR(BG9*CL9,0) -> 0 | CT9: =IFERROR(BH9*CM9,0) -> 0 | CU9: =IFERROR(BI9*CN9,0) -> 0 | CV9: =IFERROR(BJ9*CO9,0) -> 0.00020559066 | CW9: =IFERROR(BK9*CJ9,0) -> 0 | CX9: =IFERROR(BL9*CK9,0) -> 0 | CY9: =IFERROR(BM9*CL9,0) -> 0 | CZ9: =IFERROR(BN9*CM9,0) -> 0 | DA9: =IFERROR(BO9*CN9,0) -> 0 | DB9: =IFERROR(BP9*CO9,0) -> 0.013570222 | DC9: =IFERROR(BQ9*CJ9,0) -> 1.7441934e-06 | DD9: =IFERROR(BR9*CK9,0) -> 0 | DE9: =IFERROR(BS9*CL9,0) -> 0.00014883253 | DF9: =IFERROR(BT9*CM9,0) -> 0 | DG9: =IFERROR(BU9*CN9,0) -> 0 | DH9: =IFERROR(BV9*CO9,0) -> 0.0008231879 | DI9: =IFERROR(BW9*CJ9,0) -> 0 | DJ9: =IFERROR(BX9*CK9,0) -> 0 | DK9: =IFERROR(BY9*CL9,0) -> 0 | DL9: =IFERROR(BZ9*CM9,0) -> 0 | DM9: =IFERROR(CA9*CN9,0) -> 0 | DN9: =IFERROR(CB9*CO9,0) -> 1.2378765e-06 | DO9: =IFERROR(CC9*CJ9,0) -> 8.3281514e-06 | DP9: =IFERROR(CD9*CK9,0) -> 9.3128784e-05 | DQ9: =IFERROR(CE9*CL9,0) -> 0.00014883253 | DR9: =IFERROR(CF9*CM9,0) -> 0.0001675218 | DS9: =IFERROR(CG9*CN9,0) -> 0 | DT9: =IFERROR(CH9*CO9,0) -> 0.0029889561
A10: CZ | B10: Czechia | C10: 0 | D10: 0 | F10: 86347.407 | G10: 0.45143683 | H10: 393 | I10: 0 | J10: 11497 | K10: 5720.8 | L10: 21369.6 | M10: 0 | N10: 3425.1 | Q10: =H10/F10 -> 0.0045513816 | R10: 0 | S10: =(J10/F10)*0.988 -> 0.1315504 | T10: 0.0015977781 | U10: 0.066253292 | V10: =($L10/$F10)*0.94 -> 0.23263494 | W10: =($L10/$F10)*0.06 -> 0.014849039 | Y10: CZ | Z10: 0 | AA10: 31.257866 | AB10: 15.553623 | AC10: 58.099339 | AD10: 0 | AE10: 1085.63 | AF10: 0 | AG10: 121.64743 | AH10: 60.530624 | AI10: 226.1074 | AJ10: 0 | AK10: 2926.83 | AL10: 0 | AM10: 0.15391929 | AN10: 41.805403 | AO10: 0 | AP10: 0 | AQ10: 180.12 | AR10: 0 | AS10: 0 | AT10: 0 | AU10: 0 | AV10: 0 | AW10: 30.75 | AX10: 0 | AY10: 84.015649 | AZ10: 41.805403 | BA10: 156.16081 | BB10: 0 | BC10: 914.32 | BE10: =IFERROR(Z10/I10,0) -> 0 | BF10: =IFERROR(AA10/J10,0) -> 0.0027187846 | BG10: =IFERROR(AB10/K10,0) -> 0.0027187846 | BH10: =IFERROR(AC10/L10,0) -> 0.0027187846 | BI10: =IFERROR(AD10/M10,0) -> 0 | BJ10: =IFERROR(AE10/N10,0) -> 0.31696301 | BK10: =IFERROR(AF10/I10,0) -> 0 | BL10: =IFERROR(AG10/J10,0) -> 0.010580797 | BM10: =IFERROR(AH10/K10,0) -> 0.010580797 | BN10: =IFERROR(AI10/L10,0) -> 0.010580797 | BO10: =IFERROR(AJ10/M10,0) -> 0 | BP10: =IFERROR(AK10/N10,0) -> 0.85452396 | BQ10: =IFERROR(AL10/I10,0) -> 0 | BR10: =IFERROR(AM10/J10,0) -> 1.3387779e-05 | BS10: =IFERROR(AN10/K10,0) -> 0.0073076149 | BT10: =IFERROR(AO10/L10,0) -> 0 | BU10: =IFERROR(AP10/M10,0) -> 0 | BV10: =IFERROR(AQ10/N10,0) -> 0.052588246 | BW10: =IFERROR(AR10/I10,0) -> 0 | BX10: =IFERROR(AS10/J10,0) -> 0 | BY10: =IFERROR(AT10/K10,0) -> 0 | BZ10: =IFERROR(AU10/L10,0) -> 0 | CA10: =IFERROR(AV10/M10,0) -> 0 | CB10: =IFERROR(AW10/N10,0) -> 0.0089778401 | CC10: =IFERROR(AX10/I10,0) -> 0 | CD10: =IFERROR(AY10/J10,0) -> 0.0073076149 | CE10: =IFERROR(AZ10/K10,0) -> 0.0073076149 | CF10: =IFERROR(BA10/L10,0) -> 0.0073076149 | CG10: =IFERROR(BB10/M10,0) -> 0 | CH10: =IFERROR(BC10/N10,0) -> 0.26694695 | CJ10: =IFERROR(I10/$I$39,0) -> 0 | CK10: =IFERROR(J10/$J$39,0) -> 0.020521237 | CL10: =IFERROR(K10/$K$39,0) -> 0.077608664 | CM10: =IFERROR(L10/$L$39,0) -> 0.0087337606 | CN10: =IFERROR(M10/$M$39,0) -> 0 | CO10: =IFERROR(N10/$N$39,0) -> 0.035332091 | CQ10: =IFERROR(BE10*CJ10,0) -> 0 | CR10: =IFERROR(BF10*CK10,0) -> 5.5792822e-05 | CS10: =IFERROR(BG10*CL10,0) -> 0.00021100124 | CT10: =IFERROR(BH10*CM10,0) -> 2.3745214e-05 | CU10: =IFERROR(BI10*CN10,0) -> 0 | CV10: =IFERROR(BJ10*CO10,0) -> 0.011198966 | CW10: =IFERROR(BK10*CJ10,0) -> 0 | CX10: =IFERROR(BL10*CK10,0) -> 0.00021713104 | CY10: =IFERROR(BM10*CL10,0) -> 0.00082116154 | CZ10: =IFERROR(BN10*CM10,0) -> 9.241015e-05 | DA10: =IFERROR(BO10*CN10,0) -> 0 | DB10: =IFERROR(BP10*CO10,0) -> 0.030192118 | DC10: =IFERROR(BQ10*CJ10,0) -> 0 | DD10: =IFERROR(BR10*CK10,0) -> 2.7473378e-07 | DE10: =IFERROR(BS10*CL10,0) -> 0.00056713423 | DF10: =IFERROR(BT10*CM10,0) -> 0 | DG10: =IFERROR(BU10*CN10,0) -> 0 | DH10: =IFERROR(BV10*CO10,0) -> 0.0018580527 | DI10: =IFERROR(BW10*CJ10,0) -> 0 | DJ10: =IFERROR(BX10*CK10,0) -> 0 | DK10: =IFERROR(BY10*CL10,0) -> 0 | DL10: =IFERROR(BZ10*CM10,0) -> 0 | DM10: =IFERROR(CA10*CN10,0) -> 0 | DN10: =IFERROR(CB10*CO10,0) -> 0.00031720587 | DO10: =IFERROR(CC10*CJ10,0) -> 0 | DP10: =IFERROR(CD10*CK10,0) -> 0.0001499613 | DQ10: =IFERROR(CE10*CL10,0) -> 0.00056713423 | DR10: =IFERROR(CF10*CM10,0) -> 6.382296e-05 | DS10: =IFERROR(CG10*CN10,0) -> 0 | DT10: =IFERROR(CH10*CO10,0) -> 0.009431794
A11: DK | B11: Denmark | C11: 0 | D11: 0 | F11: 73901.108 | G11: 0.98204806 | H11: 3271.427 | I11: 600 | J11: 1200 | K11: 2094.667 | L11: 65408.346 | M11: 0 | N11: 5844.26 | Q11: =H11/F11 -> 0.044267631 | R11: 0.0081189581 | S11: =(J11/F11)*0.988 -> 0.016043061 | T11: 0.00019485499 | U11: 0.028344189 | V11: =($L11/$F11)*0.94 -> 0.83197461 | W11: =($L11/$F11)*0.06 -> 0.053104762 | Y11: DK | Z11: 0.041980389 | AA11: 3.8276666 | AB11: 6.6814057 | AC11: 208.63445 | AD11: 0 | AE11: 1405.59 | AF11: 0.16404486 | AG11: 14.957199 | AH11: 26.108626 | AI11: 815.27139 | AJ11: 0 | AK11: 1759.96 | AL11: 0.32331564 | AM11: 9.0994116 | AN11: 9.3316299 | AO11: 0 | AP11: 0 | AQ11: 3845.69 | AR11: 0 | AS11: 0 | AT11: 0 | AU11: 0 | AV11: 0 | AW11: 711.06 | AX11: 0.058632191 | AY11: 5.3459361 | AZ11: 9.3316299 | BA11: 291.3907 | BB11: 0 | BC11: 1044.09 | BE11: =IFERROR(Z11/I11,0) -> 6.9967315e-05 | BF11: =IFERROR(AA11/J11,0) -> 0.0031897221 | BG11: =IFERROR(AB11/K11,0) -> 0.0031897221 | BH11: =IFERROR(AC11/L11,0) -> 0.0031897221 | BI11: =IFERROR(AD11/M11,0) -> 0 | BJ11: =IFERROR(AE11/N11,0) -> 0.24050778 | BK11: =IFERROR(AF11/I11,0) -> 0.00027340811 | BL11: =IFERROR(AG11/J11,0) -> 0.012464333 | BM11: =IFERROR(AH11/K11,0) -> 0.012464333 | BN11: =IFERROR(AI11/L11,0) -> 0.012464333 | BO11: =IFERROR(AJ11/M11,0) -> 0 | BP11: =IFERROR(AK11/N11,0) -> 0.30114334 | BQ11: =IFERROR(AL11/I11,0) -> 0.00053885939 | BR11: =IFERROR(AM11/J11,0) -> 0.007582843 | BS11: =IFERROR(AN11/K11,0) -> 0.0044549467 | BT11: =IFERROR(AO11/L11,0) -> 0 | BU11: =IFERROR(AP11/M11,0) -> 0 | BV11: =IFERROR(AQ11/N11,0) -> 0.65802856 | BW11: =IFERROR(AR11/I11,0) -> 0 | BX11: =IFERROR(AS11/J11,0) -> 0 | BY11: =IFERROR(AT11/K11,0) -> 0 | BZ11: =IFERROR(AU11/L11,0) -> 0 | CA11: =IFERROR(AV11/M11,0) -> 0 | CB11: =IFERROR(AW11/N11,0) -> 0.1216681 | CC11: =IFERROR(AX11/I11,0) -> 9.7720318e-05 | CD11: =IFERROR(AY11/J11,0) -> 0.0044549467 | CE11: =IFERROR(AZ11/K11,0) -> 0.0044549467 | CF11: =IFERROR(BA11/L11,0) -> 0.0044549467 | CG11: =IFERROR(BB11/M11,0) -> 0 | CH11: =IFERROR(BC11/N11,0) -> 0.17865222 | CJ11: =IFERROR(I11/$I$39,0) -> 0.012909033 | CK11: =IFERROR(J11/$J$39,0) -> 0.0021419052 | CL11: =IFERROR(K11/$K$39,0) -> 0.028416359 | CM11: =IFERROR(L11/$L$39,0) -> 0.026732407 | CN11: =IFERROR(M11/$M$39,0) -> 0 | CO11: =IFERROR(N11/$N$39,0) -> 0.06028727 | CQ11: =IFERROR(BE11*CJ11,0) -> 9.0321039e-07 | CR11: =IFERROR(BF11*CK11,0) -> 6.8320824e-06 | CS11: =IFERROR(BG11*CL11,0) -> 9.064029e-05 | CT11: =IFERROR(BH11*CM11,0) -> 8.5268949e-05 | CU11: =IFERROR(BI11*CN11,0) -> 0 | CV11: =IFERROR(BJ11*CO11,0) -> 0.014499557 | CW11: =IFERROR(BK11*CJ11,0) -> 3.5294343e-06 | CX11: =IFERROR(BL11*CK11,0) -> 2.6697419e-05 | CY11: =IFERROR(BM11*CL11,0) -> 0.00035419096 | CZ11: =IFERROR(BN11*CM11,0) -> 0.00033320161 | DA11: =IFERROR(BO11*CN11,0) -> 0 | DB11: =IFERROR(BP11*CO11,0) -> 0.01815511 | DC11: =IFERROR(BQ11*CJ11,0) -> 6.9561538e-06 | DD11: =IFERROR(BR11*CK11,0) -> 1.6241731e-05 | DE11: =IFERROR(BS11*CL11,0) -> 0.00012659337 | DF11: =IFERROR(BT11*CM11,0) -> 0 | DG11: =IFERROR(BU11*CN11,0) -> 0 | DH11: =IFERROR(BV11*CO11,0) -> 0.039670745 | DI11: =IFERROR(BW11*CJ11,0) -> 0 | DJ11: =IFERROR(BX11*CK11,0) -> 0 | DK11: =IFERROR(BY11*CL11,0) -> 0 | DL11: =IFERROR(BZ11*CM11,0) -> 0 | DM11: =IFERROR(CA11*CN11,0) -> 0 | DN11: =IFERROR(CB11*CO11,0) -> 0.0073350375 | DO11: =IFERROR(CC11*CJ11,0) -> 1.2614748e-06 | DP11: =IFERROR(CD11*CK11,0) -> 9.5420736e-06 | DQ11: =IFERROR(CE11*CL11,0) -> 0.00012659337 | DR11: =IFERROR(CF11*CM11,0) -> 0.00011909145 | DS11: =IFERROR(CG11*CN11,0) -> 0 | DT11: =IFERROR(CH11*CO11,0) -> 0.010770454
A12: DE | B12: Germany | C12: 546.712 | D12: 546.712 | E12: 1 | F12: 591362.56 | G12: 0.98533433 | H12: 3504.4 | I12: 17668.431 | J12: 60884.712 | K12: 15519.565 | L12: 485112.72 | M12: 546.712 | N12: 13884.97 | Q12: =H12/F12 -> 0.0059259755 | R12: 0.029877494 | S12: =(J12/F12)*0.988 -> 0.10172118 | T12: 0.0012354799 | U12: 0.02624374 | V12: =($L12/$F12)*0.94 -> 0.77111063 | W12: =($L12/$F12)*0.06 -> 0.049219828 | Y12: DE | Z12: 10.754013 | AA12: 211.12302 | AB12: 53.815439 | AC12: 1682.1705 | AD12: 10.7505 | AE12: 2492.77 | AF12: 18.324623 | AG12: 359.7494 | AH12: 91.700429 | AI12: 2866.3847 | AJ12: 0 | AK12: 13286.42 | AL12: 6.5318587 | AM12: 4.3756579 | AN12: 162.97362 | AO12: 0 | AP12: 0 | AQ12: 915.57 | AR12: 0 | AS12: 0 | AT12: 0 | AU12: 0 | AV12: 0 | AW12: 270.29 | AX12: 32.567243 | AY12: 639.36084 | AZ12: 162.97362 | BA12: 5094.2522 | BB12: 10.8 | BC12: 3862.41 | BE12: =IFERROR(Z12/I12,0) -> 0.00060865693 | BF12: =IFERROR(AA12/J12,0) -> 0.0034675868 | BG12: =IFERROR(AB12/K12,0) -> 0.0034675868 | BH12: =IFERROR(AC12/L12,0) -> 0.0034675868 | BI12: =IFERROR(AD12/M12,0) -> 0.019663918 | BJ12: =IFERROR(AE12/N12,0) -> 0.1795301 | BK12: =IFERROR(AF12/I12,0) -> 0.0010371392 | BL12: =IFERROR(AG12/J12,0) -> 0.0059086984 | BM12: =IFERROR(AH12/K12,0) -> 0.0059086984 | BN12: =IFERROR(AI12/L12,0) -> 0.0059086984 | BO12: =IFERROR(AJ12/M12,0) -> 0 | BP12: =IFERROR(AK12/N12,0) -> 0.95689224 | BQ12: =IFERROR(AL12/I12,0) -> 0.00036969093 | BR12: =IFERROR(AM12/J12,0) -> 7.1867925e-05 | BS12: =IFERROR(AN12/K12,0) -> 0.010501172 | BT12: =IFERROR(AO12/L12,0) -> 0 | BU12: =IFERROR(AP12/M12,0) -> 0 | BV12: =IFERROR(AQ12/N12,0) -> 0.065939646 | BW12: =IFERROR(AR12/I12,0) -> 0 | BX12: =IFERROR(AS12/J12,0) -> 0 | BY12: =IFERROR(AT12/K12,0) -> 0 | BZ12: =IFERROR(AU12/L12,0) -> 0 | CA12: =IFERROR(AV12/M12,0) -> 0 | CB12: =IFERROR(AW12/N12,0) -> 0.019466373 | CC12: =IFERROR(AX12/I12,0) -> 0.0018432448 | CD12: =IFERROR(AY12/J12,0) -> 0.010501172 | CE12: =IFERROR(AZ12/K12,0) -> 0.010501172 | CF12: =IFERROR(BA12/L12,0) -> 0.010501172 | CG12: =IFERROR(BB12/M12,0) -> 0.019754459 | CH12: =IFERROR(BC12/N12,0) -> 0.27817201 | CJ12: =IFERROR(I12/$I$39,0) -> 0.38013727 | CK12: =IFERROR(J12/$J$39,0) -> 0.1086744 | CL12: =IFERROR(K12/$K$39,0) -> 0.21053921 | CM12: =IFERROR(L12/$L$39,0) -> 0.19826568 | CN12: =IFERROR(M12/$M$39,0) -> 0.010592281 | CO12: =IFERROR(N12/$N$39,0) -> 0.14323232 | CQ12: =IFERROR(BE12*CJ12,0) -> 0.00023137318 | CR12: =IFERROR(BF12*CK12,0) -> 0.00037683792 | CS12: =IFERROR(BG12*CL12,0) -> 0.00073006299 | CT12: =IFERROR(BH12*CM12,0) -> 0.00068750347 | CU12: =IFERROR(BI12*CN12,0) -> 0.00020828574 | CV12: =IFERROR(BJ12*CO12,0) -> 0.025714513 | CW12: =IFERROR(BK12*CJ12,0) -> 0.00039425527 | CX12: =IFERROR(BL12*CK12,0) -> 0.00064212426 | CY12: =IFERROR(BM12*CL12,0) -> 0.0012440127 | CZ12: =IFERROR(BN12*CM12,0) -> 0.0011714921 | DA12: =IFERROR(BO12*CN12,0) -> 0 | DB12: =IFERROR(BP12*CO12,0) -> 0.1370579 | DC12: =IFERROR(BQ12*CJ12,0) -> 0.0001405333 | DD12: =IFERROR(BR12*CK12,0) -> 7.8102038e-06 | DE12: =IFERROR(BS12*CL12,0) -> 0.0022109085 | DF12: =IFERROR(BT12*CM12,0) -> 0 | DG12: =IFERROR(BU12*CN12,0) -> 0 | DH12: =IFERROR(BV12*CO12,0) -> 0.0094446886 | DI12: =IFERROR(BW12*CJ12,0) -> 0 | DJ12: =IFERROR(BX12*CK12,0) -> 0 | DK12: =IFERROR(BY12*CL12,0) -> 0 | DL12: =IFERROR(BZ12*CM12,0) -> 0 | DM12: =IFERROR(CA12*CN12,0) -> 0 | DN12: =IFERROR(CB12*CO12,0) -> 0.0027882138 | DO12: =IFERROR(CC12*CJ12,0) -> 0.00070068603 | DP12: =IFERROR(CD12*CK12,0) -> 0.0011412086 | DQ12: =IFERROR(CE12*CL12,0) -> 0.0022109085 | DR12: =IFERROR(CF12*CM12,0) -> 0.0020820221 | DS12: =IFERROR(CG12*CN12,0) -> 0.00020924478 | DT12: =IFERROR(CH12*CO12,0) -> 0.039843223
