Workbook
Name FID_1: [1]AGR_Fuels!$A$2

Sheet Fill Data
B2: ~TFM_Fill-R: w=RdTRABYVals; Hcol=Region
B3: TimeSlice | C3: LimType | D3: Attribute | E3: Year | F3: AllRegions | G3: Pset_CI | H3: Pset_PN | I3: Pset_CO | J3: Cset_CN
D4: ACTFLO | F4: 1 | G4: TRA* | I4: TBus,TCar,THDT,TLCV,TMop,TMot
D5: AF | F5: 1 | G5: TRA* | I5: TBus,TCar,THDT,TLCV,TMop,TMot
D6: EFF | F6: 1 | G6: TRA* | I6: TBus,TCar,THDT,TLCV,TMop,Tmot,TRai_Frt,TRai_Pas_Conv,TRai_Pas_Hspd,TRai_Pas_Metro
D7: CAP2ACT | F7: 1 | G7: TRA* | I7: TBus,TCar,THDT,TLCV,TMop,TMot

Sheet RdTRABYVals
A1: scenario | B1: attribute | C1: process | D1: commodity | E1: lim_type | F1: time_slice | G1: year | H1: commodity_group | I1: currency | J1: stage | K1: sow | L1: AL | M1: AT | N1: BA | O1: BE | P1: BG | Q1: CH | R1: CY | S1: CZ | T1: DE | U1: DK | V1: EE | W1: EL | X1: ES | Y1: FI | Z1: FR | AA1: HR | AB1: HU | AC1: IE | AD1: IS | AE1: IT | AF1: KS | AG1: LT | AH1: LU | AI1: LV | AJ1: ME | AK1: MK | AL1: MT | AM1: NL | AN1: NO | AO1: PL | AP1: PT | AQ1: RO | AR1: RS | AS1: SE | AT1: SI | AU1: SK | AV1: UK | AW1: year2
A2: BASE | B2: ACTFLO | C2: TRA_Bus_Cng_Coa | D2: DEMO | E2: - | F2: - | G2: 2010 | H2: commodity_group | I2: - | J2: - | K2: - | N2: 8.8645163 | Q2: 22.708029 | T2: 20.808901 | AA2: 8.8645163 | AE2: 18 | AF2: 8.8645163 | AM2: 32.854839 | AR2: 8.8645163 | AS2: 9.5039015 | AW2: -
A3: BASE | B3: ACTFLO | C3: TRA_Bus_Cng_Urb | D3: DEMO | E3: - | F3: - | G3: 2010 | H3: commodity_group | I3: - | J3: - | K3: - | N3: 8.8645163 | Q3: 22.708029 | T3: 20.808901 | AA3: 8.8645163 | AE3: 18 | AF3: 8.8645163 | AM3: 32.854839 | AR3: 8.8645163 | AS3: 9.5039015 | AW3: -
A4: BASE | B4: ACTFLO | C4: TRA_Bus_Dis_Coa | D4: DEMO | E4: - | F4: - | G4: 2010 | H4: commodity_group | I4: - | J4: - | K4: - | L4: 27.25 | M4: 18.844231 | N4: 8.8645163 | O4: 32.854839 | P4: 19.464134 | Q4: 22.708029 | R4: 9.6167755 | S4: 24.425665 | T4: 20.808901 | U4: 12 | V4: 11.532486 | W4: 27.25 | X4: 24.299999 | Y4: 13 | Z4: 17.698154 | AA4: 8.8645163 | AB4: 30 | AC4: 27.25 | AD4: 9.6172838 | AE4: 18 | AF4: 8.8645163 | AG4: 31.747139 | AH4: 32.854839 | AI4: 12 | AJ4: 27.25 | AK4: 35.676472 | AL4: 32.854839 | AM4: 32.854839 | AN4: 12.944118 | AO4: 9.9356022 | AP4: 27.800829 | AQ4: 19.464134 | AR4: 8.8645163 | AS4: 9.5039015 | AT4: 21.951725 | AU4: 17.130739 | AV4: 17 | AW4: -
A5: BASE | B5: ACTFLO | C5: TRA_Bus_Dis_Urb | D5: DEMO | E5: - | F5: - | G5: 2010 | H5: commodity_group | I5: - | J5: - | K5: - | L5: 27.25 | M5: 18.844231 | N5: 8.8645163 | O5: 32.854839 | P5: 19.464134 | Q5: 22.708029 | R5: 9.6167755 | S5: 24.425665 | T5: 20.808901 | U5: 12 | V5: 11.532486 | W5: 27.25 | X5: 24.299999 | Y5: 13 | Z5: 17.698154 | AA5: 8.8645163 | AB5: 30 | AC5: 27.25 | AD5: 9.6172838 | AE5: 18 | AF5: 8.8645163 | AG5: 31.747139 | AH5: 32.854839 | AI5: 12 | AJ5: 27.25 | AK5: 35.676472 | AL5: 32.854839 | AM5: 32.854839 | AN5: 12.944118 | AO5: 9.9356022 | AP5: 27.800829 | AQ5: 19.464134 | AR5: 8.8645163 | AS5: 9.5039015 | AT5: 21.951725 | AU5: 17.130739 | AV5: 17 | AW5: -
A6: BASE | B6: ACTFLO | C6: TRA_Bus_Gas_Coa | D6: DEMO | E6: - | F6: - | G6: 2010 | H6: commodity_group | I6: - | J6: - | K6: - | S6: 24.425665 | U6: 12 | AD6: 9.6172838 | AK6: 35.676472 | AM6: 32.854839 | AO6: 9.9356022 | AP6: 27.800829 | AV6: 17 | AW6: -
A7: BASE | B7: ACTFLO | C7: TRA_Bus_Gas_Urb | D7: DEMO | E7: - | F7: - | G7: 2010 | H7: commodity_group | I7: - | J7: - | K7: - | S7: 24.425665 | U7: 12 | AD7: 9.6172838 | AK7: 35.676472 | AM7: 32.854839 | AO7: 9.9356022 | AP7: 27.800829 | AV7: 17 | AW7: -
A8: BASE | B8: ACTFLO | C8: TRA_Bus_Lpg_Coa | D8: DEMO | E8: - | F8: - | G8: 2010 | H8: commodity_group | I8: - | J8: - | K8: - | AI8: 12 | AK8: 35.676472 | AM8: 32.854839 | AO8: 9.9356022 | AP8: 27.800829 | AV8: 17 | AW8: -
A9: BASE | B9: ACTFLO | C9: TRA_Bus_Lpg_Urb | D9: DEMO | E9: - | F9: - | G9: 2010 | H9: commodity_group | I9: - | J9: - | K9: - | AI9: 12 | AK9: 35.676472 | AM9: 32.854839 | AO9: 9.9356022 | AP9: 27.800829 | AV9: 17 | AW9: -
A10: BASE | B10: ACTFLO | C10: TRA_Car_Cng_Exe | D10: DEMO | E10: - | F10: - | G10: 2010 | H10: commodity_group | I10: - | J10: - | K10: - | Q10: 1.6065165 | T10: 1.4904687 | AE10: 1.71 | AM10: 1.33 | AS10: 1.4534742 | AV10: 1.5599999 | AW10: -
A11: BASE | B11: ACTFLO | C11: TRA_Car_Cng_Lom | D11: DEMO | E11: - | F11: - | G11: 2010 | H11: commodity_group | I11: - | J11: - | K11: - | Q11: 1.6065165 | T11: 1.4904687 | AE11: 1.71 | AM11: 1.33 | AS11: 1.4534742 | AV11: 1.5599999 | AW11: -
A12: BASE | B12: ACTFLO | C12: TRA_Car_Cng_Sma | D12: DEMO | E12: - | F12: - | G12: 2010 | H12: commodity_group | I12: - | J12: - | K12: - | Q12: 1.6065165 | T12: 1.4904687 | AE12: 1.71 | AM12: 1.33 | AS12: 1.4534742 | AV12: 1.5599999 | AW12: -
A13: BASE | B13: ACTFLO | C13: TRA_Car_Cng_Upm | D13: DEMO | E13: - | F13: - | G13: 2010 | H13: commodity_group | I13: - | J13: - | K13: - | Q13: 1.6065165 | T13: 1.4904687 | AE13: 1.71 | AM13: 1.33 | AS13: 1.4534742 | AV13: 1.5599999 | AW13: -
A14: BASE | B14: ACTFLO | C14: TRA_Car_Dis_Exe | D14: DEMO | E14: - | F14: - | G14: 2010 | H14: commodity_group | I14: - | J14: - | K14: - | L14: 1.4975108 | M14: 1.1799999 | N14: 1.3824637 | O14: 1.5102819 | P14: 1.5599999 | Q14: 1.6065165 | R14: 1.4644458 | S14: 1.38 | T14: 1.4904687 | U14: 1.5599999 | V14: 1.45 | W14: 1.4975108 | X14: 1.74 | Y14: 1.4000432 | Z14: 1.8285844 | AA14: 1.3824637 | AB14: 1.84 | AC14: 1.4975108 | AD14: 2.0627906 | AE14: 1.71 | AF14: 1.3824637 | AG14: 1.9999866 | AH14: 1.5102819 | AI14: 1.4330004 | AJ14: 1.4975108 | AK14: 1.5599999 | AL14: 1.5102819 | AM14: 1.33 | AN14: 1.7 | AO14: 1.9665447 | AP14: 1.4975108 | AQ14: 1.9828243 | AR14: 1.3824637 | AS14: 1.4534742 | AT14: 1.6398644 | AU14: 1.95 | AV14: 1.5599999 | AW14: -
A15: BASE | B15: ACTFLO | C15: TRA_Car_Dis_Lom | D15: DEMO | E15: - | F15: - | G15: 2010 | H15: commodity_group | I15: - | J15: - | K15: - | L15: 1.4975108 | M15: 1.1799999 | N15: 1.3824637 | O15: 1.5102819 | P15: 1.5599999 | Q15: 1.6065165 | R15: 1.4644458 | S15: 1.38 | T15: 1.4904687 | U15: 1.5599999 | V15: 1.45 | W15: 1.4975108 | X15: 1.74 | Y15: 1.4000432 | Z15: 1.8285844 | AA15: 1.3824637 | AB15: 1.84 | AC15: 1.4975108 | AD15: 2.0627906 | AE15: 1.71 | AF15: 1.3824637 | AG15: 1.9999866 | AH15: 1.5102819 | AI15: 1.4330004 | AJ15: 1.4975108 | AK15: 1.5599999 | AL15: 1.5102819 | AM15: 1.33 | AN15: 1.7 | AO15: 1.9665447 | AP15: 1.4975108 | AQ15: 1.9828243 | AR15: 1.3824637 | AS15: 1.4534742 | AT15: 1.6398644 | AU15: 1.95 | AV15: 1.5599999 | AW15: -
A16: BASE | B16: ACTFLO | C16: TRA_Car_Dis_Sma | D16: DEMO | E16: - | F16: - | G16: 2010 | H16: commodity_group | I16: - | J16: - | K16: - | L16: 1.4975108 | M16: 1.1799999 | N16: 1.3824637 | O16: 1.5102819 | P16: 1.5599999 | Q16: 1.6065165 | R16: 1.4644458 | S16: 1.38 | T16: 1.4904687 | U16: 1.5599999 | V16: 1.45 | W16: 1.4975108 | X16: 1.74 | Y16: 1.4000432 | Z16: 1.8285844 | AA16: 1.3824637 | AB16: 1.84 | AC16: 1.4975108 | AD16: 2.0627906 | AE16: 1.71 | AF16: 1.3824637 | AG16: 1.9999866 | AH16: 1.5102819 | AI16: 1.4330004 | AJ16: 1.4975108 | AK16: 1.5599999 | AL16: 1.5102819 | AM16: 1.33 | AN16: 1.7 | AO16: 1.9665447 | AP16: 1.4975108 | AQ16: 1.9828243 | AR16: 1.3824637 | AS16: 1.4534742 | AT16: 1.6398644 | AU16: 1.95 | AV16: 1.5599999 | AW16: -
A17: BASE | B17: ACTFLO | C17: TRA_Car_Dis_Upm | D17: DEMO | E17: - | F17: - | G17: 2010 | H17: commodity_group | I17: - | J17: - | K17: - | L17: 1.4975108 | M17: 1.1799999 | N17: 1.3824637 | O17: 1.5102819 | P17: 1.5599999 | Q17: 1.6065165 | R17: 1.4644458 | S17: 1.38 | T17: 1.4904687 | U17: 1.5599999 | V17: 1.45 | W17: 1.4975108 | X17: 1.74 | Y17: 1.4000432 | Z17: 1.8285844 | AA17: 1.3824637 | AB17: 1.84 | AC17: 1.4975108 | AD17: 2.0627906 | AE17: 1.71 | AF17: 1.3824637 | AG17: 1.9999866 | AH17: 1.5102819 | AI17: 1.4330004 | AJ17: 1.4975108 | AK17: 1.5599999 | AL17: 1.5102819 | AM17: 1.33 | AN17: 1.7 | AO17: 1.9665447 | AP17: 1.4975108 | AQ17: 1.9828243 | AR17: 1.3824637 | AS17: 1.4534742 | AT17: 1.6398644 | AU17: 1.95 | AV17: 1.5599999 | AW17: -
A18: BASE | B18: ACTFLO | C18: TRA_Car_Fle_Fue_Exe | D18: DEMO | E18: - | F18: - | G18: 2010 | H18: commodity_group | I18: - | J18: - | K18: - | Q18: 1.6065165 | AS18: 1.4534742 | AW18: -
A19: BASE | B19: ACTFLO | C19: TRA_Car_Fle_Fue_Lom | D19: DEMO | E19: - | F19: - | G19: 2010 | H19: commodity_group | I19: - | J19: - | K19: - | Q19: 1.6065165 | AS19: 1.4534742 | AW19: -
A20: BASE | B20: ACTFLO | C20: TRA_Car_Fle_Fue_Sma | D20: DEMO | E20: - | F20: - | G20: 2010 | H20: commodity_group | I20: - | J20: - | K20: - | Q20: 1.6065165 | AS20: 1.4534742 | AW20: -
A21: BASE | B21: ACTFLO | C21: TRA_Car_Fle_Fue_Upm | D21: DEMO | E21: - | F21: - | G21: 2010 | H21: commodity_group | I21: - | J21: - | K21: - | Q21: 1.6065165 | AS21: 1.4534742 | AW21: -
A22: BASE | B22: ACTFLO | C22: TRA_Car_Gas_Exe | D22: DEMO | E22: - | F22: - | G22: 2010 | H22: commodity_group | I22: - | J22: - | K22: - | L22: 1.4975108 | M22: 1.1799999 | N22: 1.3824637 | O22: 1.5102819 | P22: 1.5599999 | Q22: 1.6065165 | R22: 1.4644458 | S22: 1.38 | T22: 1.4904687 | U22: 1.5599999 | V22: 1.45 | W22: 1.4975108 | X22: 1.74 | Y22: 1.4000432 | Z22: 1.8285844 | AA22: 1.3824637 | AB22: 1.84 | AC22: 1.4975108 | AD22: 2.0627906 | AE22: 1.71 | AF22: 1.3824637 | AG22: 1.9999866 | AH22: 1.5102819 | AI22: 1.4330004 | AJ22: 1.4975108 | AK22: 1.5599999 | AL22: 1.5102819 | AM22: 1.33 | AN22: 1.7 | AO22: 1.9665447 | AP22: 1.4975108 | AQ22: 1.9828243 | AR22: 1.3824637 | AS22: 1.4534742 | AT22: 1.6398644 | AU22: 1.95 | AV22: 1.5599999 | AW22: -
A23: BASE | B23: ACTFLO | C23: TRA_Car_Gas_Lom | D23: DEMO | E23: - | F23: - | G23: 2010 | H23: commodity_group | I23: - | J23: - | K23: - | L23: 1.4975108 | M23: 1.1799999 | N23: 1.3824637 | O23: 1.5102819 | P23: 1.5599999 | Q23: 1.6065165 | R23: 1.4644458 | S23: 1.38 | T23: 1.4904687 | U23: 1.5599999 | V23: 1.45 | W23: 1.4975108 | X23: 1.74 | Y23: 1.4000432 | Z23: 1.8285844 | AA23: 1.3824637 | AB23: 1.84 | AC23: 1.4975108 | AD23: 2.0627906 | AE23: 1.71 | AF23: 1.3824637 | AG23: 1.9999866 | AH23: 1.5102819 | AI23: 1.4330004 | AJ23: 1.4975108 | AK23: 1.5599999 | AL23: 1.5102819 | AM23: 1.33 | AN23: 1.7 | AO23: 1.9665447 | AP23: 1.4975108 | AQ23: 1.9828243 | AR23: 1.3824637 | AS23: 1.4534742 | AT23: 1.6398644 | AU23: 1.95 | AV23: 1.5599999 | AW23: -
A24: BASE | B24: ACTFLO | C24: TRA_Car_Gas_Sma | D24: DEMO | E24: - | F24: - | G24: 2010 | H24: commodity_group | I24: - | J24: - | K24: - | L24: 1.4975108 | M24: 1.1799999 | N24: 1.3824637 | O24: 1.5102819 | P24: 1.5599999 | Q24: 1.6065165 | R24: 1.4644458 | S24: 1.38 | T24: 1.4904687 | U24: 1.5599999 | V24: 1.45 | W24: 1.4975108 | X24: 1.74 | Y24: 1.4000432 | Z24: 1.8285844 | AA24: 1.3824637 | AB24: 1.84 | AC24: 1.4975108 | AD24: 2.0627906 | AE24: 1.71 | AF24: 1.3824637 | AG24: 1.9999866 | AH24: 1.5102819 | AI24: 1.4330004 | AJ24: 1.4975108 | AK24: 1.5599999 | AL24: 1.5102819 | AM24: 1.33 | AN24: 1.7 | AO24: 1.9665447 | AP24: 1.4975108 | AQ24: 1.9828243 | AR24: 1.3824637 | AS24: 1.4534742 | AT24: 1.6398644 | AU24: 1.95 | AV24: 1.5599999 | AW24: -
A25: BASE | B25: ACTFLO | C25: TRA_Car_Gas_Upm | D25: DEMO | E25: - | F25: - | G25: 2010 | H25: commodity_group | I25: - | J25: - | K25: - | L25: 1.4975108 | M25: 1.1799999 | N25: 1.3824637 | O25: 1.5102819 | P25: 1.5599999 | Q25: 1.6065165 | R25: 1.4644458 | S25: 1.38 | T25: 1.4904687 | U25: 1.5599999 | V25: 1.45 | W25: 1.4975108 | X25: 1.74 | Y25: 1.4000432 | Z25: 1.8285844 | AA25: 1.3824637 | AB25: 1.84 | AC25: 1.4975108 | AD25: 2.0627906 | AE25: 1.71 | AF25: 1.3824637 | AG25: 1.9999866 | AH25: 1.5102819 | AI25: 1.4330004 | AJ25: 1.4975108 | AK25: 1.5599999 | AL25: 1.5102819 | AM25: 1.33 | AN25: 1.7 | AO25: 1.9665447 | AP25: 1.4975108 | AQ25: 1.9828243 | AR25: 1.3824637 | AS25: 1.4534742 | AT25: 1.6398644 | AU25: 1.95 | AV25: 1.5599999 | AW25: -
A26: BASE | B26: ACTFLO | C26: TRA_Car_Lpg_Exe | D26: DEMO | E26: - | F26: - | G26: 2010 | H26: commodity_group | I26: - | J26: - | K26: - | L26: 1.4975108 | N26: 1.3824637 | O26: 1.5102819 | P26: 1.5599999 | T26: 1.4904687 | U26: 1.5599999 | W26: 1.4975108 | Z26: 1.8285844 | AA26: 1.3824637 | AB26: 1.84 | AC26: 1.4975108 | AE26: 1.71 | AF26: 1.3824637 | AI26: 1.4330004 | AJ26: 1.4975108 | AK26: 1.5599999 | AM26: 1.33 | AO26: 1.9665447 | AP26: 1.4975108 | AQ26: 1.9828243 | AR26: 1.3824637 | AU26: 1.95 | AV26: 1.5599999 | AW26: -
A27: BASE | B27: ACTFLO | C27: TRA_Car_Lpg_Lom | D27: DEMO | E27: - | F27: - | G27: 2010 | H27: commodity_group | I27: - | J27: - | K27: - | L27: 1.4975108 | N27: 1.3824637 | O27: 1.5102819 | P27: 1.5599999 | T27: 1.4904687 | U27: 1.5599999 | W27: 1.4975108 | Z27: 1.8285844 | AA27: 1.3824637 | AB27: 1.84 | AC27: 1.4975108 | AE27: 1.71 | AF27: 1.3824637 | AI27: 1.4330004 | AJ27: 1.4975108 | AK27: 1.5599999 | AM27: 1.33 | AO27: 1.9665447 | AP27: 1.4975108 | AQ27: 1.9828243 | AR27: 1.3824637 | AU27: 1.95 | AV27: 1.5599999 | AW27: -
A28: BASE | B28: ACTFLO | C28: TRA_Car_Lpg_Sma | D28: DEMO | E28: - | F28: - | G28: 2010 | H28: commodity_group | I28: - | J28: - | K28: - | L28: 1.4975108 | N28: 1.3824637 | O28: 1.5102819 | P28: 1.5599999 | T28: 1.4904687 | U28: 1.5599999 | W28: 1.4975108 | Z28: 1.8285844 | AA28: 1.3824637 | AB28: 1.84 | AC28: 1.4975108 | AE28: 1.71 | AF28: 1.3824637 | AI28: 1.4330004 | AJ28: 1.4975108 | AK28: 1.5599999 | AM28: 1.33 | AO28: 1.9665447 | AP28: 1.4975108 | AQ28: 1.9828243 | AR28: 1.3824637 | AU28: 1.95 | AV28: 1.5599999 | AW28: -
A29: BASE | B29: ACTFLO | C29: TRA_Car_Lpg_Upm | D29: DEMO | E29: - | F29: - | G29: 2010 | H29: commodity_group | I29: - | J29: - | K29: - | L29: 1.4975108 | N29: 1.3824637 | O29: 1.5102819 | P29: 1.5599999 | T29: 1.4904687 | U29: 1.5599999 | W29: 1.4975108 | Z29: 1.8285844 | AA29: 1.3824637 | AB29: 1.84 | AC29: 1.4975108 | AE29: 1.71 | AF29: 1.3824637 | AI29: 1.4330004 | AJ29: 1.4975108 | AK29: 1.5599999 | AM29: 1.33 | AO29: 1.9665447 | AP29: 1.4975108 | AQ29: 1.9828243 | AR29: 1.3824637 | AU29: 1.95 | AV29: 1.5599999 | AW29: -
A30: BASE | B30: ACTFLO | C30: TRA_Car_Oth_Exe | D30: DEMO | E30: - | F30: - | G30: 2010 | H30: commodity_group | I30: - | J30: - | K30: - | S30: 1.38 | U30: 1.5599999 | AD30: 2.0627906 | AM30: 1.33 | AO30: 1.9665447 | AP30: 1.4975108 | AS30: 1.4534742 | AV30: 1.5599999 | AW30: -
A31: BASE | B31: ACTFLO | C31: TRA_Car_Oth_Lom | D31: DEMO | E31: - | F31: - | G31: 2010 | H31: commodity_group | I31: - | J31: - | K31: - | S31: 1.38 | U31: 1.5599999 | AD31: 2.0627906 | AM31: 1.33 | AO31: 1.9665447 | AP31: 1.4975108 | AS31: 1.4534742 | AV31: 1.5599999 | AW31: -
A32: BASE | B32: ACTFLO | C32: TRA_Car_Oth_Sma | D32: DEMO | E32: - | F32: - | G32: 2010 | H32: commodity_group | I32: - | J32: - | K32: - | S32: 1.38 | U32: 1.5599999 | AD32: 2.0627906 | AM32: 1.33 | AO32: 1.9665447 | AP32: 1.4975108 | AS32: 1.4534742 | AV32: 1.5599999 | AW32: -
A33: BASE | B33: ACTFLO | C33: TRA_Car_Oth_Upm | D33: DEMO | E33: - | F33: - | G33: 2010 | H33: commodity_group | I33: - | J33: - | K33: - | S33: 1.38 | U33: 1.5599999 | AD33: 2.0627906 | AM33: 1.33 | AO33: 1.9665447 | AP33: 1.4975108 | AS33: 1.4534742 | AV33: 1.5599999 | AW33: -
A34: BASE | B34: ACTFLO | C34: TRA_Hdt_Dis | D34: DEMO | E34: - | F34: - | G34: 2010 | H34: commodity_group | I34: - | J34: - | K34: - | L34: 6.473203 | M34: 12.696687 | N34: 10.154531 | O34: 3.6177164 | P34: 14.902222 | Q34: 5.0234684 | R34: 4.0249714 | S34: 9.7457024 | T34: 6.2939784 | U34: 5.7247237 | V34: 10.897256 | W34: 6.473203 | X34: 6.2476243 | Y34: 10.957165 | Z34: 8.2550465 | AA34: 10.154531 | AB34: 9.9489386 | AC34: 11.993946 | AD34: 7.0785648 | AE34: 7.5022434 | AF34: 10.154531 | AG34: 13.305332 | AH34: 5.2429919 | AI34: 10.474089 | AJ34: 6.473203 | AK34: 12.002561 | AL34: 1.204711 | AM34: 11.101495 | AN34: 12.591807 | AO34: 11.666597 | AP34: 13.56664 | AQ34: 5.6829781 | AR34: 10.154531 | AS34: 12.879972 | AT34: 11.184903 | AU34: 8.0361799 | AV34: 6.2908245 | AW34: -
A35: BASE | B35: ACTFLO | C35: TRA_Hdt_Gas | D35: DEMO | E35: - | F35: - | G35: 2010 | H35: commodity_group | I35: - | J35: - | K35: - | L35: 1.5272753 | N35: 2.786757 | P35: 2.4181894 | R35: 0.97858094 | S35: 1.6805943 | U35: 0.71403724 | V35: 2.0055233 | W35: 1.5272753 | X35: 0.89578973 | Y35: 1.6817709 | Z35: 1.080112 | AA35: 2.786757 | AB35: 1.7156413 | AC35: 4.5393498 | AD35: 1.3488346 | AE35: 1.3574516 | AF35: 2.786757 | AG35: 3.31235 | AH35: 0.85835563 | AI35: 1.9958585 | AJ35: 1.5272753 | AK35: 1.9476603 | AM35: 1.8240133 | AN35: 2.8752834 | AO35: 2.2831262 | AQ35: 1.2736668 | AR35: 2.786757 | AS35: 1.9768948 | AT35: 1.9298371 | AV35: 0.90412603 | AW35: -
A36: BASE | B36: ACTFLO | C36: TRA_Lcv_Cng | D36: DEMO | E36: - | F36: - | G36: 2010 | H36: commodity_group | I36: - | J36: - | K36: - | L36: 0.5 | M36: 0.5 | N36: 0.5 | O36: 0.5 | P36: 0.5 | Q36: 0.5 | R36: 0.5 | S36: 0.5 | T36: 0.5 | U36: 0.5 | V36: 0.5 | W36: 0.5 | X36: 0.5 | Y36: 0.5 | Z36: 0.5 | AA36: 0.5 | AB36: 0.5 | AC36: 0.5 | AD36: 0.5 | AE36: 0.5 | AF36: 0.5 | AG36: 0.5 | AH36: 0.5 | AI36: 0.5 | AJ36: 0.5 | AK36: 0.5 | AL36: 0.5 | AM36: 0.5 | AN36: 0.5 | AO36: 0.5 | AP36: 0.5 | AQ36: 0.5 | AR36: 0.5 | AS36: 0.5 | AT36: 0.5 | AU36: 0.5 | AV36: 0.5 | AW36: -
A37: BASE | B37: ACTFLO | C37: TRA_Lcv_Dis | D37: DEMO | E37: - | F37: - | G37: 2010 | H37: commodity_group | I37: - | J37: - | K37: - | L37: 0.5 | M37: 0.5 | N37: 0.5 | O37: 0.5 | P37: 0.5 | Q37: 0.5 | R37: 0.5 | S37: 0.5 | T37: 0.5 | U37: 0.5 | V37: 0.5 | W37: 0.5 | X37: 0.5 | Y37: 0.5 | Z37: 0.5 | AA37: 0.5 | AB37: 0.5 | AC37: 0.5 | AD37: 0.5 | AE37: 0.5 | AF37: 0.5 | AG37: 0.5 | AH37: 0.5 | AI37: 0.5 | AJ37: 0.5 | AK37: 0.5 | AL37: 0.5 | AM37: 0.5 | AN37: 0.5 | AO37: 0.5 | AP37: 0.5 | AQ37: 0.5 | AR37: 0.5 | AS37: 0.5 | AT37: 0.5 | AU37: 0.5 | AV37: 0.5 | AW37: -
A38: BASE | B38: ACTFLO | C38: TRA_Lcv_Gas | D38: DEMO | E38: - | F38: - | G38: 2010 | H38: commodity_group | I38: - | J38: - | K38: - | L38: 0.5 | M38: 0.5 | N38: 0.5 | O38: 0.5 | P38: 0.5 | Q38: 0.5 | R38: 0.5 | S38: 0.5 | T38: 0.5 | U38: 0.5 | V38: 0.5 | W38: 0.5 | X38: 0.5 | Y38: 0.5 | Z38: 0.5 | AA38: 0.5 | AB38: 0.5 | AC38: 0.5 | AD38: 0.5 | AE38: 0.5 | AF38: 0.5 | AG38: 0.5 | AH38: 0.5 | AI38: 0.5 | AJ38: 0.5 | AK38: 0.5 | AL38: 0.5 | AM38: 0.5 | AN38: 0.5 | AO38: 0.5 | AP38: 0.5 | AQ38: 0.5 | AR38: 0.5 | AS38: 0.5 | AT38: 0.5 | AU38: 0.5 | AV38: 0.5 | AW38: -
A39: BASE | B39: ACTFLO | C39: TRA_Lcv_Lpg | D39: DEMO | E39: - | F39: - | G39: 2010 | H39: commodity_group | I39: - | J39: - | K39: - | L39: 0.5 | M39: 0.5 | N39: 0.5 | O39: 0.5 | P39: 0.5 | Q39: 0.5 | R39: 0.5 | S39: 0.5 | T39: 0.5 | U39: 0.5 | V39: 0.5 | W39: 0.5 | X39: 0.5 | Y39: 0.5 | Z39: 0.5 | AA39: 0.5 | AB39: 0.5 | AC39: 0.5 | AD39: 0.5 | AE39: 0.5 | AF39: 0.5 | AG39: 0.5 | AH39: 0.5 | AI39: 0.5 | AJ39: 0.5 | AK39: 0.5 | AL39: 0.5 | AM39: 0.5 | AN39: 0.5 | AO39: 0.5 | AP39: 0.5 | AQ39: 0.5 | AR39: 0.5 | AS39: 0.5 | AT39: 0.5 | AU39: 0.5 | AV39: 0.5 | AW39: -
A40: BASE | B40: ACTFLO | C40: TRA_Mop_Gas | D40: DEMO | E40: - | F40: - | G40: 2010 | H40: commodity_group | I40: - | J40: - | K40: - | L40: 1.1 | M40: 1.1005542 | N40: 1.1 | O40: 1.056 | P40: 1.1 | Q40: 1.0742905 | R40: 1.1 | S40: 1.1 | T40: 1.1 | U40: 1.1 | W40: 1.1 | X40: 1.336832 | Y40: 1 | Z40: 1.1 | AA40: 1.1 | AB40: 1.1 | AC40: 1.1 | AE40: 1.1 | AF40: 1.1 | AG40: 1.1999335 | AH40: 1.1 | AI40: 1.1 | AJ40: 1.1 | AL40: 1.1 | AM40: 1.1 | AN40: 1.0825397 | AO40: 1.1 | AP40: 1.1 | AQ40: 1.1 | AR40: 1.1 | AS40: 1.1005988 | AT40: 1.1 | AU40: 1.1 | AV40: 1.1045655 | AW40: -
...

Sheet INS
C1: ~TFM_INS
C2: Attribute | D2: PSET_PN | E2: Other_Indexes | F2: AllRegions | G2: =RdTRABYVals!L$1 -> AL | H2: =RdTRABYVals!M$1 -> AT | I2: =RdTRABYVals!N$1 -> BA | J2: =RdTRABYVals!O$1 -> BE | K2: =RdTRABYVals!P$1 -> BG | L2: =RdTRABYVals!Q$1 -> CH | M2: =RdTRABYVals!R$1 -> CY | N2: =RdTRABYVals!S$1 -> CZ | ... AQ2: =RdTRABYVals!AV$1 -> UK
A3: TRA_Bus* | C3: ACTFLO | D3: =A3 -> TRA_Bus* | E3: DEMO | F3: =AVERAGE(G3:AQ3) -> 20.082371 | G3: =IFERROR(AVERAGEIFS(RdTRABYVals!L$2:L$999,RdTRABYVals!$B$2:$B$999,"="&$C3,RdTRABYVals!$C$2:$C$999,"="&INS!$A3),"") -> 27.25 | H3: =IFERROR(AVERAGEIFS(RdTRABYVals!M$2:M$999,RdTRABYVals!$B$2:$B$999,"="&$C3,RdTRABYVals!$C$2:$C$999,"="&INS!$A3),"") -> 18.844231 | I3: =IFERROR(AVERAGEIFS(RdTRABYVals!N$2:N$999,RdTRABYVals!$B$2:$B$999,"="&$C3,RdTRABYVals!$C$2:$C$999,"="&INS!$A3),"") -> 8.8645163 | J3: =IFERROR(AVERAGEIFS(RdTRABYVals!O$2:O$999,RdTRABYVals!$B$2:$B$999,"="&$C3,RdTRABYVals!$C$2:$C$999,"="&INS!$A3),"") -> 32.854839 | K3: =IFERROR(AVERAGEIFS(RdTRABYVals!P$2:P$999,RdTRABYVals!$B$2:$B$999,"="&$C3,RdTRABYVals!$C$2:$C$999,"="&INS!$A3),"") -> 19.464134 | L3: =IFERROR(AVERAGEIFS(RdTRABYVals!Q$2:Q$999,RdTRABYVals!$B$2:$B$999,"="&$C3,RdTRABYVals!$C$2:$C$999,"="&INS!$A3),"") -> 22.708029 | M3: =IFERROR(AVERAGEIFS(RdTRABYVals!R$2:R$999,RdTRABYVals!$B$2:$B$999,"="&$C3,RdTRABYVals!$C$2:$C$999,"="&INS!$A3),"") -> 9.6167755 | N3: =IFERROR(AVERAGEIFS(RdTRABYVals!S$2:S$999,RdTRABYVals!$B$2:$B$999,"="&$C3,RdTRABYVals!$C$2:$C$999,"="&INS!$A3),"") -> 24.425665 | ... AQ3: =IFERROR(AVERAGEIFS(RdTRABYVals!AV$2:AV$999,RdTRABYVals!$B$2:$B$999,"="&$C3,RdTRABYVals!$C$2:$C$999,"="&INS!$A3),"") -> 17
A4: TRA_Car* | C4: ACTFLO | D4: =A4 -> TRA_Car* | E4: DEMO | F4: =AVERAGE(G4:AQ4) -> 1.5782919 | G4: =IFERROR(AVERAGEIFS(RdTRABYVals!L$2:L$999,RdTRABYVals!$B$2:$B$999,"="&$C4,RdTRABYVals!$C$2:$C$999,"="&INS!$A4),"") -> 1.4975108 | H4: =IFERROR(AVERAGEIFS(RdTRABYVals!M$2:M$999,RdTRABYVals!$B$2:$B$999,"="&$C4,RdTRABYVals!$C$2:$C$999,"="&INS!$A4),"") -> 1.1799999 | I4: =IFERROR(AVERAGEIFS(RdTRABYVals!N$2:N$999,RdTRABYVals!$B$2:$B$999,"="&$C4,RdTRABYVals!$C$2:$C$999,"="&INS!$A4),"") -> 1.3824637 | J4: =IFERROR(AVERAGEIFS(RdTRABYVals!O$2:O$999,RdTRABYVals!$B$2:$B$999,"="&$C4,RdTRABYVals!$C$2:$C$999,"="&INS!$A4),"") -> 1.5102819 | K4: =IFERROR(AVERAGEIFS(RdTRABYVals!P$2:P$999,RdTRABYVals!$B$2:$B$999,"="&$C4,RdTRABYVals!$C$2:$C$999,"="&INS!$A4),"") -> 1.5599999 | L4: =IFERROR(AVERAGEIFS(RdTRABYVals!Q$2:Q$999,RdTRABYVals!$B$2:$B$999,"="&$C4,RdTRABYVals!$C$2:$C$999,"="&INS!$A4),"") -> 1.6065165 | M4: =IFERROR(AVERAGEIFS(RdTRABYVals!R$2:R$999,RdTRABYVals!$B$2:$B$999,"="&$C4,RdTRABYVals!$C$2:$C$999,"="&INS!$A4),"") -> 1.4644458 | N4: =IFERROR(AVERAGEIFS(RdTRABYVals!S$2:S$999,RdTRABYVals!$B$2:$B$999,"="&$C4,RdTRABYVals!$C$2:$C$999,"="&INS!$A4),"") -> 1.38 | ... AQ4: =IFERROR(AVERAGEIFS(RdTRABYVals!AV$2:AV$999,RdTRABYVals!$B$2:$B$999,"="&$C4,RdTRABYVals!$C$2:$C$999,"="&INS!$A4),"") -> 1.5599999
A5: TRA_Hdt* | C5: ACTFLO | D5: =A5 -> TRA_Hdt* | E5: DEMO | F5: =AVERAGE(G5:AQ5) -> 5.9181669 | G5: =IFERROR(AVERAGEIFS(RdTRABYVals!L$2:L$999,RdTRABYVals!$B$2:$B$999,"="&$C5,RdTRABYVals!$C$2:$C$999,"="&INS!$A5),"") -> 4.0002391 | H5: =IFERROR(AVERAGEIFS(RdTRABYVals!M$2:M$999,RdTRABYVals!$B$2:$B$999,"="&$C5,RdTRABYVals!$C$2:$C$999,"="&INS!$A5),"") -> 12.696687 | I5: =IFERROR(AVERAGEIFS(RdTRABYVals!N$2:N$999,RdTRABYVals!$B$2:$B$999,"="&$C5,RdTRABYVals!$C$2:$C$999,"="&INS!$A5),"") -> 6.4706438 | J5: =IFERROR(AVERAGEIFS(RdTRABYVals!O$2:O$999,RdTRABYVals!$B$2:$B$999,"="&$C5,RdTRABYVals!$C$2:$C$999,"="&INS!$A5),"") -> 3.6177164 | K5: =IFERROR(AVERAGEIFS(RdTRABYVals!P$2:P$999,RdTRABYVals!$B$2:$B$999,"="&$C5,RdTRABYVals!$C$2:$C$999,"="&INS!$A5),"") -> 8.6602057 | L5: =IFERROR(AVERAGEIFS(RdTRABYVals!Q$2:Q$999,RdTRABYVals!$B$2:$B$999,"="&$C5,RdTRABYVals!$C$2:$C$999,"="&INS!$A5),"") -> 5.0234684 | M5: =IFERROR(AVERAGEIFS(RdTRABYVals!R$2:R$999,RdTRABYVals!$B$2:$B$999,"="&$C5,RdTRABYVals!$C$2:$C$999,"="&INS!$A5),"") -> 2.5017761 | N5: =IFERROR(AVERAGEIFS(RdTRABYVals!S$2:S$999,RdTRABYVals!$B$2:$B$999,"="&$C5,RdTRABYVals!$C$2:$C$999,"="&INS!$A5),"") -> 5.7131483 | ... AQ5: =IFERROR(AVERAGEIFS(RdTRABYVals!AV$2:AV$999,RdTRABYVals!$B$2:$B$999,"="&$C5,RdTRABYVals!$C$2:$C$999,"="&INS!$A5),"") -> 3.5974753
A6: TRA_Lcv* | C6: ACTFLO | D6: =A6 -> TRA_Lcv* | E6: DEMO | F6: =AVERAGE(G6:AQ6) -> 0.5 | G6: =IFERROR(AVERAGEIFS(RdTRABYVals!L$2:L$999,RdTRABYVals!$B$2:$B$999,"="&$C6,RdTRABYVals!$C$2:$C$999,"="&INS!$A6),"") -> 0.5 | H6: =IFERROR(AVERAGEIFS(RdTRABYVals!M$2:M$999,RdTRABYVals!$B$2:$B$999,"="&$C6,RdTRABYVals!$C$2:$C$999,"="&INS!$A6),"") -> 0.5 | I6: =IFERROR(AVERAGEIFS(RdTRABYVals!N$2:N$999,RdTRABYVals!$B$2:$B$999,"="&$C6,RdTRABYVals!$C$2:$C$999,"="&INS!$A6),"") -> 0.5 | J6: =IFERROR(AVERAGEIFS(RdTRABYVals!O$2:O$999,RdTRABYVals!$B$2:$B$999,"="&$C6,RdTRABYVals!$C$2:$C$999,"="&INS!$A6),"") -> 0.5 | K6: =IFERROR(AVERAGEIFS(RdTRABYVals!P$2:P$999,RdTRABYVals!$B$2:$B$999,"="&$C6,RdTRABYVals!$C$2:$C$999,"="&INS!$A6),"") -> 0.5 | L6: =IFERROR(AVERAGEIFS(RdTRABYVals!Q$2:Q$999,RdTRABYVals!$B$2:$B$999,"="&$C6,RdTRABYVals!$C$2:$C$999,"="&INS!$A6),"") -> 0.5 | M6: =IFERROR(AVERAGEIFS(RdTRABYVals!R$2:R$999,RdTRABYVals!$B$2:$B$999,"="&$C6,RdTRABYVals!$C$2:$C$999,"="&INS!$A6),"") -> 0.5 | N6: =IFERROR(AVERAGEIFS(RdTRABYVals!S$2:S$999,RdTRABYVals!$B$2:$B$999,"="&$C6,RdTRABYVals!$C$2:$C$999,"="&INS!$A6),"") -> 0.5 | ... AQ6: =IFERROR(AVERAGEIFS(RdTRABYVals!AV$2:AV$999,RdTRABYVals!$B$2:$B$999,"="&$C6,RdTRABYVals!$C$2:$C$999,"="&INS!$A6),"") -> 0.5
A7: TRA_Mop* | C7: ACTFLO | D7: =A7 -> TRA_Mop* | E7: DEMO | F7: =AVERAGE(G7:AQ7) -> 1.1045681 | G7: =IFERROR(AVERAGEIFS(RdTRABYVals!L$2:L$999,RdTRABYVals!$B$2:$B$999,"="&$C7,RdTRABYVals!$C$2:$C$999,"="&INS!$A7),"") -> 1.1 | H7: =IFERROR(AVERAGEIFS(RdTRABYVals!M$2:M$999,RdTRABYVals!$B$2:$B$999,"="&$C7,RdTRABYVals!$C$2:$C$999,"="&INS!$A7),"") -> 1.1005542 | I7: =IFERROR(AVERAGEIFS(RdTRABYVals!N$2:N$999,RdTRABYVals!$B$2:$B$999,"="&$C7,RdTRABYVals!$C$2:$C$999,"="&INS!$A7),"") -> 1.1 | J7: =IFERROR(AVERAGEIFS(RdTRABYVals!O$2:O$999,RdTRABYVals!$B$2:$B$999,"="&$C7,RdTRABYVals!$C$2:$C$999,"="&INS!$A7),"") -> 1.056 | K7: =IFERROR(AVERAGEIFS(RdTRABYVals!P$2:P$999,RdTRABYVals!$B$2:$B$999,"="&$C7,RdTRABYVals!$C$2:$C$999,"="&INS!$A7),"") -> 1.1 | L7: =IFERROR(AVERAGEIFS(RdTRABYVals!Q$2:Q$999,RdTRABYVals!$B$2:$B$999,"="&$C7,RdTRABYVals!$C$2:$C$999,"="&INS!$A7),"") -> 1.0742905 | M7: =IFERROR(AVERAGEIFS(RdTRABYVals!R$2:R$999,RdTRABYVals!$B$2:$B$999,"="&$C7,RdTRABYVals!$C$2:$C$999,"="&INS!$A7),"") -> 1.1 | N7: =IFERROR(AVERAGEIFS(RdTRABYVals!S$2:S$999,RdTRABYVals!$B$2:$B$999,"="&$C7,RdTRABYVals!$C$2:$C$999,"="&INS!$A7),"") -> 1.1 | ... AQ7: =IFERROR(AVERAGEIFS(RdTRABYVals!AV$2:AV$999,RdTRABYVals!$B$2:$B$999,"="&$C7,RdTRABYVals!$C$2:$C$999,"="&INS!$A7),"") -> 1.1045655
A8: TRA_Mot* | C8: ACTFLO | D8: =A8 -> TRA_Mot* | E8: DEMO | F8: =AVERAGE(G8:AQ8) -> 1.1041977 | G8: =IFERROR(AVERAGEIFS(RdTRABYVals!L$2:L$999,RdTRABYVals!$B$2:$B$999,"="&$C8,RdTRABYVals!$C$2:$C$999,"="&INS!$A8),"") -> 1.1 | H8: =IFERROR(AVERAGEIFS(RdTRABYVals!M$2:M$999,RdTRABYVals!$B$2:$B$999,"="&$C8,RdTRABYVals!$C$2:$C$999,"="&INS!$A8),"") -> 1.1005542 | I8: =IFERROR(AVERAGEIFS(RdTRABYVals!N$2:N$999,RdTRABYVals!$B$2:$B$999,"="&$C8,RdTRABYVals!$C$2:$C$999,"="&INS!$A8),"") -> 1.1 | J8: =IFERROR(AVERAGEIFS(RdTRABYVals!O$2:O$999,RdTRABYVals!$B$2:$B$999,"="&$C8,RdTRABYVals!$C$2:$C$999,"="&INS!$A8),"") -> 1.056 | K8: =IFERROR(AVERAGEIFS(RdTRABYVals!P$2:P$999,RdTRABYVals!$B$2:$B$999,"="&$C8,RdTRABYVals!$C$2:$C$999,"="&INS!$A8),"") -> 1.1 | L8: =IFERROR(AVERAGEIFS(RdTRABYVals!Q$2:Q$999,RdTRABYVals!$B$2:$B$999,"="&$C8,RdTRABYVals!$C$2:$C$999,"="&INS!$A8),"") -> 1.0742905 | M8: =IFERROR(AVERAGEIFS(RdTRABYVals!R$2:R$999,RdTRABYVals!$B$2:$B$999,"="&$C8,RdTRABYVals!$C$2:$C$999,"="&INS!$A8),"") -> 1.1 | N8: =IFERROR(AVERAGEIFS(RdTRABYVals!S$2:S$999,RdTRABYVals!$B$2:$B$999,"="&$C8,RdTRABYVals!$C$2:$C$999,"="&INS!$A8),"") -> 1.1 | ... AQ8: =IFERROR(AVERAGEIFS(RdTRABYVals!AV$2:AV$999,RdTRABYVals!$B$2:$B$999,"="&$C8,RdTRABYVals!$C$2:$C$999,"="&INS!$A8),"") -> 1.1045655
C11: ~TFM_INS
C12: Attribute | D12: PSET_PN | E12: Other_Indexes | F12: AllRegions
C13: CAP2ACT | D13: =A3 -> TRA_Bus* | F13: 0.001
C14: CAP2ACT | D14: =A4 -> TRA_Car* | F14: 0.001
C15: CAP2ACT | D15: =A5 -> TRA_Hdt* | F15: 0.001
C16: CAP2ACT | D16: =A6 -> TRA_Lcv* | F16: 0.001
C17: CAP2ACT | D17: =A7 -> TRA_Mop* | F17: 0.001
C18: CAP2ACT | D18: =A8 -> TRA_Mot* | F18: 0.001
C21: ~TFM_INS
C22: Attribute | D22: PSET_PN | E22: Year | F22: AllRegions | G22: =RdTRABYVals!L$1 -> AL | H22: =RdTRABYVals!M$1 -> AT | I22: =RdTRABYVals!N$1 -> BA | J22: =RdTRABYVals!O$1 -> BE | K22: =RdTRABYVals!P$1 -> BG | L22: =RdTRABYVals!Q$1 -> CH | M22: =RdTRABYVals!R$1 -> CY | N22: =RdTRABYVals!S$1 -> CZ | ... AQ22: =RdTRABYVals!AV$1 -> UK
A23: TRA_Bus_Cng_Coa* | C23: AF | D23: =A23 -> TRA_Bus_Cng_Coa* | F23: =AVERAGE(G23:AQ23) -> 16.318 | G23: =IFERROR(AVERAGEIFS(RdTRABYVals!L$2:L$999,RdTRABYVals!$B$2:$B$999,"="&$C23,RdTRABYVals!$C$2:$C$999,"="&INS!$A23),"") | H23: =IFERROR(AVERAGEIFS(RdTRABYVals!M$2:M$999,RdTRABYVals!$B$2:$B$999,"="&$C23,RdTRABYVals!$C$2:$C$999,"="&INS!$A23),"") | I23: =IFERROR(AVERAGEIFS(RdTRABYVals!N$2:N$999,RdTRABYVals!$B$2:$B$999,"="&$C23,RdTRABYVals!$C$2:$C$999,"="&INS!$A23),"") | J23: =IFERROR(AVERAGEIFS(RdTRABYVals!O$2:O$999,RdTRABYVals!$B$2:$B$999,"="&$C23,RdTRABYVals!$C$2:$C$999,"="&INS!$A23),"") | K23: =IFERROR(AVERAGEIFS(RdTRABYVals!P$2:P$999,RdTRABYVals!$B$2:$B$999,"="&$C23,RdTRABYVals!$C$2:$C$999,"="&INS!$A23),"") | L23: =IFERROR(AVERAGEIFS(RdTRABYVals!Q$2:Q$999,RdTRABYVals!$B$2:$B$999,"="&$C23,RdTRABYVals!$C$2:$C$999,"="&INS!$A23),"") | M23: =IFERROR(AVERAGEIFS(RdTRABYVals!R$2:R$999,RdTRABYVals!$B$2:$B$999,"="&$C23,RdTRABYVals!$C$2:$C$999,"="&INS!$A23),"") | N23: =IFERROR(AVERAGEIFS(RdTRABYVals!S$2:S$999,RdTRABYVals!$B$2:$B$999,"="&$C23,RdTRABYVals!$C$2:$C$999,"="&INS!$A23),"") | ... AQ23: =IFERROR(AVERAGEIFS(RdTRABYVals!AV$2:AV$999,RdTRABYVals!$B$2:$B$999,"="&$C23,RdTRABYVals!$C$2:$C$999,"="&INS!$A23),"")
A24: TRA_Bus_Cng_Urb* | C24: AF | D24: =A24 -> TRA_Bus_Cng_Urb* | F24: =AVERAGE(G24:AQ24) -> 35.596783 | G24: =IFERROR(AVERAGEIFS(RdTRABYVals!L$2:L$999,RdTRABYVals!$B$2:$B$999,"="&$C24,RdTRABYVals!$C$2:$C$999,"="&INS!$A24),"") | H24: =IFERROR(AVERAGEIFS(RdTRABYVals!M$2:M$999,RdTRABYVals!$B$2:$B$999,"="&$C24,RdTRABYVals!$C$2:$C$999,"="&INS!$A24),"") | I24: =IFERROR(AVERAGEIFS(RdTRABYVals!N$2:N$999,RdTRABYVals!$B$2:$B$999,"="&$C24,RdTRABYVals!$C$2:$C$999,"="&INS!$A24),"") | J24: =IFERROR(AVERAGEIFS(RdTRABYVals!O$2:O$999,RdTRABYVals!$B$2:$B$999,"="&$C24,RdTRABYVals!$C$2:$C$999,"="&INS!$A24),"") | K24: =IFERROR(AVERAGEIFS(RdTRABYVals!P$2:P$999,RdTRABYVals!$B$2:$B$999,"="&$C24,RdTRABYVals!$C$2:$C$999,"="&INS!$A24),"") | L24: =IFERROR(AVERAGEIFS(RdTRABYVals!Q$2:Q$999,RdTRABYVals!$B$2:$B$999,"="&$C24,RdTRABYVals!$C$2:$C$999,"="&INS!$A24),"") -> 59.1877 | M24: =IFERROR(AVERAGEIFS(RdTRABYVals!R$2:R$999,RdTRABYVals!$B$2:$B$999,"="&$C24,RdTRABYVals!$C$2:$C$999,"="&INS!$A24),"") | N24: =IFERROR(AVERAGEIFS(RdTRABYVals!S$2:S$999,RdTRABYVals!$B$2:$B$999,"="&$C24,RdTRABYVals!$C$2:$C$999,"="&INS!$A24),"") | ... AQ24: =IFERROR(AVERAGEIFS(RdTRABYVals!AV$2:AV$999,RdTRABYVals!$B$2:$B$999,"="&$C24,RdTRABYVals!$C$2:$C$999,"="&INS!$A24),"")
A25: TRA_Bus_Dis_Coa* | C25: AF | D25: =A25 -> TRA_Bus_Dis_Coa* | F25: =AVERAGE(G25:AQ25) -> 66.756157 | G25: =IFERROR(AVERAGEIFS(RdTRABYVals!L$2:L$999,RdTRABYVals!$B$2:$B$999,"="&$C25,RdTRABYVals!$C$2:$C$999,"="&INS!$A25),"") -> 90.5633 | H25: =IFERROR(AVERAGEIFS(RdTRABYVals!M$2:M$999,RdTRABYVals!$B$2:$B$999,"="&$C25,RdTRABYVals!$C$2:$C$999,"="&INS!$A25),"") -> 137.92 | I25: =IFERROR(AVERAGEIFS(RdTRABYVals!N$2:N$999,RdTRABYVals!$B$2:$B$999,"="&$C25,RdTRABYVals!$C$2:$C$999,"="&INS!$A25),"") -> 82.638 | J25: =IFERROR(AVERAGEIFS(RdTRABYVals!O$2:O$999,RdTRABYVals!$B$2:$B$999,"="&$C25,RdTRABYVals!$C$2:$C$999,"="&INS!$A25),"") -> 61.8505 | K25: =IFERROR(AVERAGEIFS(RdTRABYVals!P$2:P$999,RdTRABYVals!$B$2:$B$999,"="&$C25,RdTRABYVals!$C$2:$C$999,"="&INS!$A25),"") -> 27.1992 | L25: =IFERROR(AVERAGEIFS(RdTRABYVals!Q$2:Q$999,RdTRABYVals!$B$2:$B$999,"="&$C25,RdTRABYVals!$C$2:$C$999,"="&INS!$A25),"") -> 55.6788 | M25: =IFERROR(AVERAGEIFS(RdTRABYVals!R$2:R$999,RdTRABYVals!$B$2:$B$999,"="&$C25,RdTRABYVals!$C$2:$C$999,"="&INS!$A25),"") -> 43.6949 | N25: =IFERROR(AVERAGEIFS(RdTRABYVals!S$2:S$999,RdTRABYVals!$B$2:$B$999,"="&$C25,RdTRABYVals!$C$2:$C$999,"="&INS!$A25),"") -> 50.4533 | ... AQ25: =IFERROR(AVERAGEIFS(RdTRABYVals!AV$2:AV$999,RdTRABYVals!$B$2:$B$999,"="&$C25,RdTRABYVals!$C$2:$C$999,"="&INS!$A25),"") -> 65.0539
A26: TRA_Bus_Dis_Urb* | C26: AF | D26: =A26 -> TRA_Bus_Dis_Urb* | F26: =AVERAGE(G26:AQ26) -> 59.629108 | G26: =IFERROR(AVERAGEIFS(RdTRABYVals!L$2:L$999,RdTRABYVals!$B$2:$B$999,"="&$C26,RdTRABYVals!$C$2:$C$999,"="&INS!$A26),"") -> 69.3442 | H26: =IFERROR(AVERAGEIFS(RdTRABYVals!M$2:M$999,RdTRABYVals!$B$2:$B$999,"="&$C26,RdTRABYVals!$C$2:$C$999,"="&INS!$A26),"") -> 103.075 | I26: =IFERROR(AVERAGEIFS(RdTRABYVals!N$2:N$999,RdTRABYVals!$B$2:$B$999,"="&$C26,RdTRABYVals!$C$2:$C$999,"="&INS!$A26),"") -> 78.5665 | J26: =IFERROR(AVERAGEIFS(RdTRABYVals!O$2:O$999,RdTRABYVals!$B$2:$B$999,"="&$C26,RdTRABYVals!$C$2:$C$999,"="&INS!$A26),"") -> 68.8636 | K26: =IFERROR(AVERAGEIFS(RdTRABYVals!P$2:P$999,RdTRABYVals!$B$2:$B$999,"="&$C26,RdTRABYVals!$C$2:$C$999,"="&INS!$A26),"") -> 23.7368 | L26: =IFERROR(AVERAGEIFS(RdTRABYVals!Q$2:Q$999,RdTRABYVals!$B$2:$B$999,"="&$C26,RdTRABYVals!$C$2:$C$999,"="&INS!$A26),"") -> 56.0046 | M26: =IFERROR(AVERAGEIFS(RdTRABYVals!R$2:R$999,RdTRABYVals!$B$2:$B$999,"="&$C26,RdTRABYVals!$C$2:$C$999,"="&INS!$A26),"") -> 36.5657 | N26: =IFERROR(AVERAGEIFS(RdTRABYVals!S$2:S$999,RdTRABYVals!$B$2:$B$999,"="&$C26,RdTRABYVals!$C$2:$C$999,"="&INS!$A26),"") -> 40.3638 | ... AQ26: =IFERROR(AVERAGEIFS(RdTRABYVals!AV$2:AV$999,RdTRABYVals!$B$2:$B$999,"="&$C26,RdTRABYVals!$C$2:$C$999,"="&INS!$A26),"") -> 55.87
A27: TRA_Bus_Gas_Coa* | C27: AF | D27: =A27 -> TRA_Bus_Gas_Coa* | F27: =AVERAGE(G27:AQ27) -> 39.1639 | G27: =IFERROR(AVERAGEIFS(RdTRABYVals!L$2:L$999,RdTRABYVals!$B$2:$B$999,"="&$C27,RdTRABYVals!$C$2:$C$999,"="&INS!$A27),"") | H27: =IFERROR(AVERAGEIFS(RdTRABYVals!M$2:M$999,RdTRABYVals!$B$2:$B$999,"="&$C27,RdTRABYVals!$C$2:$C$999,"="&INS!$A27),"") | I27: =IFERROR(AVERAGEIFS(RdTRABYVals!N$2:N$999,RdTRABYVals!$B$2:$B$999,"="&$C27,RdTRABYVals!$C$2:$C$999,"="&INS!$A27),"") | J27: =IFERROR(AVERAGEIFS(RdTRABYVals!O$2:O$999,RdTRABYVals!$B$2:$B$999,"="&$C27,RdTRABYVals!$C$2:$C$999,"="&INS!$A27),"") | K27: =IFERROR(AVERAGEIFS(RdTRABYVals!P$2:P$999,RdTRABYVals!$B$2:$B$999,"="&$C27,RdTRABYVals!$C$2:$C$999,"="&INS!$A27),"") | L27: =IFERROR(AVERAGEIFS(RdTRABYVals!Q$2:Q$999,RdTRABYVals!$B$2:$B$999,"="&$C27,RdTRABYVals!$C$2:$C$999,"="&INS!$A27),"") | M27: =IFERROR(AVERAGEIFS(RdTRABYVals!R$2:R$999,RdTRABYVals!$B$2:$B$999,"="&$C27,RdTRABYVals!$C$2:$C$999,"="&INS!$A27),"") | N27: =IFERROR(AVERAGEIFS(RdTRABYVals!S$2:S$999,RdTRABYVals!$B$2:$B$999,"="&$C27,RdTRABYVals!$C$2:$C$999,"="&INS!$A27),"") -> 41.3745 | ... AQ27: =IFERROR(AVERAGEIFS(RdTRABYVals!AV$2:AV$999,RdTRABYVals!$B$2:$B$999,"="&$C27,RdTRABYVals!$C$2:$C$999,"="&INS!$A27),"") -> 59.9374
A28: TRA_Bus_Gas_Urb* | C28: AF | D28: =A28 -> TRA_Bus_Gas_Urb* | F28: =AVERAGE(G28:AQ28) -> 31.403361 | G28: =IFERROR(AVERAGEIFS(RdTRABYVals!L$2:L$999,RdTRABYVals!$B$2:$B$999,"="&$C28,RdTRABYVals!$C$2:$C$999,"="&INS!$A28),"") | H28: =IFERROR(AVERAGEIFS(RdTRABYVals!M$2:M$999,RdTRABYVals!$B$2:$B$999,"="&$C28,RdTRABYVals!$C$2:$C$999,"="&INS!$A28),"") | I28: =IFERROR(AVERAGEIFS(RdTRABYVals!N$2:N$999,RdTRABYVals!$B$2:$B$999,"="&$C28,RdTRABYVals!$C$2:$C$999,"="&INS!$A28),"") | J28: =IFERROR(AVERAGEIFS(RdTRABYVals!O$2:O$999,RdTRABYVals!$B$2:$B$999,"="&$C28,RdTRABYVals!$C$2:$C$999,"="&INS!$A28),"") | K28: =IFERROR(AVERAGEIFS(RdTRABYVals!P$2:P$999,RdTRABYVals!$B$2:$B$999,"="&$C28,RdTRABYVals!$C$2:$C$999,"="&INS!$A28),"") | L28: =IFERROR(AVERAGEIFS(RdTRABYVals!Q$2:Q$999,RdTRABYVals!$B$2:$B$999,"="&$C28,RdTRABYVals!$C$2:$C$999,"="&INS!$A28),"") | M28: =IFERROR(AVERAGEIFS(RdTRABYVals!R$2:R$999,RdTRABYVals!$B$2:$B$999,"="&$C28,RdTRABYVals!$C$2:$C$999,"="&INS!$A28),"") | N28: =IFERROR(AVERAGEIFS(RdTRABYVals!S$2:S$999,RdTRABYVals!$B$2:$B$999,"="&$C28,RdTRABYVals!$C$2:$C$999,"="&INS!$A28),"") -> 28.6594 | ... AQ28: =IFERROR(AVERAGEIFS(RdTRABYVals!AV$2:AV$999,RdTRABYVals!$B$2:$B$999,"="&$C28,RdTRABYVals!$C$2:$C$999,"="&INS!$A28),"") -> 47.7124
A29: TRA_Bus_Lpg_Coa* | C29: AF | D29: =A29 -> TRA_Bus_Lpg_Coa* | F29: =AVERAGE(G29:AQ29) -> 148.262 | G29: =IFERROR(AVERAGEIFS(RdTRABYVals!L$2:L$999,RdTRABYVals!$B$2:$B$999,"="&$C29,RdTRABYVals!$C$2:$C$999,"="&INS!$A29),"") | H29: =IFERROR(AVERAGEIFS(RdTRABYVals!M$2:M$999,RdTRABYVals!$B$2:$B$999,"="&$C29,RdTRABYVals!$C$2:$C$999,"="&INS!$A29),"") | I29: =IFERROR(AVERAGEIFS(RdTRABYVals!N$2:N$999,RdTRABYVals!$B$2:$B$999,"="&$C29,RdTRABYVals!$C$2:$C$999,"="&INS!$A29),"") | J29: =IFERROR(AVERAGEIFS(RdTRABYVals!O$2:O$999,RdTRABYVals!$B$2:$B$999,"="&$C29,RdTRABYVals!$C$2:$C$999,"="&INS!$A29),"") | K29: =IFERROR(AVERAGEIFS(RdTRABYVals!P$2:P$999,RdTRABYVals!$B$2:$B$999,"="&$C29,RdTRABYVals!$C$2:$C$999,"="&INS!$A29),"") | L29: =IFERROR(AVERAGEIFS(RdTRABYVals!Q$2:Q$999,RdTRABYVals!$B$2:$B$999,"="&$C29,RdTRABYVals!$C$2:$C$999,"="&INS!$A29),"") | M29: =IFERROR(AVERAGEIFS(RdTRABYVals!R$2:R$999,RdTRABYVals!$B$2:$B$999,"="&$C29,RdTRABYVals!$C$2:$C$999,"="&INS!$A29),"") | N29: =IFERROR(AVERAGEIFS(RdTRABYVals!S$2:S$999,RdTRABYVals!$B$2:$B$999,"="&$C29,RdTRABYVals!$C$2:$C$999,"="&INS!$A29),"") | ... AQ29: =IFERROR(AVERAGEIFS(RdTRABYVals!AV$2:AV$999,RdTRABYVals!$B$2:$B$999,"="&$C29,RdTRABYVals!$C$2:$C$999,"="&INS!$A29),"") -> 148.262
A30: TRA_Bus_Lpg_Urb* | C30: AF | D30: =A30 -> TRA_Bus_Lpg_Urb* | F30: =AVERAGE(G30:AQ30) -> 54.34708 | G30: =IFERROR(AVERAGEIFS(RdTRABYVals!L$2:L$999,RdTRABYVals!$B$2:$B$999,"="&$C30,RdTRABYVals!$C$2:$C$999,"="&INS!$A30),"") | H30: =IFERROR(AVERAGEIFS(RdTRABYVals!M$2:M$999,RdTRABYVals!$B$2:$B$999,"="&$C30,RdTRABYVals!$C$2:$C$999,"="&INS!$A30),"") | I30: =IFERROR(AVERAGEIFS(RdTRABYVals!N$2:N$999,RdTRABYVals!$B$2:$B$999,"="&$C30,RdTRABYVals!$C$2:$C$999,"="&INS!$A30),"") | J30: =IFERROR(AVERAGEIFS(RdTRABYVals!O$2:O$999,RdTRABYVals!$B$2:$B$999,"="&$C30,RdTRABYVals!$C$2:$C$999,"="&INS!$A30),"") | K30: =IFERROR(AVERAGEIFS(RdTRABYVals!P$2:P$999,RdTRABYVals!$B$2:$B$999,"="&$C30,RdTRABYVals!$C$2:$C$999,"="&INS!$A30),"") | L30: =IFERROR(AVERAGEIFS(RdTRABYVals!Q$2:Q$999,RdTRABYVals!$B$2:$B$999,"="&$C30,RdTRABYVals!$C$2:$C$999,"="&INS!$A30),"") | M30: =IFERROR(AVERAGEIFS(RdTRABYVals!R$2:R$999,RdTRABYVals!$B$2:$B$999,"="&$C30,RdTRABYVals!$C$2:$C$999,"="&INS!$A30),"") | N30: =IFERROR(AVERAGEIFS(RdTRABYVals!S$2:S$999,RdTRABYVals!$B$2:$B$999,"="&$C30,RdTRABYVals!$C$2:$C$999,"="&INS!$A30),"") | ... AQ30: =IFERROR(AVERAGEIFS(RdTRABYVals!AV$2:AV$999,RdTRABYVals!$B$2:$B$999,"="&$C30,RdTRABYVals!$C$2:$C$999,"="&INS!$A30),"") -> 119.137
A31: TRA_Bus_Dis_Coa* | C31: AF | D31: TRA_Bus_GH2_Coa* | F31: =F25 -> 66.756157 | G31: =G25 -> 90.5633 | H31: =H25 -> 137.92 | I31: =I25 -> 82.638 | J31: =J25 -> 61.8505 | K31: =K25 -> 27.1992 | L31: =L25 -> 55.6788 | M31: =M25 -> 43.6949 | ... AQ31: =AQ25 -> 65.0539
A32: TRA_Bus_Dis_Coa* | C32: AF | D32: TRA_Bus_Eth_Coa* | F32: =F31 -> 66.756157 | G32: =G31 -> 90.5633 | H32: =H31 -> 137.92 | I32: =I31 -> 82.638 | J32: =J31 -> 61.8505 | K32: =K31 -> 27.1992 | L32: =L31 -> 55.6788 | M32: =M31 -> 43.6949 | ... AQ32: =AQ31 -> 65.0539
A33: TRA_Bus_Dis_Urb* | C33: AF | D33: TRA_Bus_GH2_Urb* | F33: =F26 -> 59.629108 | G33: =G26 -> 69.3442 | H33: =H26 -> 103.075 | I33: =I26 -> 78.5665 | J33: =J26 -> 68.8636 | K33: =K26 -> 23.7368 | L33: =L26 -> 56.0046 | M33: =M26 -> 36.5657 | ... AQ33: =AQ26 -> 55.87
A34: TRA_Bus_Dis_Urb* | C34: AF | D34: TRA_Bus_Eth_Urb* | F34: =F33 -> 59.629108 | G34: =G33 -> 69.3442 | H34: =H33 -> 103.075 | I34: =I33 -> 78.5665 | J34: =J33 -> 68.8636 | K34: =K33 -> 23.7368 | L34: =L33 -> 56.0046 | M34: =M33 -> 36.5657 | ... AQ34: =AQ33 -> 55.87
A35: TRA_Car_Cng_Exe* | C35: AF | D35: =A35 -> TRA_Car_Cng_Exe* | G35: =HLOOKUP(G$22,'Average km per veh'!$E$65:$AO$69,2,0) -> 17.187329 | H35: =HLOOKUP(H$22,'Average km per veh'!$E$65:$AO$69,2,0) -> 25.025053 | I35: =HLOOKUP(I$22,'Average km per veh'!$E$65:$AO$69,2,0) -> 19.086664 | J35: =HLOOKUP(J$22,'Average km per veh'!$E$65:$AO$69,2,0) -> 19.086561 | K35: =HLOOKUP(K$22,'Average km per veh'!$E$65:$AO$69,2,0) -> 12.279248 | L35: =HLOOKUP(L$22,'Average km per veh'!$E$65:$AO$69,2,0) -> 15.980351 | M35: =HLOOKUP(M$22,'Average km per veh'!$E$65:$AO$69,2,0) -> 16.797329 | N35: =HLOOKUP(N$22,'Average km per veh'!$E$65:$AO$69,2,0) -> 16.098147 | ... AQ35: =HLOOKUP(AQ$22,'Average km per veh'!$E$65:$AO$69,2,0) -> 17.313498
A36: TRA_Car_Cng_Lom* | C36: AF | D36: =A36 -> TRA_Car_Cng_Lom* | G36: =HLOOKUP(G$22,'Average km per veh'!$E$65:$AO$69,3,0) -> 11.231087 | H36: =HLOOKUP(H$22,'Average km per veh'!$E$65:$AO$69,3,0) -> 22.244049 | I36: =HLOOKUP(I$22,'Average km per veh'!$E$65:$AO$69,3,0) -> 16.42471 | J36: =HLOOKUP(J$22,'Average km per veh'!$E$65:$AO$69,3,0) -> 19.891649 | K36: =HLOOKUP(K$22,'Average km per veh'!$E$65:$AO$69,3,0) -> 10.901198 | L36: =HLOOKUP(L$22,'Average km per veh'!$E$65:$AO$69,3,0) -> 14.007954 | M36: =HLOOKUP(M$22,'Average km per veh'!$E$65:$AO$69,3,0) -> 13.758117 | N36: =HLOOKUP(N$22,'Average km per veh'!$E$65:$AO$69,3,0) -> 12.746347 | ... AQ36: =HLOOKUP(AQ$22,'Average km per veh'!$E$65:$AO$69,3,0) -> 15.161497
A37: TRA_Car_Cng_Sma* | C37: AF | D37: =A37 -> TRA_Car_Cng_Sma* | G37: =HLOOKUP(G$22,'Average km per veh'!$E$65:$AO$69,4,0) -> 7.1153893 | H37: =HLOOKUP(H$22,'Average km per veh'!$E$65:$AO$69,4,0) -> 19.046218 | I37: =HLOOKUP(I$22,'Average km per veh'!$E$65:$AO$69,4,0) -> 13.907252 | J37: =HLOOKUP(J$22,'Average km per veh'!$E$65:$AO$69,4,0) -> 15.699539 | K37: =HLOOKUP(K$22,'Average km per veh'!$E$65:$AO$69,4,0) -> 8.6603503 | L37: =HLOOKUP(L$22,'Average km per veh'!$E$65:$AO$69,4,0) -> 12.080379 | M37: =HLOOKUP(M$22,'Average km per veh'!$E$65:$AO$69,4,0) -> 12.11816 | N37: =HLOOKUP(N$22,'Average km per veh'!$E$65:$AO$69,4,0) -> 10.153642 | ... AQ37: =HLOOKUP(AQ$22,'Average km per veh'!$E$65:$AO$69,4,0) -> 12.891665
A38: TRA_Car_Cng_Upm* | C38: AF | D38: =A38 -> TRA_Car_Cng_Upm* | G38: =HLOOKUP(G$22,'Average km per veh'!$E$65:$AO$69,5,0) -> 11.979464 | H38: =HLOOKUP(H$22,'Average km per veh'!$E$65:$AO$69,5,0) -> 22.586001 | I38: =HLOOKUP(I$22,'Average km per veh'!$E$65:$AO$69,5,0) -> 16.601809 | J38: =HLOOKUP(J$22,'Average km per veh'!$E$65:$AO$69,5,0) -> 18.840384 | K38: =HLOOKUP(K$22,'Average km per veh'!$E$65:$AO$69,5,0) -> 8.9216805 | L38: =HLOOKUP(L$22,'Average km per veh'!$E$65:$AO$69,5,0) -> 13.941752 | M38: =HLOOKUP(M$22,'Average km per veh'!$E$65:$AO$69,5,0) -> 13.332813 | N38: =HLOOKUP(N$22,'Average km per veh'!$E$65:$AO$69,5,0) -> 12.806798 | ... AQ38: =HLOOKUP(AQ$22,'Average km per veh'!$E$65:$AO$69,5,0) -> 16.114876
A39: TRA_Car_Dis_Exe* | C39: AF | D39: =A39 -> TRA_Car_Dis_Exe* | G39: =G35-0.05 -> 17.137329 | H39: =H35-0.05 -> 24.975053 | I39: =I35-0.05 -> 19.036664 | J39: =J35-0.05 -> 19.036561 | K39: =K35-0.05 -> 12.229248 | L39: =L35-0.05 -> 15.930351 | M39: =M35-0.05 -> 16.747329 | N39: =N35-0.05 -> 16.048147 | ... AQ39: =AQ35-0.05 -> 17.263498
A40: TRA_Car_Dis_Lom* | C40: AF | D40: =A40 -> TRA_Car_Dis_Lom* | G40: =G36-0.05 -> 11.181087 | H40: =H36-0.05 -> 22.194049 | I40: =I36-0.05 -> 16.37471 | J40: =J36-0.05 -> 19.841649 | K40: =K36-0.05 -> 10.851198 | L40: =L36-0.05 -> 13.957954 | M40: =M36-0.05 -> 13.708117 | N40: =N36-0.05 -> 12.696347 | ... AQ40: =AQ36-0.05 -> 15.111497
A41: TRA_Car_Dis_Sma* | C41: AF | D41: =A41 -> TRA_Car_Dis_Sma* | G41: =G37-0.05 -> 7.0653893 | H41: =H37-0.05 -> 18.996218 | I41: =I37-0.05 -> 13.857252 | J41: =J37-0.05 -> 15.649539 | K41: =K37-0.05 -> 8.6103503 | L41: =L37-0.05 -> 12.030379 | M41: =M37-0.05 -> 12.06816 | N41: =N37-0.05 -> 10.103642 | ... AQ41: =AQ37-0.05 -> 12.841665
A42: TRA_Car_Dis_Upm* | C42: AF | D42: =A42 -> TRA_Car_Dis_Upm* | G42: =G38-0.05 -> 11.929464 | H42: =H38-0.05 -> 22.536001 | I42: =I38-0.05 -> 16.551809 | J42: =J38-0.05 -> 18.790384 | K42: =K38-0.05 -> 8.8716805 | L42: =L38-0.05 -> 13.891752 | M42: =M38-0.05 -> 13.282813 | N42: =N38-0.05 -> 12.756798 | ... AQ42: =AQ38-0.05 -> 16.064876
A43: TRA_Car_Fle_Fue_Exe* | C43: AF | D43: =A43 -> TRA_Car_Fle_Fue_Exe* | G43: =G39-0.05 -> 17.087329 | H43: =H39-0.05 -> 24.925053 | I43: =I39-0.05 -> 18.986664 | J43: =J39-0.05 -> 18.986561 | K43: =K39-0.05 -> 12.179248 | L43: =L39-0.05 -> 15.880351 | M43: =M39-0.05 -> 16.697329 | N43: =N39-0.05 -> 15.998147 | ... AQ43: =AQ39-0.05 -> 17.213498
A44: TRA_Car_Fle_Fue_Lom* | C44: AF | D44: =A44 -> TRA_Car_Fle_Fue_Lom* | G44: =G40-0.05 -> 11.131087 | H44: =H40-0.05 -> 22.144049 | I44: =I40-0.05 -> 16.32471 | J44: =J40-0.05 -> 19.791649 | K44: =K40-0.05 -> 10.801198 | L44: =L40-0.05 -> 13.907954 | M44: =M40-0.05 -> 13.658117 | N44: =N40-0.05 -> 12.646347 | ... AQ44: =AQ40-0.05 -> 15.061497
...

Sheet Average km per veh
B2: TechName | C2: Comm-IN | D2: Comm-OUT | E2: AL | F2: AT | G2: BA | H2: BE | I2: BG | J2: CH | K2: CY | L2: CZ | M2: DE | N2: DK | O2: EE | P2: EL | Q2: ES | R2: FI | S2: FR | T2: HR | U2: HU | V2: IE | W2: IS | X2: IT | Y2: KS | Z2: LT | AA2: LU | AB2: LV | AC2: ME | AD2: MK | AE2: MT | AF2: NL | AG2: NO | AH2: PL | AI2: PT | AJ2: RO | AK2: RS | AL2: SE | AM2: SI | AN2: SK | AO2: UK
A3: STOCK | B3: TRA_Car_Cng_Exe | C3: TRAGAS | D3: TCar | E3: 0 | F3: 0 | G3: 0 | H3: 0 | I3: 0 | J3: 0.9 | K3: 0 | L3: 0 | M3: 9.2 | N3: 0 | O3: 0 | P3: 0 | Q3: 0 | R3: 0 | S3: 0 | T3: 0 | U3: 0 | V3: 0 | W3: 0 | X3: 97.21 | Y3: 0 | Z3: 0 | AA3: 0 | AB3: 0 | AC3: 0 | AD3: 0 | AE3: 0 | AF3: 0.12 | AG3: 0 | AH3: 0 | AI3: 0 | AJ3: 0 | AK3: 1.0558825 | AL3: 2.42 | AM3: 0 | AN3: 0 | AO3: 0.18
B4: TRA_Car_Cng_Lom | C4: TRAGAS | D4: TCar | E4: 0 | F4: 0 | G4: 0 | H4: 0 | I4: 0 | J4: 2.34 | K4: 0 | L4: 0 | M4: 23.9 | N4: 0 | O4: 0 | P4: 0 | Q4: 0 | R4: 0 | S4: 0 | T4: 0 | U4: 0 | V4: 0 | W4: 0 | X4: 252.71 | Y4: 0 | Z4: 0 | AA4: 0 | AB4: 0 | AC4: 0 | AD4: 0 | AE4: 0 | AF4: 0.32 | AG4: 0 | AH4: 0 | AI4: 0 | AJ4: 0 | AK4: 2.7449036 | AL4: 8.9 | AM4: 0 | AN4: 0 | AO4: 0.48
B5: TRA_Car_Cng_Sma | C5: TRAGAS | D5: TCar | E5: 0 | F5: 0 | G5: 0 | H5: 0 | I5: 0 | J5: 2.29 | K5: 0 | L5: 0 | M5: 23.34 | N5: 0 | O5: 0 | P5: 0 | Q5: 0 | R5: 0 | S5: 0 | T5: 0 | U5: 0 | V5: 0 | W5: 0 | X5: 246.79 | Y5: 0 | Z5: 0 | AA5: 0 | AB5: 0 | AC5: 0 | AD5: 0 | AE5: 0 | AF5: 0.32 | AG5: 0 | AH5: 0 | AI5: 0 | AJ5: 0 | AK5: 2.6806013 | AL5: 8.94 | AM5: 0 | AN5: 0 | AO5: 0.47
B6: TRA_Car_Cng_Upm | C6: TRAGAS | D6: TCar | E6: 0 | F6: 0 | G6: 0 | H6: 0 | I6: 0 | J6: 1.05 | K6: 0 | L6: 0 | M6: 10.72 | N6: 0 | O6: 0 | P6: 0 | Q6: 0 | R6: 0 | S6: 0 | T6: 0 | U6: 0 | V6: 0 | W6: 0 | X6: 113.31 | Y6: 0 | Z6: 0 | AA6: 0 | AB6: 0 | AC6: 0 | AD6: 0 | AE6: 0 | AF6: 0.15 | AG6: 0 | AH6: 0 | AI6: 0 | AJ6: 0 | AK6: 1.2307587 | AL6: 4.74 | AM6: 0 | AN6: 0 | AO6: 0.21
B7: TRA_Car_Dis_Exe | C7: TRADST | D7: TCar | E7: 9.5478683 | F7: 509.07 | G7: 56.75314 | H7: 509.08 | I7: 212.83 | J7: 259.88 | K7: 34.71 | L7: 218.49 | M7: 3483.21 | N7: 93.82 | O7: 51.42 | P7: 41.98 | Q7: 2108.62 | R7: 228.8 | S7: 2771.18 | T7: 75.96 | U7: 124.01 | V7: 115.16 | W7: 16.91 | X7: 2443.14 | Y7: 15.390675 | Z7: 177.92 | AA7: 57.92 | AB7: 70.72 | AC7: 2.6764694 | AD7: 16.14 | AE7: 7.97 | AF7: 361.29 | AG7: 211.5 | AH7: 694.3 | AI7: 425.2 | AJ7: 298.81 | AK7: 70.522924 | AL7: 270.85 | AM7: 69.86 | AN7: 82.8 | AO7: 2069.75
B8: TRA_Car_Dis_Lom | C8: TRADST | D8: TCar | E8: 10.216538 | F8: 872.35 | G8: 131.07166 | H8: 1128.43 | I8: 303.18 | J8: 198.78 | K8: 8.88 | L8: 407.23 | M8: 3109.2 | N8: 189.54 | O8: 26.14 | P8: 44.92 | Q8: 4274.06 | R8: 134.11 | S8: 6576.88 | T8: 175.43 | U8: 204.45 | V8: 173.67 | W8: 8.6 | X8: 4903.81 | Y8: 35.54484 | Z8: 161.85 | AA8: 64.53 | AB8: 39.8 | AC8: 2.8639115 | AD8: 23 | AE8: 24.59 | AF8: 386.22 | AG8: 197.84 | AH8: 1310 | AI8: 681.17 | AJ8: 489.17 | AK8: 162.87305 | AL8: 151.06 | AM8: 126.18 | AN8: 144.02 | AO8: 2530.87
B9: TRA_Car_Dis_Sma | C9: TRADST | D9: TCar | E9: 8.1422984 | F9: 851.92 | G9: 128.00089 | H9: 1102.01 | I9: 296.08 | J9: 194.12 | K9: 8.67 | L9: 397.69 | M9: 3036.41 | N9: 185.11 | O9: 25.53 | P9: 35.8 | Q9: 3269.74 | R9: 130.97 | S9: 6422.89 | T9: 171.32 | U9: 199.67 | V9: 79.54 | W9: 8.39 | X9: 4788.99 | Y9: 34.71209 | Z9: 158.06 | AA9: 63.08 | AB9: 38.87 | AC9: 2.2824584 | AD9: 22.46 | AE9: 24.02 | AF9: 377.18 | AG9: 170.98 | AH9: 1279.33 | AI9: 665.22 | AJ9: 477.71 | AK9: 159.05723 | AL9: 151.77 | AM9: 123.23 | AN9: 140.65 | AO9: 2471.61
B10: TRA_Car_Dis_Upm | C10: TRADST | D10: TCar | E10: 4.8012268 | F10: 391.14 | G10: 58.770431 | H10: 505.96 | I10: 135.94 | J10: 89.13 | K10: 3.98 | L10: 182.59 | M10: 1394.08 | N10: 84.99 | O10: 11.72 | P10: 21.11 | Q10: 1814.42 | R10: 60.13 | S10: 2948.89 | T10: 78.66 | U10: 91.67 | V10: 127.95 | W10: 3.85 | X10: 2198.73 | Y10: 15.937736 | Z10: 72.57 | AA10: 30.38 | AB10: 17.85 | AC10: 1.3458854 | AD10: 10.31 | AE10: 11.03 | AF10: 173.31 | AG10: 110.94 | AH10: 587.37 | AI10: 305.42 | AJ10: 219.33 | AK10: 73.029663 | AL10: 66.63 | AM10: 56.58 | AN10: 64.58 | AO10: 1134.77
B11: TRA_Car_Fle_Fue_Exe | C11: TRAGSLSP95 | D11: TCar | E11: 0 | F11: 0 | G11: 0 | H11: 0 | I11: 0 | J11: 0.44 | K11: 0 | L11: 0 | M11: 0 | N11: 0 | O11: 0 | P11: 0 | Q11: 0 | R11: 0 | S11: 0 | T11: 0 | U11: 0 | V11: 0 | W11: 0 | X11: 0 | Y11: 0 | Z11: 0 | AA11: 0 | AB11: 0 | AC11: 0 | AD11: 0 | AE11: 0 | AF11: 0 | AG11: 0 | AH11: 0 | AI11: 0 | AJ11: 0 | AK11: 0 | AL11: 19.82 | AM11: 0 | AN11: 0 | AO11: 0
B12: TRA_Car_Fle_Fue_Lom | C12: TRAGSLSP95 | D12: TCar | E12: 0 | F12: 0 | G12: 0 | H12: 0 | I12: 0 | J12: 1.14 | K12: 0 | L12: 0 | M12: 0 | N12: 0 | O12: 0 | P12: 0 | Q12: 0 | R12: 0 | S12: 0 | T12: 0 | U12: 0 | V12: 0 | W12: 0 | X12: 0 | Y12: 0 | Z12: 0 | AA12: 0 | AB12: 0 | AC12: 0 | AD12: 0 | AE12: 0 | AF12: 0 | AG12: 0 | AH12: 0 | AI12: 0 | AJ12: 0 | AK12: 0 | AL12: 72.78 | AM12: 0 | AN12: 0 | AO12: 0
B13: TRA_Car_Fle_Fue_Sma | C13: TRAGSLSP95 | D13: TCar | E13: 0 | F13: 0 | G13: 0 | H13: 0 | I13: 0 | J13: 1.11 | K13: 0 | L13: 0 | M13: 0 | N13: 0 | O13: 0 | P13: 0 | Q13: 0 | R13: 0 | S13: 0 | T13: 0 | U13: 0 | V13: 0 | W13: 0 | X13: 0 | Y13: 0 | Z13: 0 | AA13: 0 | AB13: 0 | AC13: 0 | AD13: 0 | AE13: 0 | AF13: 0 | AG13: 0 | AH13: 0 | AI13: 0 | AJ13: 0 | AK13: 0 | AL13: 73.12 | AM13: 0 | AN13: 0 | AO13: 0
B14: TRA_Car_Fle_Fue_Upm | C14: TRAGSLSP95 | D14: TCar | E14: 0 | F14: 0 | G14: 0 | H14: 0 | I14: 0 | J14: 0.51 | K14: 0 | L14: 0 | M14: 0 | N14: 0 | O14: 0 | P14: 0 | Q14: 0 | R14: 0 | S14: 0 | T14: 0 | U14: 0 | V14: 0 | W14: 0 | X14: 0 | Y14: 0 | Z14: 0 | AA14: 0 | AB14: 0 | AC14: 0 | AD14: 0 | AE14: 0 | AF14: 0 | AG14: 0 | AH14: 0 | AI14: 0 | AJ14: 0 | AK14: 0 | AL14: 38.77 | AM14: 0 | AN14: 0 | AO14: 0
B15: TRA_Car_Gas_Exe | C15: TRAGSLSP95 | D15: TCar | E15: 7.4709744 | F15: 192.76 | G15: 11.081004 | H15: 149.02 | I15: 52.89 | J15: 805.57 | K15: 23.27 | L15: 134.5 | M15: 3124.93 | N15: 110.06 | O15: 56.61 | P15: 233.41 | Q15: 1144.8 | R15: 313.37 | S15: 509.92 | T15: 27.39 | U15: 66.04 | V15: 102.17 | W15: 30.63 | X15: 470.76 | Y15: 3.0143481 | Z15: 158.56 | AA15: 27.25 | AB15: 64.51 | AC15: 3.6577774 | AD15: 7.74 | AE15: 3.28 | AF15: 969.7 | AG15: 483.99 | AH15: 400.48 | AI15: 47.07 | AJ15: 88.69 | AK15: 20.057508 | AL15: 1515.46 | AM15: 23.4 | AN15: 48.16 | AO15: 2029.67
... B26: TRA_Car_Oth_Upm | C26: TRAGSLSP95 | D26: TCar | E26: 0 | F26: 0 | G26: 0 | H26: 0 | I26: 0 | J26: 0 | K26: 0 | L26: 0.8 | M26: 0 | N26: 0.06 | O26: 0 | P26: 0 | Q26: 0 | R26: 0 | S26: 0 | T26: 0 | U26: 0 | V26: 0 | W26: 0.14 | X26: 0 | Y26: 0 | Z26: 0 | AA26: 0 | AB26: 0 | AC26: 0 | AD26: 0 | AE26: 0 | AF26: 8.94 | AG26: 0 | AH26: 59.68 | AI26: 1.28 | AJ26: 0 | AK26: 0 | AL26: 3.68 | AM26: 0 | AN26: 0 | AO26: 0.32
B28: Exe | E28: =E3+E7+E11+E15+E19+E23 -> 17.018843 | F28: =F3+F7+F11+F15+F19+F23 -> 701.83 | G28: =G3+G7+G11+G15+G19+G23 -> 67.834143 | H28: =H3+H7+H11+H15+H19+H23 -> 663.01 | I28: =I3+I7+I11+I15+I19+I23 -> 279.18 | J28: =J3+J7+J11+J15+J19+J23 -> 1066.79 | K28: =K3+K7+K11+K15+K19+K23 -> 57.98 | L28: =L3+L7+L11+L15+L19+L23 -> 353.67 | ... AO28: =AO3+AO7+AO11+AO15+AO19+AO23 -> 4103.43
B29: Lom | E29: =E4+E8+E12+E16+E20+E24 -> 51.616254 | F29: =F4+F8+F12+F16+F20+F24 -> 1360.5 | G29: =G4+G8+G12+G16+G20+G24 -> 202.57427 | H29: =H4+H8+H12+H16+H20+H24 -> 1571.85 | I29: =I4+I8+I12+I16+I20+I24 -> 711.98 | J29: =J4+J8+J12+J16+J20+J24 -> 1269.86 | K29: =K4+K8+K12+K16+K20+K24 -> 188.12 | L29: =L4+L8+L12+L16+L20+L24 -> 1056.81 | ... AO29: =AO4+AO8+AO12+AO16+AO20+AO24 -> 8427.02
B30: Sma | E30: =E5+E9+E13+E17+E21+E25 -> 105.6593 | F30: =F5+F9+F13+F17+F21+F25 -> 1984.58 | G30: =G5+G9+G13+G17+G21+G25 -> 394.87548 | H30: =H5+H9+H13+H17+H21+H25 -> 2399.01 | I30: =I5+I9+I13+I17+I21+I25 -> 1288.96 | J30: =J5+J9+J13+J17+J21+J25 -> 1169.81 | K30: =K5+K9+K13+K17+K21+K25 -> 204.38 | L30: =L5+L9+L13+L17+L21+L25 -> 2611.68 | ... AO30: =AO5+AO9+AO13+AO17+AO21+AO25 -> 12026.44
B31: Ump | E31: =E6+E10+E14+E18+E22+E26 -> 20.571541 | F31: =F6+F10+F14+F18+F22+F26 -> 610.01 | G31: =G6+G10+G14+G18+G22+G26 -> 90.832116 | H31: =H6+H10+H14+H18+H22+H26 -> 704.78 | I31: =I6+I10+I14+I18+I22+I26 -> 319.24 | J31: =J6+J10+J14+J18+J22+J26 -> 569.37 | K31: =K6+K10+K14+K18+K22+K26 -> 84.35 | L31: =L6+L10+L14+L18+L22+L26 -> 473.84 | ... AO31: =AO6+AO10+AO14+AO18+AO22+AO26 -> 3778.44
A33: Km per veh | B33: AF
B34: TRA_Car_Cng_Exe | E34: 0 | F34: 0 | G34: 0 | H34: 0 | I34: 0 | J34: 16.1625 | K34: 0 | L34: 0 | M34: 30.5987 | N34: 0 | O34: 0 | P34: 0 | Q34: 0 | R34: 0 | S34: 0 | T34: 0 | U34: 0 | V34: 0 | W34: 0 | X34: 12.0975 | Y34: 0 | Z34: 0 | AA34: 0 | AB34: 0 | AC34: 0 | AD34: 0 | AE34: 0 | AF34: 6.6436 | AG34: 0 | AH34: 0 | AI34: 0 | AJ34: 0 | AK34: 12.0975 | AL34: 5.20098 | AM34: 0 | AN34: 0 | AO34: 0
B35: TRA_Car_Cng_Lom | E35: 0 | F35: 0 | G35: 0 | H35: 0 | I35: 0 | J35: 16.1625 | K35: 0 | L35: 0 | M35: 29.8109 | N35: 0 | O35: 0 | P35: 0 | Q35: 0 | R35: 0 | S35: 0 | T35: 0 | U35: 0 | V35: 0 | W35: 0 | X35: 12.3414 | Y35: 0 | Z35: 0 | AA35: 0 | AB35: 0 | AC35: 0 | AD35: 0 | AE35: 0 | AF35: 7.15538 | AG35: 0 | AH35: 0 | AI35: 0 | AJ35: 0 | AK35: 12.3414 | AL35: 5.28181 | AM35: 0 | AN35: 0 | AO35: 0
B36: TRA_Car_Cng_Sma | E36: 0 | F36: 0 | G36: 0 | H36: 0 | I36: 0 | J36: 16.1625 | K36: 0 | L36: 0 | M36: 29.7919 | N36: 0 | O36: 0 | P36: 0 | Q36: 0 | R36: 0 | S36: 0 | T36: 0 | U36: 0 | V36: 0 | W36: 0 | X36: 15.1212 | Y36: 0 | Z36: 0 | AA36: 0 | AB36: 0 | AC36: 0 | AD36: 0 | AE36: 0 | AF36: 6.6436 | AG36: 0 | AH36: 0 | AI36: 0 | AJ36: 0 | AK36: 15.1212 | AL36: 5.29046 | AM36: 0 | AN36: 0 | AO36: 0
B37: TRA_Car_Cng_Upm | E37: 0 | F37: 0 | G37: 0 | H37: 0 | I37: 0 | J37: 16.1625 | K37: 0 | L37: 0 | M37: 30.2524 | N37: 0 | O37: 0 | P37: 0 | Q37: 0 | R37: 0 | S37: 0 | T37: 0 | U37: 0 | V37: 0 | W37: 0 | X37: 12.7515 | Y37: 0 | Z37: 0 | AA37: 0 | AB37: 0 | AC37: 0 | AD37: 0 | AE37: 0 | AF37: 8.06019 | AG37: 0 | AH37: 0 | AI37: 0 | AJ37: 0 | AK37: 12.7515 | AL37: 5.48829 | AM37: 0 | AN37: 0 | AO37: 0
B38: TRA_Car_Dis_Exe | E38: 23.0298 | F38: 28.6446 | G38: 20.5348 | H38: 22.2029 | I38: 11.1628 | J38: 19.0919 | K38: 17.9343 | L38: 20.2401 | M38: 24.6415 | N38: 32.2135 | O38: 22.4352 | P38: 23.0298 | Q38: 19.0031 | R38: 23.7821 | S38: 18.8005 | T38: 20.5348 | U38: 25.579 | V38: 22.8608 | W38: 16.4218 | X38: 16.1706 | Y38: 20.5348 | Z38: 7.62566 | AA38: 67.863 | AB38: 24.4701 | AC38: 23.0298 | AD38: 30.495 | AE38: 3.33004 | AF38: 33.4627 | AG38: 23.3271 | AH38: 13.8141 | AI38: 19.5186 | AJ38: 10.7438 | AK38: 20.5348 | AL38: 39.2364 | AM38: 24.8525 | AN38: 11.8839 | AO38: 19.1104
B39: TRA_Car_Dis_Lom | E39: 19.6826 | F39: 26.3411 | G39: 18.9033 | H39: 23.7359 | I39: 12.5225 | J39: 17.0763 | K39: 13.6636 | L39: 18.4134 | M39: 24.1191 | N39: 30.9059 | O39: 19.7665 | P39: 19.6826 | Q39: 17.2917 | R39: 23.4268 | S39: 17.7626 | T39: 18.9033 | U39: 23.8671 | V39: 22.0542 | W39: 18.0538 | X39: 15.0969 | Y39: 18.9033 | Z39: 5.96731 | AA39: 69.0646 | AB39: 20.3945 | AC39: 19.6826 | AD39: 27.66 | AE39: 3.51014 | AF39: 33.1289 | AG39: 23.5978 | AH39: 14.1127 | AI39: 19.5186 | AJ39: 9.16727 | AK39: 18.9033 | AL39: 35.0221 | AM39: 24.9801 | AN39: 11.8965 | AO39: 17.5383
B40: TRA_Car_Dis_Sma | E40: 13.2971 | F40: 26.5225 | G40: 18.9033 | H40: 21.687 | I40: 12.5122 | J40: 17.0648 | K40: 12.8825 | L40: 18.4134 | M40: 24.033 | N40: 29.33 | O40: 21.1119 | P40: 13.2971 | Q40: 17.0657 | R40: 24.8722 | S40: 17.9041 | T40: 18.9033 | U40: 23.8671 | V40: 22.2259 | W40: 17.6751 | X40: 16.9659 | Y40: 18.9033 | Z40: 5.96731 | AA40: 68.7874 | AB40: 23.0539 | AC40: 13.2971 | AD40: 25.8461 | AE40: 3.64308 | AF40: 32.5422 | AG40: 23.7897 | AH40: 13.3304 | AI40: 19.5186 | AJ40: 9.16727 | AK40: 18.9033 | AL40: 34.8127 | AM40: 23.4068 | AN40: 11.8965 | AO40: 14.9747
B41: TRA_Car_Dis_Upm | E41: 20.2506 | F41: 26.9338 | G41: 19.4395 | H41: 22.4619 | I41: 6.63208 | J41: 18.041 | K41: 13.6481 | L41: 18.4134 | M41: 24.6652 | N41: 29.5565 | O41: 20.3336 | P41: 20.2506 | Q41: 17.0887 | R41: 22.4362 | S41: 18.0468 | T41: 19.4395 | U41: 23.8671 | V41: 22.0164 | W41: 19.2647 | X41: 15.4991 | Y41: 19.4395 | Z41: 5.96731 | AA41: 73.225 | AB41: 25.4212 | AC41: 20.2506 | AD41: 27.66 | AE41: 3.51631 | AF41: 32.6373 | AG41: 23.148 | AH41: 13.9253 | AI41: 19.5186 | AJ41: 9.16727 | AK41: 19.4395 | AL41: 36.3048 | AM41: 25.4459 | AN41: 11.8965 | AO41: 18.3772
B42: TRA_Car_Fle_Fue_Exe | E42: 0 | F42: 0 | G42: 0 | H42: 0 | I42: 0 | J42: 11.1287 | K42: 0 | L42: 0 | M42: 0 | N42: 0 | O42: 0 | P42: 0 | Q42: 0 | R42: 0 | S42: 0 | T42: 0 | U42: 0 | V42: 0 | W42: 0 | X42: 0 | Y42: 0 | Z42: 0 | AA42: 0 | AB42: 0 | AC42: 0 | AD42: 0 | AE42: 0 | AF42: 0 | AG42: 0 | AH42: 0 | AI42: 0 | AJ42: 0 | AK42: 0 | AL42: 16.7492 | AM42: 0 | AN42: 0 | AO42: 0
B43: TRA_Car_Fle_Fue_Lom | E43: 0 | F43: 0 | G43: 0 | H43: 0 | I43: 0 | J43: 11.1287 | K43: 0 | L43: 0 | M43: 0 | N43: 0 | O43: 0 | P43: 0 | Q43: 0 | R43: 0 | S43: 0 | T43: 0 | U43: 0 | V43: 0 | W43: 0 | X43: 0 | Y43: 0 | Z43: 0 | AA43: 0 | AB43: 0 | AC43: 0 | AD43: 0 | AE43: 0 | AF43: 0 | AG43: 0 | AH43: 0 | AI43: 0 | AJ43: 0 | AK43: 0 | AL43: 16.3708 | AM43: 0 | AN43: 0 | AO43: 0
B44: TRA_Car_Fle_Fue_Sma | E44: 0 | F44: 0 | G44: 0 | H44: 0 | I44: 0 | J44: 11.1287 | K44: 0 | L44: 0 | M44: 0 | N44: 0 | O44: 0 | P44: 0 | Q44: 0 | R44: 0 | S44: 0 | T44: 0 | U44: 0 | V44: 0 | W44: 0 | X44: 0 | Y44: 0 | Z44: 0 | AA44: 0 | AB44: 0 | AC44: 0 | AD44: 0 | AE44: 0 | AF44: 0 | AG44: 0 | AH44: 0 | AI44: 0 | AJ44: 0 | AK44: 0 | AL44: 15.3071 | AM44: 0 | AN44: 0 | AO44: 0
B45: TRA_Car_Fle_Fue_Upm | E45: 0 | F45: 0 | G45: 0 | H45: 0 | I45: 0 | J45: 11.1287 | K45: 0 | L45: 0 | M45: 0 | N45: 0 | O45: 0 | P45: 0 | Q45: 0 | R45: 0 | S45: 0 | T45: 0 | U45: 0 | V45: 0 | W45: 0 | X45: 0 | Y45: 0 | Z45: 0 | AA45: 0 | AB45: 0 | AC45: 0 | AD45: 0 | AE45: 0 | AF45: 0 | AG45: 0 | AH45: 0 | AI45: 0 | AJ45: 0 | AK45: 0 | AL45: 16.8051 | AM45: 0 | AN45: 0 | AO45: 0
... B57: TRA_Car_Oth_Upm | E57: 0 | F57: 0 | G57: 0 | H57: 0 | I57: 0 | J57: 0 | K57: 0 | L57: 12.6017 | M57: 0 | N57: 8.55235 | O57: 0 | P57: 0 | Q57: 0 | R57: 0 | S57: 0 | T57: 0 | U57: 0 | V57: 0 | W57: 12.6557 | X57: 0 | Y57: 0 | Z57: 0 | AA57: 0 | AB57: 0 | AC57: 0 | AD57: 0 | AE57: 0 | AF57: 13.2015 | AG57: 0 | AH57: 9.11433 | AI57: 14.7604 | AJ57: 0 | AK57: 0 | AL57: 14.0517 | AM57: 0 | AN57: 0 | AO57: 11.1743
