Workbook

Sheet INS
C2: ~TFM_DINS-TS: Region=AT,BE,BG,CY,CZ,DE,DK,EE,ES,FI,FR,EL,HU,IE,IT,LT,LU,LV,MT,NL,PL,PT,RO,SE,SI,SK,UK,CH,IS,NO,AL,BA,HR,KS,ME,MK,RS
C3: Pset_PN | D3: Curr | E3: Attribute | F3: 2015 | G3: 2020 | H3: 2025 | I3: 2030 | J3: 2035 | K3: 2040 | L3: 2045 | M3: 2050 | N3: 2060 | O3: 2070
A4: Tidal energy stream | C4: EUOCETID01 | D4: EUR17 | E4: NCAP_COST | F4: =Ocean_Summary!AF66 -> 7840 | G4: =Ocean_Summary!AG66 -> 5530 | H4: =Ocean_Summary!AH66 -> 5130 | I4: =Ocean_Summary!AI66 -> 4250 | J4: =Ocean_Summary!AJ66 -> 3370 | K4: =Ocean_Summary!AK66 -> 2780 | L4: =Ocean_Summary!AL66 -> 2320 | M4: =Ocean_Summary!AM66 -> 1980 | N4: 1980 | O4: 1980
A5: Wave (nearshore) | C5: EUOCEWAV01 | D5: EUR17 | E5: NCAP_COST | F5: =Ocean_Summary!AF67 -> 7910 | G5: =Ocean_Summary!AG67 -> 5580 | H5: =Ocean_Summary!AH67 -> 5170 | I5: =Ocean_Summary!AI67 -> 4290 | J5: =Ocean_Summary!AJ67 -> 3400 | K5: =Ocean_Summary!AK67 -> 2810 | L5: =Ocean_Summary!AL67 -> 2350 | M5: =Ocean_Summary!AM67 -> 2000 | N5: 2000 | O5: 2000
A6: Wave (offshore) | C6: EUOCEWAV02 | D6: EUR17 | E6: NCAP_COST | F6: =Ocean_Summary!AF68 -> 7910 | G6: =Ocean_Summary!AG68 -> 5580 | H6: =Ocean_Summary!AH68 -> 5170 | I6: =Ocean_Summary!AI68 -> 4290 | J6: =Ocean_Summary!AJ68 -> 3400 | K6: =Ocean_Summary!AK68 -> 2810 | L6: =Ocean_Summary!AL68 -> 2350 | M6: =Ocean_Summary!AM68 -> 2000 | N6: 2000 | O6: 2000
A7: Tidal energy stream | C7: EUOCETID01 | D7: EUR17 | E7: NCAP_FOM | F7: =Ocean_Summary!AR66 -> 493.44914 | G7: =Ocean_Summary!AS66 -> 360.22897 | H7: =Ocean_Summary!AT66 -> 316.31024 | I7: =Ocean_Summary!AU66 -> 238.88999 | J7: =Ocean_Summary!AV66 -> 200.07165 | K7: =Ocean_Summary!AW66 -> 175.55367 | L7: =Ocean_Summary!AX66 -> 133.08181 | M7: =Ocean_Summary!AY66 -> 97.440874 | N7: 97.440874 | O7: 97.440874
A8: Wave (nearshore) | C8: EUOCEWAV01 | D8: EUR17 | E8: NCAP_FOM | F8: =Ocean_Summary!AR67 -> 312.8177 | G8: =Ocean_Summary!AS67 -> 220.82653 | H8: =Ocean_Summary!AT67 -> 204.56105 | I8: =Ocean_Summary!AU67 -> 150.05345 | J8: =Ocean_Summary!AV67 -> 134.48404 | K8: =Ocean_Summary!AW67 -> 110.95853 | L8: =Ocean_Summary!AX67 -> 92.751853 | M8: =Ocean_Summary!AY67 -> 78.961762 | N8: 78.961762 | O8: 78.961762
A9: Wave (offshore) | C9: EUOCEWAV02 | D9: EUR17 | E9: NCAP_FOM | F9: =Ocean_Summary!AR68 -> 324.30202 | G9: =Ocean_Summary!AS68 -> 240.16201 | H9: =Ocean_Summary!AT68 -> 219.29006 | I9: =Ocean_Summary!AU68 -> 178.43704 | J9: =Ocean_Summary!AV68 -> 151.16394 | K9: =Ocean_Summary!AW68 -> 140.51739 | L9: =Ocean_Summary!AX68 -> 123.3174 | M9: =Ocean_Summary!AY68 -> 110.72774 | N9: 110.72774 | O9: 110.72774
A10: Utility c-Si, tracking | C10: EUPVSOLL201 | D10: EUR17 | E10: NCAP_COST | F10: =PV_Summary_Fin!AF65 -> 1120 | G10: =PV_Summary_Fin!AG65 -> 830 | H10: =PV_Summary_Fin!AH65 -> 700 | I10: =PV_Summary_Fin!AI65 -> 600 | J10: =PV_Summary_Fin!AJ65 -> 510 | K10: =PV_Summary_Fin!AK65 -> 430 | L10: =PV_Summary_Fin!AL65 -> 380 | M10: =PV_Summary_Fin!AM65 -> 340 | N10: 340 | O10: 340
A11: Utility c-Si, flat | C11: EUPVSOLL101 | D11: EUR17 | E11: NCAP_COST | F11: =PV_Summary_Fin!AF66 -> 1020 | G11: =PV_Summary_Fin!AG66 -> 750 | H11: =PV_Summary_Fin!AH66 -> 640 | I11: =PV_Summary_Fin!AI66 -> 540 | J11: =PV_Summary_Fin!AJ66 -> 460 | K11: =PV_Summary_Fin!AK66 -> 390 | L11: =PV_Summary_Fin!AL66 -> 340 | M11: =PV_Summary_Fin!AM66 -> 310 | N11: 310 | O11: 310
A12: Commercial c-Si, flat | C12: EUPVSOLS201 | D12: EUR17 | E12: NCAP_COST | F12: =PV_Summary_Fin!AF67 -> 1140 | G12: =PV_Summary_Fin!AG67 -> 840 | H12: =PV_Summary_Fin!AH67 -> 720 | I12: =PV_Summary_Fin!AI67 -> 610 | J12: =PV_Summary_Fin!AJ67 -> 520 | K12: =PV_Summary_Fin!AK67 -> 440 | L12: =PV_Summary_Fin!AL67 -> 380 | M12: =PV_Summary_Fin!AM67 -> 350 | N12: 350 | O12: 350
A13: Residential c-Si, inclined | C13: EUPVSOLS101 | D13: EUR17 | E13: NCAP_COST | F13: =PV_Summary_Fin!AF69 -> 1360 | G13: =PV_Summary_Fin!AG69 -> 1000 | H13: =PV_Summary_Fin!AH69 -> 860 | I13: =PV_Summary_Fin!AI69 -> 730 | J13: =PV_Summary_Fin!AJ69 -> 610 | K13: =PV_Summary_Fin!AK69 -> 520 | L13: =PV_Summary_Fin!AL69 -> 460 | M13: =PV_Summary_Fin!AM69 -> 410 | N13: 410 | O13: 410
A14: Utility c-Si, tracking | C14: EUPVSOLL201 | D14: EUR17 | E14: NCAP_FOM | F14: ='PV SET'!$AC20*F10 -> 25.783723 | G14: ='PV SET'!$AC20*G10 -> 19.10758 | H14: ='PV SET'!$AC20*H10 -> 16.114827 | I14: ='PV SET'!$AC20*I10 -> 13.812709 | J14: ='PV SET'!$AC20*J10 -> 11.740802 | K14: ='PV SET'!$AC20*K10 -> 9.8991078 | L14: ='PV SET'!$AC20*L10 -> 8.7480488 | M14: ='PV SET'!$AC20*M10 -> 7.8272015 | N14: 7.8272015 | O14: 7.8272015
A15: Utility c-Si, flat | C15: EUPVSOLL101 | D15: EUR17 | E15: NCAP_FOM | F15: ='PV SET'!$AC21*F11 -> 17.409869 | G15: ='PV SET'!$AC21*G11 -> 12.801374 | H15: ='PV SET'!$AC21*H11 -> 10.923839 | I15: ='PV SET'!$AC21*I11 -> 9.2169895 | J15: ='PV SET'!$AC21*J11 -> 7.8515096 | K15: ='PV SET'!$AC21*K11 -> 6.6567147 | L15: ='PV SET'!$AC21*L11 -> 5.8032897 | M15: ='PV SET'!$AC21*M11 -> 5.2912347 | N15: 5.2912347 | O15: 5.2912347
A16: Commercial c-Si, flat | C16: EUPVSOLS201 | D16: EUR17 | E16: NCAP_FOM | F16: ='PV SET'!$AC22*F12 -> 28.658557 | G16: ='PV SET'!$AC22*G12 -> 21.116831 | H16: ='PV SET'!$AC22*H12 -> 18.100141 | I16: ='PV SET'!$AC22*I12 -> 15.334842 | J16: ='PV SET'!$AC22*J12 -> 13.072324 | K16: ='PV SET'!$AC22*K12 -> 11.061197 | L16: ='PV SET'!$AC22*L12 -> 9.5528523 | M16: ='PV SET'!$AC22*M12 -> 8.7986797 | N16: 8.7986797 | O16: 8.7986797
A17: Residential c-Si, inclined | C17: EUPVSOLS101 | D17: EUR17 | E17: NCAP_FOM | F17: ='PV SET'!$AC24*F13 -> 27.309599 | G17: ='PV SET'!$AC24*G13 -> 20.080587 | H17: ='PV SET'!$AC24*H13 -> 17.269305 | I17: ='PV SET'!$AC24*I13 -> 14.658829 | J17: ='PV SET'!$AC24*J13 -> 12.249158 | K17: ='PV SET'!$AC24*K13 -> 10.441905 | L17: ='PV SET'!$AC24*L13 -> 9.2370701 | M17: ='PV SET'!$AC24*M13 -> 8.2330407 | N17: 8.2330407 | O17: 8.2330407
A18: Solar CSP Parabolic Through 6-8h storage | C18: EUCSPSOL101 | D18: EUR17 | E18: NCAP_COST | F18: =STE_Summary!AF65 -> 6000 | G18: =STE_Summary!AG65 -> 4120 | H18: =STE_Summary!AH65 -> 3790 | I18: =STE_Summary!AI65 -> 3380 | J18: =STE_Summary!AJ65 -> 3080 | K18: =STE_Summary!AK65 -> 2890 | L18: =STE_Summary!AL65 -> 2770 | M18: =STE_Summary!AM65 -> 2660 | N18: 2660 | O18: 2660
A19: Solar CSP Solar Tower 12-15h storage | C19: EUCSPSOL401 | D19: EUR17 | E19: NCAP_COST | F19: =STE_Summary!AF66 -> 5280 | G19: =STE_Summary!AG66 -> 3620 | H19: =STE_Summary!AH66 -> 3330 | I19: =STE_Summary!AI66 -> 2970 | J19: =STE_Summary!AJ66 -> 2710 | K19: =STE_Summary!AK66 -> 2550 | L19: =STE_Summary!AL66 -> 2440 | M19: =STE_Summary!AM66 -> 2340 | N19: 2340 | O19: 2340
A20: Solar PV high concentration | C20: EUPVSOLHC01 | D20: EUR17 | E20: NCAP_COST | F20: =STE_Summary!AF67 -> 3800 | G20: =STE_Summary!AG67 -> 2610 | H20: =STE_Summary!AH67 -> 2400 | I20: =STE_Summary!AI67 -> 2140 | J20: =STE_Summary!AJ67 -> 1950 | K20: =STE_Summary!AK67 -> 1830 | L20: =STE_Summary!AL67 -> 1760 | M20: =STE_Summary!AM67 -> 1680 | N20: 1680 | O20: 1680
A21: Solar CSP Parabolic Through 6-8h storage | C21: EUCSPSOL101 | D21: EUR17 | E21: NCAP_FOM | F21: ='STE SET'!$X4*INS!F18 -> 101.92868 | G21: ='STE SET'!$X4*INS!G18 -> 69.991028 | H21: ='STE SET'!$X4*INS!H18 -> 64.384951 | I21: ='STE SET'!$X4*INS!I18 -> 57.419824 | J21: ='STE SET'!$X4*INS!J18 -> 52.32339 | K21: ='STE SET'!$X4*INS!K18 -> 49.095649 | L21: ='STE SET'!$X4*INS!L18 -> 47.057075 | M21: ='STE SET'!$X4*INS!M18 -> 45.188382 | N21: 45.188382 | O21: 45.188382
A22: Solar CSP Solar Tower 12-15h storage | C22: EUCSPSOL401 | D22: EUR17 | E22: NCAP_FOM | F22: ='STE SET'!$X5*INS!F19 -> 89.688954 | G22: ='STE SET'!$X5*INS!G19 -> 61.491291 | H22: ='STE SET'!$X5*INS!H19 -> 56.565193 | I22: ='STE SET'!$X5*INS!I19 -> 50.450037 | J22: ='STE SET'!$X5*INS!J19 -> 46.033535 | K22: ='STE SET'!$X5*INS!K19 -> 43.315688 | L22: ='STE SET'!$X5*INS!L19 -> 41.447168 | M22: ='STE SET'!$X5*INS!M19 -> 39.748514 | N22: 39.748514 | O22: 39.748514
A23: Solar PV high concentration | C23: EUPVSOLHC01 | D23: EUR17 | E23: NCAP_FOM | F23: =STE_Summary!AR67 -> 64.6 | G23: =STE_Summary!AS67 -> 44.322383 | H23: =STE_Summary!AT67 -> 40.785305 | I23: =STE_Summary!AU67 -> 36.385842 | J23: =STE_Summary!AV67 -> 33.176706 | K23: =STE_Summary!AW67 -> 31.142115 | L23: =STE_Summary!AX67 -> 29.835883 | M23: =STE_Summary!AY67 -> 28.586887 | N23: 28.586887 | O23: 28.586887
A24: Wind offshore both Monopile and Jacket | C24: EUWINOFH01 | D24: EUR17 | E24: NCAP_COST | F24: ='WindOffshore Summary'!G72 -> 3600 | G24: ='WindOffshore Summary'!H72 -> 2460 | H24: ='WindOffshore Summary'!I72 -> 2190 | I24: ='WindOffshore Summary'!J72 -> 1980 | J24: ='WindOffshore Summary'!K72 -> 1840 | K24: ='WindOffshore Summary'!L72 -> 1750 | L24: ='WindOffshore Summary'!M72 -> 1680 | M24: ='WindOffshore Summary'!N72 -> 1610 | N24: 1610 | O24: 1610
A25: Wind offshore 4 floating (>50m) | C25: EUWINOFV01 | D25: EUR17 | E25: NCAP_COST | F25: ='WindOffshore Summary'!G117 -> 5300 | G25: ='WindOffshore Summary'!H117 -> 3620 | H25: ='WindOffshore Summary'!I117 -> 3230 | I25: ='WindOffshore Summary'!J117 -> 2910 | J25: ='WindOffshore Summary'!K117 -> 2720 | K25: ='WindOffshore Summary'!L117 -> 2580 | L25: ='WindOffshore Summary'!M117 -> 2480 | M25: ='WindOffshore Summary'!N117 -> 2370 | N25: 2370 | O25: 2370
A26: Wind offshore both Monopile and Jacket | C26: EUWINOFH01 | D26: EUR17 | E26: NCAP_FOM | F26: ='WindOffshore Summary'!S72 -> 72 | G26: ='WindOffshore Summary'!T72 -> 49.22789 | H26: ='WindOffshore Summary'!U72 -> 43.864998 | I26: ='WindOffshore Summary'!V72 -> 39.572893 | J26: ='WindOffshore Summary'!W72 -> 36.891111 | K26: ='WindOffshore Summary'!X72 -> 35.071739 | L26: ='WindOffshore Summary'!Y72 -> 33.664998 | M26: ='WindOffshore Summary'!Z72 -> 32.189492 | N26: 32.189492 | O26: 32.189492
A27: Wind offshore 4 floating (>50m) | C27: EUWINOFV01 | D27: EUR17 | E27: NCAP_FOM | F27: ='WindOffshore Summary'!S117 -> 106 | G27: ='WindOffshore Summary'!T117 -> 72.474393 | H27: ='WindOffshore Summary'!U117 -> 64.579025 | I27: ='WindOffshore Summary'!V117 -> 58.260093 | J27: ='WindOffshore Summary'!W117 -> 54.311913 | K27: ='WindOffshore Summary'!X117 -> 51.633394 | L27: ='WindOffshore Summary'!Y117 -> 49.562359 | M27: ='WindOffshore Summary'!Z117 -> 47.390085 | N27: 47.390085 | O27: 47.390085
A28: Wind onshore CF15-20 | C28: EUWINONL01 | D28: EUR17 | E28: NCAP_COST | F28: ='WindOnshore Summary'!G72 -> 1350 | G28: ='WindOnshore Summary'!H72 -> 1220 | H28: ='WindOnshore Summary'!I72 -> 1150 | I28: ='WindOnshore Summary'!J72 -> 1080 | J28: ='WindOnshore Summary'!K72 -> 1040 | K28: ='WindOnshore Summary'!L72 -> 1000 | L28: ='WindOnshore Summary'!M72 -> 970 | M28: ='WindOnshore Summary'!N72 -> 950 | N28: 950 | O28: 950
A29: Wind onshore CF20-25 | C29: EUWINONM01 | D29: EUR17 | E29: NCAP_COST | F29: =F28 -> 1350 | G29: =G28 -> 1220 | H29: =H28 -> 1150 | I29: =I28 -> 1080 | J29: =J28 -> 1040 | K29: =K28 -> 1000 | L29: =L28 -> 970 | M29: =M28 -> 950 | N29: 950 | O29: 950
A30: Wind onshore CF25+ | C30: EUWINONH01 | D30: EUR17 | E30: NCAP_COST | F30: =F29 -> 1350 | G30: =G29 -> 1220 | H30: =H29 -> 1150 | I30: =I29 -> 1080 | J30: =J29 -> 1040 | K30: =K29 -> 1000 | L30: =L29 -> 970 | M30: =M29 -> 950 | N30: 950 | O30: 950
A31: Wind onshore CF15-20 | C31: EUWINONL01 | D31: EUR17 | E31: NCAP_FOM | F31: ='WindOnshore Summary'!S72 -> 40.5 | G31: ='WindOnshore Summary'!T72 -> 36.605774 | H31: ='WindOnshore Summary'!U72 -> 34.441134 | I31: ='WindOnshore Summary'!V72 -> 32.497625 | J31: ='WindOnshore Summary'!W72 -> 31.186177 | K31: ='WindOnshore Summary'!X72 -> 30.123419 | L31: ='WindOnshore Summary'!Y72 -> 29.199852 | M31: ='WindOnshore Summary'!Z72 -> 28.358823 | N31: 28.358823 | O31: 28.358823
A32: Wind onshore CF20-25 | C32: EUWINONM01 | D32: EUR17 | E32: NCAP_FOM | F32: =F31 -> 40.5 | G32: =G31 -> 36.605774 | H32: =H31 -> 34.441134 | I32: =I31 -> 32.497625 | J32: =J31 -> 31.186177 | K32: =K31 -> 30.123419 | L32: =L31 -> 29.199852 | M32: =M31 -> 28.358823 | N32: 28.358823 | O32: 28.358823
A33: Wind onshore CF25+ | C33: EUWINONH01 | D33: EUR17 | E33: NCAP_FOM | F33: =F32 -> 40.5 | G33: =G32 -> 36.605774 | H33: =H32 -> 34.441134 | I33: =I32 -> 32.497625 | J33: =J32 -> 31.186177 | K33: =K32 -> 30.123419 | L33: =L32 -> 29.199852 | M33: =M32 -> 28.358823 | N33: 28.358823 | O33: 28.358823
A34: Geothermal EGS with ORC | C34: EUGEOEGS01 | D34: EUR17 | E34: NCAP_COST | F34: ='Geothermal Summary'!AF35 -> 11790 | G34: ='Geothermal Summary'!AG35 -> 10550 | H34: ='Geothermal Summary'!AH35 -> 10000 | I34: ='Geothermal Summary'!AI35 -> 9250 | J34: ='Geothermal Summary'!AJ35 -> 8840 | K34: ='Geothermal Summary'!AK35 -> 8510 | L34: ='Geothermal Summary'!AL35 -> 8160 | M34: ='Geothermal Summary'!AM35 -> 7870 | N34: 7870 | O34: 7870
A35: Geothermal hydrothermal with flash power plants | C35: EUGEOF01 | D35: EUR17 | E35: NCAP_COST | F35: ='Geothermal Summary'!AF36 -> 3540 | G35: ='Geothermal Summary'!AG36 -> 3170 | H35: ='Geothermal Summary'!AH36 -> 3000 | I35: ='Geothermal Summary'!AI36 -> 2780 | J35: ='Geothermal Summary'!AJ36 -> 2650 | K35: ='Geothermal Summary'!AK36 -> 2560 | L35: ='Geothermal Summary'!AL36 -> 2450 | M35: ='Geothermal Summary'!AM36 -> 2360 | N35: 2360 | O35: 2360
A36: Geothermal hydrothermal with ORC | C36: EUGEOORC01 | D36: EUR17 | E36: NCAP_COST | F36: ='Geothermal Summary'!AF37 -> 6970 | G36: ='Geothermal Summary'!AG37 -> 6240 | H36: ='Geothermal Summary'!AH37 -> 5910 | I36: ='Geothermal Summary'!AI37 -> 5470 | J36: ='Geothermal Summary'!AJ37 -> 5230 | K36: ='Geothermal Summary'!AK37 -> 5030 | L36: ='Geothermal Summary'!AL37 -> 4830 | M36: ='Geothermal Summary'!AM37 -> 4650 | N36: 4650 | O36: 4650
A37: Geothermal EGS with ORC | C37: EUGEOEGS01 | D37: EUR17 | E37: NCAP_FOM | F37: ='Geothermal Summary'!AR35 -> 235.8 | G37: ='Geothermal Summary'!AS35 -> 211.08689 | H37: ='Geothermal Summary'!AT35 -> 200.00371 | I37: ='Geothermal Summary'!AU35 -> 185.06385 | J37: ='Geothermal Summary'!AV35 -> 176.82993 | K37: ='Geothermal Summary'!AW35 -> 170.21452 | L37: ='Geothermal Summary'!AX35 -> 163.29942 | M37: ='Geothermal Summary'!AY35 -> 157.35581 | N37: 157.35581 | O37: 157.35581
A38: Geothermal hydrothermal with flash power plants | C38: EUGEOF01 | D38: EUR17 | E38: NCAP_FOM | F38: ='Geothermal Summary'!AR36 -> 70.8 | G38: ='Geothermal Summary'!AS36 -> 63.379779 | H38: ='Geothermal Summary'!AT36 -> 60.052004 | I38: ='Geothermal Summary'!AU36 -> 55.566246 | J38: ='Geothermal Summary'!AV36 -> 53.093975 | K38: ='Geothermal Summary'!AW36 -> 51.107667 | L38: ='Geothermal Summary'!AX36 -> 49.031377 | M38: ='Geothermal Summary'!AY36 -> 47.246782 | N38: 47.246782 | O38: 47.246782 | S38: Attribute | T38: NCAP_COST | AB38: NCAP_FOM
A39: Geothermal hydrothermal with ORC | C39: EUGEOORC01 | D39: EUR17 | E39: NCAP_FOM | F39: ='Geothermal Summary'!AR37 -> 139.4 | G39: ='Geothermal Summary'!AS37 -> 124.79013 | H39: ='Geothermal Summary'!AT37 -> 118.23799 | I39: ='Geothermal Summary'!AU37 -> 109.40586 | J39: ='Geothermal Summary'!AV37 -> 104.53814 | K39: ='Geothermal Summary'!AW37 -> 100.62724 | L39: ='Geothermal Summary'!AX37 -> 96.539181 | M39: ='Geothermal Summary'!AY37 -> 93.025444 | N39: 93.025444 | O39: 93.025444 | Q39: Process | R39: Scenario | S39: Curr\Year | T39: 2013 | U39: 2015 | V39: 2020 | W39: 2025 | X39: 2030 | Y39: 2035 | Z39: 2040 | AA39: 2050 | AB39: 2010 | AC39: 2013 | AD39: 2015 | AE39: 2020 | AF39: 2030 | AG39: 2040 | AH39: 2050
A40: CCGT Combined Cycle Gas Turbine + CCS Seq post combustion | C40: EUCCGASCCSpos20 | D40: EUR17 | E40: NCAP_COST | H40: =CCUS_Summary!AH65 -> 1510 | I40: =CCUS_Summary!AI65 -> 1320 | J40: =CCUS_Summary!AJ65 -> 1240 | K40: =CCUS_Summary!AK65 -> 1190 | L40: =CCUS_Summary!AL65 -> 1170 | M40: =CCUS_Summary!AM65 -> 1150 | N40: 1150 | O40: 1150 | Q40: EUCCGASCCSpos20 [ CCGT Combined Cycle Gas Turbine + CCS Seq post combustion ] | R40: ELC_IET4 | S40: EUR13 | T40: 1500 | AC40: 37.5
A41: Supercritical pulverised coal + CCS Seq post combustion | C41: EUPCCOHCCSpos20 | D41: EUR17 | E41: NCAP_COST | H41: =CCUS_Summary!AH66 -> 2920 | I41: =CCUS_Summary!AI66 -> 2630 | J41: =CCUS_Summary!AJ66 -> 2480 | K41: =CCUS_Summary!AK66 -> 2400 | L41: =CCUS_Summary!AL66 -> 2360 | M41: =CCUS_Summary!AM66 -> 2360 | N41: 2360 | O41: 2360 | Q41: EUPCCOHCCSpos20 [ Supercritical pulverised coal + CCS Seq post combustion ] | R41: ELC_IET4 | S41: EUR13 | T41: 3000 | V41: 2700 | X41: 2550 | AC41: 75 | AE41: 67.5 | AF41: 63.75
...

Sheet LCEO techs
B2: LCEO Technology Group 1 | C2: LCEO CCUS | D2: DataProvided | E2: Process | F2: Process Description | G2: Technology_sector | H2: Main_Activity | I2: Fossil_RES | J2: Technology_subtype | K2: Technology_main_input | L2: Unit - capacity | M2: Unit - activity | N2: Primary Resources
B3: Advanced alternative fuels | C3: CCUS | D3: NO | E3: S_CCUS_ATM | F3: Supply convert Atmospheric CO2 to Diesel | G3: Supply and transformation | H3: Power to liquid | K3: Electricity | L3: GW | M3: PJ
B4: Advanced alternative fuels | C4: CCUS | D4: NO | E4: S_CCUS_ATM_LowAF | F4: Supply convert Atmospheric CO2 to Diesel | G4: Supply and transformation | H4: Power to liquid | K4: Electricity | L4: GW | M4: PJ
B5: Advanced alternative fuels | C5: CCUS | D5: NO | E5: S_CCUS_ATM_MeOH | F5: Supply convert Atmospheric CO2 to Methanol | G5: Supply and transformation | H5: Power to liquid | K5: Electricity | L5: GW | M5: PJ
B6: Advanced alternative fuels | C6: CCUS | D6: NO | E6: S_CCUS_ATM_MeOH_LowAF | F6: Supply convert Atmospheric CO2 to Methanol LowAF | G6: Supply and transformation | H6: Power to liquid | K6: Electricity | L6: GW | M6: PJ
B7: Advanced alternative fuels | C7: CCUS | D7: NO | E7: S_CCUS_EMIS | F7: Supply convert CCS emission to Diesel | G7: Supply and transformation | H7: Power to liquid | K7: Electricity | L7: GW | M7: PJ
B8: Advanced alternative fuels | C8: CCUS | D8: NO | E8: S_CCUS_EMIS_H2T | F8: CO2 Hydrogenation to Diesel with centralized tank | G8: Supply and transformation | H8: Power to liquid | K8: Electricity | L8: GW | M8: PJ
B9: Advanced alternative fuels | C9: CCUS | D9: NO | E9: S_CCUS_EMIS_H2T_LowAF | F9: CO2 Hydrogenation to Diesel with centralized tank | G9: Supply and transformation | H9: Power to liquid | K9: Electricity | L9: GW | M9: PJ
B10: Advanced alternative fuels | C10: CCUS | D10: NO | E10: S_CCUS_EMIS_H2U | F10: CO2 Hydrogenation to Diesel with underground storage | G10: Supply and transformation | H10: Power to liquid | K10: Electricity | L10: GW | M10: PJ
B11: Advanced alternative fuels | C11: CCUS | D11: NO | E11: S_CCUS_EMIS_H2U_LowAF | F11: CO2 Hydrogenation to Diesel with underground storage | G11: Supply and transformation | H11: Power to liquid | K11: Electricity | L11: GW | M11: PJ
B12: Advanced alternative fuels | C12: CCUS | D12: NO | E12: S_CCUS_EMIS_LowAF | F12: Supply convert CCS emission to Diesel | G12: Supply and transformation | H12: Power to liquid | K12: Electricity | L12: GW | M12: PJ
B13: Advanced alternative fuels | C13: CCUS | D13: NO | E13: S_CCUS_EMISMeOH | F13: Supply convert CCS emission to Methanol | G13: Supply and transformation | H13: Power to liquid | K13: Electricity | L13: GW | M13: PJ
B14: Advanced alternative fuels | C14: CCUS | D14: NO | E14: S_CCUS_EMISMeOH_H2 | F14: Supply convert CCS emission to Methanol supplied by H2 | G14: Supply and transformation | H14: Power to liquid | K14: Electricity | L14: GW | M14: PJ
... B36: Geothermal | C36: non-CCUS | D36: YES | E36: EUGEOORC01 | F36: Geothermal hydrothermal with ORC | G36: Power sector | H36: Electricity generation | K36: Geothermal | L36: GW | M36: PJ
B37: Geothermal | C37: non-CCUS | D37: YES | E37: HHTHGEO001 | F37: District Heating. Heat.GEO. New | G37: Buildings - Residential | H37: Heat generation | J37: District heating | K37: Coal | L37: GW | M37: PJ
B38: Geothermal | C38: non-CCUS | D38: YES | E38: R_ES-SH-DH_GEO | F38: Residential boiler for sp heat - Detached house 1945 to 1969 : Geothermal Energy | G38: Buildings - Residential | H38: Heating | K38: Geothermal | L38: 000units | M38: PJ
B39: Geothermal | C39: non-CCUS | D39: YES | E39: R_ES-SH-DH-70_GEO | F39: Residential boiler for sp heat - Detached house 1970 to 2010 : Geothermal Energy | G39: Buildings - Residential | H39: Heating | K39: Geothermal | L39: 000units | M39: PJ
B40: Geothermal | C40: non-CCUS | D40: YES | E40: R_ES-SH-FL_GEO | F40: Residential boiler for sp heat - Flat : Geothermal Energy | G40: Buildings - Residential | H40: Heating | K40: Geothermal | L40: 000units | M40: PJ
B41: Geothermal | C41: non-CCUS | D41: YES | E41: R_ES-SH-SD_GEO | F41: Residential boiler for sp heat - Semi-detached house : Geothermal Energy | G41: Buildings - Residential | H41: Heating | K41: Geothermal | L41: 000units | M41: PJ
B42: Geothermal | C42: non-CCUS | D42: YES | E42: R_ES-WH-DH_GEO01 | F42: Geo Heat Exchanger water heater - Detached | G42: Buildings - Residential | H42: Hot water | K42: Geothermal | L42: GW | M42: PJ
B43: Geothermal | C43: non-CCUS | D43: YES | E43: R_ES-WH-FL_GEO01 | F43: Geo Heat Exchanger water heater - Flat | G43: Buildings - Residential | H43: Hot water | K43: Geothermal | L43: GW | M43: PJ
B44: Geothermal | C44: non-CCUS | D44: YES | E44: R_ES-WH-SD_GEO01 | F44: Geo Heat Exchanger water heater - Semi-Detached | G44: Buildings - Residential | H44: Hot water | K44: Geothermal | L44: GW | M44: PJ
B45: H2 and fuel cells - DELIV | C45: non-CCUS | D45: YES | E45: AGRGASH2C01 | F45: Fuel Tech - H2 Delivery from centralized production to blending (COMP+USTOR+TR+BLENDING+(nocosNATGASINF))-AGR | G45: Supply and transformation | H45: Transport and distribution | J45: Fuel transport | K45: Hydrogen | L45: PJ-a | M45: PJ
B46: H2 and fuel cells - DELIV | C46: non-CCUS | D46: YES | E46: COMGASH2C01 | F46: Fuel Tech - H2 Delivery from centralized production to blending (COMP+USTOR+TR+BLENDING+(nocosNATGASINF))-COM | G46: Supply and transformation | H46: Transport and distribution | J46: Fuel transport | K46: Hydrogen | L46: PJ-a | M46: PJ
B47: H2 and fuel cells - DELIV | C47: non-CCUS | D47: YES | E47: ELCGASH2C01 | F47: Fuel Tech - H2 Delivery from centralized production to blending (COMP+USTOR+TR+BLENDING+(nocosNATGASINF))-ELC | G47: Supply and transformation | H47: Transport and distribution | J47: Fuel transport | K47: Hydrogen | L47: PJ-a | M47: PJ
B48: H2 and fuel cells - DELIV | C48: non-CCUS | D48: YES | E48: INDGASH2C01 | F48: Fuel Tech - H2 Delivery from centralized production to blending (COMP+USTOR+TR+BLENDING+(nocosNATGASINF))-IND | G48: Supply and transformation | H48: Transport and distribution | J48: Fuel transport | K48: Hydrogen | L48: PJ-a | M48: PJ
B49: H2 and fuel cells - DELIV | C49: non-CCUS | D49: YES | E49: INDGH2C01 | F49: Fuel Tech - H2 Delivery from centralized production (COMP+TR+DP - Industrial) | G49: Supply and transformation | H49: Transport and distribution | J49: Fuel transport | K49: Hydrogen | L49: PJ-a | M49: PJ
B50: H2 and fuel cells - DELIV | C50: non-CCUS | D50: YES | E50: RSDGASH2C01 | F50: Fuel Tech - H2 Delivery from centralized production to blending (COMP+USTOR+TR+BLENDING+(nocosNATGASINF))-RSD | G50: Supply and transformation | H50: Transport and distribution | J50: Fuel transport | K50: Hydrogen | L50: PJ-a | M50: PJ
B51: H2 and fuel cells - DELIV | C51: non-CCUS | D51: YES | E51: RSDGH2C01 | F51: Fuel Tech - H2 Delivery from centralized production (COMP+TR+DP - Residential) | G51: Supply and transformation | H51: Transport and distribution | J51: Fuel transport | K51: Hydrogen | L51: PJ-a | M51: PJ
B52: H2 and fuel cells - DELIV | C52: non-CCUS | D52: YES | E52: RSDGH2C02 | F52: Fuel Tech - H2 Delivery from centralized production (COMP+USTOR+TR+DP - Residential) | G52: Supply and transformation | H52: Transport and distribution | J52: Fuel transport | K52: Hydrogen | L52: PJ-a | M52: PJ
B53: H2 and fuel cells - DELIV | C53: non-CCUS | D53: YES | E53: RSDGH2D01 | F53: Fuel Tech - H2 Delivery from local production (LOCGSTORB+DP - Residential) | G53: Supply and transformation | H53: Transport and distribution | J53: Fuel transport | K53: Hydrogen | L53: PJ-a | M53: PJ
B54: H2 and fuel cells - DELIV | C54: non-CCUS | D54: YES | E54: TRAGASH2C01 | F54: Fuel Tech - H2 Delivery from centralized production to blending (COMP+USTOR+TR+BLENDING+(nocosNATGASINF))-TRA | G54: Supply and transformation | H54: Transport and distribution | J54: Fuel transport | K54: Hydrogen | L54: PJ-a | M54: PJ
B55: H2 and fuel cells - DELIV | C55: non-CCUS | D55: YES | E55: TRAGH2C01 | F55: Fuel Tech - H2 Delivery from centralized production (COMP+USTOR+TR+LIQ+LSTORB+RTS+REFLG(large)) | G55: Supply and transformation | H55: Transport and distribution | J55: Fuel transport | K55: Hydrogen | L55: PJ-a | M55: PJ
B56: H2 and fuel cells - DELIV | C56: non-CCUS | D56: YES | E56: TRAGH2C02 | F56: Fuel Tech - H2 Delivery from centralized production (COMP+TR+LIQ+LSTORB+RTS+REFLG(large)) | G56: Supply and transformation | H56: Transport and distribution | J56: Fuel transport | K56: Hydrogen | L56: PJ-a | M56: PJ
... B63: H2 and fuel cells - DELIV | C63: non-CCUS | D63: YES | E63: TRALH2D01 | F63: Fuel Tech - H2 Delivery from local production (LOCGSTORB+ONSITELIQ+REFLL (large)) | G63: Supply and transformation | H63: Transport and distribution | J63: Fuel transport | K63: Hydrogen | L63: PJ-a | M63: PJ
B64: H2 and fuel cells - PROD | C64: CCUS | D64: YES | E64: SCOAH2GCC01 | F64: H2 Production-Coal Gasification + Carbon Capture, big size, centralized | G64: Supply and transformation | H64: Hydrogen generation | K64: Coal | L64: GW | M64: PJ
B65: H2 and fuel cells - PROD | C65: CCUS | D65: YES | E65: SCOAH2GCC02 | F65: H2 Production-Coal Gasification + Carbon Capture, medium size, centralized | G65: Supply and transformation | H65: Hydrogen generation | K65: Coal | L65: GW | M65: PJ
B66: H2 and fuel cells - PROD | C66: CCUS | D66: YES | E66: SGASH2RCC01 | F66: H2 Production-Methane Steam Reforming + Carbon Capture, large size, centralized | G66: Supply and transformation | H66: Hydrogen generation | K66: Gas (possibly blended) | L66: GW | M66: PJ
B67: H2 and fuel cells - PROD | C67: CCUS | D67: YES | E67: SGASH2RCC02 | F67: H2 Production-Methane Steam Reforming + Carbon Capture, small size, centralized | G67: Supply and transformation | H67: Hydrogen generation | K67: Gas (possibly blended) | L67: GW | M67: PJ
B68: H2 and fuel cells - PROD | C68: non-CCUS | D68: YES | E68: ENUCH2EC01 | F68: H2 Production-Very High Temperature Reactor CHP, centralized | G68: Power sector | H68: Hydrogen generation | K68: Nuclear | L68: GW | M68: PJ
...

Sheet Scenario names
A3: 01_ | B3: Baseline_RefL | C3: =CONCATENATE(A3,B3) -> 01_Baseline_RefL
A4: 02_ | B4: Diversified_LowL | C4: =CONCATENATE(A4,B4) -> 02_Diversified_LowL
A5: 03_ | B5: Diversified_RefL | C5: =CONCATENATE(A5,B5) -> 03_Diversified_RefL
A6: 04_ | B6: Diversified_HighL | C6: =CONCATENATE(A6,B6) -> 04_Diversified_HighL
A7: 05_ | B7: Diversified_CCS_IND_Only | C7: =CONCATENATE(A7,B7) -> 05_Diversified_CCS_IND_Only
A8: 06_ | B8: Diversified_CostCapital | C8: =CONCATENATE(A8,B8) -> 06_Diversified_CostCapital | D8: Most probable result is like 03
A9: 07_ | B9: Diversified_LowFossilPrice | C9: =CONCATENATE(A9,B9) -> 07_Diversified_LowFossilPrice | D9: Even more fossil ?
A10: 08_ | B10: Diversified_RES_EE | C10: =CONCATENATE(A10,B10) -> 08_Diversified_RES_EE
A11: 09_ | B11: PRORes_LowL | C11: =CONCATENATE(A11,B11) -> 09_PRORes_LowL
A12: 10_ | B12: PRORes_RefL | C12: =CONCATENATE(A12,B12) -> 10_PRORes_RefL
A13: 11_ | B13: PRORes_HighL | C13: =CONCATENATE(A13,B13) -> 11_PRORes_HighL
A14: 12_ | B14: PRORes_SET | C14: =CONCATENATE(A14,B14) -> 12_PRORes_SET | D14: Include Lifetime PV as well as SET-plan CSP
A15: 13_ | B15: PRORes_OffshoreDepl | C15: =CONCATENATE(A15,B15) -> 13_PRORes_OffshoreDepl | D15: Maybe already in HighL ?
A16: 14_ | B16: PRORes_HighForest | C16: =CONCATENATE(A16,B16) -> 14_PRORes_HighForest
A17: 15_ | B17: PRORes_NoCCU | C17: =CONCATENATE(A17,B17) -> 15_PRORes_NoCCU
A18: 16_ | B18: PRORes_MaxBiofuel | C18: =CONCATENATE(A18,B18) -> 16_PRORes_MaxBiofuel
A20: ?? | B20: PRORes_CSP | C20: ONLY CSP without the PV reduction | D20: entry CAPEX derived from other runs

Sheet Hydro_Summary
F1: CAPEX (Eur/kW) | R1: OPEX Eur/kW/Year | AB1: Summary | AE1: CAPEX (Eur/kW) | AP1: OPEX Eur/kW/Year | BC1: CAPEX (Eur/kW) | BN1: OPEX Eur/kW/Year | BY1: CAPEX (Eur/kW) | CI1: OPEX Eur/kW/Year
B2: Page Name | C2: Upper left cell | E2: 0 | F2: 1 | G2: 2 | H2: 3 | I2: 4 | J2: 5 | K2: 6 | L2: 7 | M2: 8 | N2: 9 | Q2: 18 | R2: 19 | S2: 20 | T2: 21 | U2: 22 | V2: 23 | W2: 24 | X2: 25 | Y2: 26 | Z2: 27 | AC2: 0 | AD2: 1 | AE2: 2 | AF2: 3 | AG2: 4 | AH2: 5 | AI2: 6 | AJ2: 7 | AK2: 8 | AL2: 9 | AM2: 10 | AR2: 15 | AS2: 16 | AT2: 17 | AU2: 18 | AV2: 19 | AW2: 20 | AX2: 21 | AY2: 22
BA3: MAX | BM3: MAX | BW3: MAX
A4: 0 | G4: 2015 | H4: 2020 | I4: 2025 | J4: 2030 | K4: 2035 | L4: 2040 | M4: 2045 | N4: 2050 | S4: 2015 | T4: 2020 | U4: 2025 | V4: 2030 | W4: 2035 | X4: 2040 | Y4: 2045 | Z4: 2050 | AF4: 2015 | AG4: 2020 | AH4: 2025 | AI4: 2030 | AJ4: 2035 | AK4: 2040 | AL4: 2045 | AM4: 2050 | AR4: 2015 | AS4: 2020 | AT4: 2025 | AU4: 2030 | AV4: 2035 | AW4: 2040 | AX4: 2045 | AY4: 2050 | BC4: 2015 | BD4: 2020 | BE4: 2025 | BF4: 2030 | BG4: 2035 | BH4: 2040 | BI4: 2045 | BJ4: 2050 | BN4: 2015 | BO4: 2020 | BP4: 2025 | BQ4: 2030 | BR4: 2035 | BS4: 2040 | BT4: 2045 | BU4: 2050 | BY4: 2015 | BZ4: 2020 | CA4: 2025 | CB4: 2030 | CC4: 2035 | CD4: 2040 | CE4: 2045 | CF4: 2050 | CG4: Reduction | CJ4: 2015 | CK4: 2020 | CL4: 2025 | CM4: 2030 | CN4: 2035 | CO4: 2040 | CP4: 2045 | CQ4: 2050
A5: 1 | B5: Hydro_large_cheap | C5: G24 | D5: Lake large scale cheap hydroelectricity > 10 MW | E5: ProRES | F5: Ref LR | G5: 1090 | H5: 1090 | I5: 1090 | J5: 1090 | K5: 1090 | L5: 1090 | M5: 1090 | N5: 1090 | P5: Lake large scale cheap hydroelectricity > 10 MW | Q5: ProRES | R5: Ref LR | S5: 5.45 | T5: 5.4432483 | U5: 5.4403565 | V5: 5.4385243 | W5: 5.4370051 | X5: 5.4358417 | Y5: 5.4344153 | Z5: 5.432744 | AB5: 5 | AC5: Lake large scale cheap hydroelectricity > 10 MW | AD5: ProRES | AE5: Ref LR | AF5: 1090 | AG5: 1090 | AH5: 1090 | AI5: 1090 | AJ5: 1090 | AK5: 1090 | AL5: 1090 | AM5: 1090 | AO5: Lake large scale cheap hydroelectricity > 10 MW | AP5: ProRES | AQ5: Ref LR | AR5: 5.45 | AS5: 5.4432483 | AT5: 5.4403565 | AU5: 5.4385243 | AV5: 5.4370051 | AW5: 5.4358417 | AX5: 5.4344153 | AY5: 5.432744 | BA5: ProRES | BC5: 5000 | BD5: 5000 | BE5: 5000 | BF5: 5000 | BG5: 5000 | BH5: 5000 | BI5: 5000 | BJ5: 5000 | BM5: ProRES | BN5: 50 | BO5: 50 | BP5: 50 | BQ5: 50 | BR5: 50 | BS5: 50 | BT5: 50 | BU5: 50 | BW5: Lake large scale cheap hydroelectricity > 10 MW | BY5: 1090 | BZ5: 1090 | CA5: 1090 | CB5: 1090 | CC5: 1090 | CD5: 1090 | CE5: 1090 | CF5: 1090 | CG5: 0 | CI5: Lake large scale cheap hydroelectricity > 10 MW | CK5: 5.45 | CL5: 5.45 | CM5: 5.45 | CN5: 5.45 | CO5: 5.45 | CP5: 5.45 | CQ5: 5.45
A6: 2 | C6: -1 | E6: Baseline | F6: Ref LR | G6: 1090 | H6: 1090 | I6: 1090 | J6: 1090 | K6: 1090 | L6: 1090 | M6: 1090 | N6: 1090 | Q6: Baseline | R6: Ref LR | S6: 5.45 | T6: 5.448274 | U6: 5.4445047 | V6: 5.4406311 | W6: 5.4367103 | X6: 5.4322844 | Y6: 5.4283872 | Z6: 5.4251266 | AB6: 20 | AC6: Lake large scale expensive hydroelectricity > 10 MW | AD6: ProRES | AE6: Ref LR | AF6: 3500 | AG6: 3500 | AH6: 3490 | AI6: 3490 | AJ6: 3490 | AK6: 3490 | AL6: 3490 | AM6: 3490 | AO6: Lake large scale expensive hydroelectricity > 10 MW | AP6: ProRES | AQ6: Ref LR | AR6: 17.5 | AS6: 17.47832 | AT6: 17.469035 | AU6: 17.463151 | AV6: 17.458273 | AW6: 17.454538 | AX6: 17.449957 | AY6: 17.444591 | BA6: Baseline | BC6: 5000 | BD6: 5000 | BE6: 5000 | BF6: 5000 | BG6: 5000 | BH6: 5000 | BI6: 5000 | BJ6: 5000 | BM6: Baseline | BN6: 50 | BO6: 50 | BP6: 50 | BQ6: 50 | BR6: 50 | BS6: 50 | BT6: 50 | BU6: 50 | BW6: Lake large scale expensive hydroelectricity > 10 MW | BY6: 3500 | BZ6: 3500 | CA6: 3500 | CB6: 3500 | CC6: 3500 | CD6: 3500 | CE6: 3500 | CF6: 3500 | CI6: Lake large scale expensive hydroelectricity > 10 MW | CK6: 17.5 | CL6: 17.5 | CM6: 17.5 | CN6: 17.5 | CO6: 17.5 | CP6: 17.5 | CQ6: 17.5
A7: 3 | E7: Diversified portfolio | F7: Ref LR | G7: 1090 | H7: 1090 | I7: 1090 | J7: 1090 | K7: 1080 | L7: 1080 | M7: 1080 | N7: 1080 | Q7: Diversified portfolio | R7: Ref LR | S7: 5.45 | T7: 5.4475549 | U7: 5.437562 | V7: 5.4289669 | W7: 5.4235221 | X7: 5.4158634 | Y7: 5.4090875 | Z7: 5.403072 | AB7: 35 | AC7: Lake medium scale cheap hydroelectricity 1-10 MW | AD7: ProRES | AE7: Ref LR | AF7: 1410 | AG7: 1410 | AH7: 1410 | AI7: 1410 | AJ7: 1410 | AK7: 1410 | AL7: 1410 | AM7: 1410 | AO7: Lake medium scale cheap hydroelectricity 1-10 MW | AP7: ProRES | AQ7: Ref LR | AR7: 7.05 | AS7: 7.0412661 | AT7: 7.0375253 | AU7: 7.0351553 | AV7: 7.0331901 | AW7: 7.0316852 | AX7: 7.02984 | AY7: 7.027678 | BA7: Diversified portfolio | BC7: 5000 | BD7: 5000 | BE7: 5000 | BF7: 5000 | BG7: 5000 | BH7: 5000 | BI7: 5000 | BJ7: 5000 | BM7: Diversified portfolio | BN7: 50 | BO7: 50 | BP7: 50 | BQ7: 50 | BR7: 50 | BS7: 50 | BT7: 50 | BU7: 50 | BW7: Lake medium scale cheap hydroelectricity 1-10 MW | BY7: 1410 | BZ7: 1410 | CA7: 1410 | CB7: 1410 | CC7: 1410 | CD7: 1410 | CE7: 1410 | CF7: 1410 | CI7: Lake medium scale cheap hydroelectricity 1-10 MW | CK7: 7.05 | CL7: 7.05 | CM7: 7.05 | CN7: 7.05 | CO7: 7.05 | CP7: 7.05 | CQ7: 7.05
AB8: 50 | AC8: Lake medium scale expensive hydroelectricity 1-10 MW | AD8: ProRES | AE8: Ref LR | AF8: 4000 | AG8: 4000 | AH8: 3990 | AI8: 3990 | AJ8: 3990 | AK8: 3990 | AL8: 3990 | AM8: 3990 | AO8: Lake medium scale expensive hydroelectricity 1-10 MW | AP8: ProRES | AQ8: Ref LR | AR8: 20 | AS8: 19.975223 | AT8: 19.964611 | AU8: 19.957887 | AV8: 19.952312 | AW8: 19.948043 | AX8: 19.942809 | AY8: 19.936675 | BW8: Lake medium scale expensive hydroelectricity 1-10 MW | BY8: 4000 | BZ8: 4000 | CA8: 4000 | CB8: 4000 | CC8: 4000 | CD8: 4000 | CE8: 4000 | CF8: 4000 | CI8: Lake medium scale expensive hydroelectricity 1-10 MW | CK8: 20 | CL8: 20 | CM8: 20 | CN8: 20 | CO8: 20 | CP8: 20 | CQ8: 20
A9: 0 | G9: 2015 | H9: 2020 | I9: 2025 | J9: 2030 | K9: 2035 | L9: 2040 | M9: 2045 | N9: 2050 | S9: 2015 | T9: 2020 | U9: 2025 | V9: 2030 | W9: 2035 | X9: 2040 | Y9: 2045 | Z9: 2050 | AB9: 65 | AC9: Lake very small cheap hydroelectricity <1 MW | AD9: ProRES | AE9: Ref LR | AF9: 1740 | AG9: 1740 | AH9: 1740 | AI9: 1740 | AJ9: 1740 | AK9: 1740 | AL9: 1740 | AM9: 1730 | AO9: Lake very small cheap hydroelectricity <1 MW | AP9: ProRES | AQ9: Ref LR | AR9: 17.4 | AS9: 17.378444 | AT9: 17.369211 | AU9: 17.363362 | AV9: 17.358512 | AW9: 17.354797 | AX9: 17.350243 | AY9: 17.344907 | BW9: Lake very small cheap hydroelectricity <1 MW | BY9: 1740 | BZ9: 1740 | CA9: 1740 | CB9: 1740 | CC9: 1740 | CD9: 1740 | CE9: 1740 | CF9: 1740 | CI9: Lake very small cheap hydroelectricity <1 MW | CK9: 17.4 | CL9: 17.4 | CM9: 17.4 | CN9: 17.4 | CO9: 17.4 | CP9: 17.4 | CQ9: 17.4
A10: 1 | B10: Hydro_large_cheap | C10: G31 | D10: Lake large scale cheap hydroelectricity > 10 MW | E10: ProRES | F10: High LR | G10: 1090 | H10: 1090 | I10: 1090 | J10: 1090 | K10: 1080 | L10: 1080 | M10: 1080 | N10: 1080 | P10: Lake large scale cheap hydroelectricity > 10 MW | Q10: ProRES | R10: High LR | S10: 5.45 | T10: 5.4364365 | U10: 5.4306323 | V10: 5.4269567 | W10: 5.4239097 | X10: 5.4215771 | Y10: 5.4187177 | Z10: 5.4153682 | AB10: 80 | AC10: Lake very small expensive hydroelectricity <1 MW | AD10: ProRES | AE10: Ref LR | AF10: 5000 | AG10: 4990 | AH10: 4990 | AI10: 4990 | AJ10: 4990 | AK10: 4990 | AL10: 4990 | AM10: 4980 | AO10: Lake very small expensive hydroelectricity <1 MW | AP10: ProRES | AQ10: Ref LR | AR10: 50 | AS10: 49.938058 | AT10: 49.911527 | AU10: 49.894718 | AV10: 49.880781 | AW10: 49.870108 | AX10: 49.857021 | AY10: 49.841688 | BA10: MIN | BM10: MIN | BW10: Lake very small expensive hydroelectricity <1 MW | BY10: 5000 | BZ10: 5000 | CA10: 5000 | CB10: 5000 | CC10: 5000 | CD10: 5000 | CE10: 5000 | CF10: 5000 | CI10: Lake very small expensive hydroelectricity <1 MW | CK10: 50 | CL10: 50 | CM10: 50 | CN10: 50 | CO10: 50 | CP10: 50 | CQ10: 50
A11: 2 | C11: -1 | E11: Baseline | F11: High LR | G11: 1090 | H11: 1090 | I11: 1090 | J11: 1090 | K11: 1080 | L11: 1080 | M11: 1080 | N11: 1080 | Q11: Baseline | R11: High LR | S11: 5.45 | T11: 5.4465311 | U11: 5.4389592 | V11: 5.4311835 | W11: 5.4233186 | X11: 5.4144475 | Y11: 5.4066421 | Z11: 5.400116 | AB11: 95 | AC11: Run of River hydroelectricity | AD11: ProRES | AE11: Ref LR | AF11: 3000 | AG11: 3000 | AH11: 2990 | AI11: 2990 | AJ11: 2990 | AK11: 2990 | AL11: 2990 | AM11: 2990 | AO11: Run of River hydroelectricity | AP11: ProRES | AQ11: Ref LR | AR11: 15 | AS11: 14.981417 | AT11: 14.973458 | AU11: 14.968416 | AV11: 14.964234 | AW11: 14.961032 | AX11: 14.957106 | AY11: 14.952506 | BC11: 2015 | BD11: 2020 | BE11: 2025 | BF11: 2030 | BG11: 2035 | BH11: 2040 | BI11: 2045 | BJ11: 2050 | BN11: 2015 | BO11: 2020 | BP11: 2025 | BQ11: 2030 | BR11: 2035 | BS11: 2040 | BT11: 2045 | BU11: 2050 | BW11: Run of River hydroelectricity | BY11: 3000 | BZ11: 3000 | CA11: 3000 | CB11: 3000 | CC11: 3000 | CD11: 3000 | CE11: 3000 | CF11: 3000 | CI11: Run of River hydroelectricity | CK11: 15 | CL11: 15 | CM11: 15 | CN11: 15 | CO11: 15 | CP11: 15 | CQ11: 15
A12: 3 | E12: Diversified portfolio | F12: High LR | G12: 1090 | H12: 1090 | I12: 1090 | J12: 1080 | K12: 1080 | L12: 1080 | M12: 1070 | N12: 1070 | Q12: Diversified portfolio | R12: High LR | S12: 5.45 | T12: 5.4450862 | U12: 5.4250265 | V12: 5.4078027 | W12: 5.3969059 | X12: 5.3815973 | Y12: 5.3680715 | Z12: 5.3560779 | AB12: 110 | BA12: ProRES | BC12: 1090 | BD12: 1090 | BE12: 1090 | BF12: 1090 | BG12: 1080 | BH12: 1080 | BI12: 1080 | BJ12: 1080 | BM12: ProRES | BN12: 5.45 | BO12: 5.4364365 | BP12: 5.4306323 | BQ12: 5.4269567 | BR12: 5.4239097 | BS12: 5.4215771 | BT12: 5.4187177 | BU12: 5.4153682
AB13: 125 | BA13: Baseline | BC13: 1090 | BD13: 1090 | BE13: 1090 | BF13: 1090 | BG13: 1080 | BH13: 1080 | BI13: 1080 | BJ13: 1080 | BM13: Baseline | BN13: 5.45 | BO13: 5.4465311 | BP13: 5.4389592 | BQ13: 5.4311835 | BR13: 5.4233186 | BS13: 5.4144475 | BT13: 5.4066421 | BU13: 5.400116
A14: 0 | G14: 2015 | H14: 2020 | I14: 2025 | J14: 2030 | K14: 2035 | L14: 2040 | M14: 2045 | N14: 2050 | S14: 2015 | T14: 2020 | U14: 2025 | V14: 2030 | W14: 2035 | X14: 2040 | Y14: 2045 | Z14: 2050 | BA14: Diversified portfolio | BC14: 1090 | BD14: 1090 | BE14: 1090 | BF14: 1080 | BG14: 1080 | BH14: 1080 | BI14: 1070 | BJ14: 1070 | BM14: Diversified portfolio | BN14: 5.45 | BO14: 5.4450862 | BP14: 5.4250265 | BQ14: 5.4078027 | BR14: 5.3969059 | BS14: 5.3815973 | BT14: 5.3680715 | BU14: 5.3560779
A15: 1 | B15: Hydro_large_cheap | C15: G38 | D15: Lake large scale cheap hydroelectricity > 10 MW | E15: ProRES | F15: Low LR | G15: 1090 | H15: 1090 | I15: 1090 | J15: 1090 | K15: 1090 | L15: 1090 | M15: 1090 | N15: 1090 | P15: Lake large scale cheap hydroelectricity > 10 MW | Q15: ProRES | R15: Low LR | S15: 5.45 | T15: 5.45 | U15: 5.45 | V15: 5.45 | W15: 5.45 | X15: 5.45 | Y15: 5.45 | Z15: 5.45
A16: 2 | C16: -1 | E16: Baseline | F16: Low LR | G16: 1090 | H16: 1090 | I16: 1090 | J16: 1090 | K16: 1090 | L16: 1090 | M16: 1090 | N16: 1090 | Q16: Baseline | R16: Low LR | S16: 5.45 | T16: 5.45 | U16: 5.45 | V16: 5.45 | W16: 5.45 | X16: 5.45 | Y16: 5.45 | Z16: 5.45 | AF16: 2015 | AG16: 2020 | AH16: 2025 | AI16: 2030 | AJ16: 2035 | AK16: 2040 | AL16: 2045 | AM16: 2050 | AR16: 2015 | AS16: 2020 | AT16: 2025 | AU16: 2030 | AV16: 2035 | AW16: 2040 | AX16: 2045 | AY16: 2050
A17: 3 | E17: Diversified portfolio | F17: Low LR | G17: 1090 | H17: 1090 | I17: 1090 | J17: 1090 | K17: 1090 | L17: 1090 | M17: 1090 | N17: 1090 | Q17: Diversified portfolio | R17: Low LR | S17: 5.45 | T17: 5.45 | U17: 5.45 | V17: 5.45 | W17: 5.45 | X17: 5.45 | Y17: 5.45 | Z17: 5.45 | AB17: 6 | AC17: Lake large scale cheap hydroelectricity > 10 MW | AD17: Baseline | AE17: Ref LR | AF17: 1090 | AG17: 1090 | AH17: 1090 | AI17: 1090 | AJ17: 1090 | AK17: 1090 | AL17: 1090 | AM17: 1090 | AO17: Lake large scale cheap hydroelectricity > 10 MW | AP17: Baseline | AQ17: Ref LR | AR17: 5.45 | AS17: 5.448274 | AT17: 5.4445047 | AU17: 5.4406311 | AV17: 5.4367103 | AW17: 5.4322844 | AX17: 5.4283872 | AY17: 5.4251266 | BC17: 2015 | BD17: 2020 | BE17: 2025 | BF17: 2030 | BG17: 2035 | BH17: 2040 | BI17: 2045 | BJ17: 2050 | BN17: 2015 | BO17: 2020 | BP17: 2025 | BQ17: 2030 | BR17: 2035 | BS17: 2040 | BT17: 2045 | BU17: 2050 | BW17: MIN
AB18: 21 | AC18: Lake large scale expensive hydroelectricity > 10 MW | AD18: Baseline | AE18: Ref LR | AF18: 3500 | AG18: 3500 | AH18: 3500 | AI18: 3490 | AJ18: 3490 | AK18: 3490 | AL18: 3490 | AM18: 3480 | AO18: Lake large scale expensive hydroelectricity > 10 MW | AP18: Baseline | AQ18: Ref LR | AR18: 17.5 | AS18: 17.494458 | AT18: 17.482354 | AU18: 17.469916 | AV18: 17.457327 | AW18: 17.443115 | AX18: 17.430601 | AY18: 17.420131 | BB18: Max | BC18: 5000 | BD18: 5000 | BE18: 5000 | BF18: 5000 | BG18: 5000 | BH18: 5000 | BI18: 5000 | BJ18: 5000 | BM18: Max | BN18: 50 | BO18: 50 | BP18: 50 | BQ18: 50 | BR18: 50 | BS18: 50 | BT18: 50 | BU18: 50 | BY18: 2015 | BZ18: 2020 | CA18: 2025 | CB18: 2030 | CC18: 2035 | CD18: 2040 | CE18: 2045 | CF18: 2050 | CG18: Reduction | CJ18: 2015 | CK18: 2020 | CL18: 2025 | CM18: 2030 | CN18: 2035 | CO18: 2040 | CP18: 2045 | CQ18: 2050
A19: 0 | G19: 2015 | H19: 2020 | I19: 2025 | J19: 2030 | K19: 2035 | L19: 2040 | M19: 2045 | N19: 2050 | S19: 2015 | T19: 2020 | U19: 2025 | V19: 2030 | W19: 2035 | X19: 2040 | Y19: 2045 | Z19: 2050 | AB19: 36 | AC19: Lake medium scale cheap hydroelectricity 1-10 MW | AD19: Baseline | AE19: Ref LR | AF19: 1410 | AG19: 1410 | AH19: 1410 | AI19: 1410 | AJ19: 1410 | AK19: 1410 | AL19: 1400 | AM19: 1400 | AO19: Lake medium scale cheap hydroelectricity 1-10 MW | AP19: Baseline | AQ19: Ref LR | AR19: 7.05 | AS19: 7.0477673 | AT19: 7.0428914 | AU19: 7.0378806 | AV19: 7.0328088 | AW19: 7.0270835 | AX19: 7.0220422 | AY19: 7.0178243 | BB19: Min | BC19: 1090 | BD19: 1090 | BE19: 1090 | BF19: 1080 | BG19: 1080 | BH19: 1080 | BI19: 1070 | BJ19: 1070 | BM19: Min | BN19: 5.45 | BO19: 5.4364365 | BP19: 5.4250265 | BQ19: 5.4078027 | BR19: 5.3969059 | BS19: 5.3815973 | BT19: 5.3680715 | BU19: 5.3560779 | BW19: Lake large scale cheap hydroelectricity > 10 MW | BY19: 1090 | BZ19: 1090 | CA19: 1090 | CB19: 1080 | CC19: 1080 | CD19: 1080 | CE19: 1070 | CF19: 1070 | CG19: 0.018348624 | CI19: Lake large scale cheap hydroelectricity > 10 MW | CK19: 5.45 | CL19: 5.4364365 | CM19: 5.4250265 | CN19: 5.4078027 | CO19: 5.3969059 | CP19: 5.3815973 | CQ19: 5.3680715
A20: 1 | B20: Hydro_large_expensive | C20: G24 | D20: Lake large scale expensive hydroelectricity > 10 MW | E20: ProRES | F20: Ref LR | G20: 3500 | H20: 3500 | I20: 3490 | J20: 3490 | K20: 3490 | L20: 3490 | M20: 3490 | N20: 3490 | P20: Lake large scale expensive hydroelectricity > 10 MW | Q20: ProRES | R20: Ref LR | S20: 17.5 | T20: 17.47832 | U20: 17.469035 | V20: 17.463151 | W20: 17.458273 | X20: 17.454538 | Y20: 17.449957 | Z20: 17.444591 | AB20: 51 | AC20: Lake medium scale expensive hydroelectricity 1-10 MW | AD20: Baseline | AE20: Ref LR | AF20: 4000 | AG20: 4000 | AH20: 4000 | AI20: 3990 | AJ20: 3990 | AK20: 3990 | AL20: 3980 | AM20: 3980 | AO20: Lake medium scale expensive hydroelectricity 1-10 MW | AP20: Baseline | AQ20: Ref LR | AR20: 20 | AS20: 19.993666 | AT20: 19.979834 | AU20: 19.965619 | AV20: 19.951231 | AW20: 19.934989 | AX20: 19.920687 | AY20: 19.908722 | BW20: Lake large scale expensive hydroelectricity > 10 MW | BY20: 3500 | BZ20: 3490 | CA20: 3480 | CB20: 3470 | CC20: 3470 | CD20: 3460 | CE20: 3450 | CF20: 3440 | CI20: Lake large scale expensive hydroelectricity > 10 MW | CK20: 17.5 | CL20: 17.456448 | CM20: 17.41981 | CN20: 17.364504 | CO20: 17.329514 | CP20: 17.280358 | CQ20: 17.236927
A21: 2 | C21: -1 | E21: Baseline | F21: Ref LR | G21: 3500 | H21: 3500 | I21: 3500 | J21: 3490 | K21: 3490 | L21: 3490 | M21: 3490 | N21: 3480 | Q21: Baseline | R21: Ref LR | S21: 17.5 | T21: 17.494458 | U21: 17.482354 | V21: 17.469916 | W21: 17.457327 | X21: 17.443115 | Y21: 17.430601 | Z21: 17.420131 | AB21: 66 | AC21: Lake very small cheap hydroelectricity <1 MW | AD21: Baseline | AE21: Ref LR | AF21: 1740 | AG21: 1740 | AH21: 1740 | AI21: 1740 | AJ21: 1740 | AK21: 1730 | AL21: 1730 | AM21: 1730 | AO21: Lake very small cheap hydroelectricity <1 MW | AP21: Baseline | AQ21: Ref LR | AR21: 17.4 | AS21: 17.39449 | AT21: 17.382455 | AU21: 17.370088 | AV21: 17.357571 | AW21: 17.34344 | AX21: 17.330998 | AY21: 17.320588 | BW21: Lake medium scale cheap hydroelectricity 1-10 MW | BY21: 1410 | BZ21: 1410 | CA21: 1400 | CB21: 1400 | CC21: 1400 | CD21: 1390 | CE21: 1390 | CF21: 1390 | CI21: Lake medium scale cheap hydroelectricity 1-10 MW | CK21: 7.05 | CL21: 7.0324546 | CM21: 7.0176948 | CN21: 6.9954145 | CO21: 6.9813186 | CP21: 6.9615157 | CQ21: 6.9440191
A22: 3 | E22: Diversified portfolio | F22: Ref LR | G22: 3500 | H22: 3500 | I22: 3490 | J22: 3490 | K22: 3480 | L22: 3480 | M22: 3470 | N22: 3470 | Q22: Diversified portfolio | R22: Ref LR | S22: 17.5 | T22: 17.492149 | U22: 17.460061 | V22: 17.432463 | W22: 17.414979 | X22: 17.390387 | Y22: 17.36863 | Z22: 17.349314 | AB22: 81 | AC22: Lake very small expensive hydroelectricity <1 MW | AD22: Baseline | AE22: Ref LR | AF22: 5000 | AG22: 5000 | AH22: 4990 | AI22: 4990 | AJ22: 4990 | AK22: 4980 | AL22: 4980 | AM22: 4980 | AO22: Lake very small expensive hydroelectricity <1 MW | AP22: Baseline | AQ22: Ref LR | AR22: 50 | AS22: 49.984166 | AT22: 49.949584 | AU22: 49.914047 | AV22: 49.878076 | AW22: 49.837472 | AX22: 49.801718 | AY22: 49.771804 | BW22: Lake medium scale expensive hydroelectricity 1-10 MW | BY22: 4000 | BZ22: 3990 | CA22: 3980 | CB22: 3970 | CC22: 3960 | CD22: 3950 | CE22: 3940 | CF22: 3930 | CI22: Lake medium scale expensive hydroelectricity 1-10 MW | CK22: 20 | CL22: 19.950226 | CM22: 19.908354 | CN22: 19.845148 | CO22: 19.805159 | CP22: 19.748981 | CQ22: 19.699345
AB23: 96 | AC23: Run of River hydroelectricity | AD23: Baseline | AE23: Ref LR | AF23: 3000 | AG23: 3000 | AH23: 3000 | AI23: 2990 | AJ23: 2990 | AK23: 2990 | AL23: 2990 | AM23: 2990 | AO23: Run of River hydroelectricity | AP23: Baseline | AQ23: Ref LR | AR23: 15 | AS23: 14.99525 | AT23: 14.984875 | AU23: 14.974214 | AV23: 14.963423 | AW23: 14.951242 | AX23: 14.940515 | AY23: 14.931541 | BW23: Lake very small cheap hydroelectricity <1 MW | BY23: 1740 | BZ23: 1740 | CA23: 1730 | CB23: 1730 | CC23: 1720 | CD23: 1720 | CE23: 1710 | CF23: 1710 | CI23: Lake very small cheap hydroelectricity <1 MW | CK23: 17.4 | CL23: 17.356696 | CM23: 17.320268 | CN23: 17.265278 | CO23: 17.230489 | CP23: 17.181613 | CQ23: 17.13843
A24: 0 | G24: 2015 | H24: 2020 | I24: 2025 | J24: 2030 | K24: 2035 | L24: 2040 | M24: 2045 | N24: 2050 | S24: 2015 | T24: 2020 | U24: 2025 | V24: 2030 | W24: 2035 | X24: 2040 | Y24: 2045 | Z24: 2050 | AB24: 111 | BW24: Lake very small expensive hydroelectricity <1 MW | BY24: 5000 | BZ24: 4990 | CA24: 4980 | CB24: 4960 | CC24: 4950 | CD24: 4940 | CE24: 4920 | CF24: 4910 | CI24: Lake very small expensive hydroelectricity <1 MW | CK24: 50 | CL24: 49.875564 | CM24: 49.770885 | CN24: 49.612869 | CO24: 49.512898 | CP24: 49.372452 | CQ24: 49.248362
A25: 1 | B25: Hydro_large_expensive | C25: G31 | D25: Lake large scale expensive hydroelectricity > 10 MW | E25: ProRES | F25: High LR | G25: 3500 | H25: 3490 | I25: 3490 | J25: 3490 | K25: 3480 | L25: 3480 | M25: 3480 | N25: 3480 | P25: Lake large scale expensive hydroelectricity > 10 MW | Q25: ProRES | R25: High LR | S25: 17.5 | T25: 17.456448 | U25: 17.43781 | V25: 17.426008 | W25: 17.416224 | X25: 17.408734 | Y25: 17.399552 | Z25: 17.388797 | AB25: 126 | BW25: Run of River hydroelectricity | BY25: 3000 | BZ25: 2990 | CA25: 2990 | CB25: 2980 | CC25: 2970 | CD25: 2960 | CE25: 2950 | CF25: 2950 | CI25: Run of River hydroelectricity | CK25: 15 | CL25: 14.962669 | CM25: 14.931265 | CN25: 14.883861 | CO25: 14.853869 | CP25: 14.811736 | CQ25: 14.774509
A26: 2 | C26: -1 | E26: Baseline | F26: High LR | G26: 3500 | H26: 3500 | I26: 3490 | J26: 3490 | K26: 3480 | L26: 3480 | M26: 3470 | N26: 3470 | Q26: Baseline | R26: High LR | S26: 17.5 | T26: 17.488861 | U26: 17.464548 | V26: 17.43958 | W26: 17.414326 | X26: 17.385841 | Y26: 17.360777 | Z26: 17.339822
A27: 3 | E27: Diversified portfolio | F27: High LR | G27: 3500 | H27: 3500 | I27: 3480 | J27: 3470 | K27: 3470 | L27: 3460 | M27: 3450 | N27: 3440 | Q27: Diversified portfolio | R27: High LR | S27: 17.5 | T27: 17.484222 | U27: 17.41981 | V27: 17.364504 | W27: 17.329514 | X27: 17.280358 | Y27: 17.236927 | Z27: 17.198415
AF28: 2015 | AG28: 2020 | AH28: 2025 | AI28: 2030 | AJ28: 2035 | AK28: 2040 | AL28: 2045 | AM28: 2050 | AR28: 2015 | AS28: 2020 | AT28: 2025 | AU28: 2030 | AV28: 2035 | AW28: 2040 | AX28: 2045 | AY28: 2050
A29: 0 | G29: 2015 | H29: 2020 | I29: 2025 | J29: 2030 | K29: 2035 | L29: 2040 | M29: 2045 | N29: 2050 | S29: 2015 | T29: 2020 | U29: 2025 | V29: 2030 | W29: 2035 | X29: 2040 | Y29: 2045 | Z29: 2050 | AB29: 7 | AC29: Lake large scale cheap hydroelectricity > 10 MW | AD29: Diversified portfolio | AE29: Ref LR | AF29: 1090 | AG29: 1090 | AH29: 1090 | AI29: 1090 | AJ29: 1080 | AK29: 1080 | AL29: 1080 | AM29: 1080 | AO29: Lake large scale cheap hydroelectricity > 10 MW | AP29: Diversified portfolio | AQ29: Ref LR | AR29: 5.45 | AS29: 5.4475549 | AT29: 5.437562 | AU29: 5.4289669 | AV29: 5.4235221 | AW29: 5.4158634 | AX29: 5.4090875 | AY29: 5.403072
A30: 1 | B30: Hydro_large_expensive | C30: G38 | D30: Lake large scale expensive hydroelectricity > 10 MW | E30: ProRES | F30: Low LR | G30: 3500 | H30: 3500 | I30: 3500 | J30: 3500 | K30: 3500 | L30: 3500 | M30: 3500 | N30: 3500 | P30: Lake large scale expensive hydroelectricity > 10 MW | Q30: ProRES | R30: Low LR | S30: 17.5 | T30: 17.5 | U30: 17.5 | V30: 17.5 | W30: 17.5 | X30: 17.5 | Y30: 17.5 | Z30: 17.5 | AB30: 22 | AC30: Lake large scale expensive hydroelectricity > 10 MW | AD30: Diversified portfolio | AE30: Ref LR | AF30: 3500 | AG30: 3500 | AH30: 3490 | AI30: 3490 | AJ30: 3480 | AK30: 3480 | AL30: 3470 | AM30: 3470 | AO30: Lake large scale expensive hydroelectricity > 10 MW | AP30: Diversified portfolio | AQ30: Ref LR | AR30: 17.5 | AS30: 17.492149 | AT30: 17.460061 | AU30: 17.432463 | AV30: 17.414979 | AW30: 17.390387 | AX30: 17.36863 | AY30: 17.349314
A31: 2 | C31: -1 | E31: Baseline | F31: Low LR | G31: 3500 | H31: 3500 | I31: 3500 | J31: 3500 | K31: 3500 | L31: 3500 | M31: 3500 | N31: 3500 | Q31: Baseline | R31: Low LR | S31: 17.5 | T31: 17.5 | U31: 17.5 | V31: 17.5 | W31: 17.5 | X31: 17.5 | Y31: 17.5 | Z31: 17.5 | AB31: 37 | AC31: Lake medium scale cheap hydroelectricity 1-10 MW | AD31: Diversified portfolio | AE31: Ref LR | AF31: 1410 | AG31: 1410 | AH31: 1410 | AI31: 1400 | AJ31: 1400 | AK31: 1400 | AL31: 1400 | AM31: 1400 | AO31: Lake medium scale cheap hydroelectricity 1-10 MW | AP31: Diversified portfolio | AQ31: Ref LR | AR31: 7.05 | AS31: 7.0468371 | AT31: 7.0339104 | AU31: 7.0227921 | AV31: 7.0157487 | AW31: 7.0058416 | AX31: 6.9970765 | AY31: 6.989295
A32: 3 | E32: Diversified portfolio | F32: Low LR | G32: 3500 | H32: 3500 | I32: 3500 | J32: 3500 | K32: 3500 | L32: 3500 | M32: 3500 | N32: 3500 | Q32: Diversified portfolio | R32: Low LR | S32: 17.5 | T32: 17.5 | U32: 17.5 | V32: 17.5 | W32: 17.5 | X32: 17.5 | Y32: 17.5 | Z32: 17.5 | AB32: 52 | AC32: Lake medium scale expensive hydroelectricity 1-10 MW | AD32: Diversified portfolio | AE32: Ref LR | AF32: 4000 | AG32: 4000 | AH32: 3990 | AI32: 3980 | AJ32: 3980 | AK32: 3970 | AL32: 3970 | AM32: 3970 | AO32: Lake medium scale expensive hydroelectricity 1-10 MW | AP32: Diversified portfolio | AQ32: Ref LR | AR32: 20 | AS32: 19.991027 | AT32: 19.954356 | AU32: 19.922814 | AV32: 19.902833 | AW32: 19.874728 | AX32: 19.849862 | AY32: 19.827787
AB33: 67 | AC33: Lake very small cheap hydroelectricity <1 MW | AD33: Diversified portfolio | AE33: Ref LR | AF33: 1740 | AG33: 1740 | AH33: 1740 | AI33: 1730 | AJ33: 1730 | AK33: 1730 | AL33: 1730 | AM33: 1730 | AO33: Lake very small cheap hydroelectricity <1 MW | AP33: Diversified portfolio | AQ33: Ref LR | AR33: 17.4 | AS33: 17.392194 | AT33: 17.36029 | AU33: 17.332849 | AV33: 17.315465 | AW33: 17.291013 | AX33: 17.26938 | AY33: 17.250175
A34: 0 | G34: 2015 | H34: 2020 | I34: 2025 | J34: 2030 | K34: 2035 | L34: 2040 | M34: 2045 | N34: 2050 | S34: 2015 | T34: 2020 | U34: 2025 | V34: 2030 | W34: 2035 | X34: 2040 | Y34: 2045 | Z34: 2050 | AB34: 82 | AC34: Lake very small expensive hydroelectricity <1 MW | AD34: Diversified portfolio | AE34: Ref LR | AF34: 5000 | AG34: 5000 | AH34: 4990 | AI34: 4980 | AJ34: 4980 | AK34: 4970 | AL34: 4960 | AM34: 4960 | AO34: Lake very small expensive hydroelectricity <1 MW | AP34: Diversified portfolio | AQ34: Ref LR | AR34: 50 | AS34: 49.977568 | AT34: 49.88589 | AU34: 49.807036 | AV34: 49.757083 | AW34: 49.68682 | AX34: 49.624656 | AY34: 49.569468
A35: 1 | B35: Hydro_medium_cheap | C35: G24 | D35: Lake medium scale cheap hydroelectricity 1-10 MW | E35: ProRES | F35: Ref LR | G35: 1410 | H35: 1410 | I35: 1410 | J35: 1410 | K35: 1410 | L35: 1410 | M35: 1410 | N35: 1410 | P35: Lake medium scale cheap hydroelectricity 1-10 MW | Q35: ProRES | R35: Ref LR | S35: 7.05 | T35: 7.0412661 | U35: 7.0375253 | V35: 7.0351553 | W35: 7.0331901 | X35: 7.0316852 | Y35: 7.02984 | Z35: 7.027678 | AB35: 97 | AC35: Run of River hydroelectricity | AD35: Diversified portfolio | AE35: Ref LR | AF35: 3000 | AG35: 3000 | AH35: 2990 | AI35: 2990 | AJ35: 2990 | AK35: 2980 | AL35: 2980 | AM35: 2970 | AO35: Run of River hydroelectricity | AP35: Diversified portfolio | AQ35: Ref LR | AR35: 15 | AS35: 14.99327 | AT35: 14.965767 | AU35: 14.942111 | AV35: 14.927125 | AW35: 14.906046 | AX35: 14.887397 | AY35: 14.87084
A36: 2 | C36: -1 | E36: Baseline | F36: Ref LR | G36: 1410 | H36: 1410 | I36: 1410 | J36: 1410 | K36: 1410 | L36: 1410 | M36: 1400 | N36: 1400 | Q36: Baseline | R36: Ref LR | S36: 7.05 | T36: 7.0477673 | U36: 7.0428914 | V36: 7.0378806 | W36: 7.0328088 | X36: 7.0270835 | Y36: 7.0220422 | Z36: 7.0178243 | AB36: 112
A37: 3 | E37: Diversified portfolio | F37: Ref LR | G37: 1410 | H37: 1410 | I37: 1410 | J37: 1400 | K37: 1400 | L37: 1400 | M37: 1400 | N37: 1400 | Q37: Diversified portfolio | R37: Ref LR | S37: 7.05 | T37: 7.0468371 | U37: 7.0339104 | V37: 7.0227921 | W37: 7.0157487 | X37: 7.0058416 | Y37: 6.9970765 | Z37: 6.989295 | AB37: 127
A39: 0 | G39: 2015 | H39: 2020 | I39: 2025 | J39: 2030 | K39: 2035 | L39: 2040 | M39: 2045 | N39: 2050 | S39: 2015 | T39: 2020 | U39: 2025 | V39: 2030 | W39: 2035 | X39: 2040 | Y39: 2045 | Z39: 2050
A40: 1 | B40: Hydro_medium_cheap | C40: G31 | D40: Lake medium scale cheap hydroelectricity 1-10 MW | E40: ProRES | F40: High LR | G40: 1410 | H40: 1410 | I40: 1400 | J40: 1400 | K40: 1400 | L40: 1400 | M40: 1400 | N40: 1400 | P40: Lake medium scale cheap hydroelectricity 1-10 MW | Q40: ProRES | R40: High LR | S40: 7.05 | T40: 7.0324546 | U40: 7.0249464 | V40: 7.0201916 | W40: 7.0162502 | X40: 7.0132327 | Y40: 7.0095339 | Z40: 7.0052011 | AF40: 2015 | AG40: 2020 | AH40: 2025 | AI40: 2030 | AJ40: 2035 | AK40: 2040 | AL40: 2045 | AM40: 2050 | AR40: 2015 | AS40: 2020 | AT40: 2025 | AU40: 2030 | AV40: 2035 | AW40: 2040 | AX40: 2045 | AY40: 2050
A41: 2 | C41: -1 | E41: Baseline | F41: High LR | G41: 1410 | H41: 1410 | I41: 1410 | J41: 1410 | K41: 1400 | L41: 1400 | M41: 1400 | N41: 1400 | Q41: Baseline | R41: High LR | S41: 7.05 | T41: 7.0455127 | U41: 7.0357179 | V41: 7.0256594 | W41: 7.0154856 | X41: 7.00401 | Y41: 6.9939132 | Z41: 6.9854711 | AB41: 10 | AC41: Lake large scale cheap hydroelectricity > 10 MW | AD41: ProRES | AE41: High LR | AF41: 1090 | AG41: 1090 | AH41: 1090 | AI41: 1090 | AJ41: 1080 | AK41: 1080 | AL41: 1080 | AM41: 1080 | AO41: Lake large scale cheap hydroelectricity > 10 MW | AP41: ProRES | AQ41: High LR | AR41: 5.45 | AS41: 5.4364365 | AT41: 5.4306323 | AU41: 5.4269567 | AV41: 5.4239097 | AW41: 5.4215771 | AX41: 5.4187177 | AY41: 5.4153682
...

Sheet Biomass
F1: CAPEX (Eur/kW) | R1: OPEX Eur/kW/Year | AB1: Summary | AE1: CAPEX (Eur/kW) | AP1: OPEX Eur/kW/Year | BC1: CAPEX (Eur/kW) | BN1: OPEX Eur/kW/Year | BY1: CAPEX (Eur/kW) | CI1: OPEX Eur/kW/Year
B2: Page Name | C2: Upper left cell | E2: 0 | F2: 1 | G2: 2 | H2: 3 | I2: 4 | J2: 5 | K2: 6 | L2: 7 | M2: 8 | N2: 9 | Q2: 18 | R2: 19 | S2: 20 | T2: 21 | U2: 22 | V2: 23 | W2: 24 | X2: 25 | Y2: 26 | Z2: 27 | AC2: 0 | AD2: 1 | AE2: 2 | AF2: 3 | AG2: 4 | AH2: 5 | AI2: 6 | AJ2: 7 | AK2: 8 | AL2: 9 | AM2: 10 | AR2: 15 | AS2: 16 | AT2: 17 | AU2: 18 | AV2: 19 | AW2: 20 | AX2: 21 | AY2: 22
BA3: MAX | BM3: MAX | BW3: MAX
A4: 0 | G4: 2015 | H4: 2020 | I4: 2025 | J4: 2030 | K4: 2035 | L4: 2040 | M4: 2045 | N4: 2050 | S4: 2015 | T4: 2020 | U4: 2025 | V4: 2030 | W4: 2035 | X4: 2040 | Y4: 2045 | Z4: 2050 | AF4: 2015 | AG4: 2020 | AH4: 2025 | AI4: 2030 | AJ4: 2035 | AK4: 2040 | AL4: 2045 | AM4: 2050 | AR4: 2015 | AS4: 2020 | AT4: 2025 | AU4: 2030 | AV4: 2035 | AW4: 2040 | AX4: 2045 | AY4: 2050 | BC4: 2015 | BD4: 2020 | BE4: 2025 | BF4: 2030 | BG4: 2035 | BH4: 2040 | BI4: 2045 | BJ4: 2050 | BN4: 2015 | BO4: 2020 | BP4: 2025 | BQ4: 2030 | BR4: 2035 | BS4: 2040 | BT4: 2045 | BU4: 2050 | BY4: 2015 | BZ4: 2020 | CA4: 2025 | CB4: 2030 | CC4: 2035 | CD4: 2040 | CE4: 2045 | CF4: 2050 | CG4: Reduction | CJ4: 2015 | CK4: 2020 | CL4: 2025 | CM4: 2030 | CN4: 2035 | CO4: 2040 | CP4: 2045 | CQ4: 2050
A5: 1 | B5: Subcritical | C5: G24 | D5: BiomassSubcirical | E5: ProRES | F5: Ref LR | G5: 3600 | H5: 3380 | I5: 3270 | J5: 3190 | K5: 3140 | L5: 3100 | M5: 3030 | N5: 2980 | P5: BiomassSubcirical | Q5: ProRES | R5: Ref LR | S5: 72 | T5: 67.680518 | U5: 65.309715 | V5: 63.785692 | W5: 62.820864 | X5: 61.939563 | Y5: 60.644861 | Z5: 59.685434 | AB5: 5 | AC5: BiomassSubcirical | AD5: ProRES | AE5: Ref LR | AF5: 3600 | AG5: 3380 | AH5: 3270 | AI5: 3190 | AJ5: 3140 | AK5: 3100 | AL5: 3030 | AM5: 2980 | AO5: BiomassSubcirical | AP5: ProRES | AQ5: Ref LR | AR5: 72 | AS5: 67.680518 | AT5: 65.309715 | AU5: 63.785692 | AV5: 62.820864 | AW5: 61.939563 | AX5: 60.644861 | AY5: 59.685434 | BA5: ProRES | BC5: 5300 | BD5: 5170 | BE5: 5100 | BF5: 5050 | BG5: 5020 | BH5: 4990 | BI5: 4950 | BJ5: 4920 | BM5: ProRES | BN5: 124 | BO5: 121.01493 | BP5: 119.32724 | BQ5: 118.22265 | BR5: 117.51506 | BS5: 116.86295 | BT5: 115.89467 | BU5: 115.16903 | BW5: BiomassSubcirical | BY5: 3600 | BZ5: 3520 | CA5: 3490 | CB5: 3480 | CC5: 3470 | CD5: 3450 | CE5: 3420 | CF5: 3400 | CG5: 0.055555556 | CI5: BiomassSubcirical | CK5: 72 | CL5: 70.395234 | CM5: 69.841764 | CN5: 69.62294 | CO5: 69.376489 | CP5: 69.018004 | CQ5: 68.382494
A6: 2 | C6: -1 | E6: Baseline | F6: Ref LR | G6: 3600 | H6: 3400 | I6: 3330 | J6: 3310 | K6: 3280 | L6: 3230 | M6: 3160 | N6: 3120 | Q6: Baseline | R6: Ref LR | S6: 72 | T6: 67.995206 | U6: 66.64609 | V6: 66.11721 | W6: 65.524614 | X6: 64.668392 | Y6: 63.167257 | Z6: 62.337865 | AB6: 20 | AC6: BiomassGasified | AD6: ProRES | AE6: Ref LR | AF6: 5300 | AG6: 4980 | AH6: 4810 | AI6: 4700 | AJ6: 4620 | AK6: 4560 | AL6: 4460 | AM6: 4390 | AO6: BiomassGasified | AP6: ProRES | AQ6: Ref LR | AR6: 106 | AS6: 99.640762 | AT6: 96.150414 | AU6: 93.906714 | AV6: 92.486272 | AW6: 91.188801 | AX6: 89.282712 | AY6: 87.870222 | BA6: Baseline | BC6: 5300 | BD6: 5180 | BE6: 5140 | BF6: 5130 | BG6: 5110 | BH6: 5080 | BI6: 5030 | BJ6: 5010 | BM6: Baseline | BN6: 124 | BO6: 121.23624 | BP6: 120.28304 | BQ6: 119.90617 | BR6: 119.48173 | BS6: 118.86434 | BT6: 117.76985 | BU6: 117.15836 | BW6: BiomassGasified | BY6: 5300 | BZ6: 5180 | CA6: 5140 | CB6: 5130 | CC6: 5110 | CD6: 5080 | CE6: 5030 | CF6: 5010 | CI6: BiomassGasified | CK6: 106 | CL6: 103.63743 | CM6: 102.8226 | CN6: 102.50044 | CO6: 102.13761 | CP6: 101.60984 | CQ6: 100.67423
