Workbook

Sheet INS
A1: Trans - Insert
B2: ~TFM_INS
B3: TimeSlice | C3: LimType | D3: Attribute | E3: Year | F3: Cset_Set | G3: Cset_CN | H3: Cset_CD | I3: AT | J3: BE | K3: BG | L3: CH | M3: CY | N3: CZ | O3: DE | P3: DK | Q3: EE | R3: EL | S3: ES | T3: FI | U3: FR | V3: HR | W3: HU | X3: IE | Y3: IS | Z3: IT | AA3: LT | AB3: LU | AC3: LV | AD3: Mt | AE3: NL | AF3: NO | AG3: PL | AH3: PT | AI3: RO | AJ3: SE | AK3: SI | AL3: SK | AM3: UK

Sheet UPD
A1: Trans - Update
B2: ~TFM_UPD
B3: TimeSlice | C3: LimType | D3: Attribute | E3: Year | F3: Cset_Set | G3: Cset_CN | H3: AT | I3: BE | J3: BG | K3: CH | L3: CY | M3: CZ | N3: DE | O3: DK | P3: EE | Q3: EL | R3: ES | S3: FI | T3: FR | U3: HR | V3: HU | W3: IE | X3: IS | Y3: IT | Z3: LT | AA3: LU | AB3: LV | AC3: Mt | AD3: NL | AE3: NO | AF3: PL | AG3: PT | AH3: RO | AI3: SE | AJ3: SI | AK3: SK | AL3: UK
D4: COM_PROJ | E4: 2040 | F4: DEM | G4: R_Flat | H4: 1802.45 | I4: 1239.95 | J4: 975.2 | K4: 2249.3 | L4: 113.40765 | M4: 2715.05 | N4: 22561.062 | O4: 1468.375 | P4: 775.0625 | Q4: 2211.8438 | R4: 9054.2 | S4: 1332.3457 | T4: 11137.575 | U4: 730.4125 | V4: 2171.1562 | W4: 260.96875 | X4: 102.51535 | Y4: 22392.825 | Z4: 1171.3625 | AA4: 100.175 | AB4: 863.36875 | AC4: 31.90625 | AD4: 2371.4375 | AE4: 1609.95 | AF4: 10683.775 | AG4: 617.84375 | AH4: 3085.9125 | AI4: 3402.625 | AJ4: 668.8125 | AK4: 764.775 | AL4: 4736.45
D5: COM_PROJ | E5: 2050 | F5: DEM | G5: R_Flat | H5: 1951.35 | I5: 1353.15 | J5: 1040.05 | K5: 2446.75 | L5: 124.7076 | M5: 2971.2875 | N5: 24253.25 | O5: 1611.6875 | P5: 848.625 | Q5: 2331.425 | R5: 9760.7 | S5: 1439.7222 | T5: 11899 | U5: 805.15 | V5: 2409.125 | W5: 297.625 | X5: 111.923 | Y5: 23765.75 | Z5: 1252.9 | AA5: 112.05 | AB5: 919.0875 | AC5: 36.8125 | AD5: 2594.125 | AE5: 1778.2 | AF5: 11673.15 | AG5: 657.4375 | AH5: 3367.95 | AI5: 3803.85 | AJ5: 737.75 | AK5: 843.3125 | AL5: 5130.65
D6: COM_PROJ | E6: 2060 | F6: DEM | G6: R_Flat | H6: 2116.957 | I6: 1481.7252 | J6: 1113.7649 | K6: 2679.5722 | L6: 137.69798 | M6: 3268.6504 | N6: 26191.564 | O6: 1780.7864 | P6: 938.70251 | Q6: 2459.6534 | R6: 10543.137 | S6: 1561.5796 | T6: 12791.89 | U6: 889.67332 | V6: 2686.0468 | W6: 340.55515 | X6: 121.94596 | Y6: 25311.42 | Z6: 1347.682 | AA6: 126.41538 | AB6: 981.90283 | AC6: 42.071429 | AD6: 2854.4249 | AE6: 1974.8673 | AF6: 12783.932 | AG6: 699.7288 | AH6: 3688.303 | AI6: 4279.6172 | AJ6: 817.99649 | AK6: 936.03272 | AL6: 5592.3308
D7: COM_PROJ | E7: 2070 | F7: DEM | G7: R_Flat | H7: 2296.6186 | I7: 1622.5174 | J7: 1192.7044 | K7: 2934.5488 | L7: 152.04151 | M7: 3595.773 | N7: 28284.788 | O7: 1967.6272 | P7: 1038.3413 | Q7: 2594.9343 | R7: 11388.295 | S7: 1693.7509 | T7: 13751.782 | U7: 983.06976 | V7: 2994.7999 | W7: 389.67765 | X7: 132.86649 | Y7: 26957.618 | Z7: 1449.6343 | AA7: 142.62249 | AB7: 1049.0113 | AC7: 48.081633 | AD7: 3140.8438 | AE7: 2193.2858 | AF7: 14000.413 | AG7: 744.7406 | AH7: 4039.1275 | AI7: 4814.891 | AJ7: 906.97155 | AK7: 1038.9473 | AL7: 6095.5559
D9: COM_PROJ | E9: 2040 | F9: DEM | G9: R_DetH | H9: 1030.8877 | I9: 1106.6086 | J9: 575.86004 | K9: 901.11793 | L9: 112.80936 | M9: 1072.8374 | N9: 6297.5105 | O9: 955.27342 | P9: 89.612757 | Q9: 639.52491 | R9: 991.60809 | S9: 734.86325 | T9: 6110.0413 | U9: 605.05024 | V9: 1234.4091 | W9: 488.62307 | X9: 45.097682 | Y9: 1910.094 | Z9: 208.30268 | AA9: 91.753194 | AB9: 147.9384 | AC9: 5.4655055 | AD9: 638.68276 | AE9: 499.38081 | AF9: 3122.7046 | AG9: 666.68511 | AH9: 2058.2699 | AI9: 1311.1139 | AJ9: 188.9527 | AK9: 446.59806 | AL9: 4177.2667
D10: COM_PROJ | E10: 2050 | F10: DEM | G10: R_DetH | H10: 1086.8902 | I10: 1206.204 | J10: 592.99481 | K10: 963.05337 | L10: 120.42158 | M10: 1139.4524 | N10: 6205.4976 | O10: 991.10891 | P10: 87.928849 | Q10: 646.20479 | R10: 1046.4675 | S10: 755.3852 | T10: 6362.0577 | U10: 626.51153 | V10: 1211.6204 | W10: 519.60875 | X10: 47.782265 | Y10: 1948.4511 | Z10: 204.1122 | AA10: 107.51642 | AB10: 145.16365 | AC10: 6.2766693 | AD10: 671.43838 | AE10: 534.48544 | AF10: 3221.5674 | AG10: 772.80027 | AH10: 2148.3785 | AI10: 1414.181 | AJ10: 196.66931 | AK10: 473.20609 | AL10: 4489.9202
D11: COM_PROJ | E11: 2070 | F11: DEM | G11: R_DetH | H11: 1086.8899 | I11: 1206.2037 | J11: 592.99449 | K11: 963.05307 | L11: 120.42127 | M11: 1139.4521 | N11: 6205.4973 | O11: 991.10859 | P11: 84.680545 | Q11: 646.20448 | R11: 1046.4672 | S11: 755.38489 | T11: 6362.0574 | U11: 626.51121 | V11: 1184.166 | W11: 519.60847 | X11: 47.781957 | Y11: 1948.4508 | Z11: 196.04148 | AA11: 107.51614 | AB11: 139.81082 | AC11: 6.2763873 | AD11: 671.43808 | AE11: 534.48516 | AF11: 3221.5671 | AG11: 772.79997 | AH11: 2148.3782 | AI11: 1414.1807 | AJ11: 196.66899 | AK11: 473.20578 | AL11: 4489.9199
D12: COM_PROJ | E12: 2040 | F12: DEM | G12: R_SDetH | H12: 477.72853 | I12: 1846.3361 | J12: 312.96749 | K12: 1010.918 | L12: 115.20957 | M12: 635.91578 | N12: 6583.761 | O12: 508.58698 | P12: 41.467684 | Q12: 361.60061 | R12: 2198.3075 | S12: 555.429 | T12: 5432.6838 | U12: 216.53349 | V12: 454.27785 | W12: 734.96984 | X12: 42.125657 | Y12: 3396.9284 | Z12: 105.49389 | AA12: 118.72458 | AB12: 58.925358 | AC12: 69.835451 | AD12: 3372.7964 | AE12: 392.22377 | AF12: 1171.8125 | AG12: 538.19226 | AH12: 591.1148 | AI12: 628.99793 | AJ12: 62.842484 | AK12: 132.90554 | AL12: 14502.456
D13: COM_PROJ | E13: 2050 | F13: DEM | G13: R_SDetH | H13: 503.6812 | I13: 2012.5073 | J13: 322.28014 | K13: 1080.4003 | L13: 122.98385 | M13: 675.40155 | N13: 6487.5658 | O13: 527.66604 | P13: 40.645754 | Q13: 365.37781 | R13: 2319.9256 | S13: 570.94021 | T13: 5656.7619 | U13: 224.21432 | V13: 445.27457 | W13: 781.57738 | X13: 44.63346 | Y13: 3465.1429 | Z13: 103.4029 | AA13: 139.12153 | AB13: 57.757401 | AC13: 80.196514 | AD13: 3545.773 | AE13: 419.79583 | AF13: 1208.9117 | AG13: 623.85559 | AH13: 616.99349 | AI13: 678.44391 | AJ13: 65.409245 | AK13: 140.82433 | AL13: 15587.912
D14: COM_PROJ | E14: 2070 | F14: DEM | G14: R_SDetH | H14: 503.6808 | I14: 2012.5069 | J14: 322.27973 | K14: 1080.3999 | L14: 122.98346 | M14: 675.40115 | N14: 6487.5654 | O14: 527.66563 | P14: 39.05045 | Q14: 365.37741 | R14: 2319.9252 | S14: 570.93982 | T14: 5656.7615 | U14: 224.21392 | V14: 437.34369 | W14: 781.577 | X14: 44.633057 | Y14: 3465.1425 | Z14: 99.344438 | AA14: 139.12115 | AB14: 55.49048 | AC14: 80.196122 | AD14: 3545.7726 | AE14: 419.79546 | AF14: 1208.9113 | AG14: 623.85522 | AH14: 616.99308 | AI14: 678.44352 | AJ14: 65.408839 | AK14: 140.82393 | AL14: 15587.912
B16: ~TFM_UPD
B17: TimeSlice | C17: LimType | D17: Attribute | E17: Year | F17: Cset_Set | G17: Cset_CN | H17: AT | I17: BE | J17: BG | K17: CH | L17: CY | M17: CZ | N17: DE | O17: DK | P17: EE | Q17: EL | R17: ES | S17: FI | T17: FR | U17: HR | V17: HU | W17: IE | X17: IS | Y17: IT | Z17: LT | AA17: LU | AB17: LV | AC17: Mt | AD17: NL | AE17: NO | AF17: PL | AG17: PT | AH17: RO | AI17: SE | AJ17: SI | AK17: SK | AL17: UK
D18: COM_PROJ | E18: 2040 | F18: DEM | G18: RR_Flat | H18: 13.845 | I18: 10.395 | J18: 6.12 | K18: 18.13 | L18: 1.040765 | M18: 23.405 | N18: 157.40625 | O18: 13.0375 | P18: 6.70625 | Q18: 11.284375 | R18: 65.52 | S18: 9.934575 | T18: 71.3575 | U18: 6.64125 | V18: 21.515625 | W18: 3.196875 | X18: 0.851535 | Y18: 129.4825 | Z18: 7.63625 | AA18: 1.0175 | AB18: 5.236875 | AC18: 0.490625 | AD18: 20.34375 | AE18: 15.295 | AF18: 90.5775 | AG18: 3.584375 | AH18: 25.89125 | AI18: 35.8625 | AJ18: 6.28125 | AK18: 7.0775 | AL18: 36.445
D19: COM_PROJ | E19: 2050 | F19: DEM | G19: RR_Flat | H19: 14.89 | I19: 11.32 | J19: 6.485 | K19: 19.745 | L19: 1.129995 | M19: 25.62375 | N19: 169.21875 | O19: 14.33125 | P19: 7.35625 | Q19: 11.958125 | R19: 70.65 | S19: 10.737645 | T19: 76.1425 | U19: 7.47375 | V19: 23.796875 | W19: 3.665625 | X19: 0.940765 | Y19: 137.2925 | Z19: 8.15375 | AA19: 1.1875 | AB19: 5.571875 | AC19: 0.490625 | AD19: 22.26875 | AE19: 16.825 | AF19: 98.9375 | AG19: 3.959375 | AH19: 28.20375 | AI19: 40.1225 | AJ19: 6.89375 | AK19: 7.85375 | AL19: 39.42
D20: COM_PROJ | E20: 2060 | F20: DEM | G20: RR_Flat | H20: 16.560697 | I20: 12.857517 | J20: 7.3714884 | K20: 23.282223 | L20: 1.2990375 | M20: 29.736289 | N20: 193.8314 | O20: 16.909891 | P20: 9.0077514 | Q20: 12.822837 | R20: 78.243668 | S20: 12.185736 | T20: 89.289005 | U20: 8.4523323 | V20: 27.692178 | W20: 4.2930152 | X20: 1.0022955 | Y20: 154.56704 | Z20: 9.4782033 | AA20: 1.4365385 | AB20: 6.2815333 | AC20: 0.52589286 | AD20: 26.029989 | AE20: 19.666728 | AF20: 111.07822 | AG20: 4.2291301 | AH20: 32.035304 | AI20: 47.576717 | AJ20: 8.0246491 | AK20: 9.2720223 | AL20: 46.168081
D21: COM_PROJ | E21: 2070 | F21: DEM | G21: RR_Flat | H21: 17.966168 | I21: 14.079228 | J21: 7.8939521 | K21: 25.49766 | L21: 1.4343539 | M21: 32.712262 | N21: 209.32236 | O21: 18.684083 | P21: 9.9638814 | Q21: 13.528094 | R21: 84.515832 | S21: 13.217131 | T21: 95.98917 | U21: 9.3396442 | V21: 30.875312 | W21: 4.9122501 | X21: 1.0920533 | Y21: 164.61973 | Z21: 10.195231 | AA21: 1.6207101 | AB21: 6.7108467 | AC21: 0.60102041 | AD21: 28.641892 | AE21: 21.84185 | AF21: 121.64809 | AG21: 4.5011794 | AH21: 35.082442 | AI21: 53.527382 | AJ21: 8.8975057 | AK21: 10.291459 | AL21: 50.32251
D27: COM_PROJ | E27: 2040 | F27: DEM | G27: RR_DetH | H27: 5.6015 | I27: 9.962 | J27: 1.717 | K27: 6.1965 | L27: 0.765 | M27: 6.664 | N27: 3.587 | O27: 0.6715 | P27: 5.4825 | Q27: 2.0485 | R27: 25.2025 | S27: 2.142 | T27: 3.1025 | U27: 0.272 | V27: 3.8335 | W27: 1.5725 | X27: 0.085 | Y27: 3.2725 | Z27: 3.5105 | AA27: 9.8855 | AB27: 10.608 | AC27: 9.0112329 | AD27: 10.3105 | AE27: 0.7735 | AF27: 2.6605 | AG27: 31.263
D28: COM_PROJ | E28: 2050 | F28: DEM | G28: RR_DetH | H28: 5.6015 | I28: 9.962 | J28: 1.717 | K28: 6.1965 | L28: 0.765 | M28: 6.664 | N28: 3.587 | O28: 0.6715 | P28: 5.4825 | Q28: 2.0485 | R28: 25.2025 | S28: 2.142 | T28: 3.1025 | U28: 0.272 | V28: 3.8335 | W28: 1.5725 | X28: 0.085 | Y28: 3.2725 | Z28: 3.5105 | AA28: 9.8855 | AB28: 10.608 | AC28: 9.0143712 | AD28: 10.3105 | AE28: 0.7735 | AF28: 2.6605 | AG28: 31.263
D29: COM_PROJ | E29: 2070 | F29: DEM | G29: RR_DetH | H29: 5.6015 | I29: 9.962 | J29: 1.717 | K29: 6.1965 | L29: 0.765 | M29: 6.664 | N29: 3.587 | O29: 0.6715 | P29: 5.4825 | Q29: 2.0485 | R29: 25.2025 | S29: 2.142 | T29: 3.1025 | U29: 0.272 | V29: 3.8335 | W29: 1.5725 | X29: 0.085 | Y29: 3.2725 | Z29: 3.5105 | AA29: 9.8855 | AB29: 10.608 | AC29: 9.01 | AD29: 10.3105 | AE29: 0.7735 | AF29: 2.6605 | AG29: 31.263
D30: COM_PROJ | E30: 2040 | F30: DEM | G30: RR_SDetH | H30: 2.5952056 | I30: 16.617041 | J30: 0.9312056 | K30: 6.9481516 | L30: 0.7773845 | M30: 3.948511 | N30: 1.9078369 | O30: 0.37765415 | P30: 12.161672 | Q30: 1.5510477 | R30: 22.407479 | S30: 0.76803025 | T30: 4.6606877 | U30: 0.2507381 | V30: 6.821182 | W30: 2.0396609 | X30: 1.0360676 | Y30: 17.297466 | Z30: 2.7571552 | AA30: 3.709808 | AB30: 8.5663085 | AC30: 2.5911188 | AD30: 4.944541 | AE30: 0.256632 | AF30: 0.7918328 | AG30: 108.54509
D31: COM_PROJ | E31: 2050 | F31: DEM | G31: RR_SDetH | H31: 2.5952056 | I31: 16.617041 | J31: 0.9312056 | K31: 6.9481516 | L31: 0.7773845 | M31: 3.948511 | N31: 1.9078369 | O31: 0.37765415 | P31: 12.161672 | Q31: 1.5510477 | R31: 22.407479 | S31: 0.76803025 | T31: 4.6606877 | U31: 0.2507381 | V31: 6.821182 | W31: 2.0396609 | X31: 1.0360676 | Y31: 17.297466 | Z31: 2.7571552 | AA31: 3.709808 | AB31: 8.5663085 | AC31: 2.5960197 | AD31: 4.944541 | AE31: 0.256632 | AF31: 0.7918328 | AG31: 108.54509
D32: COM_PROJ | E32: 2070 | F32: DEM | G32: RR_SDetH | H32: 2.5952056 | I32: 16.617041 | J32: 0.9312056 | K32: 6.9481516 | L32: 0.7773845 | M32: 3.948511 | N32: 1.9078369 | O32: 0.37765415 | P32: 12.161672 | Q32: 1.5510477 | R32: 22.407479 | S32: 0.76803025 | T32: 4.6606877 | U32: 0.2507381 | V32: 6.821182 | W32: 2.0396609 | X32: 1.0360676 | Y32: 17.297466 | Z32: 2.7571552 | AA32: 3.709808 | AB32: 8.5663085 | AC32: 2.5877969 | AD32: 4.944541 | AE32: 0.256632 | AF32: 0.7918328 | AG32: 108.54509
B40: Pset_PN | C40: Attribute | D40: LimType | E40: Year | F40: AT | G40: BE | H40: BG | I40: CH | J40: CY | K40: CZ | L40: DK | M40: EL | N40: ES | O40: FI | P40: FR | Q40: HR | R40: IE | S40: IS | T40: IT | U40: LU | V40: MT | W40: NL | X40: NO | Y40: PL | Z40: PT | AA40: RO | AB40: SE | AC40: SI | AD40: SK | AE40: UK
B41: ICNBNEFLAT00 | C41: BNDACT | D41: fx | E41: 2020 | F41: 9.528627 | G41: 11.16393 | H41: 2.53917 | I41: 14.2715 | J41: 0.7068 | K41: 16.8484 | L41: 4.508746 | M41: 1.81031 | N41: 49.3049 | O41: 3.37753 | P41: 43.28228 | Q41: 2.00458 | R41: 1.159933 | S41: 0.486652 | T41: 36.4271 | U41: 2.41064 | V41: 0.436729 | W41: 10.47769 | X41: 10.25912 | Y41: 23.5566 | Z41: 15.679 | AA41: 10.336 | AB41: 24.964 | AC41: 2.1473 | AD41: 4.2102 | AE41: 37.9142
B42: ICNBNEFLAT00 | C42: BNDACT | D42: fx | E42: 2030 | F42: 9.528627 | G42: 11.16393 | H42: 2.53917 | I42: 14.2715 | J42: 0.7068 | K42: 16.8484 | L42: 4.508746 | M42: 1.81031 | N42: 49.3049 | O42: 3.37753 | P42: 43.28228 | Q42: 2.00458 | R42: 1.159933 | S42: 0.486652 | T42: 36.4271 | U42: 2.41064 | V42: 0.436729 | W42: 10.47769 | X42: 10.25912 | Y42: 23.5566 | Z42: 15.679 | AA42: 10.336 | AB42: 24.964 | AC42: 2.1473 | AD42: 4.2102 | AE42: 37.9142
B43: ICNBNEFLAT00 | C43: BNDACT | D43: fx | E43: 2040 | F43: 8.0993329 | G43: 9.4893405 | H43: 2.1582936 | I43: 12.130741 | J43: 0.60077915 | K43: 14.321131 | L43: 3.8324341 | M43: 1.5387635 | N43: 41.909182 | O43: 2.8708997 | P43: 36.789938 | Q43: 1.7038904 | R43: 0.98594305 | S43: 0.4136542 | T43: 30.963052 | U43: 2.0490449 | V43: 0.37121965 | W43: 8.9060365 | X43: 8.720252 | Y43: 20.023101 | Z43: 13.326954 | AA43: 8.7855235 | AB43: 21.219391 | AC43: 1.8252347 | AD43: 3.5786496 | AE43: 32.227096
B44: ICNBNEFLAT00 | C44: BNDACT | D44: fx | E44: 2050 | F44: 8.0993329 | G44: 9.4893405 | H44: 2.1582936 | I44: 12.130741 | J44: 0.60077915 | K44: 14.321131 | L44: 3.8324341 | M44: 1.5387635 | N44: 41.909182 | O44: 2.8708997 | P44: 36.789938 | Q44: 1.7038904 | R44: 0.98594305 | S44: 0.4136542 | T44: 30.963052 | U44: 2.0490449 | V44: 0.37121965 | W44: 8.9060365 | X44: 8.720252 | Y44: 20.023101 | Z44: 13.326954 | AA44: 8.7855235 | AB44: 21.219391 | AC44: 1.8252347 | AD44: 3.5786496 | AE44: 32.227096
B45: ICNBNEFLAT00 | C45: BNDACT | D45: fx | E45: 2070 | F45: 8.0993329 | G45: 9.4893405 | H45: 2.1582936 | I45: 12.130741 | J45: 0.60077915 | K45: 14.321131 | L45: 3.8324341 | M45: 1.5387635 | N45: 41.909182 | O45: 2.8708997 | P45: 36.789938 | Q45: 1.7038904 | R45: 0.98594305 | S45: 0.4136542 | T45: 30.963052 | U45: 2.0490449 | V45: 0.37121965 | W45: 8.9060365 | X45: 8.720252 | Y45: 20.023101 | Z45: 13.326954 | AA45: 8.7855235 | AB45: 21.219391 | AC45: 1.8252347 | AD45: 3.5786496 | AE45: 32.227096

Sheet UCT1
A1: UC - Each Region/Period
B2: ~UC_Sets: R_E: AllRegions
B3: ~UC_Sets: T_E:
J4: ~UC_T
B5: UC_N | C5: Pset_Set | D5: Pset_PN | E5: Pset_CI | F5: Pset_CO | G5: Cset_CN | H5: Attribute | I5: Year | J5: LimType | K5: UC_CAP | L5: UC_FLO | M5: AllRegions | N5: UC_RHSRTS | O5: UC_Desc

Sheet UCT2
A1: UC - Each Region/All Periods
B2: ~UC_Sets: R_E: AllRegions
B3: ~UC_Sets: T_S:
J4: ~UC_T
B5: UC_N | C5: Pset_Set | D5: Pset_PN | E5: Pset_CI | F5: Pset_CO | G5: Cset_CN | H5: Attribute | I5: Year | J5: LimType | K5: UC_CAP | L5: UC_FLO | M5: AllRegions | N5: UC_RHSR | O5: UC_Desc

Sheet UCT3
A1: UC - All Regions/Each Period
B2: ~UC_Sets: R_S: AllRegions
B3: ~UC_Sets: T_E:
J4: ~UC_T
B5: UC_N | C5: Pset_Set | D5: Pset_PN | E5: Pset_CI | F5: Pset_CO | G5: Cset_CN | H5: Attribute | I5: Year | J5: LimType | K5: UC_CAP | L5: UC_FLO | M5: AllRegions | N5: UC_RHSTS | O5: UC_Desc

Sheet UCT4
A1: UC - All Regions/Periods
B2: ~UC_Sets: R_S: AllRegions
B3: ~UC_Sets: T_S:
J4: ~UC_T
B5: UC_N | C5: Pset_Set | D5: Pset_PN | E5: Pset_CI | F5: Pset_CO | G5: Cset_CN | H5: Attribute | I5: Year | J5: LimType | K5: UC_CAP | L5: UC_FLO | M5: AllRegions | N5: UC_RHS | O5: UC_Desc

Sheet Sheet6

Sheet Sheet7

Sheet data
A1: NEW stock in JET model in 000dwellings
C2: AT | D2: BE | E2: BG | F2: CH | G2: CY | H2: CZ | I2: DE | J2: DK | K2: EE | L2: EL | M2: ES | N2: FI | O2: FR | P2: HR | Q2: HU | R2: IE | S2: IS | T2: IT | U2: LT | V2: LU | W2: LV | X2: Mt | Y2: NL | Z2: NO | AA2: PL | AB2: PT | AC2: RO | AD2: SE | AE2: SI | AF2: SK | AG2: UK | AH2: new | AI2: old
A3: R_DetH | B3: 2010 | C3: 1015 | D3: 950 | E3: 617 | F3: 842 | G3: 106 | H3: 1027 | I3: 7734 | J3: 997 | K3: 112 | L3: 729 | M3: 973 | N3: 792 | O3: 6299 | P3: 636 | Q3: 1537 | R3: 465 | S3: 44 | T3: 2112 | U3: 261 | V3: 52 | W3: 184 | X3: 4 | Y3: 636 | Z3: 464 | AA3: 3325 | AB3: 410 | AC3: 2103 | AD3: 1179 | AE3: 195 | AF3: 432 | AG3: 3811 | AH3: 0 | AI3: 0
A4: R_DetH | B4: 2020 | C4: 1056 | D4: 1064 | E4: 648 | F4: 943 | G4: 113 | H4: 1089 | I4: 8352 | J4: 1137 | K4: 149 | L4: 758 | M4: 1012 | N4: 832 | O4: 6551 | P4: 674 | Q4: 1921 | R4: 554 | S4: 53 | T4: 2196 | U4: 336 | V4: 61 | W4: 236 | X4: 5 | Y4: 706 | Z4: 515 | AA4: 3990 | AB4: 426 | AC4: 2377 | AD4: 1332 | AE4: 207 | AF4: 449 | AG4: 4002 | AH4: #N/A | AI4: #N/A
A5: R_DetH | B5: 2030 | C5: 1151 | D5: 1192 | E5: 726 | F5: 1056 | G5: 130 | H5: 1154 | I5: 8770 | J5: 1251 | K5: 162 | L5: 947 | M5: 1143 | N5: 882 | O5: 7140 | P5: 836 | Q5: 2286 | R5: 720 | S5: 61 | T5: 2614 | U5: 393 | V5: 69 | W5: 260 | X5: 6 | Y5: 797 | Z5: 587 | AA5: 4828 | AB5: 482 | AC5: 2900 | AD5: 1478 | AE5: 256 | AF5: 516 | AG5: 4242 | AH5: #N/A | AI5: #N/A
A6: R_DetH | B6: 2040 | C6: 1249 | D6: 1305 | E6: 776 | F6: 1156 | G6: 144 | H6: 1269 | I6: 9472 | J6: 1382 | K6: 179 | L6: 1000 | M6: 1235 | N6: 957 | O6: 7676 | P6: 924 | Q6: 2549 | R6: 825 | S6: 67 | T6: 2783 | U6: 423 | V6: 78 | W6: 278 | X6: 7 | Y6: 877 | Z6: 651 | AA6: 5286 | AB6: 513 | AC6: 3175 | AD6: 1663 | AE6: 285 | AF6: 573 | AG6: 4623 | AH6: #N/A | AI6: #N/A
A7: R_DetH | B7: 2050 | C7: 1355 | D7: 1429 | E7: 831 | F7: 1266 | G7: 159 | H7: 1396 | I7: 10229 | J7: 1527 | K7: 198 | L7: 1055 | M7: 1334 | N7: 1038 | O7: 8252 | P7: 1021 | Q7: 2842 | R7: 944 | S7: 73 | T7: 2964 | U7: 455 | V7: 88 | W7: 297 | X7: 8 | Y7: 965 | Z7: 723 | AA7: 5789 | AB7: 546 | AC7: 3477 | AD7: 1871 | AE7: 316 | AF7: 636 | AG7: 5039 | AH7: #N/A | AI7: #N/A
A8: R_DetH | B8: 2060 | C8: 1480 | D8: 1578 | E8: 893 | F8: 1397 | G8: 178 | H8: 1550 | I8: 11113 | J8: 1705 | K8: 221 | L8: 1116 | M8: 1449 | N8: 1134 | O8: 8917 | P8: 1139 | Q8: 3207 | R8: 1102 | S8: 81 | T8: 3169 | U8: 491 | V8: 100 | W8: 319 | X8: 10 | Y8: 1071 | Z8: 811 | AA8: 6391 | AB8: 584 | AC8: 3839 | AD8: 2135 | AE8: 355 | AF8: 714 | AG8: 5534
A9: R_DetH | B9: 2070 | C9: 1616 | D9: 1742 | E9: 960 | F9: 1543 | G9: 198 | H9: 1721 | I9: 12073 | J9: 1903 | K9: 246 | L9: 1180 | M9: 1574 | N9: 1238 | O9: 9635 | P9: 1272 | Q9: 3619 | R9: 1285 | S9: 89 | T9: 3389 | U9: 531 | V9: 114 | W9: 343 | X9: 12 | Y9: 1189 | Z9: 910 | AA9: 7056 | AB9: 624 | AC9: 4238 | AD9: 2436 | AE9: 398 | AF9: 801 | AG9: 6077
A10: R_Flat | B10: 2010 | C10: 1468 | D10: 906 | E10: 777 | F10: 1648 | G10: 84 | H10: 2208 | I10: 18507 | J10: 1067 | K10: 488 | L10: 1679 | M10: 7433 | N10: 1108 | O10: 9195 | P10: 505 | Q10: 1315 | R10: 148 | S10: 67 | T10: 17048 | U10: 726 | V10: 68 | W10: 576 | X10: 16 | Y10: 1729 | Z10: 1152 | AA10: 6734 | AB10: 515 | AC10: 2051 | AD10: 2427 | AE10: 461 | AF10: 580 | AG10: 3928 | AH10: 0 | AI10: 0
A11: R_Flat | B11: 2020 | C11: 1527 | D11: 1014 | E11: 816 | F11: 1846 | G11: 89 | H11: 2341 | I11: 19988 | J11: 1216 | K11: 649 | L11: 1746 | M11: 7730 | N11: 1164 | O11: 9563 | P11: 535 | Q11: 1643 | R11: 176 | S11: 81 | T11: 17730 | U11: 936 | V11: 79 | W11: 737 | X11: 22 | Y11: 1919 | Z11: 1278 | AA11: 8081 | AB11: 535 | AC11: 2318 | AD11: 2742 | AE11: 489 | AF11: 604 | AG11: 4125 | AH11: #N/A | AI11: #N/A
A12: R_Flat | B12: 2030 | C12: 1664 | D12: 1136 | E12: 914 | F12: 2068 | G12: 103 | H12: 2481 | I12: 20987 | J12: 1338 | K12: 708 | L12: 2099 | M12: 8399 | N12: 1233 | O12: 10424 | P12: 664 | Q12: 1956 | R12: 229 | S12: 94 | T12: 21098 | U12: 1095 | V12: 90 | W12: 811 | X12: 27 | Y12: 2168 | Z12: 1457 | AA12: 9778 | AB12: 582 | AC12: 2827 | AD12: 3044 | AE12: 606 | AF12: 694 | AG12: 4372 | AH12: #N/A | AI12: #N/A
A13: R_Flat | B13: 2040 | C13: 1806 | D13: 1244 | E13: 978 | F13: 2264 | G13: 114 | H13: 2729 | I13: 22666 | J13: 1478 | K13: 782 | L13: 2214 | M13: 9071 | N13: 1338 | O13: 11206 | P13: 733 | Q13: 2181 | R13: 262 | S13: 103 | T13: 22470 | U13: 1177 | V13: 101 | W13: 868 | X13: 32 | Y13: 2385 | Z13: 1618 | AA13: 10707 | AB13: 619 | AC13: 3096 | AD13: 3424 | AE13: 673 | AF13: 770 | AG13: 4766 | AH13: #N/A | AI13: #N/A
A14: R_Flat | B14: 2050 | C14: 1959 | D14: 1362 | E14: 1046 | F14: 2479 | G14: 126 | H14: 3002 | I14: 24480 | J14: 1633 | K14: 864 | L14: 2336 | M14: 9797 | N14: 1452 | O14: 12046 | P14: 811 | Q14: 2431 | R14: 300 | S14: 113 | T14: 23930 | U14: 1265 | V14: 114 | W14: 929 | X14: 37 | Y14: 2624 | Z14: 1796 | AA14: 11724 | AB14: 660 | AC14: 3390 | AD14: 3852 | AE14: 747 | AF14: 855 | AG14: 5195 | AH14: #N/A | AI14: #N/A
A15: R_Flat | B15: 2060 | C15: 2140 | D15: 1504 | E15: 1125 | F15: 2737 | G15: 140 | H15: 3332 | I15: 26594 | J15: 1823 | K15: 964 | L15: 2471 | M15: 10643 | N15: 1586 | O15: 13017 | P15: 905 | Q15: 2744 | R15: 351 | S15: 125 | T15: 25586 | U15: 1367 | V15: 130 | W15: 998 | X15: 45 | Y15: 2913 | Z15: 2015 | AA15: 12944 | AB15: 705 | AC15: 3743 | AD15: 4396 | AE15: 839 | AF15: 960 | AG15: 5704 | AH15: =(AH14*(1+AH49)) -> #N/A | AI15: =(AI14*(1+AI49)) -> #N/A
A16: R_Flat | B16: 2070 | C16: 2337 | D16: 1660 | E16: 1209 | F16: 3022 | G16: 156 | H16: 3699 | I16: 28892 | J16: 2035 | K16: 1076 | L16: 2615 | M16: 11563 | N16: 1732 | O16: 14066 | P16: 1010 | Q16: 3096 | R16: 409 | S16: 138 | T16: 27356 | U16: 1478 | V16: 148 | W16: 1073 | X16: 54 | Y16: 3233 | Z16: 2262 | AA16: 14292 | AB16: 754 | AC16: 4133 | AD16: 5016 | AE16: 941 | AF16: 1077 | AG16: 6264 | AH16: =(AH15*(1+AH49)) -> #N/A | AI16: =(AI15*(1+AI49)) -> #N/A
A17: R_SDetH | B17: 2010 | C17: 470 | D17: 1586 | E17: 335 | F17: 944 | G17: 108 | H17: 609 | I17: 8085 | J17: 531 | K17: 52 | L17: 412 | M17: 2157 | N17: 599 | O17: 5601 | P17: 228 | Q17: 568 | R17: 700 | S17: 41 | T17: 3756 | U17: 132 | V17: 68 | W17: 74 | X17: 46 | Y17: 3358 | Z17: 364 | AA17: 1248 | AB17: 331 | AC17: 604 | AD17: 565 | AE17: 65 | AF17: 128 | AG17: 13231 | AH17: 0 | AI17: 0
A18: R_SDetH | B18: 2020 | C18: 489 | D18: 1776 | E18: 352 | F18: 1057 | G18: 116 | H18: 645 | I18: 8732 | J18: 605 | K18: 69 | L18: 429 | M18: 2243 | N18: 629 | O18: 5825 | P18: 241 | Q18: 709 | R18: 833 | S18: 49 | T18: 3906 | U18: 170 | V18: 79 | W18: 94 | X18: 61 | Y18: 3727 | Z18: 404 | AA18: 1497 | AB18: 344 | AC18: 683 | AD18: 639 | AE18: 69 | AF18: 134 | AG18: 13892 | AH18: #N/A | AI18: #N/A
A19: R_SDetH | B19: 2030 | C19: 533 | D19: 1989 | E19: 394 | F19: 1184 | G19: 133 | H19: 684 | I19: 9169 | J19: 666 | K19: 75 | L19: 536 | M19: 2535 | N19: 666 | O19: 6349 | P19: 299 | Q19: 844 | R19: 1083 | S19: 57 | T19: 4648 | U19: 199 | V19: 90 | W19: 104 | X19: 75 | Y19: 4211 | Z19: 461 | AA19: 1812 | AB19: 389 | AC19: 833 | AD19: 709 | AE19: 85 | AF19: 154 | AG19: 14726 | AH19: #N/A | AI19: #N/A
A20: R_SDetH | B20: 2040 | C20: 579 | D20: 2178 | E20: 422 | F20: 1297 | G20: 147 | H20: 752 | I20: 9902 | J20: 736 | K20: 83 | L20: 565 | M20: 2738 | N20: 723 | O20: 6825 | P20: 331 | Q20: 941 | R20: 1240 | S20: 63 | T20: 4950 | U20: 214 | V20: 101 | W20: 111 | X20: 88 | Y20: 4632 | Z20: 511 | AA20: 1984 | AB20: 414 | AC20: 912 | AD20: 798 | AE20: 95 | AF20: 170 | AG20: 16051 | AH20: #N/A | AI20: #N/A
A21: R_SDetH | B21: 2050 | C21: 628 | D21: 2385 | E21: 451 | F21: 1420 | G21: 162 | H21: 828 | I21: 10694 | J21: 813 | K21: 92 | L21: 596 | M21: 2957 | N21: 784 | O21: 7337 | P21: 365 | Q21: 1050 | R21: 1420 | S21: 69 | T21: 5272 | U21: 230 | V21: 113 | W21: 119 | X21: 104 | Y21: 5096 | Z21: 568 | AA21: 2172 | AB21: 441 | AC21: 999 | AD21: 898 | AE21: 105 | AF21: 189 | AG21: 17496 | AH21: #N/A | AI21: #N/A
A22: R_SDetH | B22: 2060 | C22: 686 | D22: 2633 | E22: 485 | F22: 1568 | G22: 181 | H22: 919 | I22: 11618 | J22: 908 | K22: 102 | L22: 631 | M22: 3212 | N22: 857 | O22: 7928 | P22: 408 | Q22: 1184 | R22: 1657 | S22: 76 | T22: 5637 | U22: 248 | V22: 129 | W22: 128 | X22: 125 | Y22: 5657 | Z22: 637 | AA22: 2398 | AB22: 471 | AC22: 1102 | AD22: 1024 | AE22: 118 | AF22: 212 | AG22: 19213
A23: R_SDetH | B23: 2070 | C23: 749 | D23: 2907 | E23: 522 | F23: 1731 | G23: 202 | H23: 1020 | I23: 12622 | J23: 1013 | K23: 114 | L23: 667 | M23: 3490 | N23: 936 | O23: 8567 | P23: 455 | Q23: 1337 | R23: 1933 | S23: 84 | T23: 6026 | U23: 268 | V23: 147 | W23: 137 | X23: 151 | Y23: 6280 | Z23: 715 | AA23: 2648 | AB23: 504 | AC23: 1217 | AD23: 1169 | AE23: 132 | AF23: 238 | AG23: 21098
A25: NEW added stock per year in thounsand dwellings
C26: AT | D26: BE | E26: BG | F26: CH | G26: CY | H26: CZ | I26: DE | J26: DK | K26: EE | L26: EL | M26: ES | N26: FI | O26: FR | P26: HR | Q26: HU | R26: IE | S26: IS | T26: IT | U26: LT | V26: LU | W26: LV | X26: Mt | Y26: NL | Z26: NO | AA26: PL | AB26: PT | AC26: RO | AD26: SE | AE26: SI | AF26: SK | AG26: UK | AH26: new | AI26: old
A27: thousands of dwellings (yearly) | AH27: 0 | AI27: 0
A28: RR_DetH | B28: 2010 | C28: 3.9 | D28: 10.18 | E28: 2.94 | F28: 9.02 | G28: 0.69 | H28: 5.81 | I28: 57.29 | J28: 12.25 | K28: 2.77 | L28: 0 | M28: 0 | N28: 3.77 | O28: 24.23 | P28: 3.6 | Q28: 30.73 | R28: 7.43 | S28: 0.76 | T28: 0 | U28: 5.86 | V28: 0.72 | W28: 4.03 | X28: 0.09 | Y28: 6.3 | Z28: 4.59 | AA28: 55.41 | AB28: 0 | AC28: 24.2 | AD28: 13.56 | AE28: 1.1 | AF28: 1.66 | AG28: 18.15 | AH28: =SUM(C28:AG28) -> 311.04
A29: RR_DetH | B29: 2020 | C29: 4.06 | D29: 11.4 | E29: 3.08 | F29: 10.1 | G29: 0.74 | H29: 6.16 | I29: 61.87 | J29: 13.96 | K29: 3.68 | L29: 3 | M29: 4 | N29: 3.96 | O29: 25.2 | P29: 3.82 | Q29: 38.42 | R29: 8.84 | S29: 0.91 | T29: 8 | U29: 7.56 | V29: 0.84 | W29: 5.16 | X29: 0.12 | Y29: 6.99 | Z29: 5.1 | AA29: 66.5 | AB29: 2 | AC29: 27.345015 | AD29: 15.323935 | AE29: 1.1705239 | AF29: 1.725699 | AG29: 19.054997 | AH29: =SUM(C29:AG29) -> 370.09017
A30: RR_DetH | B30: 2030 | C30: 9.5 | D30: 12.77 | E30: 7.78 | F30: 11.31 | G30: 1.7 | H30: 6.53 | I30: 41.76 | J30: 11.37 | K30: 1.34 | L30: 18.95 | M30: 13.16 | N30: 4.99 | O30: 58.96 | P30: 16.18 | Q30: 36.49 | R30: 16.62 | S30: 0.84 | T30: 41.73 | U30: 5.72 | V30: 0.85 | W30: 2.36 | X30: 0.11 | Y30: 9.17 | Z30: 7.21 | AA30: 83.79 | AB30: 5.54 | AC30: 52.293 | AD30: 14.651 | AE30: 4.9620001 | AF30: 6.7320001 | AG30: 24.009 | AH30: =SUM(C30:AG30) -> 529.377
A31: RR_DetH | B31: 2040 | C31: 9.78 | D31: 11.32 | E31: 5.08 | F31: 10.03 | G31: 1.37 | H31: 11.54 | I31: 70.16 | J31: 13.13 | K31: 1.7 | L31: 5.21 | M31: 9.15 | N31: 7.49 | O31: 53.55 | P31: 8.78 | Q31: 26.29 | R31: 10.44 | S31: 0.58 | T31: 16.99 | U31: 2.95 | V31: 0.86 | W31: 1.82 | X31: 0.1 | Y31: 7.97 | Z31: 6.45 | AA31: 45.86 | AB31: 3.13 | AC31: 27.548 | AD31: 18.481 | AE31: 2.8209999 | AF31: 5.6769998 | AG31: 38.174 | AH31: =SUM(C31:AG31) -> 434.431
A32: RR_DetH | B32: 2050 | C32: 10.61 | D32: 12.4 | E32: 5.44 | F32: 10.98 | G32: 1.51 | H32: 12.69 | I32: 75.77 | J32: 14.51 | K32: 1.88 | L32: 5.5 | M32: 9.88 | N32: 8.13 | O32: 57.57 | P32: 9.7 | Q32: 29.31 | R32: 11.96 | S32: 0.64 | T32: 18.09 | U32: 3.17 | V32: 0.97 | W32: 1.94 | X32: 0.12 | Y32: 8.77 | Z32: 7.16 | AA32: 50.22 | AB32: 3.33 | AC32: 30.166 | AD32: 20.791 | AE32: 3.1300001 | AF32: 6.3010001 | AG32: 41.611 | AH32: =SUM(C32:AG32) -> 474.249
A33: RR_DetH | B33: 2060 | C33: 12.49 | D33: 14.88 | E33: 6.22 | F33: 13.17 | G33: 1.85 | H33: 15.37 | I33: 88.36 | J33: 17.74 | K33: 2.3 | L33: 6.11 | M33: 11.52 | N33: 9.57 | O33: 66.5 | P33: 11.86 | Q33: 36.51 | R33: 15.75 | S33: 0.76 | T33: 20.51 | U33: 3.66 | V33: 1.23 | W33: 2.22 | X33: 0.17 | Y33: 10.62 | Z33: 8.84 | AA33: 60.25 | AB33: 3.78 | AC33: 36.1895 | AD33: 26.3875 | AE33: 3.8634999 | AF33: 7.7759999 | AG33: 49.4505 | AH33: =SUM(C33:AG33) -> 565.907
A34: RR_DetH | B34: 2070 | C34: 13.65 | D34: 16.43 | E34: 6.68 | F34: 14.55 | G34: 2.06 | H34: 17.07 | I34: 96 | J34: 19.8 | K34: 2.56 | L34: 6.47 | M34: 12.52 | N34: 10.45 | O34: 71.86 | P34: 13.24 | Q34: 41.2 | R34: 18.38 | S34: 0.84 | T34: 21.92 | U34: 3.96 | V34: 1.41 | W34: 2.39 | X34: 0.2 | Y34: 11.79 | Z34: 9.92 | AA34: 66.52 | AB34: 4.04 | AC34: 39.956195 | AD34: 30.108642 | AE34: 4.3360112 | AF34: 8.7269352 | AG34: 54.302899 | AH34: =SUM(C34:AG34) -> 623.34068
A35: RR_Flat | B35: 2010 | C35: 5.65 | D35: 9.7 | E35: 3.7 | F35: 17.66 | G35: 0.55 | H35: 12.5 | I35: 137.09 | J35: 13.1 | K35: 12.11 | L35: - | M35: - | N35: 5.28 | O35: 35.37 | P35: 2.86 | Q35: 26.3 | R35: 2.36 | S35: 1.17 | T35: - | U35: 16.31 | V35: 0.94 | W35: 12.6 | X35: 0.41 | Y35: 17.13 | Z35: 11.41 | AA35: 112.24 | AB35: - | AC35: 23.59 | AD35: 27.92 | AE35: 2.61 | AF35: 2.23 | AG35: 18.71 | AH35: =SUM(C35:AG35) -> 531.5
A36: RR_Flat | B36: 2020 | C36: 5.9 | D36: 10.9 | E36: 3.9 | F36: 19.8 | G36: 0.6 | H36: 13.2 | I36: 148.1 | J36: 14.9 | K36: 16.1 | L36: 6.7 | M36: 29.7 | N36: 5.5 | O36: 36.8 | P36: 3 | Q36: 32.9 | R36: 2.8 | S36: 1.4 | T36: 68.2 | U36: 21 | V36: 1.1 | W36: 16.1 | X36: 0.5 | Y36: 19 | Z36: 12.7 | AA36: 134.7 | AB36: 2.1 | AC36: 26.7 | AD36: 31.5 | AE36: 2.8 | AF36: 2.3 | AG36: 19.6 | AH36: =SUM(C36:AG36) -> 710.5
A37: RR_Flat | B37: 2030 | C37: 13.7 | D37: 12.2 | E37: 9.8 | F37: 22.2 | G37: 1.3 | H37: 14 | I37: 99.9 | J37: 12.2 | K37: 5.8 | L37: 35.3 | M37: 66.9 | N37: 7 | O37: 86.1 | P37: 12.8 | Q37: 31.2 | R37: 5.3 | S37: 1.3 | T37: 336.9 | U37: 15.9 | V37: 1.1 | W37: 7.4 | X37: 0.5 | Y37: 24.9 | Z37: 17.9 | AA37: 169.7 | AB37: 4.6 | AC37: 51 | AD37: 30.2 | AE37: 11.7 | AF37: 9.1 | AG37: 24.7 | AH37: =SUM(C37:AG37) -> 1142.6
A38: RR_Flat | B38: 2040 | C38: 14.1 | D38: 10.8 | E38: 6.4 | F38: 19.6 | G38: 1.1 | H38: 24.8 | I38: 167.9 | J38: 14 | K38: 7.4 | L38: 11.5 | M38: 67.2 | N38: 10.5 | O38: 78.2 | P38: 7 | Q38: 22.5 | R38: 3.3 | S38: 0.9 | T38: 137.1 | U38: 8.2 | V38: 1.1 | W38: 5.7 | X38: 0.5 | Y38: 21.7 | Z38: 16 | AA38: 92.9 | AB38: 3.8 | AC38: 26.9 | AD38: 38 | AE38: 6.7 | AF38: 7.6 | AG38: 39.3 | AH38: =SUM(C38:AG38) -> 872.7
A39: RR_Flat | B39: 2050 | C39: 15.4 | D39: 11.8 | E39: 6.8 | F39: 21.5 | G39: 1.2 | H39: 27.3 | I39: 181.3 | J39: 15.5 | K39: 8.2 | L39: 12.2 | M39: 72.6 | N39: 11.4 | O39: 84 | P39: 7.7 | Q39: 25.1 | R39: 3.8 | S39: 1 | T39: 146.1 | U39: 8.8 | V39: 1.3 | W39: 6.1 | X39: 0.6 | Y39: 23.9 | Z39: 17.8 | AA39: 101.7 | AB39: 4 | AC39: 29.4 | AD39: 42.8 | AE39: 7.4 | AF39: 8.5 | AG39: 42.9 | AH39: =SUM(C39:AG39) -> 948.1
A40: RR_Flat | B40: 2060 | C40: 18.1 | D40: 14.2 | E40: 7.8 | F40: 25.8 | G40: 1.5 | H40: 33 | I40: 211.5 | J40: 19 | K40: 10 | L40: 13.5 | M40: 84.6 | N40: 13.4 | O40: 97.1 | P40: 9.4 | Q40: 31.2 | R40: 5 | S40: 1.2 | T40: 165.5 | U40: 10.2 | V40: 1.6 | W40: 7 | X40: 0.8 | Y40: 28.9 | Z40: 22 | AA40: 122 | AB40: 4.6 | AC40: 35.3 | AD40: 54.3 | AE40: 9.1 | AF40: 10.5 | AG40: 51 | AH40: =SUM(C40:AG40) -> 1119.1
A41: RR_Flat | B41: 2070 | C41: 19.7 | D41: 15.7 | E41: 8.4 | F41: 28.5 | G41: 1.6 | H41: 36.7 | I41: 229.7 | J41: 21.2 | K41: 11.2 | L41: 14.3 | M41: 91.9 | N41: 14.6 | O41: 104.9 | P41: 10.5 | Q41: 35.3 | R41: 5.8 | S41: 1.3 | T41: 177 | U41: 11 | V41: 1.8 | W41: 7.5 | X41: 0.9 | Y41: 32.1 | Z41: 24.6 | AA41: 134.7 | AB41: 4.9 | AC41: 39 | AD41: 62 | AE41: 10.3 | AF41: 11.7 | AG41: 56 | AH41: =SUM(C41:AG41) -> 1224.8
...

Sheet ciemat
A1: FID | B1: Country ID | C1: COuntry Name in English | D1: Scenario 0, Sharing willness percentage [%] | E1: Scenario 0, Sharing willness intensity [%] | F1: Scenario 0, Builidng Stock [Mm2] | G1: Scenario 0, Energy Consumption, Operational Heating [PJ] | H1: Scenario 0, Energy Consumption, Operational Cooling [PJ | I1: Scenario 0, Energy Consumption, Operational Total [PJ | J1: Scenario 0, Energy Consumption, Embodied [PJ | K1: Scenario 0, CO2 emissions [Mt CO2 eq] | L1: Scenario 0, Saved Building Stock [%] | M1: Scenario 0, Saved Enery Consumption, Operational Total [%] | N1: Scenario 0, Saved Enery Consumption, Embodied Total [%] | O1: Scenario 0, Saved Enery Consumption Total [%] | P1: Scenario 0, Saved CO2 emissions [%] | Q1: Scenario 1, Sharing willness percentage [%] | R1: Scenario 1, Sharing willness intensity [%] | S1: Scenario 1, Builidng Stock [Mm2] | T1: Scenario 1, Energy Consumption, Operational Heating [PJ] | U1: Scenario 1, Energy Consumption, Operational Cooling [PJ | V1: Scenario 1, Energy Consumption, Operational Total [PJ | W1: Scenario 1, Energy Consumption, Embodied [PJ | X1: Scenario 1, CO2 emissions [Mt CO2 eq] | Y1: Scenario 1, Saved Building Stock [%] | Z1: Scenario 1, Saved Enery Consumption, Operational Total [%] | AA1: Scenario 1, Saved Enery Consumption, Embodied Total [%] | AB1: Scenario 1, Saved Enery Consumption Total [%] | AC1: Scenario 1, Saved CO2 emissions [%] | AD1: Scenario 2, Sharing willness percentage [%] | AE1: Scenario 2, Sharing willness intensity [%] | AF1: Scenario 2, Builidng Stock [Mm2] | AG1: Scenario 2, Energy Consumption, Operational Heating [PJ] | AH1: Scenario 2, Energy Consumption, Operational Cooling [PJ | AI1: Scenario 2, Energy Consumption, Operational Total [PJ | AJ1: Scenario 2, Energy Consumption, Embodied [PJ | AK1: Scenario 2, CO2 emissions [Mt CO2 eq] | AL1: Scenario 2, Saved Building Stock [%] | AM1: Scenario 2, Saved Enery Consumption, Operational Total [%] | AN1: Scenario 2, Saved Enery Consumption, Embodied Total [%] | AO1: Scenario 2, Saved Enery Consumption Total [%] | AP1: Scenario 2, Saved CO2 emissions [%] | AQ1: Scenario 3, Sharing willness percentage [%] | AR1: Scenario 3, Sharing willness intensity [%] | AS1: Scenario 3, Builidng Stock [Mm2] | AT1: Scenario 3, Energy Consumption, Operational Heating [PJ] | AU1: Scenario 3, Energy Consumption, Operational Cooling [PJ | AV1: Scenario 3, Energy Consumption, Operational Total [PJ | AW1: Scenario 3, Energy Consumption, Embodied [PJ | AX1: Scenario 3, CO2 emissions [Mt CO2 eq] | AY1: Scenario 3, Saved Building Stock [%] | AZ1: Scenario 3, Saved Enery Consumption, Operational Total [%] | BA1: Scenario 3, Saved Enery Consumption, Embodied Total [%] | BB1: Scenario 3, Saved Enery Consumption Total [%] | BC1: Scenario 3, Saved CO2 emissions [%] | BD1: x | BE1: y
A2: 0 | B2: AL | C2: Albania | D2: 0 | E2: None | F2: 85.6 | G2: 8.4 | H2: 0.4 | I2: 20.4 | J2: 5.1 | K2: 1.4 | L2: 0 | M2: 0 | N2: 0 | O2: 0 | P2: 0 | Q2: 10 | R2: Light | S2: 81.32 | T2: 7.98 | U2: 0.38 | V2: 19.38 | W2: 4.845 | X2: 1.33 | Y2: 3 | Z2: 3.21 | AA2: 3.27 | AB2: 3.36 | AC2: 3.3 | AD2: 20 | AE2: Medium | AF2: 72.76 | AG2: 7.14 | AH2: 0.34 | AI2: 17.34 | AJ2: 4.335 | AK2: 1.19 | AL2: 3.75 | AM2: 4.0125 | AN2: 4.0875 | AO2: 4.2 | AP2: 4.125 | AQ2: 30 | AR2: Strong | AS2: 64.2 | AT2: 6.3 | AU2: 0.3 | AV2: 15.3 | AW2: 3.825 | AX2: 1.05 | AY2: 4.05 | AZ2: 4.3335 | BA2: 4.4145 | BB2: 4.536 | BC2: 4.455 | BF2: =(AF2-F2)/F2 -> -0.15
A3: 1 | B3: AT | C3: Austria | D3: 0 | E3: None | F3: 341.5 | G3: 184.1 | H3: 0.3 | I3: 266.5 | J3: 66.625 | K3: 18.1 | L3: 0 | M3: 0 | N3: 0 | O3: 0 | P3: 0 | Q3: 10 | R3: Light | S3: 324.425 | T3: 174.895 | U3: 0.285 | V3: 253.175 | W3: 63.2938 | X3: 17.195 | Y3: 4 | Z3: 4.28 | AA3: 4.36 | AB3: 4.48 | AC3: 4.4 | AD3: 20 | AE3: Medium | AF3: 290.275 | AG3: 156.485 | AH3: 0.255 | AI3: 226.525 | AJ3: 56.6312 | AK3: 15.385 | AL3: 5 | AM3: 5.35 | AN3: 5.45 | AO3: 5.6 | AP3: 5.5 | AQ3: 30 | AR3: Strong | AS3: 256.125 | AT3: 138.075 | AU3: 0.225 | AV3: 199.875 | AW3: 49.9688 | AX3: 13.575 | AY3: 5.4 | AZ3: 5.778 | BA3: 5.886 | BB3: 6.048 | BC3: 5.94
A4: 2 | B4: BA | C4: Bosnia and Herzegovina | D4: 0 | E4: None | F4: 85.6 | G4: 17.1 | H4: 1.8 | I4: 34.3 | J4: 8.575 | K4: 2.3 | L4: 0 | M4: 0 | N4: 0 | O4: 0 | P4: 0 | Q4: 10 | R4: Light | S4: 81.32 | T4: 16.245 | U4: 1.71 | V4: 32.585 | W4: 8.14625 | X4: 2.185 | Y4: 5 | Z4: 5.35 | AA4: 5.45 | AB4: 5.6 | AC4: 5.5 | AD4: 20 | AE4: Medium | AF4: 72.76 | AG4: 14.535 | AH4: 1.53 | AI4: 29.155 | AJ4: 7.28875 | AK4: 1.955 | AL4: 6.25 | AM4: 6.6875 | AN4: 6.8125 | AO4: 7 | AP4: 6.875 | AQ4: 30 | AR4: Strong | AS4: 64.2 | AT4: 12.825 | AU4: 1.35 | AV4: 25.725 | AW4: 6.43125 | AX4: 1.725 | AY4: 6.75 | AZ4: 7.2225 | BA4: 7.3575 | BB4: 7.56 | BC4: 7.425
A5: 3 | B5: BE | C5: Belgium | D5: 0 | E5: None | F5: 466.4 | G5: 277.2 | H5: 1.6 | I5: 387.8 | J5: 96.95 | K5: 26.3 | L5: 0 | M5: 0 | N5: 0 | O5: 0 | P5: 0 | Q5: 10 | R5: Light | S5: 443.08 | T5: 263.34 | U5: 1.52 | V5: 368.41 | W5: 92.1025 | X5: 24.985 | Y5: 6 | Z5: 6.42 | AA5: 6.54 | AB5: 6.72 | AC5: 6.6 | AD5: 20 | AE5: Medium | AF5: 396.44 | AG5: 235.62 | AH5: 1.36 | AI5: 329.63 | AJ5: 82.4075 | AK5: 22.355 | AL5: 7.5 | AM5: 8.025 | AN5: 8.175 | AO5: 8.4 | AP5: 8.25 | AQ5: 30 | AR5: Strong | AS5: 349.8 | AT5: 207.9 | AU5: 1.2 | AV5: 290.85 | AW5: 72.7125 | AX5: 19.725 | AY5: 8.1 | AZ5: 8.667 | BA5: 8.829 | BB5: 9.072 | BC5: 8.91
A6: 4 | B6: BG | C6: Bulgaria | D6: 0 | E6: None | F6: 197.2 | G6: 50 | H6: 0.4 | I6: 92.8 | J6: 23.2 | K6: 6.3 | L6: 0 | M6: 0 | N6: 0 | O6: 0 | P6: 0 | Q6: 10 | R6: Light | S6: 187.34 | T6: 47.5 | U6: 0.38 | V6: 88.16 | W6: 22.04 | X6: 5.985 | Y6: 7 | Z6: 7.49 | AA6: 7.63 | AB6: 7.84 | AC6: 7.7 | AD6: 20 | AE6: Medium | AF6: 167.62 | AG6: 42.5 | AH6: 0.34 | AI6: 78.88 | AJ6: 19.72 | AK6: 5.355 | AL6: 8.75 | AM6: 9.3625 | AN6: 9.5375 | AO6: 9.8 | AP6: 9.625 | AQ6: 30 | AR6: Strong | AS6: 147.9 | AT6: 37.5 | AU6: 0.3 | AV6: 69.6 | AW6: 17.4 | AX6: 4.725 | AY6: 9.45 | AZ6: 10.1115 | BA6: 10.3005 | BB6: 10.584 | BC6: 10.395
A7: 9 | B7: CH | C7: Switzerland | D7: 0 | E7: None | F7: 374.1 | G7: 188.4 | H7: 0.4 | I7: 270.5 | J7: 67.625 | K7: 18.3 | L7: 0 | M7: 0 | N7: 0 | O7: 0 | P7: 0 | Q7: 10 | R7: Light | S7: 355.395 | T7: 178.98 | U7: 0.38 | V7: 256.975 | W7: 64.2438 | X7: 17.385 | Y7: 12 | Z7: 12.84 | AA7: 13.08 | AB7: 13.44 | AC7: 13.2 | AD7: 20 | AE7: Medium | AF7: 317.985 | AG7: 160.14 | AH7: 0.34 | AI7: 229.925 | AJ7: 57.4813 | AK7: 15.555 | AL7: 15 | AM7: 16.05 | AN7: 16.35 | AO7: 16.8 | AP7: 16.5 | AQ7: 30 | AR7: Strong | AS7: 280.575 | AT7: 141.3 | AU7: 0.3 | AV7: 202.875 | AW7: 50.7188 | AX7: 13.725 | AY7: 16.2 | AZ7: 17.334 | BA7: 17.658 | BB7: 18.144 | BC7: 17.82
A8: 6 | B8: CZ | C8: Czechia | D8: 0 | E8: None | F8: 309.6 | G8: 232.6 | H8: 0.1 | I8: 301 | J8: 75.25 | K8: 20.4 | L8: 0 | M8: 0 | N8: 0 | O8: 0 | P8: 0 | Q8: 10 | R8: Light | S8: 294.12 | T8: 220.97 | U8: 0.095 | V8: 285.95 | W8: 71.4875 | X8: 19.38 | Y8: 9 | Z8: 9.63 | AA8: 9.81 | AB8: 10.08 | AC8: 9.9 | AD8: 20 | AE8: Medium | AF8: 263.16 | AG8: 197.71 | AH8: 0.085 | AI8: 255.85 | AJ8: 63.9625 | AK8: 17.34 | AL8: 11.25 | AM8: 12.0375 | AN8: 12.2625 | AO8: 12.6 | AP8: 12.375 | AQ8: 30 | AR8: Strong | AS8: 232.2 | AT8: 174.45 | AU8: 0.075 | AV8: 225.75 | AW8: 56.4375 | AX8: 15.3 | AY8: 12.15 | AZ8: 13.0005 | BA8: 13.2435 | BB8: 13.608 | BC8: 13.365
A9: 7 | B9: DE | C9: Germany | D9: 0 | E9: None | F9: 3252.4 | G9: 1811.3 | H9: 3.2 | I9: 2574.1 | J9: 643.525 | K9: 174.5 | L9: 0 | M9: 0 | N9: 0 | O9: 0 | P9: 0 | Q9: 10 | R9: Light | S9: 3089.78 | T9: 1720.74 | U9: 3.04 | V9: 2445.4 | W9: 611.349 | X9: 165.775 | Y9: 10 | Z9: 10.7 | AA9: 10.9 | AB9: 11.2 | AC9: 11 | AD9: 20 | AE9: Medium | AF9: 2764.54 | AG9: 1539.6 | AH9: 2.72 | AI9: 2187.99 | AJ9: 546.996 | AK9: 148.325 | AL9: 12.5 | AM9: 13.375 | AN9: 13.625 | AO9: 14 | AP9: 13.75 | AQ9: 30 | AR9: Strong | AS9: 2439.3 | AT9: 1358.48 | AU9: 2.4 | AV9: 1930.58 | AW9: 482.644 | AX9: 130.875 | AY9: 13.5 | AZ9: 14.445 | BA9: 14.715 | BB9: 15.12 | BC9: 14.85
A10: 8 | B10: DK | C10: Denmark | D10: 0 | E10: None | F10: 297.5 | G10: 143.6 | H10: 0.2 | I10: 2020.6 | J10: 505.15 | K10: 13.7 | L10: 0 | M10: 0 | N10: 0 | O10: 0 | P10: 0 | Q10: 10 | R10: Light | S10: 282.625 | T10: 136.42 | U10: 0.19 | V10: 1919.57 | W10: 479.892 | X10: 13.015 | Y10: 11 | Z10: 11.77 | AA10: 11.99 | AB10: 12.32 | AC10: 12.1 | AD10: 20 | AE10: Medium | AF10: 252.875 | AG10: 122.06 | AH10: 0.17 | AI10: 1717.51 | AJ10: 429.378 | AK10: 11.645 | AL10: 13.75 | AM10: 14.7125 | AN10: 14.9875 | AO10: 15.4 | AP10: 15.125 | AQ10: 30 | AR10: Strong | AS10: 223.125 | AT10: 107.7 | AU10: 0.15 | AV10: 1515.45 | AW10: 378.862 | AX10: 10.275 | AY10: 14.85 | AZ10: 15.8895 | BA10: 16.1865 | BB10: 16.632 | BC10: 16.335
A11: 12 | B11: EE | C11: Estonia | D11: 0 | E11: None | F11: 37.4 | G11: 30.5 | H11: 0 | I11: 42.9 | J11: 10.725 | K11: 2.9 | L11: 0 | M11: 0 | N11: 0 | O11: 0 | P11: 0 | Q11: 10 | R11: Light | S11: 35.53 | T11: 28.975 | U11: 0 | V11: 40.755 | W11: 10.1888 | X11: 2.755 | Y11: 15 | Z11: 16.05 | AA11: 16.35 | AB11: 16.8 | AC11: 16.5 | AD11: 20 | AE11: Medium | AF11: 31.79 | AG11: 25.925 | AH11: 0 | AI11: 36.465 | AJ11: 9.11625 | AK11: 2.465 | AL11: 18.75 | AM11: 20.0625 | AN11: 20.4375 | AO11: 21 | AP11: 20.625 | AQ11: 30 | AR11: Strong | AS11: 28.05 | AT11: 22.875 | AU11: 0 | AV11: 32.175 | AW11: 8.04375 | AX11: 2.175 | AY11: 20.25 | AZ11: 21.6675 | BA11: 22.0725 | BB11: 22.68 | BC11: 22.275
A12: 13 | B12: EL | C12: Greece | D12: 0 | E12: None | F12: 309.7 | G12: 110.4 | H12: 2.5 | I12: 185.5 | J12: 46.375 | K12: 12.6 | L12: 0 | M12: 0 | N12: 0 | O12: 0 | P12: 0 | Q12: 10 | R12: Light | S12: 294.215 | T12: 104.88 | U12: 2.375 | V12: 176.225 | W12: 44.0563 | X12: 11.97 | Y12: 3 | Z12: 3.21 | AA12: 3.27 | AB12: 3.36 | AC12: 3.3 | AD12: 20 | AE12: Medium | AF12: 263.245 | AG12: 93.84 | AH12: 2.125 | AI12: 157.675 | AJ12: 39.4188 | AK12: 10.71 | AL12: 3.75 | AM12: 4.0125 | AN12: 4.0875 | AO12: 4.2 | AP12: 4.125 | AQ12: 30 | AR12: Strong | AS12: 232.275 | AT12: 82.8 | AU12: 1.875 | AV12: 139.125 | AW12: 34.7812 | AX12: 9.45 | AY12: 4.05 | AZ12: 4.3335 | BA12: 4.4145 | BB12: 4.536 | BC12: 4.455
A13: 14 | B13: ES | C13: Spain | D13: 0 | E13: None | F13: 1568 | G13: 340.3 | H13: 6.1 | I13: 721.2 | J13: 180.3 | K13: 48.9 | L13: 0 | M13: 0 | N13: 0 | O13: 0 | P13: 0 | Q13: 10 | R13: Light | S13: 1489.6 | T13: 323.285 | U13: 5.795 | V13: 685.14 | W13: 171.285 | X13: 46.455 | Y13: 4 | Z13: 4.28 | AA13: 4.36 | AB13: 4.48 | AC13: 4.4 | AD13: 20 | AE13: Medium | AF13: 1332.8 | AG13: 289.255 | AH13: 5.185 | AI13: 613.02 | AJ13: 153.255 | AK13: 41.565 | AL13: 5 | AM13: 5.35 | AN13: 5.45 | AO13: 5.6 | AP13: 5.5 | AQ13: 30 | AR13: Strong | AS13: 1176 | AT13: 255.225 | AU13: 4.575 | AV13: 540.9 | AW13: 135.225 | AX13: 36.675 | AY13: 5.4 | AZ13: 5.778 | BA13: 5.886 | BB13: 6.048 | BC13: 5.94
A14: 11 | B14: FR | C14: France | D14: 0 | E14: None | F14: 2479.5 | G14: 1168.2 | H14: 17.2 | I14: 1893.2 | J14: 473.3 | K14: 128.4 | L14: 0 | M14: 0 | N14: 0 | O14: 0 | P14: 0 | Q14: 10 | R14: Light | S14: 2355.52 | T14: 1109.79 | U14: 16.34 | V14: 1798.54 | W14: 449.635 | X14: 121.98 | Y14: 14 | Z14: 14.98 | AA14: 15.26 | AB14: 15.68 | AC14: 15.4 | AD14: 20 | AE14: Medium | AF14: 2107.57 | AG14: 992.97 | AH14: 14.62 | AI14: 1609.22 | AJ14: 402.305 | AK14: 109.14 | AL14: 17.5 | AM14: 18.725 | AN14: 19.075 | AO14: 19.6 | AP14: 19.25 | AQ14: 30 | AR14: Strong | AS14: 1859.62 | AT14: 876.15 | AU14: 12.9 | AV14: 1419.9 | AW14: 354.975 | AX14: 96.3 | AY14: 18.9 | AZ14: 20.223 | BA14: 20.601 | BB14: 21.168 | BC14: 20.79
... A35: 35 | B35: UK | C35: United Kingdom | D35: 0 | E35: None | F35: 1925 | G35: 1308.4 | H35: 1.1 | I35: 1894.5 | J35: 473.625 | K35: 128.5 | L35: 0 | M35: 0 | N35: 0 | O35: 0 | P35: 0 | Q35: 10 | R35: Light | S35: 1828.75 | T35: 1242.98 | U35: 1.045 | V35: 1799.78 | W35: 449.944 | X35: 122.075 | Y35: 12 | Z35: 12.84 | AA35: 13.08 | AB35: 13.44 | AC35: 13.2 | AD35: 20 | AE35: Medium | AF35: 1636.25 | AG35: 1112.14 | AH35: 0.935 | AI35: 1610.32 | AJ35: 402.581 | AK35: 109.225 | AL35: 15 | AM35: 16.05 | AN35: 16.35 | AO35: 16.8 | AP35: 16.5 | AQ35: 30 | AR35: Strong | AS35: 1443.75 | AT35: 981.3 | AU35: 0.825 | AV35: 1420.88 | AW35: 355.219 | AX35: 96.375 | AY35: 16.2 | AZ35: 17.334 | BA35: 17.658 | BB35: 18.144 | BC35: 17.82

Sheet scen2
A1: Country ID | B1: AL | C1: AT | D1: BA | E1: BE | F1: BG | G1: CH | H1: CZ | I1: DE | J1: DK | K1: EE | L1: EL | M1: ES | N1: FR | O1: HR | P1: HU | Q1: IE | R1: IT | S1: KS | T1: LT | U1: LU | V1: LV | W1: ME | X1: MK | Y1: MT | Z1: NL | AA1: NO | AB1: PL | AC1: PT | AD1: RO | AE1: RS | AF1: SE | AG1: SI | AH1: SK | AI1: UK | AJ1: CY | AK1: FI | AL1: IS
A2: Scenario 2, Saved Building Stock [%] | B2: 3.75 | C2: 5 | D2: 6.25 | E2: 7.5 | F2: 8.75 | G2: 15 | H2: 11.25 | I2: 12.5 | J2: 13.75 | K2: 18.75 | L2: 3.75 | M2: 5 | N2: 17.5 | O2: 7.5 | P2: 8.75 | Q2: 6.25 | R2: 11.25 | S2: 16.25 | T2: 13.75 | U2: 15 | V2: 16.25 | W2: 17.5 | X2: 18.75 | Y2: 3.75 | Z2: 12.5 | AA2: 10 | AB2: 5 | AC2: 6.25 | AD2: 7.5 | AE2: 8.75 | AF2: 11.25 | AG2: 12.5 | AH2: 13.75 | AI2: 15 | AJ2: 10.77 | AK2: 10.77 | AL2: 10.77
A5: Country ID | B5: Scenario 2, Saved Building Stock [%]
A6: EL | B6: 3.75
A7: MT | B7: 3.75
A8: AT | B8: 5
A9: ES | B9: 5
A10: PL | B10: 5
A11: IE | B11: 6.25
A12: PT | B12: 6.25
A13: BE | B13: 7.5
A14: HR | B14: 7.5
A15: RO | B15: 7.5
A16: BG | B16: 8.75
A17: HU | B17: 8.75
... A33: EE | B33: 18.75
