Workbook

Sheet Note
B3: This scenario udpates the tlife of existing nuclear power plants
B4: The formulas are flexible

Sheet Update
B2: ~TFM_UPD
B3: Attribute | C3: Pset_PN | D3: AllRegions
B4: NCAP_TLIFE | C4: ='Existing plants_SCEN50yrs'!D2 -> ENBE_DOEL-1_00 | D4: ='Existing plants_SCEN60yrs'!H2 -> 51
B5: NCAP_TLIFE | C5: ='Existing plants_SCEN50yrs'!D3 -> ENBE_DOEL-2_00 | D5: ='Existing plants_SCEN60yrs'!H3 -> 50
B6: NCAP_TLIFE | C6: ='Existing plants_SCEN50yrs'!D4 -> ENBE_DOEL-3_00 | D6: ='Existing plants_SCEN60yrs'!H4 -> 40
B7: NCAP_TLIFE | C7: ='Existing plants_SCEN50yrs'!D5 -> ENBE_DOEL-4_00 | D7: ='Existing plants_SCEN60yrs'!H5 -> 40
B8: NCAP_TLIFE | C8: ='Existing plants_SCEN50yrs'!D6 -> ENBE_TIHANGE-1_00 | D8: ='Existing plants_SCEN60yrs'!H6 -> 50
B9: NCAP_TLIFE | C9: ='Existing plants_SCEN50yrs'!D7 -> ENBE_TIHANGE-2_00 | D9: ='Existing plants_SCEN60yrs'!H7 -> 40
B10: NCAP_TLIFE | C10: ='Existing plants_SCEN50yrs'!D8 -> ENBE_TIHANGE-3_00 | D10: ='Existing plants_SCEN60yrs'!H8 -> 40
B11: NCAP_TLIFE | C11: ='Existing plants_SCEN50yrs'!D9 -> ENBG_KOZLODUY-3_00 | D11: ='Existing plants_SCEN60yrs'!H9 -> 26
B12: NCAP_TLIFE | C12: ='Existing plants_SCEN50yrs'!D10 -> ENBG_KOZLODUY-4_00 | D12: ='Existing plants_SCEN60yrs'!H10 -> 24
B13: NCAP_TLIFE | C13: ='Existing plants_SCEN50yrs'!D11 -> ENBG_KOZLODUY-5_00 | D13: ='Existing plants_SCEN60yrs'!H11 -> 60
B14: NCAP_TLIFE | C14: ='Existing plants_SCEN50yrs'!D12 -> ENBG_KOZLODUY-6_00 | D14: ='Existing plants_SCEN60yrs'!H12 -> 60
B15: NCAP_TLIFE | C15: ='Existing plants_SCEN50yrs'!D13 -> ENCH_BEZNAU-1_00 | D15: ='Existing plants_SCEN60yrs'!H13 -> 50
... B157: NCAP_TLIFE | C157: ='Existing plants_SCEN50yrs'!D155 -> ENUK_WYLFA2_00 | D157: ='Existing plants_SCEN60yrs'!H155 -> 41

Sheet Update (70 year)
B2: ~TFM_UPD
B3: Attribute | C3: Pset_PN | D3: AllRegions
B4: NCAP_TLIFE | C4: ='Existing plants_SCEN50yrs'!D2 -> ENBE_DOEL-1_00 | D4: ='Existing plants_SCEN70yrs'!H2 -> 51
B5: NCAP_TLIFE | C5: ='Existing plants_SCEN50yrs'!D3 -> ENBE_DOEL-2_00 | D5: ='Existing plants_SCEN70yrs'!H3 -> 50
B6: NCAP_TLIFE | C6: ='Existing plants_SCEN50yrs'!D4 -> ENBE_DOEL-3_00 | D6: ='Existing plants_SCEN70yrs'!H4 -> 40
B7: NCAP_TLIFE | C7: ='Existing plants_SCEN50yrs'!D5 -> ENBE_DOEL-4_00 | D7: ='Existing plants_SCEN70yrs'!H5 -> 40
B8: NCAP_TLIFE | C8: ='Existing plants_SCEN50yrs'!D6 -> ENBE_TIHANGE-1_00 | D8: ='Existing plants_SCEN70yrs'!H6 -> 50
B9: NCAP_TLIFE | C9: ='Existing plants_SCEN50yrs'!D7 -> ENBE_TIHANGE-2_00 | D9: ='Existing plants_SCEN70yrs'!H7 -> 40
B10: NCAP_TLIFE | C10: ='Existing plants_SCEN50yrs'!D8 -> ENBE_TIHANGE-3_00 | D10: ='Existing plants_SCEN70yrs'!H8 -> 40
B11: NCAP_TLIFE | C11: ='Existing plants_SCEN50yrs'!D9 -> ENBG_KOZLODUY-3_00 | D11: ='Existing plants_SCEN70yrs'!H9 -> 26
B12: NCAP_TLIFE | C12: ='Existing plants_SCEN50yrs'!D10 -> ENBG_KOZLODUY-4_00 | D12: ='Existing plants_SCEN70yrs'!H10 -> 24
B13: NCAP_TLIFE | C13: ='Existing plants_SCEN50yrs'!D11 -> ENBG_KOZLODUY-5_00 | D13: ='Existing plants_SCEN70yrs'!H11 -> 70
B14: NCAP_TLIFE | C14: ='Existing plants_SCEN50yrs'!D12 -> ENBG_KOZLODUY-6_00 | D14: ='Existing plants_SCEN70yrs'!H12 -> 70
B15: NCAP_TLIFE | C15: ='Existing plants_SCEN50yrs'!D13 -> ENCH_BEZNAU-1_00 | D15: ='Existing plants_SCEN70yrs'!H13 -> 50
... B157: NCAP_TLIFE | C157: ='Existing plants_SCEN50yrs'!D155 -> ENUK_WYLFA2_00 | D157: ='Existing plants_SCEN70yrs'!H155 -> 41

Sheet ShutdownCurve
B2: Year | C2: Remaining Capacity (40 yrs scenario) | D2: Remaining Capacity (50 yrs scenario) | E2: Remaining Capacity (60 yrs scenario) | F2: Remaining Capacity (70 yrs scenario)
B3: 2010 | C3: =SUMIF(Table157[End of life],">="&Table3[[#This Row],[Year]],Table157[Existing capacity GW]) -> 134.455 | D3: =SUMIF(Table15[End of life],">="&Table3[[#This Row],[Year]],Table15[Existing capacity GW]) -> 134.455 | E3: =SUMIF(Table1[End of life],">="&Table3[[#This Row],[Year]],Table1[Existing capacity GW]) -> 134.455 | F3: =SUMIF(Table1[End of life],">="&Table3[[#This Row],[Year]],Table1[Existing capacity GW]) -> 134.455
B4: 2011 | C4: =SUMIF(Table157[End of life],">="&Table3[[#This Row],[Year]],Table157[Existing capacity GW]) -> 134.455 | D4: =SUMIF(Table15[End of life],">="&Table3[[#This Row],[Year]],Table15[Existing capacity GW]) -> 134.455 | E4: =SUMIF(Table1[End of life],">="&Table3[[#This Row],[Year]],Table1[Existing capacity GW]) -> 134.455 | F4: =SUMIF(Table1[End of life],">="&Table3[[#This Row],[Year]],Table1[Existing capacity GW]) -> 134.455
B5: 2012 | C5: =SUMIF(Table157[End of life],">="&Table3[[#This Row],[Year]],Table157[Existing capacity GW]) -> 125.673 | D5: =SUMIF(Table15[End of life],">="&Table3[[#This Row],[Year]],Table15[Existing capacity GW]) -> 126.119 | E5: =SUMIF(Table1[End of life],">="&Table3[[#This Row],[Year]],Table1[Existing capacity GW]) -> 126.119 | F5: =SUMIF(Table1[End of life],">="&Table3[[#This Row],[Year]],Table1[Existing capacity GW]) -> 126.119
B6: 2013 | C6: =SUMIF(Table157[End of life],">="&Table3[[#This Row],[Year]],Table157[Existing capacity GW]) -> 124.966 | D6: =SUMIF(Table15[End of life],">="&Table3[[#This Row],[Year]],Table15[Existing capacity GW]) -> 125.412 | E6: =SUMIF(Table1[End of life],">="&Table3[[#This Row],[Year]],Table1[Existing capacity GW]) -> 125.412 | F6: =SUMIF(Table1[End of life],">="&Table3[[#This Row],[Year]],Table1[Existing capacity GW]) -> 125.412
B7: 2014 | C7: =SUMIF(Table157[End of life],">="&Table3[[#This Row],[Year]],Table157[Existing capacity GW]) -> 124.836 | D7: =SUMIF(Table15[End of life],">="&Table3[[#This Row],[Year]],Table15[Existing capacity GW]) -> 125.412 | E7: =SUMIF(Table1[End of life],">="&Table3[[#This Row],[Year]],Table1[Existing capacity GW]) -> 125.412 | F7: =SUMIF(Table1[End of life],">="&Table3[[#This Row],[Year]],Table1[Existing capacity GW]) -> 125.412
B8: 2015 | C8: =SUMIF(Table157[End of life],">="&Table3[[#This Row],[Year]],Table157[Existing capacity GW]) -> 124.836 | D8: =SUMIF(Table15[End of life],">="&Table3[[#This Row],[Year]],Table15[Existing capacity GW]) -> 125.412 | E8: =SUMIF(Table1[End of life],">="&Table3[[#This Row],[Year]],Table1[Existing capacity GW]) -> 125.412 | F8: =SUMIF(Table1[End of life],">="&Table3[[#This Row],[Year]],Table1[Existing capacity GW]) -> 125.412
B9: 2016 | C9: =SUMIF(Table157[End of life],">="&Table3[[#This Row],[Year]],Table157[Existing capacity GW]) -> 123.071 | D9: =SUMIF(Table15[End of life],">="&Table3[[#This Row],[Year]],Table15[Existing capacity GW]) -> 123.647 | E9: =SUMIF(Table1[End of life],">="&Table3[[#This Row],[Year]],Table1[Existing capacity GW]) -> 123.647 | F9: =SUMIF(Table1[End of life],">="&Table3[[#This Row],[Year]],Table1[Existing capacity GW]) -> 123.647
B10: 2017 | C10: =SUMIF(Table157[End of life],">="&Table3[[#This Row],[Year]],Table157[Existing capacity GW]) -> 123.071 | D10: =SUMIF(Table15[End of life],">="&Table3[[#This Row],[Year]],Table15[Existing capacity GW]) -> 123.647 | E10: =SUMIF(Table1[End of life],">="&Table3[[#This Row],[Year]],Table1[Existing capacity GW]) -> 123.647 | F10: =SUMIF(Table1[End of life],">="&Table3[[#This Row],[Year]],Table1[Existing capacity GW]) -> 123.647
B11: 2018 | C11: =SUMIF(Table157[End of life],">="&Table3[[#This Row],[Year]],Table157[Existing capacity GW]) -> 119.531 | D11: =SUMIF(Table15[End of life],">="&Table3[[#This Row],[Year]],Table15[Existing capacity GW]) -> 120.603 | E11: =SUMIF(Table1[End of life],">="&Table3[[#This Row],[Year]],Table1[Existing capacity GW]) -> 120.603 | F11: =SUMIF(Table1[End of life],">="&Table3[[#This Row],[Year]],Table1[Existing capacity GW]) -> 120.603
B12: 2019 | C12: =SUMIF(Table157[End of life],">="&Table3[[#This Row],[Year]],Table157[Existing capacity GW]) -> 116.358 | D12: =SUMIF(Table15[End of life],">="&Table3[[#This Row],[Year]],Table15[Existing capacity GW]) -> 120.13 | E12: =SUMIF(Table1[End of life],">="&Table3[[#This Row],[Year]],Table1[Existing capacity GW]) -> 120.13 | F12: =SUMIF(Table1[End of life],">="&Table3[[#This Row],[Year]],Table1[Existing capacity GW]) -> 120.13
B13: 2020 | C13: =SUMIF(Table157[End of life],">="&Table3[[#This Row],[Year]],Table157[Existing capacity GW]) -> 110.118 | D13: =SUMIF(Table15[End of life],">="&Table3[[#This Row],[Year]],Table15[Existing capacity GW]) -> 115.65 | E13: =SUMIF(Table1[End of life],">="&Table3[[#This Row],[Year]],Table1[Existing capacity GW]) -> 115.65 | F13: =SUMIF(Table1[End of life],">="&Table3[[#This Row],[Year]],Table1[Existing capacity GW]) -> 115.65
B14: 2021 | C14: =SUMIF(Table157[End of life],">="&Table3[[#This Row],[Year]],Table157[Existing capacity GW]) -> 97.973 | D14: =SUMIF(Table15[End of life],">="&Table3[[#This Row],[Year]],Table15[Existing capacity GW]) -> 113.269 | E14: =SUMIF(Table1[End of life],">="&Table3[[#This Row],[Year]],Table1[Existing capacity GW]) -> 113.269 | F14: =SUMIF(Table1[End of life],">="&Table3[[#This Row],[Year]],Table1[Existing capacity GW]) -> 113.269
... B43: 2050 | C43: =SUMIF(Table157[End of life],">="&Table3[[#This Row],[Year]],Table157[Existing capacity GW]) -> 0 | D43: =SUMIF(Table15[End of life],">="&Table3[[#This Row],[Year]],Table15[Existing capacity GW]) -> 2.576 | E43: =SUMIF(Table1[End of life],">="&Table3[[#This Row],[Year]],Table1[Existing capacity GW]) -> 18.921 | F43: =SUMIF(Table1[End of life],">="&Table3[[#This Row],[Year]],Table1[Existing capacity GW]) -> 18.921

Sheet Existing plants_SCEN40yrs
A1: Generic Lifetime | C1: Member State | D1: Process | E1: Start year | F1: Efficiency PJ/tU | G1: Lifetime Option | H1: Tlife yrs | I1: End of life (fixed) | J1: End of life | K1: Existing capacity GW | L1: Comments | M1: Source
A2: 40 | C2: BE | D2: ENBE_DOEL-1_00 | E2: 1974 | F2: 1.3464165 | G2: fixed | H2: =IF(Table157[[#This Row],[Lifetime Option]]="fixed",Table157[[#This Row],[End of life (fixed)]]-Table157[[#This Row],[Start year]],Table268[Generic Lifetime]) -> 51 | I2: 2025 | J2: =IF(Table157[[#This Row],[Lifetime Option]]="fixed",Table157[[#This Row],[End of life (fixed)]],Table157[[#This Row],[Start year]]+Table268[Generic Lifetime]) -> 2025 | K2: 0.433 | M2: http://www.engie.com/en/journalists/press-releases/agreement-conditions-extending-doel-1-doel-2-new-nuclear-contribution-system/
C3: BE | D3: ENBE_DOEL-2_00 | E3: 1975 | F3: 1.3464165 | G3: fixed | H3: =IF(Table157[[#This Row],[Lifetime Option]]="fixed",Table157[[#This Row],[End of life (fixed)]]-Table157[[#This Row],[Start year]],Table268[Generic Lifetime]) -> 50 | I3: 2025 | J3: =IF(Table157[[#This Row],[Lifetime Option]]="fixed",Table157[[#This Row],[End of life (fixed)]],Table157[[#This Row],[Start year]]+Table268[Generic Lifetime]) -> 2025 | K3: 0.433 | M3: http://www.engie.com/en/journalists/press-releases/agreement-conditions-extending-doel-1-doel-2-new-nuclear-contribution-system/
C4: BE | D4: ENBE_DOEL-3_00 | E4: 1982 | F4: 1.4638774 | G4: fixed | H4: =IF(Table157[[#This Row],[Lifetime Option]]="fixed",Table157[[#This Row],[End of life (fixed)]]-Table157[[#This Row],[Start year]],Table268[Generic Lifetime]) -> 40 | I4: 2022 | J4: =IF(Table157[[#This Row],[Lifetime Option]]="fixed",Table157[[#This Row],[End of life (fixed)]],Table157[[#This Row],[Start year]]+Table268[Generic Lifetime]) -> 2022 | K4: 1.006 | L4: uncertain - follow up | M4: http://www.fanc.fgov.be/nl/news/doel-3/tihange-2-next-steps-of-the-review-process/766.aspx
C5: BE | D5: ENBE_DOEL-4_00 | E5: 1985 | F5: 1.4183133 | G5: fixed | H5: =IF(Table157[[#This Row],[Lifetime Option]]="fixed",Table157[[#This Row],[End of life (fixed)]]-Table157[[#This Row],[Start year]],Table268[Generic Lifetime]) -> 40 | I5: 2025 | J5: =IF(Table157[[#This Row],[Lifetime Option]]="fixed",Table157[[#This Row],[End of life (fixed)]],Table157[[#This Row],[Start year]]+Table268[Generic Lifetime]) -> 2025 | K5: 1.039
C6: BE | D6: ENBE_TIHANGE-1_00 | E6: 1975 | F6: 1.3654688 | G6: fixed | H6: =IF(Table157[[#This Row],[Lifetime Option]]="fixed",Table157[[#This Row],[End of life (fixed)]]-Table157[[#This Row],[Start year]],Table268[Generic Lifetime]) -> 50 | I6: 2025 | J6: =IF(Table157[[#This Row],[Lifetime Option]]="fixed",Table157[[#This Row],[End of life (fixed)]],Table157[[#This Row],[Start year]]+Table268[Generic Lifetime]) -> 2025 | K6: 0.962 | M6: http://economie.fgov.be/fr/consommateurs/Energie/Nucleaire/centrales_nucleaires/sortie_nucleaire/#.Vdb00Y7DVE4
C7: BE | D7: ENBE_TIHANGE-2_00 | E7: 1982 | F7: 1.3387206 | G7: fixed | H7: =IF(Table157[[#This Row],[Lifetime Option]]="fixed",Table157[[#This Row],[End of life (fixed)]]-Table157[[#This Row],[Start year]],Table268[Generic Lifetime]) -> 40 | I7: 2022 | J7: =IF(Table157[[#This Row],[Lifetime Option]]="fixed",Table157[[#This Row],[End of life (fixed)]],Table157[[#This Row],[Start year]]+Table268[Generic Lifetime]) -> 2022 | K7: 1.008 | L7: uncertain - follow up | M7: http://www.fanc.fgov.be/nl/news/doel-3/tihange-2-next-steps-of-the-review-process/766.aspx
C8: BE | D8: ENBE_TIHANGE-3_00 | E8: 1985 | F8: 1.417824 | G8: fixed | H8: =IF(Table157[[#This Row],[Lifetime Option]]="fixed",Table157[[#This Row],[End of life (fixed)]]-Table157[[#This Row],[Start year]],Table268[Generic Lifetime]) -> 40 | I8: 2025 | J8: =IF(Table157[[#This Row],[Lifetime Option]]="fixed",Table157[[#This Row],[End of life (fixed)]],Table157[[#This Row],[Start year]]+Table268[Generic Lifetime]) -> 2025 | K8: 1.046
C9: BG | D9: ENBG_KOZLODUY-3_00 | E9: 1980 | F9: 0.77 | G9: fixed | H9: =IF(Table157[[#This Row],[Lifetime Option]]="fixed",Table157[[#This Row],[End of life (fixed)]]-Table157[[#This Row],[Start year]],Table268[Generic Lifetime]) -> 26 | I9: 2006 | J9: =IF(Table157[[#This Row],[Lifetime Option]]="fixed",Table157[[#This Row],[End of life (fixed)]],Table157[[#This Row],[Start year]]+Table268[Generic Lifetime]) -> 2006 | K9: 0.408 | L9: closed
C10: BG | D10: ENBG_KOZLODUY-4_00 | E10: 1982 | F10: 0.77 | G10: fixed | H10: =IF(Table157[[#This Row],[Lifetime Option]]="fixed",Table157[[#This Row],[End of life (fixed)]]-Table157[[#This Row],[Start year]],Table268[Generic Lifetime]) -> 24 | I10: 2006 | J10: =IF(Table157[[#This Row],[Lifetime Option]]="fixed",Table157[[#This Row],[End of life (fixed)]],Table157[[#This Row],[Start year]]+Table268[Generic Lifetime]) -> 2006 | K10: 0.408 | L10: closed
C11: BG | D11: ENBG_KOZLODUY-5_00 | E11: 1987 | F11: 0.7776 | G11: generic | H11: =IF(Table157[[#This Row],[Lifetime Option]]="fixed",Table157[[#This Row],[End of life (fixed)]]-Table157[[#This Row],[Start year]],Table268[Generic Lifetime]) -> 40 | J11: =IF(Table157[[#This Row],[Lifetime Option]]="fixed",Table157[[#This Row],[End of life (fixed)]],Table157[[#This Row],[Start year]]+Table268[Generic Lifetime]) -> 2027 | K11: 0.953 | M11: http://www.world-nuclear.org/info/Country-Profiles/Countries-A-F/Bulgaria/
C12: BG | D12: ENBG_KOZLODUY-6_00 | E12: 1991 | F12: 0.7776 | G12: generic | H12: =IF(Table157[[#This Row],[Lifetime Option]]="fixed",Table157[[#This Row],[End of life (fixed)]]-Table157[[#This Row],[Start year]],Table268[Generic Lifetime]) -> 40 | J12: =IF(Table157[[#This Row],[Lifetime Option]]="fixed",Table157[[#This Row],[End of life (fixed)]],Table157[[#This Row],[Start year]]+Table268[Generic Lifetime]) -> 2031 | K12: 0.953 | M12: http://www.world-nuclear.org/info/Country-Profiles/Countries-A-F/Bulgaria/
C13: CH | D13: ENCH_BEZNAU-1_00 | E13: 1969 | F13: 1.2203044 | G13: fixed | H13: =IF(Table157[[#This Row],[Lifetime Option]]="fixed",Table157[[#This Row],[End of life (fixed)]]-Table157[[#This Row],[Start year]],Table268[Generic Lifetime]) -> 50 | I13: 2019 | J13: =IF(Table157[[#This Row],[Lifetime Option]]="fixed",Table157[[#This Row],[End of life (fixed)]],Table157[[#This Row],[Start year]]+Table268[Generic Lifetime]) -> 2019 | K13: 0.365 | L13: need to follow up political developments | M13: http://www.world-nuclear.org/info/Country-Profiles/Countries-O-S/Switzerland/
C14: CH | D14: ENCH_BEZNAU-2_00 | E14: 1971 | F14: 1.2203044 | G14: fixed | H14: =IF(Table157[[#This Row],[Lifetime Option]]="fixed",Table157[[#This Row],[End of life (fixed)]]-Table157[[#This Row],[Start year]],Table268[Generic Lifetime]) -> 50 | I14: 2021 | J14: =IF(Table157[[#This Row],[Lifetime Option]]="fixed",Table157[[#This Row],[End of life (fixed)]],Table157[[#This Row],[Start year]]+Table268[Generic Lifetime]) -> 2021 | K14: 0.365 | L14: need to follow up political developments | M14: http://www.world-nuclear.org/info/Country-Profiles/Countries-O-S/Switzerland/
C15: CH | D15: ENCH_GOESGEN_00 | E15: 1979 | F15: 1.5489833 | G15: fixed | H15: =IF(Table157[[#This Row],[Lifetime Option]]="fixed",Table157[[#This Row],[End of life (fixed)]]-Table157[[#This Row],[Start year]],Table268[Generic Lifetime]) -> 50 | I15: 2029 | J15: =IF(Table157[[#This Row],[Lifetime Option]]="fixed",Table157[[#This Row],[End of life (fixed)]],Table157[[#This Row],[Start year]]+Table268[Generic Lifetime]) -> 2029 | K15: 0.985 | L15: need to follow up political developments | M15: http://www.world-nuclear.org/info/Country-Profiles/Countries-O-S/Switzerland/
C16: CH | D16: ENCH_LEIBSTADT_00 | E16: 1984 | F16: 1.28484 | G16: fixed | H16: =IF(Table157[[#This Row],[Lifetime Option]]="fixed",Table157[[#This Row],[End of life (fixed)]]-Table157[[#This Row],[Start year]],Table268[Generic Lifetime]) -> 50 | I16: 2034 | J16: =IF(Table157[[#This Row],[Lifetime Option]]="fixed",Table157[[#This Row],[End of life (fixed)]],Table157[[#This Row],[Start year]]+Table268[Generic Lifetime]) -> 2034 | K16: 1.22 | L16: need to follow up political developments | M16: http://www.world-nuclear.org/info/Country-Profiles/Countries-O-S/Switzerland/
C17: CH | D17: ENCH_MUEHLEBERG_00 | E17: 1971 | F17: 1.474392 | G17: fixed | H17: =IF(Table157[[#This Row],[Lifetime Option]]="fixed",Table157[[#This Row],[End of life (fixed)]]-Table157[[#This Row],[Start year]],Table268[Generic Lifetime]) -> 48 | I17: 2019 | J17: =IF(Table157[[#This Row],[Lifetime Option]]="fixed",Table157[[#This Row],[End of life (fixed)]],Table157[[#This Row],[Start year]]+Table268[Generic Lifetime]) -> 2019 | K17: 0.373 | L17: need to follow up political developments | M17: http://www.world-nuclear.org/info/Country-Profiles/Countries-O-S/Switzerland/
C18: CZ | D18: ENCZ_DUKOVANY-1_00 | E18: 1985 | F18: 1.2607488 | G18: generic | H18: =IF(Table157[[#This Row],[Lifetime Option]]="fixed",Table157[[#This Row],[End of life (fixed)]]-Table157[[#This Row],[Start year]],Table268[Generic Lifetime]) -> 40 | J18: =IF(Table157[[#This Row],[Lifetime Option]]="fixed",Table157[[#This Row],[End of life (fixed)]],Table157[[#This Row],[Start year]]+Table268[Generic Lifetime]) -> 2025 | K18: 0.468 | M18: http://www.oecd-nea.org/ndd/pubs/2014/7197-bb-2014.pdf
C19: CZ | D19: ENCZ_DUKOVANY-2_00 | E19: 1986 | F19: 1.2607488 | G19: generic | H19: =IF(Table157[[#This Row],[Lifetime Option]]="fixed",Table157[[#This Row],[End of life (fixed)]]-Table157[[#This Row],[Start year]],Table268[Generic Lifetime]) -> 40 | J19: =IF(Table157[[#This Row],[Lifetime Option]]="fixed",Table157[[#This Row],[End of life (fixed)]],Table157[[#This Row],[Start year]]+Table268[Generic Lifetime]) -> 2026 | K19: 0.471
C20: CZ | D20: ENCZ_DUKOVANY-3_00 | E20: 1986 | F20: 1.3110781 | G20: generic | H20: =IF(Table157[[#This Row],[Lifetime Option]]="fixed",Table157[[#This Row],[End of life (fixed)]]-Table157[[#This Row],[Start year]],Table268[Generic Lifetime]) -> 40 | J20: =IF(Table157[[#This Row],[Lifetime Option]]="fixed",Table157[[#This Row],[End of life (fixed)]],Table157[[#This Row],[Start year]]+Table268[Generic Lifetime]) -> 2026 | K20: 0.468
C21: CZ | D21: ENCZ_DUKOVANY-4_00 | E21: 1987 | F21: 1.2607488 | G21: generic | H21: =IF(Table157[[#This Row],[Lifetime Option]]="fixed",Table157[[#This Row],[End of life (fixed)]]-Table157[[#This Row],[Start year]],Table268[Generic Lifetime]) -> 40 | J21: =IF(Table157[[#This Row],[Lifetime Option]]="fixed",Table157[[#This Row],[End of life (fixed)]],Table157[[#This Row],[Start year]]+Table268[Generic Lifetime]) -> 2027 | K21: 0.471
C22: CZ | D22: ENCZ_TEMELIN-1_00 | E22: 2000 | F22: 1.312848 | G22: generic | H22: =IF(Table157[[#This Row],[Lifetime Option]]="fixed",Table157[[#This Row],[End of life (fixed)]]-Table157[[#This Row],[Start year]],Table268[Generic Lifetime]) -> 40 | J22: =IF(Table157[[#This Row],[Lifetime Option]]="fixed",Table157[[#This Row],[End of life (fixed)]],Table157[[#This Row],[Start year]]+Table268[Generic Lifetime]) -> 2040 | K22: 0.963
C23: CZ | D23: ENCZ_TEMELIN-2_00 | E23: 2002 | F23: 1.312848 | G23: generic | H23: =IF(Table157[[#This Row],[Lifetime Option]]="fixed",Table157[[#This Row],[End of life (fixed)]]-Table157[[#This Row],[Start year]],Table268[Generic Lifetime]) -> 40 | J23: =IF(Table157[[#This Row],[Lifetime Option]]="fixed",Table157[[#This Row],[End of life (fixed)]],Table157[[#This Row],[Start year]]+Table268[Generic Lifetime]) -> 2042 | K23: 0.963
C24: DE | D24: ENDE_BIBLIS-A_00 | E24: 1974 | F24: 0.940896 | G24: fixed | H24: =IF(Table157[[#This Row],[Lifetime Option]]="fixed",Table157[[#This Row],[End of life (fixed)]]-Table157[[#This Row],[Start year]],Table268[Generic Lifetime]) -> 37 | I24: 2011 | J24: =IF(Table157[[#This Row],[Lifetime Option]]="fixed",Table157[[#This Row],[End of life (fixed)]],Table157[[#This Row],[Start year]]+Table268[Generic Lifetime]) -> 2011 | K24: 1.167 | L24: closed
C25: DE | D25: ENDE_BIBLIS-B_00 | E25: 1976 | F25: 0.940896 | G25: fixed | H25: =IF(Table157[[#This Row],[Lifetime Option]]="fixed",Table157[[#This Row],[End of life (fixed)]]-Table157[[#This Row],[Start year]],Table268[Generic Lifetime]) -> 35 | I25: 2011 | J25: =IF(Table157[[#This Row],[Lifetime Option]]="fixed",Table157[[#This Row],[End of life (fixed)]],Table157[[#This Row],[Start year]]+Table268[Generic Lifetime]) -> 2011 | K25: 1.24 | L25: closed
C26: DE | D26: ENDE_BROKDORF_KBR_00 | E26: 1986 | F26: 1.1147815 | G26: fixed | H26: =IF(Table157[[#This Row],[Lifetime Option]]="fixed",Table157[[#This Row],[End of life (fixed)]]-Table157[[#This Row],[Start year]],Table268[Generic Lifetime]) -> 35 | I26: 2021 | J26: =IF(Table157[[#This Row],[Lifetime Option]]="fixed",Table157[[#This Row],[End of life (fixed)]],Table157[[#This Row],[Start year]]+Table268[Generic Lifetime]) -> 2021 | K26: 1.41
C27: DE | D27: ENDE_BRUNSBUETTEL_00 | E27: 1976 | F27: 0.912384 | G27: fixed | H27: =IF(Table157[[#This Row],[Lifetime Option]]="fixed",Table157[[#This Row],[End of life (fixed)]]-Table157[[#This Row],[Start year]],Table268[Generic Lifetime]) -> 35 | I27: 2011 | J27: =IF(Table157[[#This Row],[Lifetime Option]]="fixed",Table157[[#This Row],[End of life (fixed)]],Table157[[#This Row],[Start year]]+Table268[Generic Lifetime]) -> 2011 | K27: 0.771 | L27: closed
C28: DE | D28: ENDE_EMSLAND_KKE_00 | E28: 1988 | F28: 1.0053818 | G28: fixed | H28: =IF(Table157[[#This Row],[Lifetime Option]]="fixed",Table157[[#This Row],[End of life (fixed)]]-Table157[[#This Row],[Start year]],Table268[Generic Lifetime]) -> 34 | I28: 2022 | J28: =IF(Table157[[#This Row],[Lifetime Option]]="fixed",Table157[[#This Row],[End of life (fixed)]],Table157[[#This Row],[Start year]]+Table268[Generic Lifetime]) -> 2022 | K28: 1.335 | M28: capacity according to operator website
C29: DE | D29: ENDE_GRAFENRHEINFELD_KKG_00 | E29: 1981 | F29: 1.0494215 | G29: fixed | H29: =IF(Table157[[#This Row],[Lifetime Option]]="fixed",Table157[[#This Row],[End of life (fixed)]]-Table157[[#This Row],[Start year]],Table268[Generic Lifetime]) -> 34 | I29: 2015 | J29: =IF(Table157[[#This Row],[Lifetime Option]]="fixed",Table157[[#This Row],[End of life (fixed)]],Table157[[#This Row],[Start year]]+Table268[Generic Lifetime]) -> 2015 | K29: 1.275 | L29: closed
C30: DE | D30: ENDE_GROHNDE_KWG_00 | E30: 1984 | F30: 1.07712 | G30: fixed | H30: =IF(Table157[[#This Row],[Lifetime Option]]="fixed",Table157[[#This Row],[End of life (fixed)]]-Table157[[#This Row],[Start year]],Table268[Generic Lifetime]) -> 37 | I30: 2021 | J30: =IF(Table157[[#This Row],[Lifetime Option]]="fixed",Table157[[#This Row],[End of life (fixed)]],Table157[[#This Row],[Start year]]+Table268[Generic Lifetime]) -> 2021 | K30: 1.36
C31: DE | D31: ENDE_GUNDREM-B_GUN-B_00 | E31: 1984 | F31: 0.8316 | G31: fixed | H31: =IF(Table157[[#This Row],[Lifetime Option]]="fixed",Table157[[#This Row],[End of life (fixed)]]-Table157[[#This Row],[Start year]],Table268[Generic Lifetime]) -> 33 | I31: 2017 | J31: =IF(Table157[[#This Row],[Lifetime Option]]="fixed",Table157[[#This Row],[End of life (fixed)]],Table157[[#This Row],[Start year]]+Table268[Generic Lifetime]) -> 2017 | K31: 1.284
C32: DE | D32: ENDE_GUNDREM-C_GUN-C_00 | E32: 1984 | F32: 0.8316 | G32: fixed | H32: =IF(Table157[[#This Row],[Lifetime Option]]="fixed",Table157[[#This Row],[End of life (fixed)]]-Table157[[#This Row],[Start year]],Table268[Generic Lifetime]) -> 37 | I32: 2021 | J32: =IF(Table157[[#This Row],[Lifetime Option]]="fixed",Table157[[#This Row],[End of life (fixed)]],Table157[[#This Row],[Start year]]+Table268[Generic Lifetime]) -> 2021 | K32: 1.288
C33: DE | D33: ENDE_ISAR-1_00 | E33: 1988 | F33: 1.28304 | G33: fixed | H33: =IF(Table157[[#This Row],[Lifetime Option]]="fixed",Table157[[#This Row],[End of life (fixed)]]-Table157[[#This Row],[Start year]],Table268[Generic Lifetime]) -> 23 | I33: 2011 | J33: =IF(Table157[[#This Row],[Lifetime Option]]="fixed",Table157[[#This Row],[End of life (fixed)]],Table157[[#This Row],[Start year]]+Table268[Generic Lifetime]) -> 2011 | K33: 0.878 | L33: closed
C34: DE | D34: ENDE_ISAR-2_KKI2_00 | E34: 1988 | F34: 1.0394248 | G34: fixed | H34: =IF(Table157[[#This Row],[Lifetime Option]]="fixed",Table157[[#This Row],[End of life (fixed)]]-Table157[[#This Row],[Start year]],Table268[Generic Lifetime]) -> 34 | I34: 2022 | J34: =IF(Table157[[#This Row],[Lifetime Option]]="fixed",Table157[[#This Row],[End of life (fixed)]],Table157[[#This Row],[Start year]]+Table268[Generic Lifetime]) -> 2022 | K34: 1.41
C35: DE | D35: ENDE_KRUEMMEL_00 | E35: 1983 | F35: 0.912384 | G35: fixed | H35: =IF(Table157[[#This Row],[Lifetime Option]]="fixed",Table157[[#This Row],[End of life (fixed)]]-Table157[[#This Row],[Start year]],Table268[Generic Lifetime]) -> 28 | I35: 2011 | J35: =IF(Table157[[#This Row],[Lifetime Option]]="fixed",Table157[[#This Row],[End of life (fixed)]],Table157[[#This Row],[Start year]]+Table268[Generic Lifetime]) -> 2011 | K35: 1.26
C36: DE | D36: ENDE_NECKARWEST-2_GKN2_00 | E36: 1989 | F36: 1.4452364 | G36: fixed | H36: =IF(Table157[[#This Row],[Lifetime Option]]="fixed",Table157[[#This Row],[End of life (fixed)]]-Table157[[#This Row],[Start year]],Table268[Generic Lifetime]) -> 33 | I36: 2022 | J36: =IF(Table157[[#This Row],[Lifetime Option]]="fixed",Table157[[#This Row],[End of life (fixed)]],Table157[[#This Row],[Start year]]+Table268[Generic Lifetime]) -> 2022 | K36: 1.31
C37: DE | D37: ENDE_NECKARWESTHEIM-1_00 | E37: 1976 | F37: 1.0463904 | G37: fixed | H37: =IF(Table157[[#This Row],[Lifetime Option]]="fixed",Table157[[#This Row],[End of life (fixed)]]-Table157[[#This Row],[Start year]],Table268[Generic Lifetime]) -> 35 | I37: 2011 | J37: =IF(Table157[[#This Row],[Lifetime Option]]="fixed",Table157[[#This Row],[End of life (fixed)]],Table157[[#This Row],[Start year]]+Table268[Generic Lifetime]) -> 2011 | K37: 0.785 | L37: closed
C38: DE | D38: ENDE_PHILIPPSBURG-1_00 | E38: 1979 | F38: 1.1376288 | G38: fixed | H38: =IF(Table157[[#This Row],[Lifetime Option]]="fixed",Table157[[#This Row],[End of life (fixed)]]-Table157[[#This Row],[Start year]],Table268[Generic Lifetime]) -> 32 | I38: 2011 | J38: =IF(Table157[[#This Row],[Lifetime Option]]="fixed",Table157[[#This Row],[End of life (fixed)]],Table157[[#This Row],[Start year]]+Table268[Generic Lifetime]) -> 2011 | K38: 0.89 | L38: closed
C39: DE | D39: ENDE_PHILIPPSBURG-2_KKP2_00 | E39: 1984 | F39: 1.0596358 | G39: fixed | H39: =IF(Table157[[#This Row],[Lifetime Option]]="fixed",Table157[[#This Row],[End of life (fixed)]]-Table157[[#This Row],[Start year]],Table268[Generic Lifetime]) -> 35 | I39: 2019 | J39: =IF(Table157[[#This Row],[Lifetime Option]]="fixed",Table157[[#This Row],[End of life (fixed)]],Table157[[#This Row],[Start year]]+Table268[Generic Lifetime]) -> 2019 | K39: 1.402
C40: DE | D40: ENDE_UNTERWESER_00 | E40: 1978 | F40: 1.0093248 | G40: fixed | H40: =IF(Table157[[#This Row],[Lifetime Option]]="fixed",Table157[[#This Row],[End of life (fixed)]]-Table157[[#This Row],[Start year]],Table268[Generic Lifetime]) -> 33 | I40: 2011 | J40: =IF(Table157[[#This Row],[Lifetime Option]]="fixed",Table157[[#This Row],[End of life (fixed)]],Table157[[#This Row],[Start year]]+Table268[Generic Lifetime]) -> 2011 | K40: 1.345 | L40: closed
...

Sheet Existing plants_SCEN50yrs
A1: Generic Lifetime | C1: Member State | D1: Process | E1: Start year | F1: Efficiency PJ/tU | G1: Lifetime Option | H1: Tlife yrs | I1: End of life (fixed) | J1: End of life | K1: Existing capacity GW | L1: Comments | M1: Source
A2: 50 | C2: BE | D2: ENBE_DOEL-1_00 | E2: 1974 | F2: 1.3464165 | G2: fixed | H2: =IF(Table15[[#This Row],[Lifetime Option]]="fixed",Table15[[#This Row],[End of life (fixed)]]-Table15[[#This Row],[Start year]],Table26[Generic Lifetime]) -> 51 | I2: 2025 | J2: =IF(Table15[[#This Row],[Lifetime Option]]="fixed",Table15[[#This Row],[End of life (fixed)]],Table15[[#This Row],[Start year]]+Table26[Generic Lifetime]) -> 2025 | K2: 0.433 | M2: http://www.engie.com/en/journalists/press-releases/agreement-conditions-extending-doel-1-doel-2-new-nuclear-contribution-system/
C3: BE | D3: ENBE_DOEL-2_00 | E3: 1975 | F3: 1.3464165 | G3: fixed | H3: =IF(Table15[[#This Row],[Lifetime Option]]="fixed",Table15[[#This Row],[End of life (fixed)]]-Table15[[#This Row],[Start year]],Table26[Generic Lifetime]) -> 50 | I3: 2025 | J3: =IF(Table15[[#This Row],[Lifetime Option]]="fixed",Table15[[#This Row],[End of life (fixed)]],Table15[[#This Row],[Start year]]+Table26[Generic Lifetime]) -> 2025 | K3: 0.433 | M3: http://www.engie.com/en/journalists/press-releases/agreement-conditions-extending-doel-1-doel-2-new-nuclear-contribution-system/
C4: BE | D4: ENBE_DOEL-3_00 | E4: 1982 | F4: 1.4638774 | G4: fixed | H4: =IF(Table15[[#This Row],[Lifetime Option]]="fixed",Table15[[#This Row],[End of life (fixed)]]-Table15[[#This Row],[Start year]],Table26[Generic Lifetime]) -> 40 | I4: 2022 | J4: =IF(Table15[[#This Row],[Lifetime Option]]="fixed",Table15[[#This Row],[End of life (fixed)]],Table15[[#This Row],[Start year]]+Table26[Generic Lifetime]) -> 2022 | K4: 1.006 | L4: uncertain - follow up | M4: http://www.fanc.fgov.be/nl/news/doel-3/tihange-2-next-steps-of-the-review-process/766.aspx
C5: BE | D5: ENBE_DOEL-4_00 | E5: 1985 | F5: 1.4183133 | G5: fixed | H5: =IF(Table15[[#This Row],[Lifetime Option]]="fixed",Table15[[#This Row],[End of life (fixed)]]-Table15[[#This Row],[Start year]],Table26[Generic Lifetime]) -> 40 | I5: 2025 | J5: =IF(Table15[[#This Row],[Lifetime Option]]="fixed",Table15[[#This Row],[End of life (fixed)]],Table15[[#This Row],[Start year]]+Table26[Generic Lifetime]) -> 2025 | K5: 1.039
C6: BE | D6: ENBE_TIHANGE-1_00 | E6: 1975 | F6: 1.3654688 | G6: fixed | H6: =IF(Table15[[#This Row],[Lifetime Option]]="fixed",Table15[[#This Row],[End of life (fixed)]]-Table15[[#This Row],[Start year]],Table26[Generic Lifetime]) -> 50 | I6: 2025 | J6: =IF(Table15[[#This Row],[Lifetime Option]]="fixed",Table15[[#This Row],[End of life (fixed)]],Table15[[#This Row],[Start year]]+Table26[Generic Lifetime]) -> 2025 | K6: 0.962 | M6: http://economie.fgov.be/fr/consommateurs/Energie/Nucleaire/centrales_nucleaires/sortie_nucleaire/#.Vdb00Y7DVE4
C7: BE | D7: ENBE_TIHANGE-2_00 | E7: 1982 | F7: 1.3387206 | G7: fixed | H7: =IF(Table15[[#This Row],[Lifetime Option]]="fixed",Table15[[#This Row],[End of life (fixed)]]-Table15[[#This Row],[Start year]],Table26[Generic Lifetime]) -> 40 | I7: 2022 | J7: =IF(Table15[[#This Row],[Lifetime Option]]="fixed",Table15[[#This Row],[End of life (fixed)]],Table15[[#This Row],[Start year]]+Table26[Generic Lifetime]) -> 2022 | K7: 1.008 | L7: uncertain - follow up | M7: http://www.fanc.fgov.be/nl/news/doel-3/tihange-2-next-steps-of-the-review-process/766.aspx
C8: BE | D8: ENBE_TIHANGE-3_00 | E8: 1985 | F8: 1.417824 | G8: fixed | H8: =IF(Table15[[#This Row],[Lifetime Option]]="fixed",Table15[[#This Row],[End of life (fixed)]]-Table15[[#This Row],[Start year]],Table26[Generic Lifetime]) -> 40 | I8: 2025 | J8: =IF(Table15[[#This Row],[Lifetime Option]]="fixed",Table15[[#This Row],[End of life (fixed)]],Table15[[#This Row],[Start year]]+Table26[Generic Lifetime]) -> 2025 | K8: 1.046
C9: BG | D9: ENBG_KOZLODUY-3_00 | E9: 1980 | F9: 0.77 | G9: fixed | H9: =IF(Table15[[#This Row],[Lifetime Option]]="fixed",Table15[[#This Row],[End of life (fixed)]]-Table15[[#This Row],[Start year]],Table26[Generic Lifetime]) -> 26 | I9: 2006 | J9: =IF(Table15[[#This Row],[Lifetime Option]]="fixed",Table15[[#This Row],[End of life (fixed)]],Table15[[#This Row],[Start year]]+Table26[Generic Lifetime]) -> 2006 | K9: 0.408 | L9: closed
C10: BG | D10: ENBG_KOZLODUY-4_00 | E10: 1982 | F10: 0.77 | G10: fixed | H10: =IF(Table15[[#This Row],[Lifetime Option]]="fixed",Table15[[#This Row],[End of life (fixed)]]-Table15[[#This Row],[Start year]],Table26[Generic Lifetime]) -> 24 | I10: 2006 | J10: =IF(Table15[[#This Row],[Lifetime Option]]="fixed",Table15[[#This Row],[End of life (fixed)]],Table15[[#This Row],[Start year]]+Table26[Generic Lifetime]) -> 2006 | K10: 0.408 | L10: closed
C11: BG | D11: ENBG_KOZLODUY-5_00 | E11: 1987 | F11: 0.7776 | G11: generic | H11: =IF(Table15[[#This Row],[Lifetime Option]]="fixed",Table15[[#This Row],[End of life (fixed)]]-Table15[[#This Row],[Start year]],Table26[Generic Lifetime]) -> 50 | J11: =IF(Table15[[#This Row],[Lifetime Option]]="fixed",Table15[[#This Row],[End of life (fixed)]],Table15[[#This Row],[Start year]]+Table26[Generic Lifetime]) -> 2037 | K11: 0.953 | M11: http://www.world-nuclear.org/info/Country-Profiles/Countries-A-F/Bulgaria/
C12: BG | D12: ENBG_KOZLODUY-6_00 | E12: 1991 | F12: 0.7776 | G12: generic | H12: =IF(Table15[[#This Row],[Lifetime Option]]="fixed",Table15[[#This Row],[End of life (fixed)]]-Table15[[#This Row],[Start year]],Table26[Generic Lifetime]) -> 50 | J12: =IF(Table15[[#This Row],[Lifetime Option]]="fixed",Table15[[#This Row],[End of life (fixed)]],Table15[[#This Row],[Start year]]+Table26[Generic Lifetime]) -> 2041 | K12: 0.953 | M12: http://www.world-nuclear.org/info/Country-Profiles/Countries-A-F/Bulgaria/
C13: CH | D13: ENCH_BEZNAU-1_00 | E13: 1969 | F13: 1.2203044 | G13: fixed | H13: =IF(Table15[[#This Row],[Lifetime Option]]="fixed",Table15[[#This Row],[End of life (fixed)]]-Table15[[#This Row],[Start year]],Table26[Generic Lifetime]) -> 50 | I13: 2019 | J13: =IF(Table15[[#This Row],[Lifetime Option]]="fixed",Table15[[#This Row],[End of life (fixed)]],Table15[[#This Row],[Start year]]+Table26[Generic Lifetime]) -> 2019 | K13: 0.365 | L13: need to follow up political developments | M13: http://www.world-nuclear.org/info/Country-Profiles/Countries-O-S/Switzerland/
C14: CH | D14: ENCH_BEZNAU-2_00 | E14: 1971 | F14: 1.2203044 | G14: fixed | H14: =IF(Table15[[#This Row],[Lifetime Option]]="fixed",Table15[[#This Row],[End of life (fixed)]]-Table15[[#This Row],[Start year]],Table26[Generic Lifetime]) -> 50 | I14: 2021 | J14: =IF(Table15[[#This Row],[Lifetime Option]]="fixed",Table15[[#This Row],[End of life (fixed)]],Table15[[#This Row],[Start year]]+Table26[Generic Lifetime]) -> 2021 | K14: 0.365 | L14: need to follow up political developments | M14: http://www.world-nuclear.org/info/Country-Profiles/Countries-O-S/Switzerland/
C15: CH | D15: ENCH_GOESGEN_00 | E15: 1979 | F15: 1.5489833 | G15: fixed | H15: =IF(Table15[[#This Row],[Lifetime Option]]="fixed",Table15[[#This Row],[End of life (fixed)]]-Table15[[#This Row],[Start year]],Table26[Generic Lifetime]) -> 50 | I15: 2029 | J15: =IF(Table15[[#This Row],[Lifetime Option]]="fixed",Table15[[#This Row],[End of life (fixed)]],Table15[[#This Row],[Start year]]+Table26[Generic Lifetime]) -> 2029 | K15: 0.985 | L15: need to follow up political developments | M15: http://www.world-nuclear.org/info/Country-Profiles/Countries-O-S/Switzerland/
C16: CH | D16: ENCH_LEIBSTADT_00 | E16: 1984 | F16: 1.28484 | G16: fixed | H16: =IF(Table15[[#This Row],[Lifetime Option]]="fixed",Table15[[#This Row],[End of life (fixed)]]-Table15[[#This Row],[Start year]],Table26[Generic Lifetime]) -> 50 | I16: 2034 | J16: =IF(Table15[[#This Row],[Lifetime Option]]="fixed",Table15[[#This Row],[End of life (fixed)]],Table15[[#This Row],[Start year]]+Table26[Generic Lifetime]) -> 2034 | K16: 1.22 | L16: need to follow up political developments | M16: http://www.world-nuclear.org/info/Country-Profiles/Countries-O-S/Switzerland/
C17: CH | D17: ENCH_MUEHLEBERG_00 | E17: 1971 | F17: 1.474392 | G17: fixed | H17: =IF(Table15[[#This Row],[Lifetime Option]]="fixed",Table15[[#This Row],[End of life (fixed)]]-Table15[[#This Row],[Start year]],Table26[Generic Lifetime]) -> 48 | I17: 2019 | J17: =IF(Table15[[#This Row],[Lifetime Option]]="fixed",Table15[[#This Row],[End of life (fixed)]],Table15[[#This Row],[Start year]]+Table26[Generic Lifetime]) -> 2019 | K17: 0.373 | L17: need to follow up political developments | M17: http://www.world-nuclear.org/info/Country-Profiles/Countries-O-S/Switzerland/
C18: CZ | D18: ENCZ_DUKOVANY-1_00 | E18: 1985 | F18: 1.2607488 | G18: generic | H18: =IF(Table15[[#This Row],[Lifetime Option]]="fixed",Table15[[#This Row],[End of life (fixed)]]-Table15[[#This Row],[Start year]],Table26[Generic Lifetime]) -> 50 | J18: =IF(Table15[[#This Row],[Lifetime Option]]="fixed",Table15[[#This Row],[End of life (fixed)]],Table15[[#This Row],[Start year]]+Table26[Generic Lifetime]) -> 2035 | K18: 0.468 | M18: http://www.oecd-nea.org/ndd/pubs/2014/7197-bb-2014.pdf
C19: CZ | D19: ENCZ_DUKOVANY-2_00 | E19: 1986 | F19: 1.2607488 | G19: generic | H19: =IF(Table15[[#This Row],[Lifetime Option]]="fixed",Table15[[#This Row],[End of life (fixed)]]-Table15[[#This Row],[Start year]],Table26[Generic Lifetime]) -> 50 | J19: =IF(Table15[[#This Row],[Lifetime Option]]="fixed",Table15[[#This Row],[End of life (fixed)]],Table15[[#This Row],[Start year]]+Table26[Generic Lifetime]) -> 2036 | K19: 0.471
C20: CZ | D20: ENCZ_DUKOVANY-3_00 | E20: 1986 | F20: 1.3110781 | G20: generic | H20: =IF(Table15[[#This Row],[Lifetime Option]]="fixed",Table15[[#This Row],[End of life (fixed)]]-Table15[[#This Row],[Start year]],Table26[Generic Lifetime]) -> 50 | J20: =IF(Table15[[#This Row],[Lifetime Option]]="fixed",Table15[[#This Row],[End of life (fixed)]],Table15[[#This Row],[Start year]]+Table26[Generic Lifetime]) -> 2036 | K20: 0.468
C21: CZ | D21: ENCZ_DUKOVANY-4_00 | E21: 1987 | F21: 1.2607488 | G21: generic | H21: =IF(Table15[[#This Row],[Lifetime Option]]="fixed",Table15[[#This Row],[End of life (fixed)]]-Table15[[#This Row],[Start year]],Table26[Generic Lifetime]) -> 50 | J21: =IF(Table15[[#This Row],[Lifetime Option]]="fixed",Table15[[#This Row],[End of life (fixed)]],Table15[[#This Row],[Start year]]+Table26[Generic Lifetime]) -> 2037 | K21: 0.471
C22: CZ | D22: ENCZ_TEMELIN-1_00 | E22: 2000 | F22: 1.312848 | G22: generic | H22: =IF(Table15[[#This Row],[Lifetime Option]]="fixed",Table15[[#This Row],[End of life (fixed)]]-Table15[[#This Row],[Start year]],Table26[Generic Lifetime]) -> 50 | J22: =IF(Table15[[#This Row],[Lifetime Option]]="fixed",Table15[[#This Row],[End of life (fixed)]],Table15[[#This Row],[Start year]]+Table26[Generic Lifetime]) -> 2050 | K22: 0.963
C23: CZ | D23: ENCZ_TEMELIN-2_00 | E23: 2002 | F23: 1.312848 | G23: generic | H23: =IF(Table15[[#This Row],[Lifetime Option]]="fixed",Table15[[#This Row],[End of life (fixed)]]-Table15[[#This Row],[Start year]],Table26[Generic Lifetime]) -> 50 | J23: =IF(Table15[[#This Row],[Lifetime Option]]="fixed",Table15[[#This Row],[End of life (fixed)]],Table15[[#This Row],[Start year]]+Table26[Generic Lifetime]) -> 2052 | K23: 0.963
C24: DE | D24: ENDE_BIBLIS-A_00 | E24: 1974 | F24: 0.940896 | G24: fixed | H24: =IF(Table15[[#This Row],[Lifetime Option]]="fixed",Table15[[#This Row],[End of life (fixed)]]-Table15[[#This Row],[Start year]],Table26[Generic Lifetime]) -> 37 | I24: 2011 | J24: =IF(Table15[[#This Row],[Lifetime Option]]="fixed",Table15[[#This Row],[End of life (fixed)]],Table15[[#This Row],[Start year]]+Table26[Generic Lifetime]) -> 2011 | K24: 1.167 | L24: closed
C25: DE | D25: ENDE_BIBLIS-B_00 | E25: 1976 | F25: 0.940896 | G25: fixed | H25: =IF(Table15[[#This Row],[Lifetime Option]]="fixed",Table15[[#This Row],[End of life (fixed)]]-Table15[[#This Row],[Start year]],Table26[Generic Lifetime]) -> 35 | I25: 2011 | J25: =IF(Table15[[#This Row],[Lifetime Option]]="fixed",Table15[[#This Row],[End of life (fixed)]],Table15[[#This Row],[Start year]]+Table26[Generic Lifetime]) -> 2011 | K25: 1.24 | L25: closed
C26: DE | D26: ENDE_BROKDORF_KBR_00 | E26: 1986 | F26: 1.1147815 | G26: fixed | H26: =IF(Table15[[#This Row],[Lifetime Option]]="fixed",Table15[[#This Row],[End of life (fixed)]]-Table15[[#This Row],[Start year]],Table26[Generic Lifetime]) -> 35 | I26: 2021 | J26: =IF(Table15[[#This Row],[Lifetime Option]]="fixed",Table15[[#This Row],[End of life (fixed)]],Table15[[#This Row],[Start year]]+Table26[Generic Lifetime]) -> 2021 | K26: 1.41
C27: DE | D27: ENDE_BRUNSBUETTEL_00 | E27: 1976 | F27: 0.912384 | G27: fixed | H27: =IF(Table15[[#This Row],[Lifetime Option]]="fixed",Table15[[#This Row],[End of life (fixed)]]-Table15[[#This Row],[Start year]],Table26[Generic Lifetime]) -> 35 | I27: 2011 | J27: =IF(Table15[[#This Row],[Lifetime Option]]="fixed",Table15[[#This Row],[End of life (fixed)]],Table15[[#This Row],[Start year]]+Table26[Generic Lifetime]) -> 2011 | K27: 0.771 | L27: closed
C28: DE | D28: ENDE_EMSLAND_KKE_00 | E28: 1988 | F28: 1.0053818 | G28: fixed | H28: =IF(Table15[[#This Row],[Lifetime Option]]="fixed",Table15[[#This Row],[End of life (fixed)]]-Table15[[#This Row],[Start year]],Table26[Generic Lifetime]) -> 34 | I28: 2022 | J28: =IF(Table15[[#This Row],[Lifetime Option]]="fixed",Table15[[#This Row],[End of life (fixed)]],Table15[[#This Row],[Start year]]+Table26[Generic Lifetime]) -> 2022 | K28: 1.335 | M28: capacity according to operator website
C29: DE | D29: ENDE_GRAFENRHEINFELD_KKG_00 | E29: 1981 | F29: 1.0494215 | G29: fixed | H29: =IF(Table15[[#This Row],[Lifetime Option]]="fixed",Table15[[#This Row],[End of life (fixed)]]-Table15[[#This Row],[Start year]],Table26[Generic Lifetime]) -> 34 | I29: 2015 | J29: =IF(Table15[[#This Row],[Lifetime Option]]="fixed",Table15[[#This Row],[End of life (fixed)]],Table15[[#This Row],[Start year]]+Table26[Generic Lifetime]) -> 2015 | K29: 1.275 | L29: closed
C30: DE | D30: ENDE_GROHNDE_KWG_00 | E30: 1984 | F30: 1.07712 | G30: fixed | H30: =IF(Table15[[#This Row],[Lifetime Option]]="fixed",Table15[[#This Row],[End of life (fixed)]]-Table15[[#This Row],[Start year]],Table26[Generic Lifetime]) -> 37 | I30: 2021 | J30: =IF(Table15[[#This Row],[Lifetime Option]]="fixed",Table15[[#This Row],[End of life (fixed)]],Table15[[#This Row],[Start year]]+Table26[Generic Lifetime]) -> 2021 | K30: 1.36
C31: DE | D31: ENDE_GUNDREM-B_GUN-B_00 | E31: 1984 | F31: 0.8316 | G31: fixed | H31: =IF(Table15[[#This Row],[Lifetime Option]]="fixed",Table15[[#This Row],[End of life (fixed)]]-Table15[[#This Row],[Start year]],Table26[Generic Lifetime]) -> 33 | I31: 2017 | J31: =IF(Table15[[#This Row],[Lifetime Option]]="fixed",Table15[[#This Row],[End of life (fixed)]],Table15[[#This Row],[Start year]]+Table26[Generic Lifetime]) -> 2017 | K31: 1.284
C32: DE | D32: ENDE_GUNDREM-C_GUN-C_00 | E32: 1984 | F32: 0.8316 | G32: fixed | H32: =IF(Table15[[#This Row],[Lifetime Option]]="fixed",Table15[[#This Row],[End of life (fixed)]]-Table15[[#This Row],[Start year]],Table26[Generic Lifetime]) -> 37 | I32: 2021 | J32: =IF(Table15[[#This Row],[Lifetime Option]]="fixed",Table15[[#This Row],[End of life (fixed)]],Table15[[#This Row],[Start year]]+Table26[Generic Lifetime]) -> 2021 | K32: 1.288
C33: DE | D33: ENDE_ISAR-1_00 | E33: 1988 | F33: 1.28304 | G33: fixed | H33: =IF(Table15[[#This Row],[Lifetime Option]]="fixed",Table15[[#This Row],[End of life (fixed)]]-Table15[[#This Row],[Start year]],Table26[Generic Lifetime]) -> 23 | I33: 2011 | J33: =IF(Table15[[#This Row],[Lifetime Option]]="fixed",Table15[[#This Row],[End of life (fixed)]],Table15[[#This Row],[Start year]]+Table26[Generic Lifetime]) -> 2011 | K33: 0.878 | L33: closed
C34: DE | D34: ENDE_ISAR-2_KKI2_00 | E34: 1988 | F34: 1.0394248 | G34: fixed | H34: =IF(Table15[[#This Row],[Lifetime Option]]="fixed",Table15[[#This Row],[End of life (fixed)]]-Table15[[#This Row],[Start year]],Table26[Generic Lifetime]) -> 34 | I34: 2022 | J34: =IF(Table15[[#This Row],[Lifetime Option]]="fixed",Table15[[#This Row],[End of life (fixed)]],Table15[[#This Row],[Start year]]+Table26[Generic Lifetime]) -> 2022 | K34: 1.41
C35: DE | D35: ENDE_KRUEMMEL_00 | E35: 1983 | F35: 0.912384 | G35: fixed | H35: =IF(Table15[[#This Row],[Lifetime Option]]="fixed",Table15[[#This Row],[End of life (fixed)]]-Table15[[#This Row],[Start year]],Table26[Generic Lifetime]) -> 28 | I35: 2011 | J35: =IF(Table15[[#This Row],[Lifetime Option]]="fixed",Table15[[#This Row],[End of life (fixed)]],Table15[[#This Row],[Start year]]+Table26[Generic Lifetime]) -> 2011 | K35: 1.26
C36: DE | D36: ENDE_NECKARWEST-2_GKN2_00 | E36: 1989 | F36: 1.4452364 | G36: fixed | H36: =IF(Table15[[#This Row],[Lifetime Option]]="fixed",Table15[[#This Row],[End of life (fixed)]]-Table15[[#This Row],[Start year]],Table26[Generic Lifetime]) -> 33 | I36: 2022 | J36: =IF(Table15[[#This Row],[Lifetime Option]]="fixed",Table15[[#This Row],[End of life (fixed)]],Table15[[#This Row],[Start year]]+Table26[Generic Lifetime]) -> 2022 | K36: 1.31
C37: DE | D37: ENDE_NECKARWESTHEIM-1_00 | E37: 1976 | F37: 1.0463904 | G37: fixed | H37: =IF(Table15[[#This Row],[Lifetime Option]]="fixed",Table15[[#This Row],[End of life (fixed)]]-Table15[[#This Row],[Start year]],Table26[Generic Lifetime]) -> 35 | I37: 2011 | J37: =IF(Table15[[#This Row],[Lifetime Option]]="fixed",Table15[[#This Row],[End of life (fixed)]],Table15[[#This Row],[Start year]]+Table26[Generic Lifetime]) -> 2011 | K37: 0.785 | L37: closed
C38: DE | D38: ENDE_PHILIPPSBURG-1_00 | E38: 1979 | F38: 1.1376288 | G38: fixed | H38: =IF(Table15[[#This Row],[Lifetime Option]]="fixed",Table15[[#This Row],[End of life (fixed)]]-Table15[[#This Row],[Start year]],Table26[Generic Lifetime]) -> 32 | I38: 2011 | J38: =IF(Table15[[#This Row],[Lifetime Option]]="fixed",Table15[[#This Row],[End of life (fixed)]],Table15[[#This Row],[Start year]]+Table26[Generic Lifetime]) -> 2011 | K38: 0.89 | L38: closed
C39: DE | D39: ENDE_PHILIPPSBURG-2_KKP2_00 | E39: 1984 | F39: 1.0596358 | G39: fixed | H39: =IF(Table15[[#This Row],[Lifetime Option]]="fixed",Table15[[#This Row],[End of life (fixed)]]-Table15[[#This Row],[Start year]],Table26[Generic Lifetime]) -> 35 | I39: 2019 | J39: =IF(Table15[[#This Row],[Lifetime Option]]="fixed",Table15[[#This Row],[End of life (fixed)]],Table15[[#This Row],[Start year]]+Table26[Generic Lifetime]) -> 2019 | K39: 1.402
C40: DE | D40: ENDE_UNTERWESER_00 | E40: 1978 | F40: 1.0093248 | G40: fixed | H40: =IF(Table15[[#This Row],[Lifetime Option]]="fixed",Table15[[#This Row],[End of life (fixed)]]-Table15[[#This Row],[Start year]],Table26[Generic Lifetime]) -> 33 | I40: 2011 | J40: =IF(Table15[[#This Row],[Lifetime Option]]="fixed",Table15[[#This Row],[End of life (fixed)]],Table15[[#This Row],[Start year]]+Table26[Generic Lifetime]) -> 2011 | K40: 1.345 | L40: closed
...

Sheet Existing plants_SCEN60yrs
A1: Generic Lifetime | C1: Member State | D1: Process | E1: Start year | F1: Efficiency PJ/tU | G1: Lifetime Option | H1: Tlife yrs | I1: End of life (fixed) | J1: End of life | K1: Existing capacity GW | L1: Comments | M1: Source
A2: 60 | C2: BE | D2: ENBE_DOEL-1_00 | E2: 1974 | F2: 1.3464165 | G2: fixed | H2: =IF(Table1[[#This Row],[Lifetime Option]]="fixed",Table1[[#This Row],[End of life (fixed)]]-Table1[[#This Row],[Start year]],Table2[Generic Lifetime]) -> 51 | I2: 2025 | J2: =IF(Table1[[#This Row],[Lifetime Option]]="fixed",Table1[[#This Row],[End of life (fixed)]],Table1[[#This Row],[Start year]]+Table2[Generic Lifetime]) -> 2025 | K2: 0.433 | M2: http://www.engie.com/en/journalists/press-releases/agreement-conditions-extending-doel-1-doel-2-new-nuclear-contribution-system/
C3: BE | D3: ENBE_DOEL-2_00 | E3: 1975 | F3: 1.3464165 | G3: fixed | H3: =IF(Table1[[#This Row],[Lifetime Option]]="fixed",Table1[[#This Row],[End of life (fixed)]]-Table1[[#This Row],[Start year]],Table2[Generic Lifetime]) -> 50 | I3: 2025 | J3: =IF(Table1[[#This Row],[Lifetime Option]]="fixed",Table1[[#This Row],[End of life (fixed)]],Table1[[#This Row],[Start year]]+Table2[Generic Lifetime]) -> 2025 | K3: 0.433 | M3: http://www.engie.com/en/journalists/press-releases/agreement-conditions-extending-doel-1-doel-2-new-nuclear-contribution-system/
C4: BE | D4: ENBE_DOEL-3_00 | E4: 1982 | F4: 1.4638774 | G4: fixed | H4: =IF(Table1[[#This Row],[Lifetime Option]]="fixed",Table1[[#This Row],[End of life (fixed)]]-Table1[[#This Row],[Start year]],Table2[Generic Lifetime]) -> 40 | I4: 2022 | J4: =IF(Table1[[#This Row],[Lifetime Option]]="fixed",Table1[[#This Row],[End of life (fixed)]],Table1[[#This Row],[Start year]]+Table2[Generic Lifetime]) -> 2022 | K4: 1.006 | L4: uncertain - follow up | M4: http://www.fanc.fgov.be/nl/news/doel-3/tihange-2-next-steps-of-the-review-process/766.aspx
C5: BE | D5: ENBE_DOEL-4_00 | E5: 1985 | F5: 1.4183133 | G5: fixed | H5: =IF(Table1[[#This Row],[Lifetime Option]]="fixed",Table1[[#This Row],[End of life (fixed)]]-Table1[[#This Row],[Start year]],Table2[Generic Lifetime]) -> 40 | I5: 2025 | J5: =IF(Table1[[#This Row],[Lifetime Option]]="fixed",Table1[[#This Row],[End of life (fixed)]],Table1[[#This Row],[Start year]]+Table2[Generic Lifetime]) -> 2025 | K5: 1.039
C6: BE | D6: ENBE_TIHANGE-1_00 | E6: 1975 | F6: 1.3654688 | G6: fixed | H6: =IF(Table1[[#This Row],[Lifetime Option]]="fixed",Table1[[#This Row],[End of life (fixed)]]-Table1[[#This Row],[Start year]],Table2[Generic Lifetime]) -> 50 | I6: 2025 | J6: =IF(Table1[[#This Row],[Lifetime Option]]="fixed",Table1[[#This Row],[End of life (fixed)]],Table1[[#This Row],[Start year]]+Table2[Generic Lifetime]) -> 2025 | K6: 0.962 | M6: http://economie.fgov.be/fr/consommateurs/Energie/Nucleaire/centrales_nucleaires/sortie_nucleaire/#.Vdb00Y7DVE4
C7: BE | D7: ENBE_TIHANGE-2_00 | E7: 1982 | F7: 1.3387206 | G7: fixed | H7: =IF(Table1[[#This Row],[Lifetime Option]]="fixed",Table1[[#This Row],[End of life (fixed)]]-Table1[[#This Row],[Start year]],Table2[Generic Lifetime]) -> 40 | I7: 2022 | J7: =IF(Table1[[#This Row],[Lifetime Option]]="fixed",Table1[[#This Row],[End of life (fixed)]],Table1[[#This Row],[Start year]]+Table2[Generic Lifetime]) -> 2022 | K7: 1.008 | L7: uncertain - follow up | M7: http://www.fanc.fgov.be/nl/news/doel-3/tihange-2-next-steps-of-the-review-process/766.aspx
C8: BE | D8: ENBE_TIHANGE-3_00 | E8: 1985 | F8: 1.417824 | G8: fixed | H8: =IF(Table1[[#This Row],[Lifetime Option]]="fixed",Table1[[#This Row],[End of life (fixed)]]-Table1[[#This Row],[Start year]],Table2[Generic Lifetime]) -> 40 | I8: 2025 | J8: =IF(Table1[[#This Row],[Lifetime Option]]="fixed",Table1[[#This Row],[End of life (fixed)]],Table1[[#This Row],[Start year]]+Table2[Generic Lifetime]) -> 2025 | K8: 1.046
C9: BG | D9: ENBG_KOZLODUY-3_00 | E9: 1980 | F9: 0.77 | G9: fixed | H9: =IF(Table1[[#This Row],[Lifetime Option]]="fixed",Table1[[#This Row],[End of life (fixed)]]-Table1[[#This Row],[Start year]],Table2[Generic Lifetime]) -> 26 | I9: 2006 | J9: =IF(Table1[[#This Row],[Lifetime Option]]="fixed",Table1[[#This Row],[End of life (fixed)]],Table1[[#This Row],[Start year]]+Table2[Generic Lifetime]) -> 2006 | K9: 0.408 | L9: closed
C10: BG | D10: ENBG_KOZLODUY-4_00 | E10: 1982 | F10: 0.77 | G10: fixed | H10: =IF(Table1[[#This Row],[Lifetime Option]]="fixed",Table1[[#This Row],[End of life (fixed)]]-Table1[[#This Row],[Start year]],Table2[Generic Lifetime]) -> 24 | I10: 2006 | J10: =IF(Table1[[#This Row],[Lifetime Option]]="fixed",Table1[[#This Row],[End of life (fixed)]],Table1[[#This Row],[Start year]]+Table2[Generic Lifetime]) -> 2006 | K10: 0.408 | L10: closed
C11: BG | D11: ENBG_KOZLODUY-5_00 | E11: 1987 | F11: 0.7776 | G11: generic | H11: =IF(Table1[[#This Row],[Lifetime Option]]="fixed",Table1[[#This Row],[End of life (fixed)]]-Table1[[#This Row],[Start year]],Table2[Generic Lifetime]) -> 60 | J11: =IF(Table1[[#This Row],[Lifetime Option]]="fixed",Table1[[#This Row],[End of life (fixed)]],Table1[[#This Row],[Start year]]+Table2[Generic Lifetime]) -> 2047 | K11: 0.953 | M11: http://www.world-nuclear.org/info/Country-Profiles/Countries-A-F/Bulgaria/
C12: BG | D12: ENBG_KOZLODUY-6_00 | E12: 1991 | F12: 0.7776 | G12: generic | H12: =IF(Table1[[#This Row],[Lifetime Option]]="fixed",Table1[[#This Row],[End of life (fixed)]]-Table1[[#This Row],[Start year]],Table2[Generic Lifetime]) -> 60 | J12: =IF(Table1[[#This Row],[Lifetime Option]]="fixed",Table1[[#This Row],[End of life (fixed)]],Table1[[#This Row],[Start year]]+Table2[Generic Lifetime]) -> 2051 | K12: 0.953 | M12: http://www.world-nuclear.org/info/Country-Profiles/Countries-A-F/Bulgaria/
C13: CH | D13: ENCH_BEZNAU-1_00 | E13: 1969 | F13: 1.2203044 | G13: fixed | H13: =IF(Table1[[#This Row],[Lifetime Option]]="fixed",Table1[[#This Row],[End of life (fixed)]]-Table1[[#This Row],[Start year]],Table2[Generic Lifetime]) -> 50 | I13: 2019 | J13: =IF(Table1[[#This Row],[Lifetime Option]]="fixed",Table1[[#This Row],[End of life (fixed)]],Table1[[#This Row],[Start year]]+Table2[Generic Lifetime]) -> 2019 | K13: 0.365 | L13: need to follow up political developments | M13: http://www.world-nuclear.org/info/Country-Profiles/Countries-O-S/Switzerland/
C14: CH | D14: ENCH_BEZNAU-2_00 | E14: 1971 | F14: 1.2203044 | G14: fixed | H14: =IF(Table1[[#This Row],[Lifetime Option]]="fixed",Table1[[#This Row],[End of life (fixed)]]-Table1[[#This Row],[Start year]],Table2[Generic Lifetime]) -> 50 | I14: 2021 | J14: =IF(Table1[[#This Row],[Lifetime Option]]="fixed",Table1[[#This Row],[End of life (fixed)]],Table1[[#This Row],[Start year]]+Table2[Generic Lifetime]) -> 2021 | K14: 0.365 | L14: need to follow up political developments | M14: http://www.world-nuclear.org/info/Country-Profiles/Countries-O-S/Switzerland/
C15: CH | D15: ENCH_GOESGEN_00 | E15: 1979 | F15: 1.5489833 | G15: fixed | H15: =IF(Table1[[#This Row],[Lifetime Option]]="fixed",Table1[[#This Row],[End of life (fixed)]]-Table1[[#This Row],[Start year]],Table2[Generic Lifetime]) -> 50 | I15: 2029 | J15: =IF(Table1[[#This Row],[Lifetime Option]]="fixed",Table1[[#This Row],[End of life (fixed)]],Table1[[#This Row],[Start year]]+Table2[Generic Lifetime]) -> 2029 | K15: 0.985 | L15: need to follow up political developments | M15: http://www.world-nuclear.org/info/Country-Profiles/Countries-O-S/Switzerland/
C16: CH | D16: ENCH_LEIBSTADT_00 | E16: 1984 | F16: 1.28484 | G16: fixed | H16: =IF(Table1[[#This Row],[Lifetime Option]]="fixed",Table1[[#This Row],[End of life (fixed)]]-Table1[[#This Row],[Start year]],Table2[Generic Lifetime]) -> 50 | I16: 2034 | J16: =IF(Table1[[#This Row],[Lifetime Option]]="fixed",Table1[[#This Row],[End of life (fixed)]],Table1[[#This Row],[Start year]]+Table2[Generic Lifetime]) -> 2034 | K16: 1.22 | L16: need to follow up political developments | M16: http://www.world-nuclear.org/info/Country-Profiles/Countries-O-S/Switzerland/
C17: CH | D17: ENCH_MUEHLEBERG_00 | E17: 1971 | F17: 1.474392 | G17: fixed | H17: =IF(Table1[[#This Row],[Lifetime Option]]="fixed",Table1[[#This Row],[End of life (fixed)]]-Table1[[#This Row],[Start year]],Table2[Generic Lifetime]) -> 48 | I17: 2019 | J17: =IF(Table1[[#This Row],[Lifetime Option]]="fixed",Table1[[#This Row],[End of life (fixed)]],Table1[[#This Row],[Start year]]+Table2[Generic Lifetime]) -> 2019 | K17: 0.373 | L17: need to follow up political developments | M17: http://www.world-nuclear.org/info/Country-Profiles/Countries-O-S/Switzerland/
C18: CZ | D18: ENCZ_DUKOVANY-1_00 | E18: 1985 | F18: 1.2607488 | G18: generic | H18: =IF(Table1[[#This Row],[Lifetime Option]]="fixed",Table1[[#This Row],[End of life (fixed)]]-Table1[[#This Row],[Start year]],Table2[Generic Lifetime]) -> 60 | J18: =IF(Table1[[#This Row],[Lifetime Option]]="fixed",Table1[[#This Row],[End of life (fixed)]],Table1[[#This Row],[Start year]]+Table2[Generic Lifetime]) -> 2045 | K18: 0.468 | M18: http://www.oecd-nea.org/ndd/pubs/2014/7197-bb-2014.pdf
C19: CZ | D19: ENCZ_DUKOVANY-2_00 | E19: 1986 | F19: 1.2607488 | G19: generic | H19: =IF(Table1[[#This Row],[Lifetime Option]]="fixed",Table1[[#This Row],[End of life (fixed)]]-Table1[[#This Row],[Start year]],Table2[Generic Lifetime]) -> 60 | J19: =IF(Table1[[#This Row],[Lifetime Option]]="fixed",Table1[[#This Row],[End of life (fixed)]],Table1[[#This Row],[Start year]]+Table2[Generic Lifetime]) -> 2046 | K19: 0.471
C20: CZ | D20: ENCZ_DUKOVANY-3_00 | E20: 1986 | F20: 1.3110781 | G20: generic | H20: =IF(Table1[[#This Row],[Lifetime Option]]="fixed",Table1[[#This Row],[End of life (fixed)]]-Table1[[#This Row],[Start year]],Table2[Generic Lifetime]) -> 60 | J20: =IF(Table1[[#This Row],[Lifetime Option]]="fixed",Table1[[#This Row],[End of life (fixed)]],Table1[[#This Row],[Start year]]+Table2[Generic Lifetime]) -> 2046 | K20: 0.468
C21: CZ | D21: ENCZ_DUKOVANY-4_00 | E21: 1987 | F21: 1.2607488 | G21: generic | H21: =IF(Table1[[#This Row],[Lifetime Option]]="fixed",Table1[[#This Row],[End of life (fixed)]]-Table1[[#This Row],[Start year]],Table2[Generic Lifetime]) -> 60 | J21: =IF(Table1[[#This Row],[Lifetime Option]]="fixed",Table1[[#This Row],[End of life (fixed)]],Table1[[#This Row],[Start year]]+Table2[Generic Lifetime]) -> 2047 | K21: 0.471
C22: CZ | D22: ENCZ_TEMELIN-1_00 | E22: 2000 | F22: 1.312848 | G22: generic | H22: =IF(Table1[[#This Row],[Lifetime Option]]="fixed",Table1[[#This Row],[End of life (fixed)]]-Table1[[#This Row],[Start year]],Table2[Generic Lifetime]) -> 60 | J22: =IF(Table1[[#This Row],[Lifetime Option]]="fixed",Table1[[#This Row],[End of life (fixed)]],Table1[[#This Row],[Start year]]+Table2[Generic Lifetime]) -> 2060 | K22: 0.963
C23: CZ | D23: ENCZ_TEMELIN-2_00 | E23: 2002 | F23: 1.312848 | G23: generic | H23: =IF(Table1[[#This Row],[Lifetime Option]]="fixed",Table1[[#This Row],[End of life (fixed)]]-Table1[[#This Row],[Start year]],Table2[Generic Lifetime]) -> 60 | J23: =IF(Table1[[#This Row],[Lifetime Option]]="fixed",Table1[[#This Row],[End of life (fixed)]],Table1[[#This Row],[Start year]]+Table2[Generic Lifetime]) -> 2062 | K23: 0.963
C24: DE | D24: ENDE_BIBLIS-A_00 | E24: 1974 | F24: 0.940896 | G24: fixed | H24: =IF(Table1[[#This Row],[Lifetime Option]]="fixed",Table1[[#This Row],[End of life (fixed)]]-Table1[[#This Row],[Start year]],Table2[Generic Lifetime]) -> 37 | I24: 2011 | J24: =IF(Table1[[#This Row],[Lifetime Option]]="fixed",Table1[[#This Row],[End of life (fixed)]],Table1[[#This Row],[Start year]]+Table2[Generic Lifetime]) -> 2011 | K24: 1.167 | L24: closed
C25: DE | D25: ENDE_BIBLIS-B_00 | E25: 1976 | F25: 0.940896 | G25: fixed | H25: =IF(Table1[[#This Row],[Lifetime Option]]="fixed",Table1[[#This Row],[End of life (fixed)]]-Table1[[#This Row],[Start year]],Table2[Generic Lifetime]) -> 35 | I25: 2011 | J25: =IF(Table1[[#This Row],[Lifetime Option]]="fixed",Table1[[#This Row],[End of life (fixed)]],Table1[[#This Row],[Start year]]+Table2[Generic Lifetime]) -> 2011 | K25: 1.24 | L25: closed
C26: DE | D26: ENDE_BROKDORF_KBR_00 | E26: 1986 | F26: 1.1147815 | G26: fixed | H26: =IF(Table1[[#This Row],[Lifetime Option]]="fixed",Table1[[#This Row],[End of life (fixed)]]-Table1[[#This Row],[Start year]],Table2[Generic Lifetime]) -> 35 | I26: 2021 | J26: =IF(Table1[[#This Row],[Lifetime Option]]="fixed",Table1[[#This Row],[End of life (fixed)]],Table1[[#This Row],[Start year]]+Table2[Generic Lifetime]) -> 2021 | K26: 1.41
