Workbook
Name FID_1: [1]AGR_Fuels!$A$2

Sheet Fill Data
B2: ~TFM_Fill-R: w=OldHouses; Hcol=Region
B3: TimeSlice | C3: LimType | D3: Attribute | E3: Year | F3: AllRegions | G3: Pset_CI | H3: Pset_PN | I3: Pset_CO | J3: Cset_CN
D4: PASTI | F4: 1 | H4: Rdw[_]*
D5: INPUT | F5: 1 | H5: Rdw[_]*
B8: ~TFM_Fill-R: w=ServBldg; Hcol=Region
B9: TimeSlice | C9: LimType | D9: Attribute | E9: Year | F9: AllRegions | G9: Pset_CI | H9: Pset_PN
D10: PASTI | F10: 1 | H10: NRBldg*

Sheet OldHouses
A1: scenario | B1: attribute | C1: process | D1: commodity | E1: lim_type | F1: time_slice | G1: year | H1: commodity_group | I1: currency | J1: stage | K1: sow | L1: AL | M1: AT | N1: BA | O1: BE | P1: BG | Q1: CH | R1: CY | S1: CZ | T1: DE | U1: DK | V1: EE | W1: EL | X1: ES | Y1: FI | Z1: FR | AA1: HR | AB1: HU | AC1: IE | AD1: IS | AE1: IT | AF1: KS | AG1: LT | AH1: LU | AI1: LV | AJ1: ME | AK1: MK | AL1: MT | AM1: NL | AN1: NO | AO1: PL | AP1: PT | AQ1: RO | AR1: RS | AS1: SE | AT1: SI | AU1: SK | AV1: UK | AW1: year2
A2: BASE | B2: INPUT | C2: Rdw_DetH | D2: R_ES-DH-Cook | E2: - | F2: ANNUAL | G2: 2010 | H2: - | I2: - | J2: - | K2: - | L2: 0.0096401693 | M2: 0.0030415223 | N2: 0.0042581434 | O2: 0.0034102939 | P2: 0.0036540878 | Q2: 0.0035508104 | R2: 0.0031439568 | S2: 0.002828146 | T2: 0.0032488706 | U2: 0.0028361457 | V2: 0.0027654135 | W2: 0.0056266963 | X2: 0.0038085079 | Y2: 0.0026293573 | Z2: 0.0046456786 | AA2: 0.0030876066 | AB2: 0.0027436497 | AC2: 0.0029710596 | AD2: 0.0022971798 | AE2: 0.0024563525 | AF2: 0.0037550697 | AG2: 0.0024095487 | AH2: 0.0028929007 | AI2: 0.0018737846 | AJ2: 0.0079551734 | AK2: 0.0052408565 | AL2: 0.0040527979 | AM2: 0.0033325711 | AN2: 0.0074120673 | AO2: 0.0031582031 | AP2: 0.015925988 | AQ2: 0.0026716941 | AR2: 0.0048263692 | AS2: 0.0026513054 | AT2: 0.0023401915 | AU2: 0.003632819 | AV2: 0.0020315869 | AW2: -
A3: BASE | B3: INPUT | C3: Rdw_DetH | D3: R_ES-DH-SpCool | E3: - | F3: ANNUAL | G3: 2010 | H3: - | I3: - | J3: - | K3: - | L3: 0.0033023629 | M3: 0.00031367532 | N3: 0.0081355238 | O3: 0.001064478 | P3: 0.00053515446 | Q3: 0.00031900864 | R3: 0.0075016642 | S3: 5.791538e-05 | T3: 0.00027938653 | U3: 0.0002158663 | V3: 1.1300493e-05 | W3: 0.0024745307 | X3: 0.0017885701 | Y3: 7.7066365e-05 | Z3: 0.0021914253 | AA3: 0.0040321319 | AB3: 6.3675396e-05 | AC3: 0.00018202999 | AD3: 6.6958366e-05 | AE3: 0.0018281929 | AF3: 0.006817581 | AH3: 0.0029769779 | AJ3: 0.0032922644 | AK3: 0.0096533093 | AL3: 0.0086615593 | AM3: 0.00068788026 | AN3: 0.00024065938 | AO3: 3.7704133e-05 | AP3: 0.0013701653 | AQ3: 8.1424878e-05 | AR3: 0.0088705237 | AS3: 0.00015883064 | AT3: 0.00060158929 | AU3: 0.00019404844 | AV3: 0.00012129152 | AW3: -
A4: BASE | B4: INPUT | C4: Rdw_DetH | D4: R_ES-DH-SpHeat-I | E4: - | F4: ANNUAL | G4: 1940 | H4: - | I4: - | J4: - | K4: - | L4: 0.022981595 | M4: 0.096111982 | N4: 0.028884986 | O4: 0.084974409 | P4: 0.033193906 | Q4: 0.10020342 | R4: 0.034305089 | S4: 0.08306798 | T4: 0.10348827 | U4: 0.078256878 | V4: 0.085208712 | W4: 0.054265075 | X4: 0.059224176 | Y4: 0.1416462 | Z4: 0.096680431 | AA4: 0.055515125 | AB4: 0.06891109 | AC4: 0.091948721 | AD4: 0.19555453 | AE4: 0.072728605 | AF4: 0.027913236 | AG4: 0.064323141 | AH4: 0.1238417 | AI4: 0.084406724 | AJ4: 0.055533011 | AK4: 0.030888509 | AL4: 0.013402284 | AM4: 0.098131719 | AN4: 0.077260408 | AO4: 0.10394198 | AP4: 0.020709667 | AQ4: 0.056147168 | AR4: 0.04095778 | AS4: 0.099843971 | AT4: 0.077196421 | AU4: 0.080024814 | AV4: 0.080194295 | AW4: -
A5: BASE | B5: INPUT | C5: Rdw_DetH | D5: R_ES-DH-SpHeat-I | E5: - | F5: ANNUAL | G5: 1957 | H5: - | I5: - | J5: - | K5: - | L5: 0.022981595 | M5: 0.08951184 | N5: 0.028884986 | O5: 0.084974409 | P5: 0.033193906 | Q5: 0.093322317 | R5: 0.03233403 | S5: 0.071271836 | T5: 0.089392889 | U5: 0.076040258 | V5: 0.085208712 | W5: 0.054265075 | X5: 0.054016123 | Y5: 0.13093622 | Z5: 0.096680431 | AA5: 0.058254327 | AB5: 0.06891109 | AC5: 0.093135935 | AD5: 0.18076849 | AE5: 0.06937349 | AF5: 0.027913236 | AG5: 0.064323141 | AH5: 0.12588379 | AI5: 0.083252979 | AJ5: 0.055533011 | AK5: 0.030888509 | AL5: 0.013385958 | AM5: 0.080500612 | AN5: 0.076916432 | AO5: 0.076433835 | AP5: 0.018977565 | AQ5: 0.051310149 | AR5: 0.04095778 | AS5: 0.09939945 | AT5: 0.077196421 | AU5: 0.0689258 | AV5: 0.0837608 | AW5: -
A6: BASE | B6: INPUT | C6: Rdw_DetH | D6: R_ES-DH-WatHeat | E6: - | F6: ANNUAL | G6: 2010 | H6: - | I6: - | J6: - | K6: - | L6: 0.010671601 | M6: 0.011251381 | N6: 0.0056302138 | O6: 0.0095272111 | P6: 0.0075855179 | Q6: 0.0085103269 | R6: 0.0094679451 | S6: 0.0071258839 | T6: 0.0092098032 | U6: 0.0097229186 | V6: 0.0089376629 | W6: 0.010422415 | X6: 0.012010718 | Y6: 0.01135997 | Z6: 0.0099539709 | AA6: 0.0061370923 | AB6: 0.0053359982 | AC6: 0.010752265 | AD6: 0.010532394 | AE6: 0.0084432134 | AF6: 0.0042840393 | AG6: 0.0073425045 | AH6: 0.0076613003 | AI6: 0.010300905 | AJ6: 0.0075894075 | AK6: 0.0062653176 | AL6: 0.0046083001 | AM6: 0.009244366 | AN6: 0.015409946 | AO6: 0.0091778714 | AP6: 0.014817587 | AQ6: 0.0061500457 | AR6: 0.006927562 | AS6: 0.0092939988 | AT6: 0.012373113 | AU6: 0.0093921415 | AV6: 0.0092111061 | AW6: -
A7: BASE | B7: INPUT | C7: Rdw_DetH-70 | D7: R_ES-DH-70-SpHeat-I | E7: - | F7: ANNUAL | G7: 1975 | H7: - | I7: - | J7: - | K7: - | L7: 0.022981595 | M7: 0.071890665 | N7: 0.028884986 | O7: 0.084974409 | P7: 0.03149259 | Q7: 0.074951017 | R7: 0.033773547 | S7: 0.071271836 | T7: 0.05958274 | U7: 0.053832597 | V7: 0.071252784 | W7: 0.054265075 | X7: 0.054016123 | Y7: 0.10949317 | Z7: 0.047847184 | AA7: 0.050537165 | AB7: 0.060626468 | AC7: 0.081340753 | AD7: 0.15116456 | AE7: 0.065300666 | AF7: 0.027913236 | AG7: 0.042648736 | AH7: 0.07317577 | AI7: 0.07779035 | AJ7: 0.055533011 | AK7: 0.02928467 | AL7: 0.011388099 | AM7: 0.078159089 | AN7: 0.056327587 | AO7: 0.05578075 | AP7: 0.018661058 | AQ7: 0.051310149 | AR7: 0.04095778 | AS7: 0.072792393 | AT7: 0.071119406 | AU7: 0.0689258 | AV7: 0.06703361 | AW7: -
A8: BASE | B8: INPUT | C8: Rdw_DetH-70 | D8: R_ES-DH-70-SpHeat-I | E8: - | F8: ANNUAL | G8: 1985 | H8: - | I8: - | J8: - | K8: - | L8: 0.022400084 | M8: 0.050185499 | N8: 0.025445408 | O8: 0.072602693 | P8: 0.027563117 | Q8: 0.052321872 | R8: 0.032893328 | S8: 0.064471406 | T8: 0.048282126 | U8: 0.045793922 | V8: 0.053095941 | W8: 0.052891988 | X8: 0.036094596 | Y8: 0.090150811 | Z8: 0.041046721 | AA8: 0.050537165 | AB8: 0.046299777 | AC8: 0.055143942 | AD8: 0.1244608 | AE8: 0.050378569 | AF8: 0.024589372 | AG8: 0.042648736 | AH8: 0.06032501 | AI8: 0.046670033 | AJ8: 0.04855439 | AK8: 0.02558408 | AL8: 0.01058451 | AM8: 0.051427336 | AN8: 0.055473812 | AO8: 0.05578075 | AP8: 0.01820093 | AQ8: 0.04415738 | AR8: 0.036080593 | AS8: 0.071689056 | AT8: 0.054753715 | AU8: 0.058733338 | AV8: 0.042175089 | AW8: -
A9: BASE | B9: INPUT | C9: Rdw_DetH-70 | D9: R_ES-DH-70-SpHeat-I | E9: - | F9: ANNUAL | G9: 1995 | H9: - | I9: - | J9: - | K9: - | L9: 0.022400084 | M9: 0.042973891 | N9: 0.024328911 | O9: 0.072602693 | P9: 0.022521092 | Q9: 0.044803269 | R9: 0.028197795 | S9: 0.049699372 | T9: 0.028782762 | U9: 0.045793922 | V9: 0.046604478 | W9: 0.052891988 | X9: 0.036094596 | Y9: 0.089156054 | Z9: 0.024415125 | AA9: 0.036811367 | AB9: 0.046299777 | AC9: 0.04773153 | AD9: 0.12308745 | AE9: 0.04688109 | AF9: 0.023510436 | AG9: 0.042648736 | AH9: 0.051585466 | AI9: 0.045991889 | AJ9: 0.046216872 | AK9: 0.020806595 | AL9: 0.010430532 | AM9: 0.046057939 | AN9: 0.050623271 | AO9: 0.05578075 | AP9: 0.016922284 | AQ9: 0.04415738 | AR9: 0.034497443 | AS9: 0.06542068 | AT9: 0.040423456 | AU9: 0.054180883 | AV9: 0.031101521 | AW9: -
A10: BASE | B10: INPUT | C10: Rdw_DetH-70 | D10: R_ES-DH-70-SpHeat-I | E10: - | F10: ANNUAL | G10: 2004 | H10: - | I10: - | J10: - | K10: - | L10: 0.009072442 | M10: 0.038216553 | N10: 0.021076246 | O10: 0.043568869 | P10: 0.015681843 | Q10: 0.039843413 | R10: 0.02481191 | S10: 0.039103013 | T10: 0.031008037 | U10: 0.033433575 | V10: 0.046604478 | W10: 0.021422218 | X10: 0.024680365 | Y10: 0.079872548 | Z10: 0.023614074 | AA10: 0.02351873 | AB10: 0.028633312 | AC10: 0.030803334 | AD10: 0.11027079 | AE10: 0.044205442 | AF10: 0.020367198 | AG10: 0.025955619 | AH10: 0.041764705 | AI10: 0.029800539 | AJ10: 0.040108513 | AK10: 0.014447878 | AL10: 0.010027607 | AM10: 0.03287312 | AN10: 0.04406805 | AO10: 0.044694994 | AP10: 0.011554767 | AQ10: 0.034372644 | AR10: 0.029885291 | AS10: 0.056949338 | AT10: 0.023933423 | AU10: 0.032557854 | AV10: 0.026105856 | AW10: -
A11: BASE | B11: INPUT | C11: Rdw_DetH-70 | D11: R_ES-DH-Cook | E11: - | F11: ANNUAL | G11: 2010 | H11: - | I11: - | J11: - | K11: - | L11: 0.0096401693 | M11: 0.0030415223 | N11: 0.0042581434 | O11: 0.0034102939 | P11: 0.0036540878 | Q11: 0.0035508104 | R11: 0.0031439568 | S11: 0.002828146 | T11: 0.0032488706 | U11: 0.0028361457 | V11: 0.0027654135 | W11: 0.0056266963 | X11: 0.0038085079 | Y11: 0.0026293573 | Z11: 0.0046456786 | AA11: 0.0030876066 | AB11: 0.0027436497 | AC11: 0.0029710596 | AD11: 0.0022971798 | AE11: 0.0024563525 | AF11: 0.0037550697 | AG11: 0.0024095487 | AH11: 0.0028929007 | AI11: 0.0018737846 | AJ11: 0.0079551734 | AK11: 0.0052408565 | AL11: 0.0040527979 | AM11: 0.0033325711 | AN11: 0.0074120673 | AO11: 0.0031582031 | AP11: 0.015925988 | AQ11: 0.0026716941 | AR11: 0.0048263692 | AS11: 0.0026513054 | AT11: 0.0023401915 | AU11: 0.003632819 | AV11: 0.0020315869 | AW11: -
A12: BASE | B12: INPUT | C12: Rdw_DetH-70 | D12: R_ES-DH-SpCool | E12: - | F12: ANNUAL | G12: 2010 | H12: - | I12: - | J12: - | K12: - | L12: 0.0033023629 | M12: 0.00031367532 | N12: 0.0081355238 | O12: 0.001064478 | P12: 0.00053515446 | Q12: 0.00031900864 | R12: 0.0075016642 | S12: 5.791538e-05 | T12: 0.00027938653 | U12: 0.0002158663 | V12: 1.1300493e-05 | W12: 0.0024745307 | X12: 0.0017885701 | Y12: 7.7066365e-05 | Z12: 0.0021914253 | AA12: 0.0040321319 | AB12: 6.3675396e-05 | AC12: 0.00018202999 | AD12: 6.6958366e-05 | AE12: 0.0018281929 | AF12: 0.006817581 | AH12: 0.0029769779 | AJ12: 0.0032922644 | AK12: 0.0096533093 | AL12: 0.0086615593 | AM12: 0.00068788026 | AN12: 0.00024065938 | AO12: 3.7704133e-05 | AP12: 0.0013701653 | AQ12: 8.1424878e-05 | AR12: 0.0088705237 | AS12: 0.00015883064 | AT12: 0.00060158929 | AU12: 0.00019404844 | AV12: 0.00012129152 | AW12: -
A13: BASE | B13: INPUT | C13: Rdw_DetH-70 | D13: R_ES-DH-WatHeat | E13: - | F13: ANNUAL | G13: 2010 | H13: - | I13: - | J13: - | K13: - | L13: 0.010671601 | M13: 0.011251381 | N13: 0.0056302138 | O13: 0.0095272111 | P13: 0.0075855179 | Q13: 0.0085103269 | R13: 0.0094679451 | S13: 0.0071258839 | T13: 0.0092098032 | U13: 0.0097229186 | V13: 0.0089376629 | W13: 0.010422415 | X13: 0.012010718 | Y13: 0.01135997 | Z13: 0.0099539709 | AA13: 0.0061370923 | AB13: 0.0053359982 | AC13: 0.010752265 | AD13: 0.010532394 | AE13: 0.0084432134 | AF13: 0.0042840393 | AG13: 0.0073425045 | AH13: 0.0076613003 | AI13: 0.010300905 | AJ13: 0.0075894075 | AK13: 0.0062653176 | AL13: 0.0046083001 | AM13: 0.009244366 | AN13: 0.015409946 | AO13: 0.0091778714 | AP13: 0.014817587 | AQ13: 0.0061500457 | AR13: 0.006927562 | AS13: 0.0092939988 | AT13: 0.012373113 | AU13: 0.0093921415 | AV13: 0.0092111061 | AW13: -
A14: BASE | B14: INPUT | C14: Rdw_Flat | D14: R_ES-FL-Cook | E14: - | F14: ANNUAL | G14: 2010 | H14: - | I14: - | J14: - | K14: - | L14: 0.0096401693 | M14: 0.0030415223 | N14: 0.0042581434 | O14: 0.0034102939 | P14: 0.0036540878 | Q14: 0.0035508104 | R14: 0.0031439568 | S14: 0.002828146 | T14: 0.0032488706 | U14: 0.0028361457 | V14: 0.0027654135 | W14: 0.0056266963 | X14: 0.0038085079 | Y14: 0.0026293573 | Z14: 0.0046456786 | AA14: 0.0030876066 | AB14: 0.0027436497 | AC14: 0.0029710596 | AD14: 0.0022971798 | AE14: 0.0024563525 | AF14: 0.0037550697 | AG14: 0.0024095487 | AH14: 0.0028929007 | AI14: 0.0018737846 | AJ14: 0.0079551734 | AK14: 0.0052408565 | AL14: 0.0040527979 | AM14: 0.0033325711 | AN14: 0.0074120673 | AO14: 0.0031582031 | AP14: 0.015925988 | AQ14: 0.0026716941 | AR14: 0.0048263692 | AS14: 0.0026513054 | AT14: 0.0023401915 | AU14: 0.003632819 | AV14: 0.0020315869 | AW14: -
A15: BASE | B15: INPUT | C15: Rdw_Flat | D15: R_ES-FL-SpCool | E15: - | F15: ANNUAL | G15: 2010 | H15: - | I15: - | J15: - | K15: - | L15: 0.0016511814 | M15: 0.00015683766 | N15: 0.0040677619 | O15: 0.000532239 | P15: 0.00026757723 | Q15: 0.00015950432 | R15: 0.0037508321 | S15: 2.895769e-05 | T15: 8e-05 | U15: 0.00010793315 | W15: 0.001 | X15: 0.00069 | Y15: 3.8533182e-05 | Z15: 0.0009 | AA15: 0.0020160659 | AB15: 3.1837698e-05 | AC15: 9.1014997e-05 | AD15: 3.3479183e-05 | AE15: 0.00081 | AF15: 0.0034087905 | AH15: 0.001488489 | AJ15: 0.0016461322 | AK15: 0.0048266546 | AL15: 0.0043307797 | AM15: 0.00034394013 | AN15: 0.00012032969 | AO15: 1.8852066e-05 | AP15: 0.00068508265 | AQ15: 4.0712439e-05 | AR15: 0.0044352619 | AS15: 7.9415318e-05 | AT15: 0.00030079465 | AU15: 9.702422e-05 | AV15: 6.0645759e-05 | AW15: -
A16: BASE | B16: INPUT | C16: Rdw_Flat | D16: R_ES-FL-SpHeat-I | E16: - | F16: ANNUAL | G16: 1940 | H16: - | I16: - | J16: - | K16: - | L16: 0.0060880978 | M16: 0.02260157 | N16: 0.009104341 | O16: 0.02060963 | P16: 0.0088744951 | Q16: 0.023563708 | R16: 0.0089824859 | S16: 0.018348495 | T16: 0.023674127 | U16: 0.015649148 | V16: 0.019331898 | W16: 0.018048127 | X16: 0.01973433 | Y16: 0.024911494 | Z16: 0.022031529 | AA16: 0.016856261 | AB16: 0.015120218 | AC16: 0.013860579 | AD16: 0.04488454 | AE16: 0.019679655 | AF16: 0.0087980523 | AG16: 0.014054509 | AH16: 0.03582544 | AI16: 0.018203297 | AJ16: 0.015730896 | AK16: 0.0098556186 | AL16: 0.0038567291 | AM16: 0.023533097 | AN16: 0.017078255 | AO16: 0.0200024 | AP16: 0.0055484692 | AQ16: 0.0093377491 | AR16: 0.012909599 | AS16: 0.022070306 | AT16: 0.017217398 | AU16: 0.01840318 | AV16: 0.012767179 | AW16: -
A17: BASE | B17: INPUT | C17: Rdw_Flat | D17: R_ES-FL-SpHeat-I | E17: - | F17: ANNUAL | G17: 1957 | H17: - | I17: - | J17: - | K17: - | L17: 0.0060880978 | M17: 0.02041616 | N17: 0.009104341 | O17: 0.02060963 | P17: 0.0088744951 | Q17: 0.021285266 | R17: 0.0082479206 | S17: 0.016537174 | T17: 0.019539949 | U17: 0.0153705 | V17: 0.019331898 | W17: 0.018048127 | X17: 0.017732098 | Y17: 0.023407045 | Z17: 0.022031529 | AA17: 0.017984771 | AB17: 0.015120218 | AC17: 0.014004223 | AD17: 0.042214284 | AE17: 0.018540689 | AF17: 0.0087980523 | AG17: 0.014054509 | AH17: 0.039854128 | AI17: 0.017937407 | AJ17: 0.015730896 | AK17: 0.0098556186 | AL17: 0.003853633 | AM17: 0.019804703 | AN17: 0.01700062 | AO17: 0.01485518 | AP17: 0.0048916693 | AQ17: 0.0085744441 | AR17: 0.012909599 | AS17: 0.021969977 | AT17: 0.017217398 | AU17: 0.015857882 | AV17: 0.013317989 | AW17: -
A18: BASE | B18: INPUT | C18: Rdw_Flat | D18: R_ES-FL-SpHeat-I | E18: - | F18: ANNUAL | G18: 1975 | H18: - | I18: - | J18: - | K18: - | L18: 0.0060880978 | M18: 0.016668709 | N18: 0.009104341 | O18: 0.02060963 | P18: 0.0084074089 | Q18: 0.017378288 | R18: 0.0083150517 | S18: 0.016537174 | T18: 0.013309585 | U18: 0.011065875 | V18: 0.016029882 | W18: 0.018048127 | X18: 0.017732098 | Y18: 0.019809326 | Z18: 0.011175792 | AA18: 0.015678447 | AB18: 0.013219247 | AC18: 0.012580411 | AD18: 0.034942161 | AE18: 0.017698755 | AF18: 0.0087980523 | AG18: 0.0092842663 | AH18: 0.021862408 | AI18: 0.016770417 | AJ18: 0.015730896 | AK18: 0.0093165389 | AL18: 0.0030869373 | AM18: 0.01946823 | AN18: 0.012444089 | AO18: 0.010761353 | AP18: 0.0048331539 | AQ18: 0.0085744441 | AR18: 0.012909599 | AS18: 0.016081552 | AT18: 0.016352583 | AU18: 0.015857882 | AV18: 0.011171579 | AW18: -
A19: BASE | B19: INPUT | C19: Rdw_Flat | D19: R_ES-FL-SpHeat-I | E19: - | F19: ANNUAL | G19: 1985 | H19: - | I19: - | J19: - | K19: - | L19: 0.0059848034 | M19: 0.011780817 | N19: 0.0079623413 | O19: 0.017770166 | P19: 0.0073156621 | Q19: 0.012282321 | R19: 0.0081564801 | S19: 0.015079895 | T19: 0.011382828 | U19: 0.0093897102 | V19: 0.012056867 | W19: 0.017721932 | X19: 0.012484202 | Y19: 0.016350683 | Z19: 0.0096436848 | AA19: 0.015678447 | AB19: 0.009925021 | AC19: 0.0088154863 | AD19: 0.02827882 | AE19: 0.01313356 | AF19: 0.0076944718 | AG19: 0.0092842663 | AH19: 0.01853761 | AI19: 0.010438103 | AJ19: 0.013721543 | AK19: 0.0080392086 | AL19: 0.002933104 | AM19: 0.011779739 | AN19: 0.012251367 | AO19: 0.010761353 | AP19: 0.004681756 | AQ19: 0.0074368789 | AR19: 0.011290288 | AS19: 0.015832496 | AT19: 0.012085742 | AU19: 0.01348883 | AV19: 0.0072616012 | AW19: -
A20: BASE | B20: INPUT | C20: Rdw_Flat | D20: R_ES-FL-SpHeat-I | E20: - | F20: ANNUAL | G20: 1995 | H20: - | I20: - | J20: - | K20: - | L20: 0.0059848034 | M20: 0.0099166423 | N20: 0.0075614719 | O20: 0.017770166 | P20: 0.0059838939 | Q20: 0.010338789 | R20: 0.0070446675 | S20: 0.011459275 | T20: 0.0064976087 | U20: 0.0093897102 | V20: 0.010809644 | W20: 0.017721932 | X20: 0.012484202 | Y20: 0.016204097 | Z20: 0.0056458804 | AA20: 0.011296877 | AB20: 0.009925021 | AC20: 0.0077612233 | AD20: 0.027995606 | AE20: 0.012062827 | AF20: 0.0073070884 | AG20: 0.0092842663 | AH20: 0.015897113 | AI20: 0.010358868 | AJ20: 0.013009839 | AK20: 0.0065706152 | AL20: 0.0029037036 | AM20: 0.010552299 | AN20: 0.011006241 | AO20: 0.010761353 | AP20: 0.0043016583 | AQ20: 0.0074368789 | AR20: 0.010721871 | AS20: 0.014223414 | AT20: 0.0090735226 | AU20: 0.01284777 | AV20: 0.0051886343 | AW20: -
A21: BASE | B21: INPUT | C21: Rdw_Flat | D21: R_ES-FL-SpHeat-I | E21: - | F21: ANNUAL | G21: 2004 | H21: - | I21: - | J21: - | K21: - | L21: 0.0023973967 | M21: 0.0089647782 | N21: 0.0065004651 | O21: 0.010608168 | P21: 0.0040331239 | Q21: 0.0093464046 | R21: 0.0065101969 | S21: 0.0092054613 | T21: 0.0071493454 | U21: 0.0069368217 | V21: 0.010809644 | W21: 0.0068099725 | X21: 0.0080128509 | Y21: 0.014524278 | Z21: 0.0054596279 | AA21: 0.0067215635 | AB21: 0.0061803825 | AC21: 0.005181653 | AD21: 0.025312848 | AE21: 0.011437455 | AF21: 0.0062817761 | AG21: 0.0054382511 | AH21: 0.012705262 | AI21: 0.0063971724 | AJ21: 0.011190453 | AK21: 0.0042298008 | AL21: 0.0027534446 | AM21: 0.0078121083 | AN21: 0.0095212161 | AO21: 0.0085096927 | AP21: 0.0029593185 | AQ21: 0.0056691672 | AR21: 0.0092174051 | AS21: 0.01230431 | AT21: 0.0054401498 | AU21: 0.0074386773 | AV21: 0.0043657947 | AW21: -
A22: BASE | B22: INPUT | C22: Rdw_Flat | D22: R_ES-FL-WatHeat | E22: - | F22: ANNUAL | G22: 2010 | H22: - | I22: - | J22: - | K22: - | L22: 0.0053358007 | M22: 0.0056256905 | N22: 0.0028151069 | O22: 0.0047636056 | P22: 0.003792759 | Q22: 0.0042551634 | R22: 0.0047339725 | S22: 0.003562942 | T22: 0.0046049016 | U22: 0.0048614593 | V22: 0.0044688314 | W22: 0.0052112074 | X22: 0.0060053589 | Y22: 0.0056799848 | Z22: 0.0049769855 | AA22: 0.0030685461 | AB22: 0.0026679991 | AC22: 0.0053761326 | AD22: 0.0052661971 | AE22: 0.0042216067 | AF22: 0.0021420197 | AG22: 0.0036712523 | AH22: 0.0038306502 | AI22: 0.0051504524 | AJ22: 0.0037947037 | AK22: 0.0031326588 | AL22: 0.0023041501 | AM22: 0.004622183 | AN22: 0.007704973 | AO22: 0.0045889357 | AP22: 0.0074087934 | AQ22: 0.0030750229 | AR22: 0.003463781 | AS22: 0.0046469994 | AT22: 0.0061865566 | AU22: 0.0046960708 | AV22: 0.0046055531 | AW22: -
A23: BASE | B23: INPUT | C23: Rdw_SDetH | D23: R_ES-SD-Cook | E23: - | F23: ANNUAL | G23: 2010 | H23: - | I23: - | J23: - | K23: - | L23: 0.0096401693 | M23: 0.0030415223 | N23: 0.0042581434 | O23: 0.0034102939 | P23: 0.0036540878 | Q23: 0.0035508104 | R23: 0.0031439568 | S23: 0.002828146 | T23: 0.0032488706 | U23: 0.0028361457 | V23: 0.0027654135 | W23: 0.0056266963 | X23: 0.0038085079 | Y23: 0.0026293573 | Z23: 0.0046456786 | AA23: 0.0030876066 | AB23: 0.0027436497 | AC23: 0.0029710596 | AD23: 0.0022971798 | AE23: 0.0024563525 | AF23: 0.0037550697 | AG23: 0.0024095487 | AH23: 0.0028929007 | AI23: 0.0018737846 | AJ23: 0.0079551734 | AK23: 0.0052408565 | AL23: 0.0040527979 | AM23: 0.0033325711 | AN23: 0.0074120673 | AO23: 0.0031582031 | AP23: 0.015925988 | AQ23: 0.0026716941 | AR23: 0.0048263692 | AS23: 0.0026513054 | AT23: 0.0023401915 | AU23: 0.003632819 | AV23: 0.0020315869 | AW23: -
A24: BASE | B24: INPUT | C24: Rdw_SDetH | D24: R_ES-SD-SpCool | E24: - | F24: ANNUAL | G24: 2010 | H24: - | I24: - | J24: - | K24: - | L24: 0.0033023629 | M24: 0.00031367532 | N24: 0.0081355238 | O24: 0.001064478 | P24: 0.00053515446 | Q24: 0.00031900864 | R24: 0.0075016642 | S24: 5.791538e-05 | T24: 0.00027938653 | U24: 0.0002158663 | V24: 1.1300493e-05 | W24: 0.0024745307 | X24: 0.0017885701 | Y24: 7.7066365e-05 | Z24: 0.0021914253 | AA24: 0.0040321319 | AB24: 6.3675396e-05 | AC24: 0.00018202999 | AD24: 6.6958366e-05 | AE24: 0.0018281929 | AF24: 0.006817581 | AH24: 0.0029769779 | AJ24: 0.0032922644 | AK24: 0.0096533093 | AL24: 0.0086615593 | AM24: 0.00068788026 | AN24: 0.00024065938 | AO24: 3.7704133e-05 | AP24: 0.0013701653 | AQ24: 8.1424878e-05 | AR24: 0.0088705237 | AS24: 0.00015883064 | AT24: 0.00060158929 | AU24: 0.00019404844 | AV24: 0.00012129152 | AW24: -
A25: BASE | B25: INPUT | C25: Rdw_SDetH | D25: R_ES-SD-SpHeat-I | E25: - | F25: ANNUAL | G25: 1940 | H25: - | I25: - | J25: - | K25: - | L25: 0.013113768 | M25: 0.051145996 | N25: 0.014836167 | O25: 0.047088523 | P25: 0.017541727 | Q25: 0.05512199 | R25: 0.020334626 | S25: 0.045190187 | T25: 0.056942729 | U25: 0.040208966 | V25: 0.043264964 | W25: 0.031915753 | X25: 0.033175663 | Y25: 0.072863643 | Z25: 0.053688646 | AA25: 0.027390225 | AB25: 0.036262524 | AC25: 0.051098753 | AD25: 0.10137657 | AE25: 0.040384525 | AF25: 0.014337048 | AG25: 0.034286568 | AH25: 0.069501471 | AI25: 0.044486295 | AJ25: 0.029157723 | AK25: 0.016347765 | AL25: 0.0078981698 | AM25: 0.057861354 | AN25: 0.037931759 | AO25: 0.055065929 | AP25: 0.011692942 | AQ25: 0.029875732 | AR25: 0.021037104 | AS25: 0.048250417 | AT25: 0.040882288 | AU25: 0.043090099 | AV25: 0.045352858 | AW25: -
A26: BASE | B26: INPUT | C26: Rdw_SDetH | D26: R_ES-SD-SpHeat-I | E26: - | F26: ANNUAL | G26: 1957 | H26: - | I26: - | J26: - | K26: - | L26: 0.013113768 | M26: 0.048066753 | N26: 0.014836167 | O26: 0.047088523 | P26: 0.017541727 | Q26: 0.051842902 | R26: 0.019325446 | S26: 0.037075548 | T26: 0.050682764 | U26: 0.038705258 | V26: 0.043264964 | W26: 0.031915753 | X26: 0.030080447 | Y26: 0.06577111 | Z26: 0.053688646 | AA26: 0.028825578 | AB26: 0.036262524 | AC26: 0.051977602 | AD26: 0.091480345 | AE26: 0.038497211 | AF26: 0.014337048 | AG26: 0.034286568 | AH26: 0.06990541 | AI26: 0.044147558 | AJ26: 0.029157723 | AK26: 0.016347765 | AL26: 0.007885014 | AM26: 0.046160272 | AN26: 0.037829879 | AO26: 0.040013616 | AP26: 0.010809308 | AQ26: 0.027121094 | AR26: 0.021037104 | AS26: 0.048118862 | AT26: 0.040882288 | AU26: 0.036479459 | AV26: 0.047569056 | AW26: -
A27: BASE | B27: INPUT | C27: Rdw_SDetH | D27: R_ES-SD-SpHeat-I | E27: - | F27: ANNUAL | G27: 1975 | H27: - | I27: - | J27: - | K27: - | L27: 0.013113768 | M27: 0.037759791 | N27: 0.014836167 | O27: 0.047088523 | P27: 0.016527602 | Q27: 0.040681871 | R27: 0.019303467 | S27: 0.037075548 | T27: 0.031722686 | U27: 0.025895899 | V27: 0.035066755 | W27: 0.031915753 | X27: 0.030080447 | Y27: 0.05391994 | Z27: 0.024597628 | AA27: 0.025940092 | AB27: 0.031627862 | AC27: 0.043210896 | AD27: 0.074983829 | AE27: 0.036350519 | AF27: 0.014337048 | AG27: 0.022069174 | AH27: 0.038475608 | AI27: 0.040924388 | AJ27: 0.029157723 | AK27: 0.015395286 | AL27: 0.0067946142 | AM27: 0.04431757 | AN27: 0.025650985 | AO27: 0.028813787 | AP27: 0.01058487 | AQ27: 0.027121094 | AR27: 0.021037104 | AS27: 0.032686599 | AT27: 0.037224287 | AU27: 0.036479459 | AV27: 0.03660165 | AW27: -
A28: BASE | B28: INPUT | C28: Rdw_SDetH | D28: R_ES-SD-SpHeat-I | E28: - | F28: ANNUAL | G28: 1985 | H28: - | I28: - | J28: - | K28: - | L28: 0.012706432 | M28: 0.025729751 | N28: 0.012798172 | O28: 0.039651636 | P28: 0.014211573 | Q28: 0.027688811 | R28: 0.018664221 | S28: 0.032838128 | T28: 0.024363123 | U28: 0.021563683 | V28: 0.026423334 | W28: 0.030952744 | X28: 0.019615291 | Y28: 0.04415995 | Z28: 0.020908266 | AA28: 0.025940092 | AB28: 0.023589938 | AC28: 0.027941655 | AD28: 0.06141161 | AE28: 0.028899396 | AF28: 0.012367616 | AG28: 0.022069174 | AH28: 0.032556931 | AI28: 0.023340988 | AJ28: 0.025002603 | AK28: 0.013223058 | AL28: 0.006146986 | AM28: 0.028677655 | AN28: 0.025394545 | AO28: 0.028813787 | AP28: 0.010307379 | AQ28: 0.023260763 | AR28: 0.018147307 | AS28: 0.032355576 | AT28: 0.029126743 | AU28: 0.031279398 | AV28: 0.021537148 | AW28: -
A29: BASE | B29: INPUT | C29: Rdw_SDetH | D29: R_ES-SD-SpHeat-I | E29: - | F29: ANNUAL | G29: 1995 | H29: - | I29: - | J29: - | K29: - | L29: 0.012706432 | M29: 0.02206144 | N29: 0.012083939 | O29: 0.039651636 | P29: 0.011039859 | Q29: 0.023748243 | R29: 0.0173014 | S29: 0.024847262 | T29: 0.014517092 | U29: 0.021563683 | V29: 0.02253689 | W29: 0.030952744 | X29: 0.019615291 | Y29: 0.043525693 | Z29: 0.01225173 | AA29: 0.018497522 | AB29: 0.023589938 | AC29: 0.024045092 | AD29: 0.060527151 | AE29: 0.026795522 | AF29: 0.011677411 | AG29: 0.022069174 | AH29: 0.028008285 | AI29: 0.022863792 | AJ29: 0.023527269 | AK29: 0.010227385 | AL29: 0.0060224941 | AM29: 0.025789602 | AN29: 0.022697436 | AO29: 0.028813787 | AP29: 0.0095785473 | AQ29: 0.023260763 | AR29: 0.017134553 | AS29: 0.028929869 | AT29: 0.020659411 | AU29: 0.028151684 | AV29: 0.016478948 | AW29: -
A30: BASE | B30: INPUT | C30: Rdw_SDetH | D30: R_ES-SD-SpHeat-I | E30: - | F30: ANNUAL | G30: 2004 | H30: - | I30: - | J30: - | K30: - | L30: 0.0045375001 | M30: 0.01927544 | N30: 0.010524796 | O30: 0.023212984 | P30: 0.0075046921 | Q30: 0.020729087 | R30: 0.01432004 | S30: 0.019541419 | T30: 0.015706078 | U30: 0.015472885 | V30: 0.02253689 | W30: 0.011033869 | X30: 0.013060899 | Y30: 0.038986089 | Z30: 0.011854989 | AA30: 0.011631408 | AB30: 0.014432789 | AC30: 0.015172219 | AD30: 0.05421233 | AE30: 0.026018574 | AF30: 0.01017072 | AG30: 0.012651996 | AH30: 0.022622098 | AI30: 0.014086222 | AJ30: 0.020544978 | AK30: 0.0069508975 | AL30: 0.0057951458 | AM30: 0.017873352 | AN30: 0.020730322 | AO30: 0.022664164 | AP30: 0.0063944258 | AQ30: 0.018767063 | AR30: 0.014923749 | AS30: 0.0263905 | AT30: 0.011464475 | AU30: 0.017061768 | AV30: 0.013718798 | AW30: -
A31: BASE | B31: INPUT | C31: Rdw_SDetH | D31: R_ES-SD-WatHeat | E31: - | F31: ANNUAL | G31: 2010 | H31: - | I31: - | J31: - | K31: - | L31: 0.010671601 | M31: 0.011251381 | N31: 0.0056302138 | O31: 0.0095272111 | P31: 0.0075855179 | Q31: 0.0085103269 | R31: 0.0094679451 | S31: 0.0071258839 | T31: 0.0092098032 | U31: 0.0097229186 | V31: 0.0089376629 | W31: 0.010422415 | X31: 0.012010718 | Y31: 0.01135997 | Z31: 0.0099539709 | AA31: 0.0061370923 | AB31: 0.0053359982 | AC31: 0.010752265 | AD31: 0.010532394 | AE31: 0.0084432134 | AF31: 0.0042840393 | AG31: 0.0073425045 | AH31: 0.0076613003 | AI31: 0.010300905 | AJ31: 0.0075894075 | AK31: 0.0062653176 | AL31: 0.0046083001 | AM31: 0.009244366 | AN31: 0.015409946 | AO31: 0.0091778714 | AP31: 0.014817587 | AQ31: 0.0061500457 | AR31: 0.006927562 | AS31: 0.0092939988 | AT31: 0.012373113 | AU31: 0.0093921415 | AV31: 0.0092111061 | AW31: -
A32: BASE | B32: PASTI | C32: Rdw_DetH | D32: - | E32: - | F32: - | G32: 1940 | H32: - | I32: - | J32: - | K32: - | L32: 7.1060889 | M32: 244.72894 | N32: 29.107516 | O32: 376.06049 | P32: 87.260262 | Q32: 202.87575 | R32: 3.2037613 | S32: 247.83002 | T32: 1672.6828 | U32: 358.06515 | V32: 20.940128 | W32: 60.668506 | X32: 127.03985 | Y32: 111.65023 | Z32: 1676.3359 | AA32: 94.298145 | AB32: 293.18281 | AC32: 78.419274 | AD32: 6.1429929 | AE32: 508.82779 | AF32: 17.13412 | AG32: 67.066683 | AH32: 14.810399 | AI32: 38.56528 | AJ32: 5.5810511 | AK32: 16.468824 | AL32: 0.77894954 | AM32: 144.57043 | AN32: 88.26653 | AO32: 680.48065 | AP32: 55.55239 | AQ32: 218.4573 | AR32: 86.00399 | AS32: 380.67209 | AT32: 62.074833 | AU32: 104.06478 | AV32: 1548.8514 | AW32: -
A33: BASE | B33: PASTI | C33: Rdw_DetH | D33: - | E33: - | F33: - | G33: 1957 | H33: - | I33: - | J33: - | K33: - | L33: 25.861614 | M33: 295.27191 | N33: 66.455662 | O33: 208.92249 | P33: 180.64218 | Q33: 244.77493 | R33: 10.674429 | S33: 336.59146 | T33: 2538.9736 | U33: 260.0065 | V33: 30.955962 | W33: 220.79452 | X33: 225.83044 | Y33: 204.21026 | Z33: 1133.795 | AA33: 171.33427 | AB33: 395.01159 | AC33: 71.157683 | AD33: 11.235644 | AE33: 713.7355 | AF33: 39.119081 | AG33: 71.672234 | AH33: 13.621892 | AI33: 46.7711 | AJ33: 12.742154 | AK33: 34.093002 | AL33: 0.81665532 | AM33: 162.71434 | AN33: 117.42942 | AO33: 755.06274 | AP33: 75.148462 | AQ33: 632.98785 | AR33: 196.35657 | AS33: 345.23952 | AT33: 41.492685 | AU33: 133.70726 | AV33: 974.58961 | AW33: -
A34: BASE | B34: PASTI | C34: Rdw_DetH-70 | D34: - | E34: - | F34: - | G34: 1975 | H34: - | I34: - | J34: - | K34: - | L34: 20.606959 | M34: 151.92494 | N34: 49.616283 | O34: 113.06629 | P34: 104.73453 | Q34: 125.94296 | R34: 14.450273 | S34: 137.91927 | T34: 1308.7091 | U34: 160.6097 | V34: 24.04537 | W34: 175.9327 | X34: 186.45602 | Y34: 162.21316 | Z34: 1252.37 | AA34: 132.34862 | AB34: 236.90753 | AC34: 60.133431 | AD34: 8.924964 | AE34: 403.80457 | AF34: 29.206592 | AG34: 47.179043 | AH34: 7.3560417 | AI34: 37.812351 | AJ34: 9.5133851 | AK34: 19.766782 | AL34: 0.536607 | AM34: 100.25132 | AN34: 75.379176 | AO34: 433.94373 | AP34: 84.219719 | AQ34: 456.66918 | AR34: 146.60125 | AS34: 187.86914 | AT34: 35.720099 | AU34: 54.728975 | AV34: 428.1624 | AW34: -
A35: BASE | B35: PASTI | C35: Rdw_DetH-70 | D35: - | E35: - | F35: - | G35: 1985 | H35: - | I35: - | J35: - | K35: - | L35: 15.774388 | M35: 120.54341 | N35: 41.93357 | O35: 113.06629 | P35: 98.695125 | Q35: 99.928247 | R35: 20.860764 | S35: 159.8616 | T35: 912.14145 | U35: 65.784463 | V35: 22.613386 | W35: 134.67444 | X35: 118.13656 | Y35: 128.53247 | Z35: 922.92144 | AA35: 104.92812 | AB35: 322.05482 | AC35: 52.333781 | AD35: 7.0718532 | AE35: 292.52111 | AF35: 24.684168 | AG35: 47.179043 | AH35: 5.7173903 | AI35: 36.500011 | AJ35: 8.040308 | AK35: 18.626951 | AL35: 0.61637658 | AM35: 97.511532 | AN35: 63.401944 | AO35: 448.60136 | AP35: 71.982217 | AQ35: 624.76475 | AR35: 123.90114 | AS35: 129.41926 | AT35: 19.404941 | AU35: 63.484778 | AV35: 303.9921 | AW35: -
A36: BASE | B36: PASTI | C36: Rdw_DetH-70 | D36: - | E36: - | F36: - | G36: 1995 | H36: - | I36: - | J36: - | K36: - | L36: 10.612196 | M36: 143.87085 | N36: 20.553205 | O36: 83.286957 | P36: 56.998206 | Q36: 119.26626 | R36: 17.987549 | S36: 82.519378 | T36: 839.50055 | U36: 65.83661 | V36: 7.3370538 | W36: 90.602033 | X36: 116.97492 | Y36: 93.848682 | Z36: 555.95651 | AA36: 56.164547 | AB36: 132.83257 | AC36: 67.997343 | AD36: 5.1635522 | AE36: 108.23171 | AF36: 12.09863 | AG36: 14.671159 | AH36: 4.548861 | AI36: 11.42511 | AJ36: 3.9408545 | AK36: 10.757399 | AL36: 0.59693102 | AM36: 86.021987 | AN36: 69.830034 | AO36: 448.60136 | AP36: 78.393357 | AQ36: 86.036627 | AR36: 60.728562 | AS36: 105.96675 | AT36: 19.404941 | AU36: 33.777188 | AV36: 303.9921 | AW36: -
... A49: BASE | B49: PASTI | C49: Rdw_SDetH | D49: - | E49: - | F49: - | G49: 2004 | H49: - | I49: - | J49: - | K49: - | L49: 3.0557661 | M49: 27.258836 | N49: 5.5237303 | O49: 93.408433 | P49: 48.196764 | Q49: 54.703697 | R49: 39.498209 | S49: 36.949558 | T49: 482.62059 | U49: 46.36073 | V49: 2.6796566 | W49: 26.08872 | X49: 440.16079 | Y49: 69.284074 | Z49: 673.508 | AA49: 27.56014 | AB49: 57.863486 | AC49: 203.74266 | AD49: 4.7111182 | AE49: 150.60825 | AF49: 3.2515401 | AG49: 6.501996 | AH49: 8.0960147 | AI49: 5.2936688 | AJ49: 1.6733295 | AK49: 9.0962831 | AL49: 2.8443737 | AM49: 236.15743 | AN49: 38.725452 | AO49: 209.45934 | AP49: 35.938849 | AQ49: 24.285976 | AR49: 16.320968 | AS49: 14.183067 | AT49: 5.6430154 | AU49: 12.421631 | AV49: 872.76483 | AW49: -

Sheet Stock
E1: =OldHouses!L1 -> AL | F1: =OldHouses!M1 -> AT | G1: =OldHouses!N1 -> BA | H1: =OldHouses!O1 -> BE | I1: =OldHouses!P1 -> BG | J1: =OldHouses!Q1 -> CH | K1: =OldHouses!R1 -> CY | L1: =OldHouses!S1 -> CZ | ... AO1: =OldHouses!AV1 -> UK
D2: Rdw_DetH | E2: =SUMIFS(OldHouses!L$2:L$82,OldHouses!$B$2:$B$82,"PASTI",OldHouses!$C$2:$C$82,Stock!$D2) -> 32.967703 | F2: =SUMIFS(OldHouses!M$2:M$82,OldHouses!$B$2:$B$82,"PASTI",OldHouses!$C$2:$C$82,Stock!$D2) -> 540.00084 | G2: =SUMIFS(OldHouses!N$2:N$82,OldHouses!$B$2:$B$82,"PASTI",OldHouses!$C$2:$C$82,Stock!$D2) -> 95.563178 | H2: =SUMIFS(OldHouses!O$2:O$82,OldHouses!$B$2:$B$82,"PASTI",OldHouses!$C$2:$C$82,Stock!$D2) -> 584.98298 | I2: =SUMIFS(OldHouses!P$2:P$82,OldHouses!$B$2:$B$82,"PASTI",OldHouses!$C$2:$C$82,Stock!$D2) -> 267.90244 | J2: =SUMIFS(OldHouses!Q$2:Q$82,OldHouses!$B$2:$B$82,"PASTI",OldHouses!$C$2:$C$82,Stock!$D2) -> 447.65068 | K2: =SUMIFS(OldHouses!R$2:R$82,OldHouses!$B$2:$B$82,"PASTI",OldHouses!$C$2:$C$82,Stock!$D2) -> 13.878191 | L2: =SUMIFS(OldHouses!S$2:S$82,OldHouses!$B$2:$B$82,"PASTI",OldHouses!$C$2:$C$82,Stock!$D2) -> 584.42148 | ... AO2: =SUMIFS(OldHouses!AV$2:AV$82,OldHouses!$B$2:$B$82,"PASTI",OldHouses!$C$2:$C$82,Stock!$D2) -> 2523.441
D3: Rdw_DetH-70 | E3: =SUMIFS(OldHouses!L$2:L$82,OldHouses!$B$2:$B$82,"PASTI",OldHouses!$C$2:$C$82,Stock!$D3) -> 52.397956 | F3: =SUMIFS(OldHouses!M$2:M$82,OldHouses!$B$2:$B$82,"PASTI",OldHouses!$C$2:$C$82,Stock!$D3) -> 475.1609 | G3: =SUMIFS(OldHouses!N$2:N$82,OldHouses!$B$2:$B$82,"PASTI",OldHouses!$C$2:$C$82,Stock!$D3) -> 127.53779 | H3: =SUMIFS(OldHouses!O$2:O$82,OldHouses!$B$2:$B$82,"PASTI",OldHouses!$C$2:$C$82,Stock!$D3) -> 365.40424 | I3: =SUMIFS(OldHouses!P$2:P$82,OldHouses!$B$2:$B$82,"PASTI",OldHouses!$C$2:$C$82,Stock!$D3) -> 349.10991 | J3: =SUMIFS(OldHouses!Q$2:Q$82,OldHouses!$B$2:$B$82,"PASTI",OldHouses!$C$2:$C$82,Stock!$D3) -> 393.89956 | K3: =SUMIFS(OldHouses!R$2:R$82,OldHouses!$B$2:$B$82,"PASTI",OldHouses!$C$2:$C$82,Stock!$D3) -> 91.973916 | L3: =SUMIFS(OldHouses!S$2:S$82,OldHouses!$B$2:$B$82,"PASTI",OldHouses!$C$2:$C$82,Stock!$D3) -> 442.63692 | ... AO3: =SUMIFS(OldHouses!AV$2:AV$82,OldHouses!$B$2:$B$82,"PASTI",OldHouses!$C$2:$C$82,Stock!$D3) -> 1287.5365
D4: Rdw_Flat | E4: =SUMIFS(OldHouses!L$2:L$82,OldHouses!$B$2:$B$82,"PASTI",OldHouses!$C$2:$C$82,Stock!$D4) -> 196.66972 | F4: =SUMIFS(OldHouses!M$2:M$82,OldHouses!$B$2:$B$82,"PASTI",OldHouses!$C$2:$C$82,Stock!$D4) -> 1468.1931 | G4: =SUMIFS(OldHouses!N$2:N$82,OldHouses!$B$2:$B$82,"PASTI",OldHouses!$C$2:$C$82,Stock!$D4) -> 271.1874 | H4: =SUMIFS(OldHouses!O$2:O$82,OldHouses!$B$2:$B$82,"PASTI",OldHouses!$C$2:$C$82,Stock!$D4) -> 905.52301 | I4: =SUMIFS(OldHouses!P$2:P$82,OldHouses!$B$2:$B$82,"PASTI",OldHouses!$C$2:$C$82,Stock!$D4) -> 777.21771 | J4: =SUMIFS(OldHouses!Q$2:Q$82,OldHouses!$B$2:$B$82,"PASTI",OldHouses!$C$2:$C$82,Stock!$D4) -> 1648.2852 | K4: =SUMIFS(OldHouses!R$2:R$82,OldHouses!$B$2:$B$82,"PASTI",OldHouses!$C$2:$C$82,Stock!$D4) -> 83.544874 | L4: =SUMIFS(OldHouses!S$2:S$82,OldHouses!$B$2:$B$82,"PASTI",OldHouses!$C$2:$C$82,Stock!$D4) -> 2208.0312 | ... AO4: =SUMIFS(OldHouses!AV$2:AV$82,OldHouses!$B$2:$B$82,"PASTI",OldHouses!$C$2:$C$82,Stock!$D4) -> 3928.2271
D5: Rdw_SDetH | E5: =SUMIFS(OldHouses!L$2:L$82,OldHouses!$B$2:$B$82,"PASTI",OldHouses!$C$2:$C$82,Stock!$D5) -> 48.267499 | F5: =SUMIFS(OldHouses!M$2:M$82,OldHouses!$B$2:$B$82,"PASTI",OldHouses!$C$2:$C$82,Stock!$D5) -> 470.44081 | G5: =SUMIFS(OldHouses!N$2:N$82,OldHouses!$B$2:$B$82,"PASTI",OldHouses!$C$2:$C$82,Stock!$D5) -> 79.84264 | H5: =SUMIFS(OldHouses!O$2:O$82,OldHouses!$B$2:$B$82,"PASTI",OldHouses!$C$2:$C$82,Stock!$D5) -> 1585.6865 | I5: =SUMIFS(OldHouses!P$2:P$82,OldHouses!$B$2:$B$82,"PASTI",OldHouses!$C$2:$C$82,Stock!$D5) -> 335.3328 | J5: =SUMIFS(OldHouses!Q$2:Q$82,OldHouses!$B$2:$B$82,"PASTI",OldHouses!$C$2:$C$82,Stock!$D5) -> 944.09207 | K5: =SUMIFS(OldHouses!R$2:R$82,OldHouses!$B$2:$B$82,"PASTI",OldHouses!$C$2:$C$82,Stock!$D5) -> 108.10428 | L5: =SUMIFS(OldHouses!S$2:S$82,OldHouses!$B$2:$B$82,"PASTI",OldHouses!$C$2:$C$82,Stock!$D5) -> 608.78058 | ... AO5: =SUMIFS(OldHouses!AV$2:AV$82,OldHouses!$B$2:$B$82,"PASTI",OldHouses!$C$2:$C$82,Stock!$D5) -> 13230.789
E6: =E3/SUM(E2:E5) -> 0.15863608 | F6: =F3/SUM(F2:F5) -> 0.16086451 | G6: =G3/SUM(G2:G5) -> 0.22214057 | H6: =H3/SUM(H2:H5) -> 0.10617288 | I6: =I3/SUM(I2:I5) -> 0.20184864 | J6: =J3/SUM(J2:J5) -> 0.11470818 | K6: =K3/SUM(K2:K5) -> 0.30915471 | L6: =L3/SUM(L2:L5) -> 0.11515397 | ... AO6: =AO3/SUM(AO2:AO5) -> 0.061398995
D8: DemolitionRate | E8: =E1 -> AL | F8: =F1 -> AT | G8: =G1 -> BA | H8: =H1 -> BE | I8: =I1 -> BG | J8: =J1 -> CH | K8: =K1 -> CY | L8: =L1 -> CZ | ... AO8: =AO1 -> UK
D9: =D2 -> Rdw_DetH | E9: 0.003 | F9: 0.003 | G9: 0.003 | H9: 0.003 | I9: 0.003 | J9: 0.003 | K9: 0.003 | L9: 0.003 | M9: 0.003 | N9: 0.003 | O9: 0.003 | P9: 0.003 | Q9: 0.003 | R9: 0.003 | S9: 0.003 | T9: 0.003 | U9: 0.003 | V9: 0.003 | W9: 0.003 | X9: 0.003 | Y9: 0.003 | Z9: 0.003 | AA9: 0.003 | AB9: 0.003 | AC9: 0.003 | AD9: 0.003 | AE9: 0.003 | AF9: 0.003 | AG9: 0.003 | AH9: 0.003 | AI9: 0.003 | AJ9: 0.003 | AK9: 0.003 | AL9: 0.003 | AM9: 0.003 | AN9: 0.003 | AO9: 0.003
D10: =D3 -> Rdw_DetH-70 | E10: 0.001 | F10: 0.001 | G10: 0.001 | H10: 0.001 | I10: 0.001 | J10: 0.001 | K10: 0.001 | L10: 0.001 | M10: 0.001 | N10: 0.001 | O10: 0.001 | P10: 0.001 | Q10: 0.001 | R10: 0.001 | S10: 0.001 | T10: 0.001 | U10: 0.001 | V10: 0.001 | W10: 0.001 | X10: 0.001 | Y10: 0.001 | Z10: 0.001 | AA10: 0.001 | AB10: 0.001 | AC10: 0.001 | AD10: 0.001 | AE10: 0.001 | AF10: 0.001 | AG10: 0.001 | AH10: 0.001 | AI10: 0.001 | AJ10: 0.001 | AK10: 0.001 | AL10: 0.001 | AM10: 0.001 | AN10: 0.001 | AO10: 0.001
D11: =D4 -> Rdw_Flat | E11: =E12 -> 0.002 | F11: =F12 -> 0.002 | G11: =G12 -> 0.002 | H11: =H12 -> 0.0025 | I11: =I12 -> 0.002 | J11: =J12 -> 0.002 | K11: =K12 -> 0.002 | L11: =L12 -> 0.002 | ... AO11: =AO12 -> 0.00443
D12: =D5 -> Rdw_SDetH | E12: 0.002 | F12: =HLOOKUP(F8,Demolition!$G$3:$AJ$4,2,FALSE) -> 0.002 | G12: 0.002 | H12: =HLOOKUP(H8,Demolition!$G$3:$AJ$4,2,FALSE) -> 0.0025 | I12: =HLOOKUP(I8,Demolition!$G$3:$AJ$4,2,FALSE) -> 0.002 | J12: =HLOOKUP(J8,Demolition!$G$3:$AJ$4,2,FALSE) -> 0.002 | K12: =HLOOKUP(K8,Demolition!$G$3:$AJ$4,2,FALSE) -> 0.002 | L12: =HLOOKUP(L8,Demolition!$G$3:$AJ$4,2,FALSE) -> 0.002 | M12: =HLOOKUP(M8,Demolition!$G$3:$AJ$4,2,FALSE) -> 0.002 | N12: =HLOOKUP(N8,Demolition!$G$3:$AJ$4,2,FALSE) -> 0.002 | O12: =HLOOKUP(O8,Demolition!$G$3:$AJ$4,2,FALSE) -> 0.002 | P12: 0.002 | Q12: =HLOOKUP(Q8,Demolition!$G$3:$AJ$4,2,FALSE) -> 0.0021 | R12: =HLOOKUP(R8,Demolition!$G$3:$AJ$4,2,FALSE) -> 0.002 | S12: =HLOOKUP(S8,Demolition!$G$3:$AJ$4,2,FALSE) -> 0.002 | T12: 0.002 | U12: =HLOOKUP(U8,Demolition!$G$3:$AJ$4,2,FALSE) -> 0.002 | V12: =HLOOKUP(V8,Demolition!$G$3:$AJ$4,2,FALSE) -> 0.013 | W12: =HLOOKUP(W8,Demolition!$G$3:$AJ$4,2,FALSE) -> 0.002 | X12: =HLOOKUP(X8,Demolition!$G$3:$AJ$4,2,FALSE) -> 0.002 | Y12: 0.002 | Z12: =HLOOKUP(Z8,Demolition!$G$3:$AJ$4,2,FALSE) -> 0.002 | AA12: =HLOOKUP(AA8,Demolition!$G$3:$AJ$4,2,FALSE) -> 0.002 | AB12: =HLOOKUP(AB8,Demolition!$G$3:$AJ$4,2,FALSE) -> 0.002 | AC12: 0.002 | AD12: 0.002 | AE12: =HLOOKUP(AE8,Demolition!$G$3:$AJ$4,2,FALSE) -> 0.002 | AF12: =HLOOKUP(AF8,Demolition!$G$3:$AJ$4,2,FALSE) -> 0.002 | AG12: =HLOOKUP(AG8,Demolition!$G$3:$AJ$4,2,FALSE) -> 0.002 | AH12: =HLOOKUP(AH8,Demolition!$G$3:$AJ$4,2,FALSE) -> 0.002 | AI12: =HLOOKUP(AI8,Demolition!$G$3:$AJ$4,2,FALSE) -> 0.002 | AJ12: =HLOOKUP(AJ8,Demolition!$G$3:$AJ$4,2,FALSE) -> 0.002 | AK12: 0.002 | AL12: =HLOOKUP(AL8,Demolition!$G$3:$AJ$4,2,FALSE) -> 0.0012 | AM12: =HLOOKUP(AM8,Demolition!$G$3:$AJ$4,2,FALSE) -> 0.002 | AN12: =HLOOKUP(AN8,Demolition!$G$3:$AJ$4,2,FALSE) -> 0.002 | AO12: =HLOOKUP(AO8,Demolition!$G$3:$AJ$4,2,FALSE) -> 0.00443
B13: ~UC_Sets: R_E: AllRegions
D14: ~UC_T: UC_RHSRT~FX
B15: UC_N | C15: PSET_PN | D15: Year | E15: =E$1 -> AL | F15: =F$1 -> AT | G15: =G$1 -> BA | H15: =H$1 -> BE | I15: =I$1 -> BG | J15: =J$1 -> CH | K15: =K$1 -> CY | L15: =L$1 -> CZ | ... AO15: =AO$1 -> UK | AP15: UC_CAP
B16: ="UCR_OldStock-"&MID(C16,5,20) -> UCR_OldStock-DetH | C16: =D9 -> Rdw_DetH | D16: 2012 | E16: =E2*(1-E$9)^2 -> 32.770193 | F16: =F2*(1-F$9)^2 -> 536.7657 | G16: =G2*(1-G$9)^2 -> 94.990659 | H16: =H2*(1-H$9)^2 -> 581.47835 | I16: =I2*(1-I$9)^2 -> 266.29744 | J16: =J2*(1-J$9)^2 -> 444.9688 | K16: =K2*(1-K$9)^2 -> 13.795046 | L16: =L2*(1-L$9)^2 -> 580.92021 | ... AO16: =AO2*(1-AO$9)^2 -> 2508.3231 | AP16: 1
D17: =D16+2 -> 2014 | E17: =E16*(1-E$9)^2 -> 32.573867 | F17: =F16*(1-F$9)^2 -> 533.54994 | G17: =G16*(1-G$9)^2 -> 94.42157 | H17: =H16*(1-H$9)^2 -> 577.99471 | I17: =I16*(1-I$9)^2 -> 264.70205 | J17: =J16*(1-J$9)^2 -> 442.30299 | K17: =K16*(1-K$9)^2 -> 13.7124 | L17: =L16*(1-L$9)^2 -> 577.43991 | ... AO17: =AO16*(1-AO$9)^2 -> 2493.2957
D18: =D17+2 -> 2016 | E18: =E17*(1-E$9)^2 -> 32.378717 | F18: =F17*(1-F$9)^2 -> 530.35344 | G18: =G17*(1-G$9)^2 -> 93.85589 | H18: =H17*(1-H$9)^2 -> 574.53194 | I18: =I17*(1-I$9)^2 -> 263.11622 | J18: =J17*(1-J$9)^2 -> 439.65315 | K18: =K17*(1-K$9)^2 -> 13.630249 | L18: =L17*(1-L$9)^2 -> 573.98047 | ... AO18: =AO17*(1-AO$9)^2 -> 2478.3584
D19: =D18+2 -> 2018 | E19: =E18*(1-E$9)^2 -> 32.184736 | F19: =F18*(1-F$9)^2 -> 527.17609 | G19: =G18*(1-G$9)^2 -> 93.293599 | H19: =H18*(1-H$9)^2 -> 571.08992 | I19: =I18*(1-I$9)^2 -> 261.53989 | J19: =J18*(1-J$9)^2 -> 437.01919 | K19: =K18*(1-K$9)^2 -> 13.548591 | L19: =L18*(1-L$9)^2 -> 570.54175 | ... AO19: =AO18*(1-AO$9)^2 -> 2463.5105
D20: =D19+2 -> 2020 | E20: =E19*(1-E$9)^2 -> 31.991917 | F20: =F19*(1-F$9)^2 -> 524.01778 | G20: =G19*(1-G$9)^2 -> 92.734677 | H20: =H19*(1-H$9)^2 -> 567.66852 | I20: =I19*(1-I$9)^2 -> 259.97301 | J20: =J19*(1-J$9)^2 -> 434.40101 | K20: =K19*(1-K$9)^2 -> 13.467421 | L20: =L19*(1-L$9)^2 -> 567.12364 | ... AO20: =AO19*(1-AO$9)^2 -> 2448.7516
D21: =D20+2 -> 2022 | E21: =E20*(1-E$9)^2 -> 31.800254 | F21: =F20*(1-F$9)^2 -> 520.87839 | G21: =G20*(1-G$9)^2 -> 92.179104 | H21: =H20*(1-H$9)^2 -> 564.26762 | I21: =I20*(1-I$9)^2 -> 258.41551 | J21: =J20*(1-J$9)^2 -> 431.79851 | K21: =K20*(1-K$9)^2 -> 13.386738 | L21: =L20*(1-L$9)^2 -> 563.726 | ... AO21: =AO20*(1-AO$9)^2 -> 2434.0812
D22: =D21+2 -> 2024 | E22: =E21*(1-E$9)^2 -> 31.609738 | F22: =F21*(1-F$9)^2 -> 517.75781 | G22: =G21*(1-G$9)^2 -> 91.626859 | H22: =H21*(1-H$9)^2 -> 560.88709 | I22: =I21*(1-I$9)^2 -> 256.86734 | J22: =J21*(1-J$9)^2 -> 429.21161 | K22: =K21*(1-K$9)^2 -> 13.306538 | L22: =L21*(1-L$9)^2 -> 560.34872 | ... AO22: =AO21*(1-AO$9)^2 -> 2419.4986
D23: =D22+2 -> 2026 | E23: =E22*(1-E$9)^2 -> 31.420364 | F23: =F22*(1-F$9)^2 -> 514.65592 | G23: =G22*(1-G$9)^2 -> 91.077922 | H23: =H22*(1-H$9)^2 -> 557.52682 | I23: =I22*(1-I$9)^2 -> 255.32845 | J23: =J22*(1-J$9)^2 -> 426.6402 | K23: =K22*(1-K$9)^2 -> 13.226818 | L23: =L22*(1-L$9)^2 -> 556.99167 | ... AO23: =AO22*(1-AO$9)^2 -> 2405.0034
D24: =D23+2 -> 2028 | E24: =E23*(1-E$9)^2 -> 31.232125 | F24: =F23*(1-F$9)^2 -> 511.57262 | G24: =G23*(1-G$9)^2 -> 90.532275 | H24: =H23*(1-H$9)^2 -> 554.18668 | I24: =I23*(1-I$9)^2 -> 253.79877 | J24: =J23*(1-J$9)^2 -> 424.0842 | K24: =K23*(1-K$9)^2 -> 13.147576 | L24: =L23*(1-L$9)^2 -> 553.65473 | ... AO24: =AO23*(1-AO$9)^2 -> 2390.595
D25: =D24+2 -> 2030 | E25: =E24*(1-E$9)^2 -> 31.045013 | F25: =F24*(1-F$9)^2 -> 508.50778 | G25: =G24*(1-G$9)^2 -> 89.989896 | H25: =H24*(1-H$9)^2 -> 550.86654 | I25: =I24*(1-I$9)^2 -> 252.27827 | J25: =J24*(1-J$9)^2 -> 421.54351 | K25: =K24*(1-K$9)^2 -> 13.068809 | L25: =L24*(1-L$9)^2 -> 550.33779 | ... AO25: =AO24*(1-AO$9)^2 -> 2376.2729
D26: =D25+2 -> 2032 | E26: =E25*(1-E$9)^2 -> 30.859023 | F26: =F25*(1-F$9)^2 -> 505.46131 | G26: =G25*(1-G$9)^2 -> 89.450766 | H26: =H25*(1-H$9)^2 -> 547.5663 | I26: =I25*(1-I$9)^2 -> 250.76687 | J26: =J25*(1-J$9)^2 -> 419.01805 | K26: =K25*(1-K$9)^2 -> 12.990514 | L26: =L25*(1-L$9)^2 -> 547.04071 | ... AO26: =AO25*(1-AO$9)^2 -> 2362.0367
D27: =D26+2 -> 2034 | E27: =E26*(1-E$9)^2 -> 30.674146 | F27: =F26*(1-F$9)^2 -> 502.43309 | G27: =G26*(1-G$9)^2 -> 88.914867 | H27: =H26*(1-H$9)^2 -> 544.28583 | I27: =I26*(1-I$9)^2 -> 249.26452 | J27: =J26*(1-J$9)^2 -> 416.50771 | K27: =K26*(1-K$9)^2 -> 12.912688 | L27: =L26*(1-L$9)^2 -> 543.76339 | ... AO27: =AO26*(1-AO$9)^2 -> 2347.8857
D28: =D27+2 -> 2036 | E28: =E27*(1-E$9)^2 -> 30.490378 | F28: =F27*(1-F$9)^2 -> 499.42302 | G28: =G27*(1-G$9)^2 -> 88.382178 | H28: =H27*(1-H$9)^2 -> 541.02502 | I28: =I27*(1-I$9)^2 -> 247.77118 | J28: =J27*(1-J$9)^2 -> 414.01241 | K28: =K27*(1-K$9)^2 -> 12.835328 | L28: =L27*(1-L$9)^2 -> 540.50571 | ... AO28: =AO27*(1-AO$9)^2 -> 2333.8195
... D45: =D44+2 -> 2070 | E45: =E44*(1-E$9)^2 -> 27.529491 | F45: =F44*(1-F$9)^2 -> 450.92461 | G45: =G44*(1-G$9)^2 -> 79.799484 | H45: =H44*(1-H$9)^2 -> 488.48668 | I45: =I44*(1-I$9)^2 -> 223.7104 | J45: =J44*(1-J$9)^2 -> 373.80813 | K45: =K44*(1-K$9)^2 -> 11.588904 | L45: =L44*(1-L$9)^2 -> 488.0178 | ... AO45: =AO44*(1-AO$9)^2 -> 2107.1849
D47: ~UC_T: UC_RHSRT~FX
B48: UC_N | C48: PSET_PN | D48: Year | E48: =E$1 -> AL | F48: =F$1 -> AT | G48: =G$1 -> BA | H48: =H$1 -> BE | I48: =I$1 -> BG | J48: =J$1 -> CH | K48: =K$1 -> CY | L48: =L$1 -> CZ | ... AO48: =AO$1 -> UK | AP48: UC_CAP
B49: ="UCR_OldStock-"&MID(C49,5,20) -> UCR_OldStock-DetH-70 | C49: =D10 -> Rdw_DetH-70 | D49: 2012 | E49: =E3*(1-E$10)^2 -> 52.293212 | F49: =F3*(1-F$10)^2 -> 474.21105 | G49: =G3*(1-G$10)^2 -> 127.28284 | H49: =H3*(1-H$10)^2 -> 364.6738 | I49: =I3*(1-I$10)^2 -> 348.41204 | J49: =J3*(1-J$10)^2 -> 393.11216 | K49: =K3*(1-K$10)^2 -> 91.79006 | L49: =L3*(1-L$10)^2 -> 441.75209 | ... AO49: =AO3*(1-AO$10)^2 -> 1284.9628 | AP49: 1
D50: =D49+2 -> 2014 | E50: =E49*(1-E$10)^2 -> 52.188678 | F50: =F49*(1-F$10)^2 -> 473.2631 | G50: =G49*(1-G$10)^2 -> 127.0284 | H50: =H49*(1-H$10)^2 -> 363.94481 | I50: =I49*(1-I$10)^2 -> 347.71556 | J50: =J49*(1-J$10)^2 -> 392.32633 | K50: =K49*(1-K$10)^2 -> 91.606572 | L50: =L49*(1-L$10)^2 -> 440.86903 | ... AO50: =AO49*(1-AO$10)^2 -> 1282.3941
D51: =D50+2 -> 2016 | E51: =E50*(1-E$10)^2 -> 52.084353 | F51: =F50*(1-F$10)^2 -> 472.31705 | G51: =G50*(1-G$10)^2 -> 126.77447 | H51: =H50*(1-H$10)^2 -> 363.21729 | I51: =I50*(1-I$10)^2 -> 347.02048 | J51: =J50*(1-J$10)^2 -> 391.54207 | K51: =K50*(1-K$10)^2 -> 91.42345 | L51: =L50*(1-L$10)^2 -> 439.98773 | ... AO51: =AO50*(1-AO$10)^2 -> 1279.8306
D52: =D51+2 -> 2018 | E52: =E51*(1-E$10)^2 -> 51.980236 | F52: =F51*(1-F$10)^2 -> 471.37289 | G52: =G51*(1-G$10)^2 -> 126.52105 | H52: =H51*(1-H$10)^2 -> 362.49122 | I52: =I51*(1-I$10)^2 -> 346.32679 | J52: =J51*(1-J$10)^2 -> 390.75937 | K52: =K51*(1-K$10)^2 -> 91.240695 | L52: =L51*(1-L$10)^2 -> 439.10819 | ... AO52: =AO51*(1-AO$10)^2 -> 1277.2722
D53: =D52+2 -> 2020 | E53: =E52*(1-E$10)^2 -> 51.876328 | F53: =F52*(1-F$10)^2 -> 470.43061 | G53: =G52*(1-G$10)^2 -> 126.26813 | H53: =H52*(1-H$10)^2 -> 361.7666 | I53: =I52*(1-I$10)^2 -> 345.63448 | J53: =J52*(1-J$10)^2 -> 389.97825 | K53: =K52*(1-K$10)^2 -> 91.058304 | L53: =L52*(1-L$10)^2 -> 438.23042 | ... AO53: =AO52*(1-AO$10)^2 -> 1274.719
D54: =D53+2 -> 2022 | E54: =E53*(1-E$10)^2 -> 51.772627 | F54: =F53*(1-F$10)^2 -> 469.49022 | G54: =G53*(1-G$10)^2 -> 126.01572 | H54: =H53*(1-H$10)^2 -> 361.04342 | I54: =I53*(1-I$10)^2 -> 344.94355 | J54: =J53*(1-J$10)^2 -> 389.19868 | K54: =K53*(1-K$10)^2 -> 90.876279 | L54: =L53*(1-L$10)^2 -> 437.35439 | ... AO54: =AO53*(1-AO$10)^2 -> 1272.1708
D55: =D54+2 -> 2024 | E55: =E54*(1-E$10)^2 -> 51.669134 | F55: =F54*(1-F$10)^2 -> 468.55171 | G55: =G54*(1-G$10)^2 -> 125.76382 | H55: =H54*(1-H$10)^2 -> 360.3217 | I55: =I54*(1-I$10)^2 -> 344.25401 | J55: =J54*(1-J$10)^2 -> 388.42067 | K55: =K54*(1-K$10)^2 -> 90.694617 | L55: =L54*(1-L$10)^2 -> 436.48012 | ... AO55: =AO54*(1-AO$10)^2 -> 1269.6277
D56: =D55+2 -> 2026 | E56: =E55*(1-E$10)^2 -> 51.565847 | F56: =F55*(1-F$10)^2 -> 467.61508 | G56: =G55*(1-G$10)^2 -> 125.51242 | H56: =H55*(1-H$10)^2 -> 359.60142 | I56: =I55*(1-I$10)^2 -> 343.56585 | J56: =J55*(1-J$10)^2 -> 387.64422 | K56: =K55*(1-K$10)^2 -> 90.513319 | L56: =L55*(1-L$10)^2 -> 435.6076 | ... AO56: =AO55*(1-AO$10)^2 -> 1267.0897
D57: =D56+2 -> 2028 | E57: =E56*(1-E$10)^2 -> 51.462767 | F57: =F56*(1-F$10)^2 -> 466.68032 | G57: =G56*(1-G$10)^2 -> 125.26152 | H57: =H56*(1-H$10)^2 -> 358.88257 | I57: =I56*(1-I$10)^2 -> 342.87906 | J57: =J56*(1-J$10)^2 -> 386.86932 | K57: =K56*(1-K$10)^2 -> 90.332383 | L57: =L56*(1-L$10)^2 -> 434.73682 | ... AO57: =AO56*(1-AO$10)^2 -> 1264.5568
D58: =D57+2 -> 2030 | E58: =E57*(1-E$10)^2 -> 51.359893 | F58: =F57*(1-F$10)^2 -> 465.74742 | G58: =G57*(1-G$10)^2 -> 125.01112 | H58: =H57*(1-H$10)^2 -> 358.16517 | I58: =I57*(1-I$10)^2 -> 342.19365 | J58: =J57*(1-J$10)^2 -> 386.09597 | K58: =K57*(1-K$10)^2 -> 90.151808 | L58: =L57*(1-L$10)^2 -> 433.86778 | ... AO58: =AO57*(1-AO$10)^2 -> 1262.029
...

Sheet Sheet1
A1: CSET_CN | B1: Year | C1: EL | D1: ES | E1: IT | F1: PT
A2: R_DetH | B2: 2010 | C2: 728.81 | D2: 972.98 | E2: 2111.81 | F2: 409.82
A3: R_DetH | B3: 2020 | C3: 728.81 | D3: 972.98 | E3: 2111.81 | F3: 409.82
A4: R_DetH | B4: 2030 | C4: 911.02 | D4: 1099.47 | E4: 2513.05 | F4: 463.09
A5: R_DetH | B5: 2040 | C5: 961.12 | D5: 1187.43 | E5: 2676.4 | F5: 493.19
A6: R_DetH | B6: 2050 | C6: 1013.98 | D6: 1282.42 | E6: 2850.37 | F6: 525.25
A7: R_DetH | B7: 2060 | C7: 1071.15 | D7: 1388.79 | E7: 3041.15 | F7: 560.41
A8: R_DetH | B8: 2070 | C8: 1131.55 | D8: 1503.98 | E8: 3244.71 | F8: 597.92
A9: R_Flat | B9: 2010 | C9: 1679.08 | D9: 7433.11 | E9: 17047.88 | F9: 514.69
A10: R_Flat | B10: 2020 | C10: 1679.08 | D10: 7433.11 | E10: 17047.88 | F10: 514.69
A11: R_Flat | B11: 2030 | C11: 2098.84 | D11: 8399.41 | E11: 20286.98 | F11: 581.59
A12: R_Flat | B12: 2040 | C12: 2214.28 | D12: 9071.37 | E12: 21605.64 | F12: 619.4
A13: R_Flat | B13: 2050 | C13: 2336.07 | D13: 9797.08 | E13: 23010 | F13: 659.66
... A22: R_SDetH | B22: 2070 | C22: 639.8 | D22: 3334.19 | E22: 5770.43 | F22: 482.68

Sheet nov25_calib_2000
A1: Sum of Pv | F1: Period | N1: increasing rate
A2: Attribute | B2: Commodity | C2: Scenario | D2: Region | F2: 2010 | G2: 2020 | H2: 2030 | I2: 2040 | J2: 2050 | K2: 2070 | L2: 2000 | M2: act_2010 | N2: 2010-2020 | O2: 2020-2030 | P2: 2030-2040 | Q2: 2040-2050 | R2: 2050-2070 | T2: 2010 | U2: =G2 -> 2020 | V2: =H2 -> 2030 | W2: =I2 -> 2040 | X2: =J2 -> 2050 | Y2: 2060 | Z2: 2070 | AA2: 2020 | AB2: 2030 | AC2: 2040 | AD2: 2050 | AE2: 2060 | AF2: 2070 | AH2: =G2 -> 2020 | AI2: =H2 -> 2030 | AJ2: =I2 -> 2040 | AK2: =J2 -> 2050 | AL2: =K2 -> 2070
A3: VAR_FOut | B3: R_DetH | C3: ref_24nov | D3: AT | F3: 1015.1617 | G3: 1055.77 | H3: 1150.79 | I3: 1248.6 | J3: 1354.74 | K3: 1604.62 | L3: 976.11541 | M3: 3.9046328 | N3: 0.040001753 | O3: 0.090000664 | P3: 0.084993786 | Q3: 0.085007209 | R3: 0.18444868 | S3: -0.39168437 | T3: =F3 -> 1015.1617 | U3: =T3*(1+N3) -> 1055.77 | V3: =U3*(1+O3) -> 1150.79 | W3: =V3*(1+P3) -> 1248.6 | X3: =W3*(1+Q3) -> 1354.74 | Y3: =X3*(1+($R3/2)) -> 1479.68 | Z3: =Y3*(1+($R3/2)) -> 1616.1425 | AA3: =(U3-T3)/10 -> 4.060825 | AB3: =(V3-U3)/10 -> 9.502 | AC3: =(W3-V3)/10 -> 9.7809998 | AD3: =(X3-W3)/10 -> 10.614 | AE3: =(Y3-X3)/10 -> 12.494 | AF3: =(Z3-Y3)/10 -> 13.646251
A4: VAR_FOut | B4: R_DetH | C4: ref_24nov | D4: BE | F4: 950.39 | G4: 1064.43 | H4: 1192.17 | I4: 1305.42 | J4: 1429.44 | K4: 1727 | L4: 848.56793 | M4: 10.182207 | N4: 0.11999284 | O4: 0.12000789 | P4: 0.09499484 | Q4: 0.095003908 | R4: 0.20816543 | S4: -0.50864625 | T4: =F4 -> 950.39 | U4: =T4*(1+N4) -> 1064.43 | V4: =U4*(1+O4) -> 1192.17 | W4: =V4*(1+P4) -> 1305.42 | X4: =W4*(1+Q4) -> 1429.44 | Y4: =X4*(1+($R4/2)) -> 1578.22 | Z4: =Y4*(1+($R4/2)) -> 1742.4854 | AA4: =(U4-T4)/10 -> 11.403999 | AB4: =(V4-U4)/10 -> 12.774 | AC4: =(W4-V4)/10 -> 11.325 | AD4: =(X4-W4)/10 -> 12.402 | AE4: =(Y4-X4)/10 -> 14.878 | AF4: =(Z4-Y4)/10 -> 16.426542
A5: VAR_FOut | B5: R_DetH | C5: ref_24nov | D5: BG | F5: 617.01235 | G5: 647.85999 | H5: 725.61 | I5: 776.39999 | J5: 830.75 | K5: 955.11999 | L5: 587.63351 | M5: 2.9378844 | N5: 0.049995182 | O5: 0.1200105 | P5: 0.069996278 | Q5: 0.070002578 | R5: 0.14970809 | S5: -0.38475426 | T5: =F5 -> 617.01235 | U5: =T5*(1+N5) -> 647.85999 | V5: =U5*(1+O5) -> 725.61 | W5: =V5*(1+P5) -> 776.39999 | X5: =W5*(1+Q5) -> 830.75 | Y5: =X5*(1+($R5/2)) -> 892.93499 | Z5: =Y5*(1+($R5/2)) -> 959.77479 | AA5: =(U5-T5)/10 -> 3.0847645 | AB5: =(V5-U5)/10 -> 7.7750001 | AC5: =(W5-V5)/10 -> 5.0789999 | AD5: =(X5-W5)/10 -> 5.4350001 | AE5: =(Y5-X5)/10 -> 6.2184999 | AF5: =(Z5-Y5)/10 -> 6.6839798
A6: VAR_FOut | B6: R_DetH | C6: ref_24nov | D6: CH | F6: 841.55024 | G6: 942.53999 | H6: 1055.64 | I6: 1155.93 | J6: 1265.74 | K6: 1529.22 | L6: 751.38117 | M6: 9.0169067 | N6: 0.12000443 | O6: 0.11999491 | P6: 0.095003978 | Q6: 0.094997103 | R6: 0.20816281 | S6: -0.5086507 | T6: =F6 -> 841.55024 | U6: =T6*(1+N6) -> 942.53999 | V6: =U6*(1+O6) -> 1055.64 | W6: =V6*(1+P6) -> 1155.93 | X6: =W6*(1+Q6) -> 1265.74 | Y6: =X6*(1+($R6/2)) -> 1397.48 | Z6: =Y6*(1+($R6/2)) -> 1542.9317 | AA6: =(U6-T6)/10 -> 10.098975 | AB6: =(V6-U6)/10 -> 11.31 | AC6: =(W6-V6)/10 -> 10.029 | AD6: =(X6-W6)/10 -> 10.981 | AE6: =(Y6-X6)/10 -> 13.174 | AF6: =(Z6-Y6)/10 -> 14.545168
A7: VAR_FOut | B7: R_DetH | C7: ref_24nov | D7: CY | F7: 105.85211 | G7: 113.26 | H7: 130.25 | I7: 143.93 | J7: 159.04 | K7: 195.99 | L7: 98.928735 | M7: 0.69233715 | N7: 0.069983423 | O7: 0.15000884 | P7: 0.10502878 | Q7: 0.1049816 | R7: 0.23233148 | S7: -0.4952358 | T7: =F7 -> 105.85211 | U7: =T7*(1+N7) -> 113.26 | V7: =U7*(1+O7) -> 130.25 | W7: =V7*(1+P7) -> 143.93 | X7: =W7*(1+Q7) -> 159.04 | Y7: =X7*(1+($R7/2)) -> 177.515 | Z7: =Y7*(1+($R7/2)) -> 198.13616 | AA7: =(U7-T7)/10 -> 0.74078927 | AB7: =(V7-U7)/10 -> 1.6990001 | AC7: =(W7-V7)/10 -> 1.3679999 | AD7: =(X7-W7)/10 -> 1.5110001 | AE7: =(Y7-X7)/10 -> 1.8474999 | AF7: =(Z7-Y7)/10 -> 2.0621161
A8: VAR_FOut | B8: R_DetH | C8: ref_24nov | D8: CZ | F8: 1027.06 | G8: 1088.68 | H8: 1154 | I8: 1269.4 | J8: 1396.34 | K8: 1703.8 | L8: 968.92774 | M8: 5.813226 | N8: 0.059996487 | O8: 0.059999266 | P8: 0.099999999 | Q8: 0.1 | R8: 0.22018992 | S8: -0.43131368 | T8: =F8 -> 1027.06 | U8: =T8*(1+N8) -> 1088.68 | V8: =U8*(1+O8) -> 1154 | W8: =V8*(1+P8) -> 1269.4 | X8: =W8*(1+Q8) -> 1396.34 | Y8: =X8*(1+($R8/2)) -> 1550.07 | Z8: =Y8*(1+($R8/2)) -> 1720.7249 | AA8: =(U8-T8)/10 -> 6.1619991 | AB8: =(V8-U8)/10 -> 6.5320001 | AC8: =(W8-V8)/10 -> 11.54 | AD8: =(X8-W8)/10 -> 12.694 | AE8: =(Y8-X8)/10 -> 15.373 | AF8: =(Z8-Y8)/10 -> 17.06549
A9: VAR_FOut | B9: R_DetH | C9: ref_24nov | D9: DE | F9: 7733.6446 | G9: 8352.3399 | H9: 8769.9499 | I9: 9471.5499 | J9: 10229.27 | K9: 11996.52 | L9: 7160.7788 | M9: 57.286581 | N9: 0.08000049 | O9: 0.049999162 | P9: 0.080000456 | Q9: 0.079999578 | R9: 0.17276404 | T9: =F9 -> 7733.6446 | U9: =T9*(1+N9) -> 8352.3399 | V9: =U9*(1+O9) -> 8769.9499 | W9: =V9*(1+P9) -> 9471.5499 | X9: =W9*(1+Q9) -> 10229.27 | Y9: =X9*(1+($R9/2)) -> 11112.895 | Z9: =Y9*(1+($R9/2)) -> 12072.849 | AA9: =(U9-T9)/10 -> 61.869536 | AB9: =(V9-U9)/10 -> 41.761 | AC9: =(W9-V9)/10 -> 70.159999 | AD9: =(X9-W9)/10 -> 75.772 | AE9: =(Y9-X9)/10 -> 88.362499 | AF9: =(Z9-Y9)/10 -> 95.99543
A10: VAR_FOut | B10: R_DetH | C10: ref_24nov | D10: DK | F10: 997.38129 | G10: 1137.01 | H10: 1250.72 | I10: 1382.04 | J10: 1527.16 | K10: 1881.96 | L10: 874.89947 | M10: 12.248182 | N10: 0.13999531 | O10: 0.10000792 | P10: 0.10499552 | Q10: 0.1050042 | R10: 0.23232667 | T10: =F10 -> 997.38129 | U10: =T10*(1+N10) -> 1137.01 | V10: =U10*(1+O10) -> 1250.72 | W10: =V10*(1+P10) -> 1382.04 | X10: =W10*(1+Q10) -> 1527.16 | Y10: =X10*(1+($R10/2)) -> 1704.56 | Z10: =Y10*(1+($R10/2)) -> 1902.5674 | AA10: =(U10-T10)/10 -> 13.96287 | AB10: =(V10-U10)/10 -> 11.371 | AC10: =(W10-V10)/10 -> 13.132 | AD10: =(X10-W10)/10 -> 14.512 | AE10: =(Y10-X10)/10 -> 17.74 | AF10: =(Z10-Y10)/10 -> 19.800737
A11: VAR_FOut | B11: R_DetH | C11: ref_24nov | D11: EE | F11: 111.67 | G11: 148.52 | H11: 161.89 | I11: 178.88 | J11: 197.67 | K11: 243.59 | L11: 83.963028 | M11: 2.7706972 | N11: 0.32999014 | O11: 0.090021554 | P11: 0.1049478 | Q11: 0.10504249 | R11: 0.23230636 | T11: =F11 -> 111.67 | U11: =T11*(1+N11) -> 148.52 | V11: =U11*(1+O11) -> 161.89 | W11: =V11*(1+P11) -> 178.88 | X11: =W11*(1+Q11) -> 197.67 | Y11: =X11*(1+($R11/2)) -> 220.63 | Z11: =Y11*(1+($R11/2)) -> 246.25688 | AA11: =(U11-T11)/10 -> 3.6849999 | AB11: =(V11-U11)/10 -> 1.3370001 | AC11: =(W11-V11)/10 -> 1.6989999 | AD11: =(X11-W11)/10 -> 1.8790001 | AE11: =(Y11-X11)/10 -> 2.2959999 | AF11: =(Z11-Y11)/10 -> 2.5626876
A12: VAR_FOut | B12: R_DetH | C12: ref_24nov | D12: EL | F12: 728.81258 | G12: 728.80999 | H12: 911.01999 | I12: 961.11999 | J12: 1013.98 | K12: 1131.55 | L12: 728.81517 | M12: -0.00025901905 | N12: 0.04 | O12: 0.25001029 | P12: 0.054993303 | Q12: 0.054998337 | R12: 0.11594903 | T12: =F12 -> 728.81258 | U12: =T12*(1+N12) -> 757.96509 | V12: =U12*(1+O12) -> 947.46416 | W12: =V12*(1+P12) -> 999.56834 | X12: =W12*(1+Q12) -> 1054.5429 | Y12: =X12*(1+($R12/2)) -> 1115.6796 | Z12: =Y12*(1+($R12/2)) -> 1180.3605 | AA12: =(U12-T12)/10 -> 2.9152503 | AB12: =(V12-U12)/10 -> 18.949907 | AC12: =(W12-V12)/10 -> 5.2104184 | AD12: =(X12-W12)/10 -> 5.4974597 | AE12: =(Y12-X12)/10 -> 6.1136616 | AF12: =(Z12-Y12)/10 -> 6.4680982
A13: VAR_FOut | B13: R_DetH | C13: ref_24nov | D13: ES | F13: 972.98462 | G13: 972.97999 | H13: 1099.47 | I13: 1187.43 | J13: 1282.42 | K13: 1503.98 | L13: 972.98924 | M13: -0.00046227376 | N13: 0.04 | O13: 0.13000267 | P13: 0.080002182 | Q13: 0.079996296 | R13: 0.17276711 | T13: =F13 -> 972.98462 | U13: =T13*(1+N13) -> 1011.904 | V13: =U13*(1+O13) -> 1143.4542 | W13: =V13*(1+P13) -> 1234.9331 | X13: =W13*(1+Q13) -> 1333.7231 | Y13: =X13*(1+($R13/2)) -> 1448.9349 | Z13: =Y13*(1+($R13/2)) -> 1574.099 | AA13: =(U13-T13)/10 -> 3.8919385 | AB13: =(V13-U13)/10 -> 13.155023 | AC13: =(W13-V13)/10 -> 9.1478833 | AD13: =(X13-W13)/10 -> 9.879007 | AE13: =(Y13-X13)/10 -> 11.521175 | AF13: =(Z13-Y13)/10 -> 12.516415
A14: VAR_FOut | B14: R_DetH | C14: ref_24nov | D14: FI | F14: 792.12147 | G14: 831.72999 | H14: 881.62999 | I14: 956.56999 | J14: 1037.88 | K14: 1229.32 | L14: 754.39918 | M14: 3.7722293 | N14: 0.050003095 | O14: 0.059995433 | P14: 0.085001643 | Q14: 0.085001622 | R14: 0.18445292 | T14: =F14 -> 792.12147 | U14: =T14*(1+N14) -> 831.72999 | V14: =U14*(1+O14) -> 881.62999 | W14: =V14*(1+P14) -> 956.56999 | X14: =W14*(1+Q14) -> 1037.88 | Y14: =X14*(1+($R14/2)) -> 1133.6 | Z14: =Y14*(1+($R14/2)) -> 1238.1479 | AA14: =(U14-T14)/10 -> 3.9608525 | AB14: =(V14-U14)/10 -> 4.9900001 | AC14: =(W14-V14)/10 -> 7.4939998 | AD14: =(X14-W14)/10 -> 8.1310001 | AE14: =(Y14-X14)/10 -> 9.5719999 | AF14: =(Z14-Y14)/10 -> 10.454792
A15: VAR_FOut | B15: R_DetH | C15: ref_24nov | D15: FR | F15: 6298.8611 | G15: 6550.8199 | H15: 7140.3899 | I15: 7675.9199 | J15: 8251.6099 | K15: 9581.6399 | L15: 6056.5932 | M15: 24.226794 | N15: 0.040000695 | O15: 0.08999942 | P15: 0.075000105 | Q15: 0.074999479 | R15: 0.1611843 | T15: =F15 -> 6298.8611 | U15: =T15*(1+N15) -> 6550.8199 | V15: =U15*(1+O15) -> 7140.3899 | W15: =V15*(1+P15) -> 7675.9199 | X15: =W15*(1+Q15) -> 8251.6099 | Y15: =X15*(1+($R15/2)) -> 8916.6249 | Z15: =Y15*(1+($R15/2)) -> 9635.2349 | AA15: =(U15-T15)/10 -> 25.195882 | AB15: =(V15-U15)/10 -> 58.957 | AC15: =(W15-V15)/10 -> 53.552999 | AD15: =(X15-W15)/10 -> 57.569 | AE15: =(Y15-X15)/10 -> 66.501499 | AF15: =(Z15-Y15)/10 -> 71.860998
A16: VAR_FOut | B16: R_DetH | C16: ref_24nov | D16: HR | F16: 636.08385 | G16: 674.24999 | H16: 836.06999 | I16: 923.85999 | J16: 1020.86 | K16: 1258.04 | L16: 600.07811 | M16: 3.6005737 | N16: 0.060001749 | O16: 0.24 | P16: 0.10500317 | Q16: 0.10499426 | R16: 0.23233352 | T16: =F16 -> 636.08385 | U16: =T16*(1+N16) -> 674.24999 | V16: =U16*(1+O16) -> 836.06999 | W16: =V16*(1+P16) -> 923.85999 | X16: =W16*(1+Q16) -> 1020.86 | Y16: =X16*(1+($R16/2)) -> 1139.45 | Z16: =Y16*(1+($R16/2)) -> 1271.8162 | AA16: =(U16-T16)/10 -> 3.8166144 | AB16: =(V16-U16)/10 -> 16.182 | AC16: =(W16-V16)/10 -> 8.7789998 | AD16: =(X16-W16)/10 -> 9.7000001 | AE16: =(Y16-X16)/10 -> 11.859 | AF16: =(Z16-Y16)/10 -> 13.236621
